<html>
<head>
<title>TestNG:  edgeTest</title>
<link href="../testng.css" rel="stylesheet" type="text/css" />
<link href="../my-testng.css" rel="stylesheet" type="text/css" />

<style type="text/css">
.log { display: none;} 
.stack-trace { display: none;} 
</style>
<script type="text/javascript">
<!--
function flip(e) {
  current = e.style.display;
  if (current == 'block') {
    e.style.display = 'none';
    return 0;
  }
  else {
    e.style.display = 'block';
    return 1;
  }
}

function toggleBox(szDivId, elem, msg1, msg2)
{
  var res = -1;  if (document.getElementById) {
    res = flip(document.getElementById(szDivId));
  }
  else if (document.all) {
    // this is the way old msie versions work
    res = flip(document.all[szDivId]);
  }
  if(elem) {
    if(res == 0) elem.innerHTML = msg1; else elem.innerHTML = msg2;
  }

}

function toggleAllBoxes() {
  if (document.getElementsByTagName) {
    d = document.getElementsByTagName('div');
    for (i = 0; i < d.length; i++) {
      if (d[i].className == 'log') {
        flip(d[i]);
      }
    }
  }
}

// -->
</script>

</head>
<body>
<h2 align='center'>edgeTest</h2><table border='1' align="center">
<tr>
<td>Tests passed/Failed/Skipped:</td><td>0/8/16</td>
</tr><tr>
<td>Started on:</td><td>Tue May 20 18:05:37 EDT 2025</td>
</tr>
<tr><td>Total time:</td><td>5 seconds (5999 ms)</td>
</tr><tr>
<td>Included groups:</td><td>sanity </td>
</tr><tr>
<td>Excluded groups:</td><td></td>
</tr>
</table><p/>
<small><i>(Hover the method name to see the test class name)</i></small><p/>
<table width='100%' border='1' class='invocation-failed'>
<tr><td colspan='4' align='center'><b>FAILED TESTS</b></td></tr>
<tr><td><b>Test method</b></td>
<td><b>Attribute(s)</b></td>
<td width="30%"><b>Exception</b></td>
<td width="10%"><b>Time (seconds)</b></td>
<td><b>Instance</b></td>
</tr>
<tr>
<td title='testCases.TC02_Login.testLogin()'><b>testLogin</b><br>Test class: testCases.TC02_Login<br>Parameters: smitasharma.qa@gmail.com, ss*QA123</td>
<td><div><pre>java.lang.AssertionError: Unexpected exception during login test execution.
	at testCases.TC02_Login.testLogin(TC02_Login.java:69)
	at java.base/java.util.ArrayList.forEach(ArrayList.java:1596)
	at java.base/java.util.concurrent.FutureTask.run(FutureTask.java:317)
	at java.base/java.util.concurrent.ThreadPoolExecutor.runWorker(ThreadPoolExecutor.java:1144)
	at java.base/java.util.concurrent.ThreadPoolExecutor$Worker.run(ThreadPoolExecutor.java:642)
	at java.base/java.lang.Thread.run(Thread.java:1583)
... Removed 16 stack frames</pre></div><a href='#' onClick='toggleBox("stack-trace1537123960", this, "Click to show all stack frames", "Click to hide stack frames")'>Click to show all stack frames</a>
<div class='stack-trace' id='stack-trace1537123960'><pre>java.lang.AssertionError: Unexpected exception during login test execution.
	at org.testng.Assert.fail(Assert.java:111)
	at testCases.TC02_Login.testLogin(TC02_Login.java:69)
	at java.base/jdk.internal.reflect.DirectMethodHandleAccessor.invoke(DirectMethodHandleAccessor.java:103)
	at java.base/java.lang.reflect.Method.invoke(Method.java:580)
	at org.testng.internal.invokers.MethodInvocationHelper.invokeMethod(MethodInvocationHelper.java:141)
	at org.testng.internal.invokers.TestInvoker.invokeMethod(TestInvoker.java:687)
	at org.testng.internal.invokers.TestInvoker.retryFailed(TestInvoker.java:269)
	at org.testng.internal.invokers.MethodRunner.runInSequence(MethodRunner.java:76)
	at org.testng.internal.invokers.TestInvoker$MethodInvocationAgent.invoke(TestInvoker.java:995)
	at org.testng.internal.invokers.TestInvoker.invokeTestMethods(TestInvoker.java:203)
	at org.testng.internal.invokers.TestMethodWorker.invokeTestMethods(TestMethodWorker.java:154)
	at org.testng.internal.invokers.TestMethodWorker.run(TestMethodWorker.java:134)
	at java.base/java.util.ArrayList.forEach(ArrayList.java:1596)
	at org.testng.TestRunner.privateRun(TestRunner.java:741)
	at org.testng.TestRunner.run(TestRunner.java:616)
	at org.testng.SuiteRunner.runTest(SuiteRunner.java:421)
	at org.testng.SuiteRunner$SuiteWorker.run(SuiteRunner.java:463)
	at org.testng.internal.thread.ThreadUtil.lambda$execute$0(ThreadUtil.java:64)
	at java.base/java.util.concurrent.FutureTask.run(FutureTask.java:317)
	at java.base/java.util.concurrent.ThreadPoolExecutor.runWorker(ThreadPoolExecutor.java:1144)
	at java.base/java.util.concurrent.ThreadPoolExecutor$Worker.run(ThreadPoolExecutor.java:642)
	at java.base/java.lang.Thread.run(Thread.java:1583)
</pre></div></td>
<td>0</td>
<td>testCases.TC02_Login@6af9fcb2</td></tr>
<tr>
<td title='testCases.TC02_Login.testLogin()'><b>testLogin</b><br>Test class: testCases.TC02_Login<br>Parameters: nona@yahoo.com, QWER!@#$</td>
<td><div><pre>java.lang.AssertionError: Unexpected exception during login test execution.
	at testCases.TC02_Login.testLogin(TC02_Login.java:69)
	at java.base/java.util.ArrayList.forEach(ArrayList.java:1596)
	at java.base/java.util.concurrent.FutureTask.run(FutureTask.java:317)
	at java.base/java.util.concurrent.ThreadPoolExecutor.runWorker(ThreadPoolExecutor.java:1144)
	at java.base/java.util.concurrent.ThreadPoolExecutor$Worker.run(ThreadPoolExecutor.java:642)
	at java.base/java.lang.Thread.run(Thread.java:1583)
... Removed 16 stack frames</pre></div><a href='#' onClick='toggleBox("stack-trace165740472", this, "Click to show all stack frames", "Click to hide stack frames")'>Click to show all stack frames</a>
<div class='stack-trace' id='stack-trace165740472'><pre>java.lang.AssertionError: Unexpected exception during login test execution.
	at org.testng.Assert.fail(Assert.java:111)
	at testCases.TC02_Login.testLogin(TC02_Login.java:69)
	at java.base/jdk.internal.reflect.DirectMethodHandleAccessor.invoke(DirectMethodHandleAccessor.java:103)
	at java.base/java.lang.reflect.Method.invoke(Method.java:580)
	at org.testng.internal.invokers.MethodInvocationHelper.invokeMethod(MethodInvocationHelper.java:141)
	at org.testng.internal.invokers.TestInvoker.invokeMethod(TestInvoker.java:687)
	at org.testng.internal.invokers.TestInvoker.retryFailed(TestInvoker.java:269)
	at org.testng.internal.invokers.MethodRunner.runInSequence(MethodRunner.java:76)
	at org.testng.internal.invokers.TestInvoker$MethodInvocationAgent.invoke(TestInvoker.java:995)
	at org.testng.internal.invokers.TestInvoker.invokeTestMethods(TestInvoker.java:203)
	at org.testng.internal.invokers.TestMethodWorker.invokeTestMethods(TestMethodWorker.java:154)
	at org.testng.internal.invokers.TestMethodWorker.run(TestMethodWorker.java:134)
	at java.base/java.util.ArrayList.forEach(ArrayList.java:1596)
	at org.testng.TestRunner.privateRun(TestRunner.java:741)
	at org.testng.TestRunner.run(TestRunner.java:616)
	at org.testng.SuiteRunner.runTest(SuiteRunner.java:421)
	at org.testng.SuiteRunner$SuiteWorker.run(SuiteRunner.java:463)
	at org.testng.internal.thread.ThreadUtil.lambda$execute$0(ThreadUtil.java:64)
	at java.base/java.util.concurrent.FutureTask.run(FutureTask.java:317)
	at java.base/java.util.concurrent.ThreadPoolExecutor.runWorker(ThreadPoolExecutor.java:1144)
	at java.base/java.util.concurrent.ThreadPoolExecutor$Worker.run(ThreadPoolExecutor.java:642)
	at java.base/java.lang.Thread.run(Thread.java:1583)
</pre></div></td>
<td>0</td>
<td>testCases.TC02_Login@6af9fcb2</td></tr>
<tr>
<td title='testCases.TC03_AddToCart.testAddToCart()'><b>testAddToCart</b><br>Test class: testCases.TC03_AddToCart</td>
<td><div><pre>java.lang.AssertionError: Test failed due to unexpected exception.
	at testCases.TC03_AddToCart.testAddToCart(TC03_AddToCart.java:55)
	at java.base/java.util.ArrayList.forEach(ArrayList.java:1596)
	at java.base/java.util.concurrent.FutureTask.run(FutureTask.java:317)
	at java.base/java.util.concurrent.ThreadPoolExecutor.runWorker(ThreadPoolExecutor.java:1144)
	at java.base/java.util.concurrent.ThreadPoolExecutor$Worker.run(ThreadPoolExecutor.java:642)
	at java.base/java.lang.Thread.run(Thread.java:1583)
... Removed 16 stack frames</pre></div><a href='#' onClick='toggleBox("stack-trace553907930", this, "Click to show all stack frames", "Click to hide stack frames")'>Click to show all stack frames</a>
<div class='stack-trace' id='stack-trace553907930'><pre>java.lang.AssertionError: Test failed due to unexpected exception.
	at org.testng.Assert.fail(Assert.java:111)
	at testCases.TC03_AddToCart.testAddToCart(TC03_AddToCart.java:55)
	at java.base/jdk.internal.reflect.DirectMethodHandleAccessor.invoke(DirectMethodHandleAccessor.java:103)
	at java.base/java.lang.reflect.Method.invoke(Method.java:580)
	at org.testng.internal.invokers.MethodInvocationHelper.invokeMethod(MethodInvocationHelper.java:141)
	at org.testng.internal.invokers.TestInvoker.invokeMethod(TestInvoker.java:687)
	at org.testng.internal.invokers.TestInvoker.retryFailed(TestInvoker.java:269)
	at org.testng.internal.invokers.MethodRunner.runInSequence(MethodRunner.java:76)
	at org.testng.internal.invokers.TestInvoker$MethodInvocationAgent.invoke(TestInvoker.java:995)
	at org.testng.internal.invokers.TestInvoker.invokeTestMethods(TestInvoker.java:203)
	at org.testng.internal.invokers.TestMethodWorker.invokeTestMethods(TestMethodWorker.java:154)
	at org.testng.internal.invokers.TestMethodWorker.run(TestMethodWorker.java:134)
	at java.base/java.util.ArrayList.forEach(ArrayList.java:1596)
	at org.testng.TestRunner.privateRun(TestRunner.java:741)
	at org.testng.TestRunner.run(TestRunner.java:616)
	at org.testng.SuiteRunner.runTest(SuiteRunner.java:421)
	at org.testng.SuiteRunner$SuiteWorker.run(SuiteRunner.java:463)
	at org.testng.internal.thread.ThreadUtil.lambda$execute$0(ThreadUtil.java:64)
	at java.base/java.util.concurrent.FutureTask.run(FutureTask.java:317)
	at java.base/java.util.concurrent.ThreadPoolExecutor.runWorker(ThreadPoolExecutor.java:1144)
	at java.base/java.util.concurrent.ThreadPoolExecutor$Worker.run(ThreadPoolExecutor.java:642)
	at java.base/java.lang.Thread.run(Thread.java:1583)
</pre></div></td>
<td>0</td>
<td>testCases.TC03_AddToCart@1fc32e4f</td></tr>
<tr>
<td title='testCases.TC04_CompletePurchase.testCompletePurchase()'><b>testCompletePurchase</b><br>Test class: testCases.TC04_CompletePurchase</td>
<td><div><pre>java.lang.AssertionError: Test failed due to unexpected exception.
	at testCases.TC04_CompletePurchase.testCompletePurchase(TC04_CompletePurchase.java:81)
	at java.base/java.util.ArrayList.forEach(ArrayList.java:1596)
	at java.base/java.util.concurrent.FutureTask.run(FutureTask.java:317)
	at java.base/java.util.concurrent.ThreadPoolExecutor.runWorker(ThreadPoolExecutor.java:1144)
	at java.base/java.util.concurrent.ThreadPoolExecutor$Worker.run(ThreadPoolExecutor.java:642)
	at java.base/java.lang.Thread.run(Thread.java:1583)
... Removed 16 stack frames</pre></div><a href='#' onClick='toggleBox("stack-trace1114451015", this, "Click to show all stack frames", "Click to hide stack frames")'>Click to show all stack frames</a>
<div class='stack-trace' id='stack-trace1114451015'><pre>java.lang.AssertionError: Test failed due to unexpected exception.
	at org.testng.Assert.fail(Assert.java:111)
	at testCases.TC04_CompletePurchase.testCompletePurchase(TC04_CompletePurchase.java:81)
	at java.base/jdk.internal.reflect.DirectMethodHandleAccessor.invoke(DirectMethodHandleAccessor.java:103)
	at java.base/java.lang.reflect.Method.invoke(Method.java:580)
	at org.testng.internal.invokers.MethodInvocationHelper.invokeMethod(MethodInvocationHelper.java:141)
	at org.testng.internal.invokers.TestInvoker.invokeMethod(TestInvoker.java:687)
	at org.testng.internal.invokers.TestInvoker.retryFailed(TestInvoker.java:269)
	at org.testng.internal.invokers.MethodRunner.runInSequence(MethodRunner.java:76)
	at org.testng.internal.invokers.TestInvoker$MethodInvocationAgent.invoke(TestInvoker.java:995)
	at org.testng.internal.invokers.TestInvoker.invokeTestMethods(TestInvoker.java:203)
	at org.testng.internal.invokers.TestMethodWorker.invokeTestMethods(TestMethodWorker.java:154)
	at org.testng.internal.invokers.TestMethodWorker.run(TestMethodWorker.java:134)
	at java.base/java.util.ArrayList.forEach(ArrayList.java:1596)
	at org.testng.TestRunner.privateRun(TestRunner.java:741)
	at org.testng.TestRunner.run(TestRunner.java:616)
	at org.testng.SuiteRunner.runTest(SuiteRunner.java:421)
	at org.testng.SuiteRunner$SuiteWorker.run(SuiteRunner.java:463)
	at org.testng.internal.thread.ThreadUtil.lambda$execute$0(ThreadUtil.java:64)
	at java.base/java.util.concurrent.FutureTask.run(FutureTask.java:317)
	at java.base/java.util.concurrent.ThreadPoolExecutor.runWorker(ThreadPoolExecutor.java:1144)
	at java.base/java.util.concurrent.ThreadPoolExecutor$Worker.run(ThreadPoolExecutor.java:642)
	at java.base/java.lang.Thread.run(Thread.java:1583)
</pre></div></td>
<td>0</td>
<td>testCases.TC04_CompletePurchase@6cce16f4</td></tr>
<tr>
<td title='testCases.TC02_Login.testLogin()'><b>testLogin</b><br>Test class: testCases.TC02_Login<br>Parameters: sid@cloudberry.services, Test123</td>
<td><div><pre>java.lang.AssertionError: Unexpected exception during login test execution.
	at testCases.TC02_Login.testLogin(TC02_Login.java:69)
	at java.base/java.util.ArrayList.forEach(ArrayList.java:1596)
	at java.base/java.util.concurrent.FutureTask.run(FutureTask.java:317)
	at java.base/java.util.concurrent.ThreadPoolExecutor.runWorker(ThreadPoolExecutor.java:1144)
	at java.base/java.util.concurrent.ThreadPoolExecutor$Worker.run(ThreadPoolExecutor.java:642)
	at java.base/java.lang.Thread.run(Thread.java:1583)
... Removed 16 stack frames</pre></div><a href='#' onClick='toggleBox("stack-trace1495315421", this, "Click to show all stack frames", "Click to hide stack frames")'>Click to show all stack frames</a>
<div class='stack-trace' id='stack-trace1495315421'><pre>java.lang.AssertionError: Unexpected exception during login test execution.
	at org.testng.Assert.fail(Assert.java:111)
	at testCases.TC02_Login.testLogin(TC02_Login.java:69)
	at java.base/jdk.internal.reflect.DirectMethodHandleAccessor.invoke(DirectMethodHandleAccessor.java:103)
	at java.base/java.lang.reflect.Method.invoke(Method.java:580)
	at org.testng.internal.invokers.MethodInvocationHelper.invokeMethod(MethodInvocationHelper.java:141)
	at org.testng.internal.invokers.TestInvoker.invokeMethod(TestInvoker.java:687)
	at org.testng.internal.invokers.TestInvoker.retryFailed(TestInvoker.java:269)
	at org.testng.internal.invokers.MethodRunner.runInSequence(MethodRunner.java:76)
	at org.testng.internal.invokers.TestInvoker$MethodInvocationAgent.invoke(TestInvoker.java:995)
	at org.testng.internal.invokers.TestInvoker.invokeTestMethods(TestInvoker.java:203)
	at org.testng.internal.invokers.TestMethodWorker.invokeTestMethods(TestMethodWorker.java:154)
	at org.testng.internal.invokers.TestMethodWorker.run(TestMethodWorker.java:134)
	at java.base/java.util.ArrayList.forEach(ArrayList.java:1596)
	at org.testng.TestRunner.privateRun(TestRunner.java:741)
	at org.testng.TestRunner.run(TestRunner.java:616)
	at org.testng.SuiteRunner.runTest(SuiteRunner.java:421)
	at org.testng.SuiteRunner$SuiteWorker.run(SuiteRunner.java:463)
	at org.testng.internal.thread.ThreadUtil.lambda$execute$0(ThreadUtil.java:64)
	at java.base/java.util.concurrent.FutureTask.run(FutureTask.java:317)
	at java.base/java.util.concurrent.ThreadPoolExecutor.runWorker(ThreadPoolExecutor.java:1144)
	at java.base/java.util.concurrent.ThreadPoolExecutor$Worker.run(ThreadPoolExecutor.java:642)
	at java.base/java.lang.Thread.run(Thread.java:1583)
</pre></div></td>
<td>0</td>
<td>testCases.TC02_Login@6af9fcb2</td></tr>
<tr>
<td title='testCases.TC02_Login.testLogin()'><b>testLogin</b><br>Test class: testCases.TC02_Login<br>Parameters: hichamkhachiai@gmail.com, hicham123</td>
<td><div><pre>java.lang.AssertionError: Unexpected exception during login test execution.
	at testCases.TC02_Login.testLogin(TC02_Login.java:69)
	at java.base/java.util.ArrayList.forEach(ArrayList.java:1596)
	at java.base/java.util.concurrent.FutureTask.run(FutureTask.java:317)
	at java.base/java.util.concurrent.ThreadPoolExecutor.runWorker(ThreadPoolExecutor.java:1144)
	at java.base/java.util.concurrent.ThreadPoolExecutor$Worker.run(ThreadPoolExecutor.java:642)
	at java.base/java.lang.Thread.run(Thread.java:1583)
... Removed 16 stack frames</pre></div><a href='#' onClick='toggleBox("stack-trace81521158", this, "Click to show all stack frames", "Click to hide stack frames")'>Click to show all stack frames</a>
<div class='stack-trace' id='stack-trace81521158'><pre>java.lang.AssertionError: Unexpected exception during login test execution.
	at org.testng.Assert.fail(Assert.java:111)
	at testCases.TC02_Login.testLogin(TC02_Login.java:69)
	at java.base/jdk.internal.reflect.DirectMethodHandleAccessor.invoke(DirectMethodHandleAccessor.java:103)
	at java.base/java.lang.reflect.Method.invoke(Method.java:580)
	at org.testng.internal.invokers.MethodInvocationHelper.invokeMethod(MethodInvocationHelper.java:141)
	at org.testng.internal.invokers.TestInvoker.invokeMethod(TestInvoker.java:687)
	at org.testng.internal.invokers.TestInvoker.retryFailed(TestInvoker.java:269)
	at org.testng.internal.invokers.MethodRunner.runInSequence(MethodRunner.java:76)
	at org.testng.internal.invokers.TestInvoker$MethodInvocationAgent.invoke(TestInvoker.java:995)
	at org.testng.internal.invokers.TestInvoker.invokeTestMethods(TestInvoker.java:203)
	at org.testng.internal.invokers.TestMethodWorker.invokeTestMethods(TestMethodWorker.java:154)
	at org.testng.internal.invokers.TestMethodWorker.run(TestMethodWorker.java:134)
	at java.base/java.util.ArrayList.forEach(ArrayList.java:1596)
	at org.testng.TestRunner.privateRun(TestRunner.java:741)
	at org.testng.TestRunner.run(TestRunner.java:616)
	at org.testng.SuiteRunner.runTest(SuiteRunner.java:421)
	at org.testng.SuiteRunner$SuiteWorker.run(SuiteRunner.java:463)
	at org.testng.internal.thread.ThreadUtil.lambda$execute$0(ThreadUtil.java:64)
	at java.base/java.util.concurrent.FutureTask.run(FutureTask.java:317)
	at java.base/java.util.concurrent.ThreadPoolExecutor.runWorker(ThreadPoolExecutor.java:1144)
	at java.base/java.util.concurrent.ThreadPoolExecutor$Worker.run(ThreadPoolExecutor.java:642)
	at java.base/java.lang.Thread.run(Thread.java:1583)
</pre></div></td>
<td>0</td>
<td>testCases.TC02_Login@6af9fcb2</td></tr>
<tr>
<td title='testCases.TC02_Login.testLogin()'><b>testLogin</b><br>Test class: testCases.TC02_Login<br>Parameters: apushedwoman@gmail.com, password123</td>
<td><div><pre>java.lang.AssertionError: Unexpected exception during login test execution.
	at testCases.TC02_Login.testLogin(TC02_Login.java:69)
	at java.base/java.util.ArrayList.forEach(ArrayList.java:1596)
	at java.base/java.util.concurrent.FutureTask.run(FutureTask.java:317)
	at java.base/java.util.concurrent.ThreadPoolExecutor.runWorker(ThreadPoolExecutor.java:1144)
	at java.base/java.util.concurrent.ThreadPoolExecutor$Worker.run(ThreadPoolExecutor.java:642)
	at java.base/java.lang.Thread.run(Thread.java:1583)
... Removed 16 stack frames</pre></div><a href='#' onClick='toggleBox("stack-trace651838308", this, "Click to show all stack frames", "Click to hide stack frames")'>Click to show all stack frames</a>
<div class='stack-trace' id='stack-trace651838308'><pre>java.lang.AssertionError: Unexpected exception during login test execution.
	at org.testng.Assert.fail(Assert.java:111)
	at testCases.TC02_Login.testLogin(TC02_Login.java:69)
	at java.base/jdk.internal.reflect.DirectMethodHandleAccessor.invoke(DirectMethodHandleAccessor.java:103)
	at java.base/java.lang.reflect.Method.invoke(Method.java:580)
	at org.testng.internal.invokers.MethodInvocationHelper.invokeMethod(MethodInvocationHelper.java:141)
	at org.testng.internal.invokers.TestInvoker.invokeMethod(TestInvoker.java:687)
	at org.testng.internal.invokers.TestInvoker.retryFailed(TestInvoker.java:269)
	at org.testng.internal.invokers.MethodRunner.runInSequence(MethodRunner.java:76)
	at org.testng.internal.invokers.TestInvoker$MethodInvocationAgent.invoke(TestInvoker.java:995)
	at org.testng.internal.invokers.TestInvoker.invokeTestMethods(TestInvoker.java:203)
	at org.testng.internal.invokers.TestMethodWorker.invokeTestMethods(TestMethodWorker.java:154)
	at org.testng.internal.invokers.TestMethodWorker.run(TestMethodWorker.java:134)
	at java.base/java.util.ArrayList.forEach(ArrayList.java:1596)
	at org.testng.TestRunner.privateRun(TestRunner.java:741)
	at org.testng.TestRunner.run(TestRunner.java:616)
	at org.testng.SuiteRunner.runTest(SuiteRunner.java:421)
	at org.testng.SuiteRunner$SuiteWorker.run(SuiteRunner.java:463)
	at org.testng.internal.thread.ThreadUtil.lambda$execute$0(ThreadUtil.java:64)
	at java.base/java.util.concurrent.FutureTask.run(FutureTask.java:317)
	at java.base/java.util.concurrent.ThreadPoolExecutor.runWorker(ThreadPoolExecutor.java:1144)
	at java.base/java.util.concurrent.ThreadPoolExecutor$Worker.run(ThreadPoolExecutor.java:642)
	at java.base/java.lang.Thread.run(Thread.java:1583)
</pre></div></td>
<td>0</td>
<td>testCases.TC02_Login@6af9fcb2</td></tr>
<tr>
<td title='testCases.TC01_LaunchApplication.testLaunchApplication()'><b>testLaunchApplication</b><br>Test class: testCases.TC01_LaunchApplication</td>
<td><div><pre>java.lang.AssertionError: Test failed due to unexpected exception
	at testCases.TC01_LaunchApplication.testLaunchApplication(TC01_LaunchApplication.java:35)
	at java.base/java.util.ArrayList.forEach(ArrayList.java:1596)
	at java.base/java.util.concurrent.FutureTask.run(FutureTask.java:317)
	at java.base/java.util.concurrent.ThreadPoolExecutor.runWorker(ThreadPoolExecutor.java:1144)
	at java.base/java.util.concurrent.ThreadPoolExecutor$Worker.run(ThreadPoolExecutor.java:642)
	at java.base/java.lang.Thread.run(Thread.java:1583)
... Removed 16 stack frames</pre></div><a href='#' onClick='toggleBox("stack-trace1076861248", this, "Click to show all stack frames", "Click to hide stack frames")'>Click to show all stack frames</a>
<div class='stack-trace' id='stack-trace1076861248'><pre>java.lang.AssertionError: Test failed due to unexpected exception
	at org.testng.Assert.fail(Assert.java:111)
	at testCases.TC01_LaunchApplication.testLaunchApplication(TC01_LaunchApplication.java:35)
	at java.base/jdk.internal.reflect.DirectMethodHandleAccessor.invoke(DirectMethodHandleAccessor.java:103)
	at java.base/java.lang.reflect.Method.invoke(Method.java:580)
	at org.testng.internal.invokers.MethodInvocationHelper.invokeMethod(MethodInvocationHelper.java:141)
	at org.testng.internal.invokers.TestInvoker.invokeMethod(TestInvoker.java:687)
	at org.testng.internal.invokers.TestInvoker.retryFailed(TestInvoker.java:269)
	at org.testng.internal.invokers.MethodRunner.runInSequence(MethodRunner.java:76)
	at org.testng.internal.invokers.TestInvoker$MethodInvocationAgent.invoke(TestInvoker.java:995)
	at org.testng.internal.invokers.TestInvoker.invokeTestMethods(TestInvoker.java:203)
	at org.testng.internal.invokers.TestMethodWorker.invokeTestMethods(TestMethodWorker.java:154)
	at org.testng.internal.invokers.TestMethodWorker.run(TestMethodWorker.java:134)
	at java.base/java.util.ArrayList.forEach(ArrayList.java:1596)
	at org.testng.TestRunner.privateRun(TestRunner.java:741)
	at org.testng.TestRunner.run(TestRunner.java:616)
	at org.testng.SuiteRunner.runTest(SuiteRunner.java:421)
	at org.testng.SuiteRunner$SuiteWorker.run(SuiteRunner.java:463)
	at org.testng.internal.thread.ThreadUtil.lambda$execute$0(ThreadUtil.java:64)
	at java.base/java.util.concurrent.FutureTask.run(FutureTask.java:317)
	at java.base/java.util.concurrent.ThreadPoolExecutor.runWorker(ThreadPoolExecutor.java:1144)
	at java.base/java.util.concurrent.ThreadPoolExecutor$Worker.run(ThreadPoolExecutor.java:642)
	at java.base/java.lang.Thread.run(Thread.java:1583)
</pre></div></td>
<td>0</td>
<td>testCases.TC01_LaunchApplication@4716be8b</td></tr>
</table><p>
<table width='100%' border='1' class='invocation-skipped'>
<tr><td colspan='4' align='center'><b>SKIPPED TESTS</b></td></tr>
<tr><td><b>Test method</b></td>
<td><b>Attribute(s)</b></td>
<td width="30%"><b>Exception</b></td>
<td width="10%"><b>Time (seconds)</b></td>
<td><b>Instance</b></td>
</tr>
<tr>
<td title='testCases.TC02_Login.testLogin()'><b>testLogin</b><br>Test class: testCases.TC02_Login<br>Parameters: nona@yahoo.com, QWER!@#$</td>
<td><div><pre>java.lang.AssertionError: Unexpected exception during login test execution.
	at testCases.TC02_Login.testLogin(TC02_Login.java:69)
	at java.base/java.util.ArrayList.forEach(ArrayList.java:1596)
	at java.base/java.util.concurrent.FutureTask.run(FutureTask.java:317)
	at java.base/java.util.concurrent.ThreadPoolExecutor.runWorker(ThreadPoolExecutor.java:1144)
	at java.base/java.util.concurrent.ThreadPoolExecutor$Worker.run(ThreadPoolExecutor.java:642)
	at java.base/java.lang.Thread.run(Thread.java:1583)
... Removed 16 stack frames</pre></div><a href='#' onClick='toggleBox("stack-trace52409977", this, "Click to show all stack frames", "Click to hide stack frames")'>Click to show all stack frames</a>
<div class='stack-trace' id='stack-trace52409977'><pre>java.lang.AssertionError: Unexpected exception during login test execution.
	at org.testng.Assert.fail(Assert.java:111)
	at testCases.TC02_Login.testLogin(TC02_Login.java:69)
	at java.base/jdk.internal.reflect.DirectMethodHandleAccessor.invoke(DirectMethodHandleAccessor.java:103)
	at java.base/java.lang.reflect.Method.invoke(Method.java:580)
	at org.testng.internal.invokers.MethodInvocationHelper.invokeMethod(MethodInvocationHelper.java:141)
	at org.testng.internal.invokers.TestInvoker.invokeMethod(TestInvoker.java:687)
	at org.testng.internal.invokers.TestInvoker.retryFailed(TestInvoker.java:269)
	at org.testng.internal.invokers.MethodRunner.runInSequence(MethodRunner.java:76)
	at org.testng.internal.invokers.TestInvoker$MethodInvocationAgent.invoke(TestInvoker.java:995)
	at org.testng.internal.invokers.TestInvoker.invokeTestMethods(TestInvoker.java:203)
	at org.testng.internal.invokers.TestMethodWorker.invokeTestMethods(TestMethodWorker.java:154)
	at org.testng.internal.invokers.TestMethodWorker.run(TestMethodWorker.java:134)
	at java.base/java.util.ArrayList.forEach(ArrayList.java:1596)
	at org.testng.TestRunner.privateRun(TestRunner.java:741)
	at org.testng.TestRunner.run(TestRunner.java:616)
	at org.testng.SuiteRunner.runTest(SuiteRunner.java:421)
	at org.testng.SuiteRunner$SuiteWorker.run(SuiteRunner.java:463)
	at org.testng.internal.thread.ThreadUtil.lambda$execute$0(ThreadUtil.java:64)
	at java.base/java.util.concurrent.FutureTask.run(FutureTask.java:317)
	at java.base/java.util.concurrent.ThreadPoolExecutor.runWorker(ThreadPoolExecutor.java:1144)
	at java.base/java.util.concurrent.ThreadPoolExecutor$Worker.run(ThreadPoolExecutor.java:642)
	at java.base/java.lang.Thread.run(Thread.java:1583)
</pre></div></td>
<td>0</td>
<td>testCases.TC02_Login@6af9fcb2</td></tr>
<tr>
<td title='testCases.TC02_Login.testLogin()'><b>testLogin</b><br>Test class: testCases.TC02_Login<br>Parameters: hichamkhachiai@gmail.com, hicham123</td>
<td><div><pre>java.lang.AssertionError: Unexpected exception during login test execution.
	at testCases.TC02_Login.testLogin(TC02_Login.java:69)
	at java.base/java.util.ArrayList.forEach(ArrayList.java:1596)
	at java.base/java.util.concurrent.FutureTask.run(FutureTask.java:317)
	at java.base/java.util.concurrent.ThreadPoolExecutor.runWorker(ThreadPoolExecutor.java:1144)
	at java.base/java.util.concurrent.ThreadPoolExecutor$Worker.run(ThreadPoolExecutor.java:642)
	at java.base/java.lang.Thread.run(Thread.java:1583)
... Removed 16 stack frames</pre></div><a href='#' onClick='toggleBox("stack-trace1336159052", this, "Click to show all stack frames", "Click to hide stack frames")'>Click to show all stack frames</a>
<div class='stack-trace' id='stack-trace1336159052'><pre>java.lang.AssertionError: Unexpected exception during login test execution.
	at org.testng.Assert.fail(Assert.java:111)
	at testCases.TC02_Login.testLogin(TC02_Login.java:69)
	at java.base/jdk.internal.reflect.DirectMethodHandleAccessor.invoke(DirectMethodHandleAccessor.java:103)
	at java.base/java.lang.reflect.Method.invoke(Method.java:580)
	at org.testng.internal.invokers.MethodInvocationHelper.invokeMethod(MethodInvocationHelper.java:141)
	at org.testng.internal.invokers.TestInvoker.invokeMethod(TestInvoker.java:687)
	at org.testng.internal.invokers.TestInvoker.retryFailed(TestInvoker.java:269)
	at org.testng.internal.invokers.MethodRunner.runInSequence(MethodRunner.java:76)
	at org.testng.internal.invokers.TestInvoker$MethodInvocationAgent.invoke(TestInvoker.java:995)
	at org.testng.internal.invokers.TestInvoker.invokeTestMethods(TestInvoker.java:203)
	at org.testng.internal.invokers.TestMethodWorker.invokeTestMethods(TestMethodWorker.java:154)
	at org.testng.internal.invokers.TestMethodWorker.run(TestMethodWorker.java:134)
	at java.base/java.util.ArrayList.forEach(ArrayList.java:1596)
	at org.testng.TestRunner.privateRun(TestRunner.java:741)
	at org.testng.TestRunner.run(TestRunner.java:616)
	at org.testng.SuiteRunner.runTest(SuiteRunner.java:421)
	at org.testng.SuiteRunner$SuiteWorker.run(SuiteRunner.java:463)
	at org.testng.internal.thread.ThreadUtil.lambda$execute$0(ThreadUtil.java:64)
	at java.base/java.util.concurrent.FutureTask.run(FutureTask.java:317)
	at java.base/java.util.concurrent.ThreadPoolExecutor.runWorker(ThreadPoolExecutor.java:1144)
	at java.base/java.util.concurrent.ThreadPoolExecutor$Worker.run(ThreadPoolExecutor.java:642)
	at java.base/java.lang.Thread.run(Thread.java:1583)
</pre></div></td>
<td>0</td>
<td>testCases.TC02_Login@6af9fcb2</td></tr>
<tr>
<td title='testCases.TC01_LaunchApplication.testLaunchApplication()'><b>testLaunchApplication</b><br>Test class: testCases.TC01_LaunchApplication</td>
<td><div><pre>java.lang.AssertionError: Test failed due to unexpected exception
	at testCases.TC01_LaunchApplication.testLaunchApplication(TC01_LaunchApplication.java:35)
	at java.base/java.util.ArrayList.forEach(ArrayList.java:1596)
	at java.base/java.util.concurrent.FutureTask.run(FutureTask.java:317)
	at java.base/java.util.concurrent.ThreadPoolExecutor.runWorker(ThreadPoolExecutor.java:1144)
	at java.base/java.util.concurrent.ThreadPoolExecutor$Worker.run(ThreadPoolExecutor.java:642)
	at java.base/java.lang.Thread.run(Thread.java:1583)
... Removed 16 stack frames</pre></div><a href='#' onClick='toggleBox("stack-trace1457673449", this, "Click to show all stack frames", "Click to hide stack frames")'>Click to show all stack frames</a>
<div class='stack-trace' id='stack-trace1457673449'><pre>java.lang.AssertionError: Test failed due to unexpected exception
	at org.testng.Assert.fail(Assert.java:111)
	at testCases.TC01_LaunchApplication.testLaunchApplication(TC01_LaunchApplication.java:35)
	at java.base/jdk.internal.reflect.DirectMethodHandleAccessor.invoke(DirectMethodHandleAccessor.java:103)
	at java.base/java.lang.reflect.Method.invoke(Method.java:580)
	at org.testng.internal.invokers.MethodInvocationHelper.invokeMethod(MethodInvocationHelper.java:141)
	at org.testng.internal.invokers.TestInvoker.invokeMethod(TestInvoker.java:687)
	at org.testng.internal.invokers.TestInvoker.retryFailed(TestInvoker.java:269)
	at org.testng.internal.invokers.MethodRunner.runInSequence(MethodRunner.java:76)
	at org.testng.internal.invokers.TestInvoker$MethodInvocationAgent.invoke(TestInvoker.java:995)
	at org.testng.internal.invokers.TestInvoker.invokeTestMethods(TestInvoker.java:203)
	at org.testng.internal.invokers.TestMethodWorker.invokeTestMethods(TestMethodWorker.java:154)
	at org.testng.internal.invokers.TestMethodWorker.run(TestMethodWorker.java:134)
	at java.base/java.util.ArrayList.forEach(ArrayList.java:1596)
	at org.testng.TestRunner.privateRun(TestRunner.java:741)
	at org.testng.TestRunner.run(TestRunner.java:616)
	at org.testng.SuiteRunner.runTest(SuiteRunner.java:421)
	at org.testng.SuiteRunner$SuiteWorker.run(SuiteRunner.java:463)
	at org.testng.internal.thread.ThreadUtil.lambda$execute$0(ThreadUtil.java:64)
	at java.base/java.util.concurrent.FutureTask.run(FutureTask.java:317)
	at java.base/java.util.concurrent.ThreadPoolExecutor.runWorker(ThreadPoolExecutor.java:1144)
	at java.base/java.util.concurrent.ThreadPoolExecutor$Worker.run(ThreadPoolExecutor.java:642)
	at java.base/java.lang.Thread.run(Thread.java:1583)
</pre></div></td>
<td>0</td>
<td>testCases.TC01_LaunchApplication@4716be8b</td></tr>
<tr>
<td title='testCases.TC04_CompletePurchase.testCompletePurchase()'><b>testCompletePurchase</b><br>Test class: testCases.TC04_CompletePurchase</td>
<td><div><pre>java.lang.AssertionError: Test failed due to unexpected exception.
	at testCases.TC04_CompletePurchase.testCompletePurchase(TC04_CompletePurchase.java:81)
	at java.base/java.util.ArrayList.forEach(ArrayList.java:1596)
	at java.base/java.util.concurrent.FutureTask.run(FutureTask.java:317)
	at java.base/java.util.concurrent.ThreadPoolExecutor.runWorker(ThreadPoolExecutor.java:1144)
	at java.base/java.util.concurrent.ThreadPoolExecutor$Worker.run(ThreadPoolExecutor.java:642)
	at java.base/java.lang.Thread.run(Thread.java:1583)
... Removed 16 stack frames</pre></div><a href='#' onClick='toggleBox("stack-trace246097831", this, "Click to show all stack frames", "Click to hide stack frames")'>Click to show all stack frames</a>
<div class='stack-trace' id='stack-trace246097831'><pre>java.lang.AssertionError: Test failed due to unexpected exception.
	at org.testng.Assert.fail(Assert.java:111)
	at testCases.TC04_CompletePurchase.testCompletePurchase(TC04_CompletePurchase.java:81)
	at java.base/jdk.internal.reflect.DirectMethodHandleAccessor.invoke(DirectMethodHandleAccessor.java:103)
	at java.base/java.lang.reflect.Method.invoke(Method.java:580)
	at org.testng.internal.invokers.MethodInvocationHelper.invokeMethod(MethodInvocationHelper.java:141)
	at org.testng.internal.invokers.TestInvoker.invokeMethod(TestInvoker.java:687)
	at org.testng.internal.invokers.TestInvoker.retryFailed(TestInvoker.java:269)
	at org.testng.internal.invokers.MethodRunner.runInSequence(MethodRunner.java:76)
	at org.testng.internal.invokers.TestInvoker$MethodInvocationAgent.invoke(TestInvoker.java:995)
	at org.testng.internal.invokers.TestInvoker.invokeTestMethods(TestInvoker.java:203)
	at org.testng.internal.invokers.TestMethodWorker.invokeTestMethods(TestMethodWorker.java:154)
	at org.testng.internal.invokers.TestMethodWorker.run(TestMethodWorker.java:134)
	at java.base/java.util.ArrayList.forEach(ArrayList.java:1596)
	at org.testng.TestRunner.privateRun(TestRunner.java:741)
	at org.testng.TestRunner.run(TestRunner.java:616)
	at org.testng.SuiteRunner.runTest(SuiteRunner.java:421)
	at org.testng.SuiteRunner$SuiteWorker.run(SuiteRunner.java:463)
	at org.testng.internal.thread.ThreadUtil.lambda$execute$0(ThreadUtil.java:64)
	at java.base/java.util.concurrent.FutureTask.run(FutureTask.java:317)
	at java.base/java.util.concurrent.ThreadPoolExecutor.runWorker(ThreadPoolExecutor.java:1144)
	at java.base/java.util.concurrent.ThreadPoolExecutor$Worker.run(ThreadPoolExecutor.java:642)
	at java.base/java.lang.Thread.run(Thread.java:1583)
</pre></div></td>
<td>0</td>
<td>testCases.TC04_CompletePurchase@6cce16f4</td></tr>
<tr>
<td title='testCases.TC03_AddToCart.testAddToCart()'><b>testAddToCart</b><br>Test class: testCases.TC03_AddToCart</td>
<td><div><pre>java.lang.AssertionError: Test failed due to unexpected exception.
	at testCases.TC03_AddToCart.testAddToCart(TC03_AddToCart.java:55)
	at java.base/java.util.ArrayList.forEach(ArrayList.java:1596)
	at java.base/java.util.concurrent.FutureTask.run(FutureTask.java:317)
	at java.base/java.util.concurrent.ThreadPoolExecutor.runWorker(ThreadPoolExecutor.java:1144)
	at java.base/java.util.concurrent.ThreadPoolExecutor$Worker.run(ThreadPoolExecutor.java:642)
	at java.base/java.lang.Thread.run(Thread.java:1583)
... Removed 16 stack frames</pre></div><a href='#' onClick='toggleBox("stack-trace918788109", this, "Click to show all stack frames", "Click to hide stack frames")'>Click to show all stack frames</a>
<div class='stack-trace' id='stack-trace918788109'><pre>java.lang.AssertionError: Test failed due to unexpected exception.
	at org.testng.Assert.fail(Assert.java:111)
	at testCases.TC03_AddToCart.testAddToCart(TC03_AddToCart.java:55)
	at java.base/jdk.internal.reflect.DirectMethodHandleAccessor.invoke(DirectMethodHandleAccessor.java:103)
	at java.base/java.lang.reflect.Method.invoke(Method.java:580)
	at org.testng.internal.invokers.MethodInvocationHelper.invokeMethod(MethodInvocationHelper.java:141)
	at org.testng.internal.invokers.TestInvoker.invokeMethod(TestInvoker.java:687)
	at org.testng.internal.invokers.TestInvoker.retryFailed(TestInvoker.java:269)
	at org.testng.internal.invokers.MethodRunner.runInSequence(MethodRunner.java:76)
	at org.testng.internal.invokers.TestInvoker$MethodInvocationAgent.invoke(TestInvoker.java:995)
	at org.testng.internal.invokers.TestInvoker.invokeTestMethods(TestInvoker.java:203)
	at org.testng.internal.invokers.TestMethodWorker.invokeTestMethods(TestMethodWorker.java:154)
	at org.testng.internal.invokers.TestMethodWorker.run(TestMethodWorker.java:134)
	at java.base/java.util.ArrayList.forEach(ArrayList.java:1596)
	at org.testng.TestRunner.privateRun(TestRunner.java:741)
	at org.testng.TestRunner.run(TestRunner.java:616)
	at org.testng.SuiteRunner.runTest(SuiteRunner.java:421)
	at org.testng.SuiteRunner$SuiteWorker.run(SuiteRunner.java:463)
	at org.testng.internal.thread.ThreadUtil.lambda$execute$0(ThreadUtil.java:64)
	at java.base/java.util.concurrent.FutureTask.run(FutureTask.java:317)
	at java.base/java.util.concurrent.ThreadPoolExecutor.runWorker(ThreadPoolExecutor.java:1144)
	at java.base/java.util.concurrent.ThreadPoolExecutor$Worker.run(ThreadPoolExecutor.java:642)
	at java.base/java.lang.Thread.run(Thread.java:1583)
</pre></div></td>
<td>0</td>
<td>testCases.TC03_AddToCart@1fc32e4f</td></tr>
<tr>
<td title='testCases.TC02_Login.testLogin()'><b>testLogin</b><br>Test class: testCases.TC02_Login<br>Parameters: smitasharma.qa@gmail.com, ss*QA123</td>
<td><div><pre>java.lang.AssertionError: Unexpected exception during login test execution.
	at testCases.TC02_Login.testLogin(TC02_Login.java:69)
	at java.base/java.util.ArrayList.forEach(ArrayList.java:1596)
	at java.base/java.util.concurrent.FutureTask.run(FutureTask.java:317)
	at java.base/java.util.concurrent.ThreadPoolExecutor.runWorker(ThreadPoolExecutor.java:1144)
	at java.base/java.util.concurrent.ThreadPoolExecutor$Worker.run(ThreadPoolExecutor.java:642)
	at java.base/java.lang.Thread.run(Thread.java:1583)
... Removed 16 stack frames</pre></div><a href='#' onClick='toggleBox("stack-trace2084463825", this, "Click to show all stack frames", "Click to hide stack frames")'>Click to show all stack frames</a>
<div class='stack-trace' id='stack-trace2084463825'><pre>java.lang.AssertionError: Unexpected exception during login test execution.
	at org.testng.Assert.fail(Assert.java:111)
	at testCases.TC02_Login.testLogin(TC02_Login.java:69)
	at java.base/jdk.internal.reflect.DirectMethodHandleAccessor.invoke(DirectMethodHandleAccessor.java:103)
	at java.base/java.lang.reflect.Method.invoke(Method.java:580)
	at org.testng.internal.invokers.MethodInvocationHelper.invokeMethod(MethodInvocationHelper.java:141)
	at org.testng.internal.invokers.TestInvoker.invokeMethod(TestInvoker.java:687)
	at org.testng.internal.invokers.TestInvoker.retryFailed(TestInvoker.java:269)
	at org.testng.internal.invokers.MethodRunner.runInSequence(MethodRunner.java:76)
	at org.testng.internal.invokers.TestInvoker$MethodInvocationAgent.invoke(TestInvoker.java:995)
	at org.testng.internal.invokers.TestInvoker.invokeTestMethods(TestInvoker.java:203)
	at org.testng.internal.invokers.TestMethodWorker.invokeTestMethods(TestMethodWorker.java:154)
	at org.testng.internal.invokers.TestMethodWorker.run(TestMethodWorker.java:134)
	at java.base/java.util.ArrayList.forEach(ArrayList.java:1596)
	at org.testng.TestRunner.privateRun(TestRunner.java:741)
	at org.testng.TestRunner.run(TestRunner.java:616)
	at org.testng.SuiteRunner.runTest(SuiteRunner.java:421)
	at org.testng.SuiteRunner$SuiteWorker.run(SuiteRunner.java:463)
	at org.testng.internal.thread.ThreadUtil.lambda$execute$0(ThreadUtil.java:64)
	at java.base/java.util.concurrent.FutureTask.run(FutureTask.java:317)
	at java.base/java.util.concurrent.ThreadPoolExecutor.runWorker(ThreadPoolExecutor.java:1144)
	at java.base/java.util.concurrent.ThreadPoolExecutor$Worker.run(ThreadPoolExecutor.java:642)
	at java.base/java.lang.Thread.run(Thread.java:1583)
</pre></div></td>
<td>0</td>
<td>testCases.TC02_Login@6af9fcb2</td></tr>
<tr>
<td title='testCases.TC02_Login.testLogin()'><b>testLogin</b><br>Test class: testCases.TC02_Login<br>Parameters: smitasharma.qa@gmail.com, ss*QA123</td>
<td><div><pre>java.lang.AssertionError: Unexpected exception during login test execution.
	at testCases.TC02_Login.testLogin(TC02_Login.java:69)
	at java.base/java.util.ArrayList.forEach(ArrayList.java:1596)
	at java.base/java.util.concurrent.FutureTask.run(FutureTask.java:317)
	at java.base/java.util.concurrent.ThreadPoolExecutor.runWorker(ThreadPoolExecutor.java:1144)
	at java.base/java.util.concurrent.ThreadPoolExecutor$Worker.run(ThreadPoolExecutor.java:642)
	at java.base/java.lang.Thread.run(Thread.java:1583)
... Removed 16 stack frames</pre></div><a href='#' onClick='toggleBox("stack-trace1706029307", this, "Click to show all stack frames", "Click to hide stack frames")'>Click to show all stack frames</a>
<div class='stack-trace' id='stack-trace1706029307'><pre>java.lang.AssertionError: Unexpected exception during login test execution.
	at org.testng.Assert.fail(Assert.java:111)
	at testCases.TC02_Login.testLogin(TC02_Login.java:69)
	at java.base/jdk.internal.reflect.DirectMethodHandleAccessor.invoke(DirectMethodHandleAccessor.java:103)
	at java.base/java.lang.reflect.Method.invoke(Method.java:580)
	at org.testng.internal.invokers.MethodInvocationHelper.invokeMethod(MethodInvocationHelper.java:141)
	at org.testng.internal.invokers.TestInvoker.invokeMethod(TestInvoker.java:687)
	at org.testng.internal.invokers.TestInvoker.invokeTestMethod(TestInvoker.java:230)
	at org.testng.internal.invokers.MethodRunner.runInSequence(MethodRunner.java:63)
	at org.testng.internal.invokers.TestInvoker$MethodInvocationAgent.invoke(TestInvoker.java:995)
	at org.testng.internal.invokers.TestInvoker.invokeTestMethods(TestInvoker.java:203)
	at org.testng.internal.invokers.TestMethodWorker.invokeTestMethods(TestMethodWorker.java:154)
	at org.testng.internal.invokers.TestMethodWorker.run(TestMethodWorker.java:134)
	at java.base/java.util.ArrayList.forEach(ArrayList.java:1596)
	at org.testng.TestRunner.privateRun(TestRunner.java:741)
	at org.testng.TestRunner.run(TestRunner.java:616)
	at org.testng.SuiteRunner.runTest(SuiteRunner.java:421)
	at org.testng.SuiteRunner$SuiteWorker.run(SuiteRunner.java:463)
	at org.testng.internal.thread.ThreadUtil.lambda$execute$0(ThreadUtil.java:64)
	at java.base/java.util.concurrent.FutureTask.run(FutureTask.java:317)
	at java.base/java.util.concurrent.ThreadPoolExecutor.runWorker(ThreadPoolExecutor.java:1144)
	at java.base/java.util.concurrent.ThreadPoolExecutor$Worker.run(ThreadPoolExecutor.java:642)
	at java.base/java.lang.Thread.run(Thread.java:1583)
</pre></div></td>
<td>0</td>
<td>testCases.TC02_Login@6af9fcb2</td></tr>
<tr>
<td title='testCases.TC02_Login.testLogin()'><b>testLogin</b><br>Test class: testCases.TC02_Login<br>Parameters: sid@cloudberry.services, Test123</td>
<td><div><pre>java.lang.AssertionError: Unexpected exception during login test execution.
	at testCases.TC02_Login.testLogin(TC02_Login.java:69)
	at java.base/java.util.ArrayList.forEach(ArrayList.java:1596)
	at java.base/java.util.concurrent.FutureTask.run(FutureTask.java:317)
	at java.base/java.util.concurrent.ThreadPoolExecutor.runWorker(ThreadPoolExecutor.java:1144)
	at java.base/java.util.concurrent.ThreadPoolExecutor$Worker.run(ThreadPoolExecutor.java:642)
	at java.base/java.lang.Thread.run(Thread.java:1583)
... Removed 16 stack frames</pre></div><a href='#' onClick='toggleBox("stack-trace398350155", this, "Click to show all stack frames", "Click to hide stack frames")'>Click to show all stack frames</a>
<div class='stack-trace' id='stack-trace398350155'><pre>java.lang.AssertionError: Unexpected exception during login test execution.
	at org.testng.Assert.fail(Assert.java:111)
	at testCases.TC02_Login.testLogin(TC02_Login.java:69)
	at java.base/jdk.internal.reflect.DirectMethodHandleAccessor.invoke(DirectMethodHandleAccessor.java:103)
	at java.base/java.lang.reflect.Method.invoke(Method.java:580)
	at org.testng.internal.invokers.MethodInvocationHelper.invokeMethod(MethodInvocationHelper.java:141)
	at org.testng.internal.invokers.TestInvoker.invokeMethod(TestInvoker.java:687)
	at org.testng.internal.invokers.TestInvoker.invokeTestMethod(TestInvoker.java:230)
	at org.testng.internal.invokers.MethodRunner.runInSequence(MethodRunner.java:63)
	at org.testng.internal.invokers.TestInvoker$MethodInvocationAgent.invoke(TestInvoker.java:995)
	at org.testng.internal.invokers.TestInvoker.invokeTestMethods(TestInvoker.java:203)
	at org.testng.internal.invokers.TestMethodWorker.invokeTestMethods(TestMethodWorker.java:154)
	at org.testng.internal.invokers.TestMethodWorker.run(TestMethodWorker.java:134)
	at java.base/java.util.ArrayList.forEach(ArrayList.java:1596)
	at org.testng.TestRunner.privateRun(TestRunner.java:741)
	at org.testng.TestRunner.run(TestRunner.java:616)
	at org.testng.SuiteRunner.runTest(SuiteRunner.java:421)
	at org.testng.SuiteRunner$SuiteWorker.run(SuiteRunner.java:463)
	at org.testng.internal.thread.ThreadUtil.lambda$execute$0(ThreadUtil.java:64)
	at java.base/java.util.concurrent.FutureTask.run(FutureTask.java:317)
	at java.base/java.util.concurrent.ThreadPoolExecutor.runWorker(ThreadPoolExecutor.java:1144)
	at java.base/java.util.concurrent.ThreadPoolExecutor$Worker.run(ThreadPoolExecutor.java:642)
	at java.base/java.lang.Thread.run(Thread.java:1583)
</pre></div></td>
<td>0</td>
<td>testCases.TC02_Login@6af9fcb2</td></tr>
<tr>
<td title='testCases.TC04_CompletePurchase.testCompletePurchase()'><b>testCompletePurchase</b><br>Test class: testCases.TC04_CompletePurchase</td>
<td><div><pre>java.lang.AssertionError: Test failed due to unexpected exception.
	at testCases.TC04_CompletePurchase.testCompletePurchase(TC04_CompletePurchase.java:81)
	at java.base/java.util.ArrayList.forEach(ArrayList.java:1596)
	at java.base/java.util.concurrent.FutureTask.run(FutureTask.java:317)
	at java.base/java.util.concurrent.ThreadPoolExecutor.runWorker(ThreadPoolExecutor.java:1144)
	at java.base/java.util.concurrent.ThreadPoolExecutor$Worker.run(ThreadPoolExecutor.java:642)
	at java.base/java.lang.Thread.run(Thread.java:1583)
... Removed 16 stack frames</pre></div><a href='#' onClick='toggleBox("stack-trace1654471595", this, "Click to show all stack frames", "Click to hide stack frames")'>Click to show all stack frames</a>
<div class='stack-trace' id='stack-trace1654471595'><pre>java.lang.AssertionError: Test failed due to unexpected exception.
	at org.testng.Assert.fail(Assert.java:111)
	at testCases.TC04_CompletePurchase.testCompletePurchase(TC04_CompletePurchase.java:81)
	at java.base/jdk.internal.reflect.DirectMethodHandleAccessor.invoke(DirectMethodHandleAccessor.java:103)
	at java.base/java.lang.reflect.Method.invoke(Method.java:580)
	at org.testng.internal.invokers.MethodInvocationHelper.invokeMethod(MethodInvocationHelper.java:141)
	at org.testng.internal.invokers.TestInvoker.invokeMethod(TestInvoker.java:687)
	at org.testng.internal.invokers.TestInvoker.invokeTestMethod(TestInvoker.java:230)
	at org.testng.internal.invokers.MethodRunner.runInSequence(MethodRunner.java:63)
	at org.testng.internal.invokers.TestInvoker$MethodInvocationAgent.invoke(TestInvoker.java:995)
	at org.testng.internal.invokers.TestInvoker.invokeTestMethods(TestInvoker.java:203)
	at org.testng.internal.invokers.TestMethodWorker.invokeTestMethods(TestMethodWorker.java:154)
	at org.testng.internal.invokers.TestMethodWorker.run(TestMethodWorker.java:134)
	at java.base/java.util.ArrayList.forEach(ArrayList.java:1596)
	at org.testng.TestRunner.privateRun(TestRunner.java:741)
	at org.testng.TestRunner.run(TestRunner.java:616)
	at org.testng.SuiteRunner.runTest(SuiteRunner.java:421)
	at org.testng.SuiteRunner$SuiteWorker.run(SuiteRunner.java:463)
	at org.testng.internal.thread.ThreadUtil.lambda$execute$0(ThreadUtil.java:64)
	at java.base/java.util.concurrent.FutureTask.run(FutureTask.java:317)
	at java.base/java.util.concurrent.ThreadPoolExecutor.runWorker(ThreadPoolExecutor.java:1144)
	at java.base/java.util.concurrent.ThreadPoolExecutor$Worker.run(ThreadPoolExecutor.java:642)
	at java.base/java.lang.Thread.run(Thread.java:1583)
</pre></div></td>
<td>0</td>
<td>testCases.TC04_CompletePurchase@6cce16f4</td></tr>
<tr>
<td title='testCases.TC02_Login.testLogin()'><b>testLogin</b><br>Test class: testCases.TC02_Login<br>Parameters: sid@cloudberry.services, Test123</td>
<td><div><pre>java.lang.AssertionError: Unexpected exception during login test execution.
	at testCases.TC02_Login.testLogin(TC02_Login.java:69)
	at java.base/java.util.ArrayList.forEach(ArrayList.java:1596)
	at java.base/java.util.concurrent.FutureTask.run(FutureTask.java:317)
	at java.base/java.util.concurrent.ThreadPoolExecutor.runWorker(ThreadPoolExecutor.java:1144)
	at java.base/java.util.concurrent.ThreadPoolExecutor$Worker.run(ThreadPoolExecutor.java:642)
	at java.base/java.lang.Thread.run(Thread.java:1583)
... Removed 16 stack frames</pre></div><a href='#' onClick='toggleBox("stack-trace1768724411", this, "Click to show all stack frames", "Click to hide stack frames")'>Click to show all stack frames</a>
<div class='stack-trace' id='stack-trace1768724411'><pre>java.lang.AssertionError: Unexpected exception during login test execution.
	at org.testng.Assert.fail(Assert.java:111)
	at testCases.TC02_Login.testLogin(TC02_Login.java:69)
	at java.base/jdk.internal.reflect.DirectMethodHandleAccessor.invoke(DirectMethodHandleAccessor.java:103)
	at java.base/java.lang.reflect.Method.invoke(Method.java:580)
	at org.testng.internal.invokers.MethodInvocationHelper.invokeMethod(MethodInvocationHelper.java:141)
	at org.testng.internal.invokers.TestInvoker.invokeMethod(TestInvoker.java:687)
	at org.testng.internal.invokers.TestInvoker.retryFailed(TestInvoker.java:269)
	at org.testng.internal.invokers.MethodRunner.runInSequence(MethodRunner.java:76)
	at org.testng.internal.invokers.TestInvoker$MethodInvocationAgent.invoke(TestInvoker.java:995)
	at org.testng.internal.invokers.TestInvoker.invokeTestMethods(TestInvoker.java:203)
	at org.testng.internal.invokers.TestMethodWorker.invokeTestMethods(TestMethodWorker.java:154)
	at org.testng.internal.invokers.TestMethodWorker.run(TestMethodWorker.java:134)
	at java.base/java.util.ArrayList.forEach(ArrayList.java:1596)
	at org.testng.TestRunner.privateRun(TestRunner.java:741)
	at org.testng.TestRunner.run(TestRunner.java:616)
	at org.testng.SuiteRunner.runTest(SuiteRunner.java:421)
	at org.testng.SuiteRunner$SuiteWorker.run(SuiteRunner.java:463)
	at org.testng.internal.thread.ThreadUtil.lambda$execute$0(ThreadUtil.java:64)
	at java.base/java.util.concurrent.FutureTask.run(FutureTask.java:317)
	at java.base/java.util.concurrent.ThreadPoolExecutor.runWorker(ThreadPoolExecutor.java:1144)
	at java.base/java.util.concurrent.ThreadPoolExecutor$Worker.run(ThreadPoolExecutor.java:642)
	at java.base/java.lang.Thread.run(Thread.java:1583)
</pre></div></td>
<td>0</td>
<td>testCases.TC02_Login@6af9fcb2</td></tr>
<tr>
<td title='testCases.TC02_Login.testLogin()'><b>testLogin</b><br>Test class: testCases.TC02_Login<br>Parameters: apushedwoman@gmail.com, password123</td>
<td><div><pre>java.lang.AssertionError: Unexpected exception during login test execution.
	at testCases.TC02_Login.testLogin(TC02_Login.java:69)
	at java.base/java.util.ArrayList.forEach(ArrayList.java:1596)
	at java.base/java.util.concurrent.FutureTask.run(FutureTask.java:317)
	at java.base/java.util.concurrent.ThreadPoolExecutor.runWorker(ThreadPoolExecutor.java:1144)
	at java.base/java.util.concurrent.ThreadPoolExecutor$Worker.run(ThreadPoolExecutor.java:642)
	at java.base/java.lang.Thread.run(Thread.java:1583)
... Removed 16 stack frames</pre></div><a href='#' onClick='toggleBox("stack-trace1010934717", this, "Click to show all stack frames", "Click to hide stack frames")'>Click to show all stack frames</a>
<div class='stack-trace' id='stack-trace1010934717'><pre>java.lang.AssertionError: Unexpected exception during login test execution.
	at org.testng.Assert.fail(Assert.java:111)
	at testCases.TC02_Login.testLogin(TC02_Login.java:69)
	at java.base/jdk.internal.reflect.DirectMethodHandleAccessor.invoke(DirectMethodHandleAccessor.java:103)
	at java.base/java.lang.reflect.Method.invoke(Method.java:580)
	at org.testng.internal.invokers.MethodInvocationHelper.invokeMethod(MethodInvocationHelper.java:141)
	at org.testng.internal.invokers.TestInvoker.invokeMethod(TestInvoker.java:687)
	at org.testng.internal.invokers.TestInvoker.invokeTestMethod(TestInvoker.java:230)
	at org.testng.internal.invokers.MethodRunner.runInSequence(MethodRunner.java:63)
	at org.testng.internal.invokers.TestInvoker$MethodInvocationAgent.invoke(TestInvoker.java:995)
	at org.testng.internal.invokers.TestInvoker.invokeTestMethods(TestInvoker.java:203)
	at org.testng.internal.invokers.TestMethodWorker.invokeTestMethods(TestMethodWorker.java:154)
	at org.testng.internal.invokers.TestMethodWorker.run(TestMethodWorker.java:134)
	at java.base/java.util.ArrayList.forEach(ArrayList.java:1596)
	at org.testng.TestRunner.privateRun(TestRunner.java:741)
	at org.testng.TestRunner.run(TestRunner.java:616)
	at org.testng.SuiteRunner.runTest(SuiteRunner.java:421)
	at org.testng.SuiteRunner$SuiteWorker.run(SuiteRunner.java:463)
	at org.testng.internal.thread.ThreadUtil.lambda$execute$0(ThreadUtil.java:64)
	at java.base/java.util.concurrent.FutureTask.run(FutureTask.java:317)
	at java.base/java.util.concurrent.ThreadPoolExecutor.runWorker(ThreadPoolExecutor.java:1144)
	at java.base/java.util.concurrent.ThreadPoolExecutor$Worker.run(ThreadPoolExecutor.java:642)
	at java.base/java.lang.Thread.run(Thread.java:1583)
</pre></div></td>
<td>0</td>
<td>testCases.TC02_Login@6af9fcb2</td></tr>
<tr>
<td title='testCases.TC02_Login.testLogin()'><b>testLogin</b><br>Test class: testCases.TC02_Login<br>Parameters: apushedwoman@gmail.com, password123</td>
<td><div><pre>java.lang.AssertionError: Unexpected exception during login test execution.
	at testCases.TC02_Login.testLogin(TC02_Login.java:69)
	at java.base/java.util.ArrayList.forEach(ArrayList.java:1596)
	at java.base/java.util.concurrent.FutureTask.run(FutureTask.java:317)
	at java.base/java.util.concurrent.ThreadPoolExecutor.runWorker(ThreadPoolExecutor.java:1144)
	at java.base/java.util.concurrent.ThreadPoolExecutor$Worker.run(ThreadPoolExecutor.java:642)
	at java.base/java.lang.Thread.run(Thread.java:1583)
... Removed 16 stack frames</pre></div><a href='#' onClick='toggleBox("stack-trace823995073", this, "Click to show all stack frames", "Click to hide stack frames")'>Click to show all stack frames</a>
<div class='stack-trace' id='stack-trace823995073'><pre>java.lang.AssertionError: Unexpected exception during login test execution.
	at org.testng.Assert.fail(Assert.java:111)
	at testCases.TC02_Login.testLogin(TC02_Login.java:69)
	at java.base/jdk.internal.reflect.DirectMethodHandleAccessor.invoke(DirectMethodHandleAccessor.java:103)
	at java.base/java.lang.reflect.Method.invoke(Method.java:580)
	at org.testng.internal.invokers.MethodInvocationHelper.invokeMethod(MethodInvocationHelper.java:141)
	at org.testng.internal.invokers.TestInvoker.invokeMethod(TestInvoker.java:687)
	at org.testng.internal.invokers.TestInvoker.retryFailed(TestInvoker.java:269)
	at org.testng.internal.invokers.MethodRunner.runInSequence(MethodRunner.java:76)
	at org.testng.internal.invokers.TestInvoker$MethodInvocationAgent.invoke(TestInvoker.java:995)
	at org.testng.internal.invokers.TestInvoker.invokeTestMethods(TestInvoker.java:203)
	at org.testng.internal.invokers.TestMethodWorker.invokeTestMethods(TestMethodWorker.java:154)
	at org.testng.internal.invokers.TestMethodWorker.run(TestMethodWorker.java:134)
	at java.base/java.util.ArrayList.forEach(ArrayList.java:1596)
	at org.testng.TestRunner.privateRun(TestRunner.java:741)
	at org.testng.TestRunner.run(TestRunner.java:616)
	at org.testng.SuiteRunner.runTest(SuiteRunner.java:421)
	at org.testng.SuiteRunner$SuiteWorker.run(SuiteRunner.java:463)
	at org.testng.internal.thread.ThreadUtil.lambda$execute$0(ThreadUtil.java:64)
	at java.base/java.util.concurrent.FutureTask.run(FutureTask.java:317)
	at java.base/java.util.concurrent.ThreadPoolExecutor.runWorker(ThreadPoolExecutor.java:1144)
	at java.base/java.util.concurrent.ThreadPoolExecutor$Worker.run(ThreadPoolExecutor.java:642)
	at java.base/java.lang.Thread.run(Thread.java:1583)
</pre></div></td>
<td>0</td>
<td>testCases.TC02_Login@6af9fcb2</td></tr>
<tr>
<td title='testCases.TC03_AddToCart.testAddToCart()'><b>testAddToCart</b><br>Test class: testCases.TC03_AddToCart</td>
<td><div><pre>java.lang.AssertionError: Test failed due to unexpected exception.
	at testCases.TC03_AddToCart.testAddToCart(TC03_AddToCart.java:55)
	at java.base/java.util.ArrayList.forEach(ArrayList.java:1596)
	at java.base/java.util.concurrent.FutureTask.run(FutureTask.java:317)
	at java.base/java.util.concurrent.ThreadPoolExecutor.runWorker(ThreadPoolExecutor.java:1144)
	at java.base/java.util.concurrent.ThreadPoolExecutor$Worker.run(ThreadPoolExecutor.java:642)
	at java.base/java.lang.Thread.run(Thread.java:1583)
... Removed 16 stack frames</pre></div><a href='#' onClick='toggleBox("stack-trace1811255819", this, "Click to show all stack frames", "Click to hide stack frames")'>Click to show all stack frames</a>
<div class='stack-trace' id='stack-trace1811255819'><pre>java.lang.AssertionError: Test failed due to unexpected exception.
	at org.testng.Assert.fail(Assert.java:111)
	at testCases.TC03_AddToCart.testAddToCart(TC03_AddToCart.java:55)
	at java.base/jdk.internal.reflect.DirectMethodHandleAccessor.invoke(DirectMethodHandleAccessor.java:103)
	at java.base/java.lang.reflect.Method.invoke(Method.java:580)
	at org.testng.internal.invokers.MethodInvocationHelper.invokeMethod(MethodInvocationHelper.java:141)
	at org.testng.internal.invokers.TestInvoker.invokeMethod(TestInvoker.java:687)
	at org.testng.internal.invokers.TestInvoker.invokeTestMethod(TestInvoker.java:230)
	at org.testng.internal.invokers.MethodRunner.runInSequence(MethodRunner.java:63)
	at org.testng.internal.invokers.TestInvoker$MethodInvocationAgent.invoke(TestInvoker.java:995)
	at org.testng.internal.invokers.TestInvoker.invokeTestMethods(TestInvoker.java:203)
	at org.testng.internal.invokers.TestMethodWorker.invokeTestMethods(TestMethodWorker.java:154)
	at org.testng.internal.invokers.TestMethodWorker.run(TestMethodWorker.java:134)
	at java.base/java.util.ArrayList.forEach(ArrayList.java:1596)
	at org.testng.TestRunner.privateRun(TestRunner.java:741)
	at org.testng.TestRunner.run(TestRunner.java:616)
	at org.testng.SuiteRunner.runTest(SuiteRunner.java:421)
	at org.testng.SuiteRunner$SuiteWorker.run(SuiteRunner.java:463)
	at org.testng.internal.thread.ThreadUtil.lambda$execute$0(ThreadUtil.java:64)
	at java.base/java.util.concurrent.FutureTask.run(FutureTask.java:317)
	at java.base/java.util.concurrent.ThreadPoolExecutor.runWorker(ThreadPoolExecutor.java:1144)
	at java.base/java.util.concurrent.ThreadPoolExecutor$Worker.run(ThreadPoolExecutor.java:642)
	at java.base/java.lang.Thread.run(Thread.java:1583)
</pre></div></td>
<td>0</td>
<td>testCases.TC03_AddToCart@1fc32e4f</td></tr>
<tr>
<td title='testCases.TC01_LaunchApplication.testLaunchApplication()'><b>testLaunchApplication</b><br>Test class: testCases.TC01_LaunchApplication</td>
<td><div><pre>java.lang.AssertionError: Test failed due to unexpected exception
	at testCases.TC01_LaunchApplication.testLaunchApplication(TC01_LaunchApplication.java:35)
	at java.base/java.util.ArrayList.forEach(ArrayList.java:1596)
	at java.base/java.util.concurrent.FutureTask.run(FutureTask.java:317)
	at java.base/java.util.concurrent.ThreadPoolExecutor.runWorker(ThreadPoolExecutor.java:1144)
	at java.base/java.util.concurrent.ThreadPoolExecutor$Worker.run(ThreadPoolExecutor.java:642)
	at java.base/java.lang.Thread.run(Thread.java:1583)
... Removed 16 stack frames</pre></div><a href='#' onClick='toggleBox("stack-trace990539604", this, "Click to show all stack frames", "Click to hide stack frames")'>Click to show all stack frames</a>
<div class='stack-trace' id='stack-trace990539604'><pre>java.lang.AssertionError: Test failed due to unexpected exception
	at org.testng.Assert.fail(Assert.java:111)
	at testCases.TC01_LaunchApplication.testLaunchApplication(TC01_LaunchApplication.java:35)
	at java.base/jdk.internal.reflect.DirectMethodHandleAccessor.invoke(DirectMethodHandleAccessor.java:103)
	at java.base/java.lang.reflect.Method.invoke(Method.java:580)
	at org.testng.internal.invokers.MethodInvocationHelper.invokeMethod(MethodInvocationHelper.java:141)
	at org.testng.internal.invokers.TestInvoker.invokeMethod(TestInvoker.java:687)
	at org.testng.internal.invokers.TestInvoker.invokeTestMethod(TestInvoker.java:230)
	at org.testng.internal.invokers.MethodRunner.runInSequence(MethodRunner.java:63)
	at org.testng.internal.invokers.TestInvoker$MethodInvocationAgent.invoke(TestInvoker.java:995)
	at org.testng.internal.invokers.TestInvoker.invokeTestMethods(TestInvoker.java:203)
	at org.testng.internal.invokers.TestMethodWorker.invokeTestMethods(TestMethodWorker.java:154)
	at org.testng.internal.invokers.TestMethodWorker.run(TestMethodWorker.java:134)
	at java.base/java.util.ArrayList.forEach(ArrayList.java:1596)
	at org.testng.TestRunner.privateRun(TestRunner.java:741)
	at org.testng.TestRunner.run(TestRunner.java:616)
	at org.testng.SuiteRunner.runTest(SuiteRunner.java:421)
	at org.testng.SuiteRunner$SuiteWorker.run(SuiteRunner.java:463)
	at org.testng.internal.thread.ThreadUtil.lambda$execute$0(ThreadUtil.java:64)
	at java.base/java.util.concurrent.FutureTask.run(FutureTask.java:317)
	at java.base/java.util.concurrent.ThreadPoolExecutor.runWorker(ThreadPoolExecutor.java:1144)
	at java.base/java.util.concurrent.ThreadPoolExecutor$Worker.run(ThreadPoolExecutor.java:642)
	at java.base/java.lang.Thread.run(Thread.java:1583)
</pre></div></td>
<td>0</td>
<td>testCases.TC01_LaunchApplication@4716be8b</td></tr>
<tr>
<td title='testCases.TC02_Login.testLogin()'><b>testLogin</b><br>Test class: testCases.TC02_Login<br>Parameters: hichamkhachiai@gmail.com, hicham123</td>
<td><div><pre>java.lang.AssertionError: Unexpected exception during login test execution.
	at testCases.TC02_Login.testLogin(TC02_Login.java:69)
	at java.base/java.util.ArrayList.forEach(ArrayList.java:1596)
	at java.base/java.util.concurrent.FutureTask.run(FutureTask.java:317)
	at java.base/java.util.concurrent.ThreadPoolExecutor.runWorker(ThreadPoolExecutor.java:1144)
	at java.base/java.util.concurrent.ThreadPoolExecutor$Worker.run(ThreadPoolExecutor.java:642)
	at java.base/java.lang.Thread.run(Thread.java:1583)
... Removed 16 stack frames</pre></div><a href='#' onClick='toggleBox("stack-trace389501001", this, "Click to show all stack frames", "Click to hide stack frames")'>Click to show all stack frames</a>
<div class='stack-trace' id='stack-trace389501001'><pre>java.lang.AssertionError: Unexpected exception during login test execution.
	at org.testng.Assert.fail(Assert.java:111)
	at testCases.TC02_Login.testLogin(TC02_Login.java:69)
	at java.base/jdk.internal.reflect.DirectMethodHandleAccessor.invoke(DirectMethodHandleAccessor.java:103)
	at java.base/java.lang.reflect.Method.invoke(Method.java:580)
	at org.testng.internal.invokers.MethodInvocationHelper.invokeMethod(MethodInvocationHelper.java:141)
	at org.testng.internal.invokers.TestInvoker.invokeMethod(TestInvoker.java:687)
	at org.testng.internal.invokers.TestInvoker.invokeTestMethod(TestInvoker.java:230)
	at org.testng.internal.invokers.MethodRunner.runInSequence(MethodRunner.java:63)
	at org.testng.internal.invokers.TestInvoker$MethodInvocationAgent.invoke(TestInvoker.java:995)
	at org.testng.internal.invokers.TestInvoker.invokeTestMethods(TestInvoker.java:203)
	at org.testng.internal.invokers.TestMethodWorker.invokeTestMethods(TestMethodWorker.java:154)
	at org.testng.internal.invokers.TestMethodWorker.run(TestMethodWorker.java:134)
	at java.base/java.util.ArrayList.forEach(ArrayList.java:1596)
	at org.testng.TestRunner.privateRun(TestRunner.java:741)
	at org.testng.TestRunner.run(TestRunner.java:616)
	at org.testng.SuiteRunner.runTest(SuiteRunner.java:421)
	at org.testng.SuiteRunner$SuiteWorker.run(SuiteRunner.java:463)
	at org.testng.internal.thread.ThreadUtil.lambda$execute$0(ThreadUtil.java:64)
	at java.base/java.util.concurrent.FutureTask.run(FutureTask.java:317)
	at java.base/java.util.concurrent.ThreadPoolExecutor.runWorker(ThreadPoolExecutor.java:1144)
	at java.base/java.util.concurrent.ThreadPoolExecutor$Worker.run(ThreadPoolExecutor.java:642)
	at java.base/java.lang.Thread.run(Thread.java:1583)
</pre></div></td>
<td>0</td>
<td>testCases.TC02_Login@6af9fcb2</td></tr>
<tr>
<td title='testCases.TC02_Login.testLogin()'><b>testLogin</b><br>Test class: testCases.TC02_Login<br>Parameters: nona@yahoo.com, QWER!@#$</td>
<td><div><pre>java.lang.AssertionError: Unexpected exception during login test execution.
	at testCases.TC02_Login.testLogin(TC02_Login.java:69)
	at java.base/java.util.ArrayList.forEach(ArrayList.java:1596)
	at java.base/java.util.concurrent.FutureTask.run(FutureTask.java:317)
	at java.base/java.util.concurrent.ThreadPoolExecutor.runWorker(ThreadPoolExecutor.java:1144)
	at java.base/java.util.concurrent.ThreadPoolExecutor$Worker.run(ThreadPoolExecutor.java:642)
	at java.base/java.lang.Thread.run(Thread.java:1583)
... Removed 16 stack frames</pre></div><a href='#' onClick='toggleBox("stack-trace1409894710", this, "Click to show all stack frames", "Click to hide stack frames")'>Click to show all stack frames</a>
<div class='stack-trace' id='stack-trace1409894710'><pre>java.lang.AssertionError: Unexpected exception during login test execution.
	at org.testng.Assert.fail(Assert.java:111)
	at testCases.TC02_Login.testLogin(TC02_Login.java:69)
	at java.base/jdk.internal.reflect.DirectMethodHandleAccessor.invoke(DirectMethodHandleAccessor.java:103)
	at java.base/java.lang.reflect.Method.invoke(Method.java:580)
	at org.testng.internal.invokers.MethodInvocationHelper.invokeMethod(MethodInvocationHelper.java:141)
	at org.testng.internal.invokers.TestInvoker.invokeMethod(TestInvoker.java:687)
	at org.testng.internal.invokers.TestInvoker.invokeTestMethod(TestInvoker.java:230)
	at org.testng.internal.invokers.MethodRunner.runInSequence(MethodRunner.java:63)
	at org.testng.internal.invokers.TestInvoker$MethodInvocationAgent.invoke(TestInvoker.java:995)
	at org.testng.internal.invokers.TestInvoker.invokeTestMethods(TestInvoker.java:203)
	at org.testng.internal.invokers.TestMethodWorker.invokeTestMethods(TestMethodWorker.java:154)
	at org.testng.internal.invokers.TestMethodWorker.run(TestMethodWorker.java:134)
	at java.base/java.util.ArrayList.forEach(ArrayList.java:1596)
	at org.testng.TestRunner.privateRun(TestRunner.java:741)
	at org.testng.TestRunner.run(TestRunner.java:616)
	at org.testng.SuiteRunner.runTest(SuiteRunner.java:421)
	at org.testng.SuiteRunner$SuiteWorker.run(SuiteRunner.java:463)
	at org.testng.internal.thread.ThreadUtil.lambda$execute$0(ThreadUtil.java:64)
	at java.base/java.util.concurrent.FutureTask.run(FutureTask.java:317)
	at java.base/java.util.concurrent.ThreadPoolExecutor.runWorker(ThreadPoolExecutor.java:1144)
	at java.base/java.util.concurrent.ThreadPoolExecutor$Worker.run(ThreadPoolExecutor.java:642)
	at java.base/java.lang.Thread.run(Thread.java:1583)
</pre></div></td>
<td>0</td>
<td>testCases.TC02_Login@6af9fcb2</td></tr>
</table><p>
</body>
</html>