<?xml version="1.0" encoding="UTF-8"?>
<!-- Generated by org.testng.reporters.JUnitXMLReporter -->
<testsuite ignored="2" hostname="MacBookAir" failures="8" tests="24" name="edgeTest" time="5.999" errors="0" timestamp="2025-05-20T18:05:46 EDT">
  <testcase classname="testCases.TC01_LaunchApplication" name="testLaunchApplication" time="0.116">
    <skipped/>
  </testcase> <!-- testLaunchApplication -->
  <testcase classname="testCases.TC01_LaunchApplication" name="testLaunchApplication" time="0.011">
    <skipped/>
  </testcase> <!-- testLaunchApplication -->
  <testcase classname="testCases.TC01_LaunchApplication" name="testLaunchApplication" time="0.012">
    <failure type="java.lang.AssertionError" message="Test failed due to unexpected exception">
      <![CDATA[java.lang.AssertionError: Test failed due to unexpected exception
at testCases.TC01_LaunchApplication.testLaunchApplication(TC01_LaunchApplication.java:35)
at java.base/java.util.ArrayList.forEach(ArrayList.java:1596)
at java.base/java.util.concurrent.FutureTask.run(FutureTask.java:317)
at java.base/java.util.concurrent.ThreadPoolExecutor.runWorker(ThreadPoolExecutor.java:1144)
at java.base/java.util.concurrent.ThreadPoolExecutor$Worker.run(ThreadPoolExecutor.java:642)
at java.base/java.lang.Thread.run(Thread.java:1583)
... Removed 16 stack frames]]>
    </failure>
  </testcase> <!-- testLaunchApplication -->
  <testcase classname="testCases.TC03_AddToCart" name="testAddToCart" time="0.013">
    <skipped/>
  </testcase> <!-- testAddToCart -->
  <testcase classname="testCases.TC03_AddToCart" name="testAddToCart" time="0.009">
    <skipped/>
  </testcase> <!-- testAddToCart -->
  <testcase classname="testCases.TC03_AddToCart" name="testAddToCart" time="0.006">
    <failure type="java.lang.AssertionError" message="Test failed due to unexpected exception.">
      <![CDATA[java.lang.AssertionError: Test failed due to unexpected exception.
at testCases.TC03_AddToCart.testAddToCart(TC03_AddToCart.java:55)
at java.base/java.util.ArrayList.forEach(ArrayList.java:1596)
at java.base/java.util.concurrent.FutureTask.run(FutureTask.java:317)
at java.base/java.util.concurrent.ThreadPoolExecutor.runWorker(ThreadPoolExecutor.java:1144)
at java.base/java.util.concurrent.ThreadPoolExecutor$Worker.run(ThreadPoolExecutor.java:642)
at java.base/java.lang.Thread.run(Thread.java:1583)
... Removed 16 stack frames]]>
    </failure>
  </testcase> <!-- testAddToCart -->
  <testcase classname="testCases.TC02_Login" name="testLogin" time="0.038">
    <skipped/>
  </testcase> <!-- testLogin -->
  <testcase classname="testCases.TC02_Login" name="testLogin" time="0.027">
    <skipped/>
  </testcase> <!-- testLogin -->
  <testcase classname="testCases.TC02_Login" name="testLogin" time="0.004">
    <failure type="java.lang.AssertionError" message="Unexpected exception during login test execution.">
      <![CDATA[java.lang.AssertionError: Unexpected exception during login test execution.
at testCases.TC02_Login.testLogin(TC02_Login.java:69)
at java.base/java.util.ArrayList.forEach(ArrayList.java:1596)
at java.base/java.util.concurrent.FutureTask.run(FutureTask.java:317)
at java.base/java.util.concurrent.ThreadPoolExecutor.runWorker(ThreadPoolExecutor.java:1144)
at java.base/java.util.concurrent.ThreadPoolExecutor$Worker.run(ThreadPoolExecutor.java:642)
at java.base/java.lang.Thread.run(Thread.java:1583)
... Removed 16 stack frames]]>
    </failure>
  </testcase> <!-- testLogin -->
  <testcase classname="testCases.TC02_Login" name="testLogin" time="0.008">
    <skipped/>
  </testcase> <!-- testLogin -->
  <testcase classname="testCases.TC02_Login" name="testLogin" time="0.029">
    <skipped/>
  </testcase> <!-- testLogin -->
  <testcase classname="testCases.TC02_Login" name="testLogin" time="0.007">
    <failure type="java.lang.AssertionError" message="Unexpected exception during login test execution.">
      <![CDATA[java.lang.AssertionError: Unexpected exception during login test execution.
at testCases.TC02_Login.testLogin(TC02_Login.java:69)
at java.base/java.util.ArrayList.forEach(ArrayList.java:1596)
at java.base/java.util.concurrent.FutureTask.run(FutureTask.java:317)
at java.base/java.util.concurrent.ThreadPoolExecutor.runWorker(ThreadPoolExecutor.java:1144)
at java.base/java.util.concurrent.ThreadPoolExecutor$Worker.run(ThreadPoolExecutor.java:642)
at java.base/java.lang.Thread.run(Thread.java:1583)
... Removed 16 stack frames]]>
    </failure>
  </testcase> <!-- testLogin -->
  <testcase classname="testCases.TC02_Login" name="testLogin" time="0.008">
    <skipped/>
  </testcase> <!-- testLogin -->
  <testcase classname="testCases.TC02_Login" name="testLogin" time="0.004">
    <skipped/>
  </testcase> <!-- testLogin -->
  <testcase classname="testCases.TC02_Login" name="testLogin" time="0.001">
    <failure type="java.lang.AssertionError" message="Unexpected exception during login test execution.">
      <![CDATA[java.lang.AssertionError: Unexpected exception during login test execution.
at testCases.TC02_Login.testLogin(TC02_Login.java:69)
at java.base/java.util.ArrayList.forEach(ArrayList.java:1596)
at java.base/java.util.concurrent.FutureTask.run(FutureTask.java:317)
at java.base/java.util.concurrent.ThreadPoolExecutor.runWorker(ThreadPoolExecutor.java:1144)
at java.base/java.util.concurrent.ThreadPoolExecutor$Worker.run(ThreadPoolExecutor.java:642)
at java.base/java.lang.Thread.run(Thread.java:1583)
... Removed 16 stack frames]]>
    </failure>
  </testcase> <!-- testLogin -->
  <testcase classname="testCases.TC02_Login" name="testLogin" time="0.001">
    <skipped/>
  </testcase> <!-- testLogin -->
  <testcase classname="testCases.TC02_Login" name="testLogin" time="0.002">
    <skipped/>
  </testcase> <!-- testLogin -->
  <testcase classname="testCases.TC02_Login" name="testLogin" time="0.026">
    <failure type="java.lang.AssertionError" message="Unexpected exception during login test execution.">
      <![CDATA[java.lang.AssertionError: Unexpected exception during login test execution.
at testCases.TC02_Login.testLogin(TC02_Login.java:69)
at java.base/java.util.ArrayList.forEach(ArrayList.java:1596)
at java.base/java.util.concurrent.FutureTask.run(FutureTask.java:317)
at java.base/java.util.concurrent.ThreadPoolExecutor.runWorker(ThreadPoolExecutor.java:1144)
at java.base/java.util.concurrent.ThreadPoolExecutor$Worker.run(ThreadPoolExecutor.java:642)
at java.base/java.lang.Thread.run(Thread.java:1583)
... Removed 16 stack frames]]>
    </failure>
  </testcase> <!-- testLogin -->
  <testcase classname="testCases.TC02_Login" name="testLogin" time="0.008">
    <skipped/>
  </testcase> <!-- testLogin -->
  <testcase classname="testCases.TC02_Login" name="testLogin" time="0.004">
    <skipped/>
  </testcase> <!-- testLogin -->
  <testcase classname="testCases.TC02_Login" name="testLogin" time="0.01">
    <failure type="java.lang.AssertionError" message="Unexpected exception during login test execution.">
      <![CDATA[java.lang.AssertionError: Unexpected exception during login test execution.
at testCases.TC02_Login.testLogin(TC02_Login.java:69)
at java.base/java.util.ArrayList.forEach(ArrayList.java:1596)
at java.base/java.util.concurrent.FutureTask.run(FutureTask.java:317)
at java.base/java.util.concurrent.ThreadPoolExecutor.runWorker(ThreadPoolExecutor.java:1144)
at java.base/java.util.concurrent.ThreadPoolExecutor$Worker.run(ThreadPoolExecutor.java:642)
at java.base/java.lang.Thread.run(Thread.java:1583)
... Removed 16 stack frames]]>
    </failure>
  </testcase> <!-- testLogin -->
  <testcase classname="testCases.TC04_CompletePurchase" name="testCompletePurchase" time="0.006">
    <skipped/>
  </testcase> <!-- testCompletePurchase -->
  <testcase classname="testCases.TC04_CompletePurchase" name="testCompletePurchase" time="0.006">
    <skipped/>
  </testcase> <!-- testCompletePurchase -->
  <testcase classname="testCases.TC04_CompletePurchase" name="testCompletePurchase" time="0.002">
    <failure type="java.lang.AssertionError" message="Test failed due to unexpected exception.">
      <![CDATA[java.lang.AssertionError: Test failed due to unexpected exception.
at testCases.TC04_CompletePurchase.testCompletePurchase(TC04_CompletePurchase.java:81)
at java.base/java.util.ArrayList.forEach(ArrayList.java:1596)
at java.base/java.util.concurrent.FutureTask.run(FutureTask.java:317)
at java.base/java.util.concurrent.ThreadPoolExecutor.runWorker(ThreadPoolExecutor.java:1144)
at java.base/java.util.concurrent.ThreadPoolExecutor$Worker.run(ThreadPoolExecutor.java:642)
at java.base/java.lang.Thread.run(Thread.java:1583)
... Removed 16 stack frames]]>
    </failure>
  </testcase> <!-- testCompletePurchase -->
  <testcase classname="testCases.TC05_AddToWishList" name="testAddToWishList" time="0.0">
    <ignored/>
  </testcase> <!-- testAddToWishList -->
  <testcase classname="testCases.TC06_AddAffiliate" name="testAddAffiliate" time="0.0">
    <ignored/>
  </testcase> <!-- testAddAffiliate -->
</testsuite> <!-- edgeTest -->
