<?xml version="1.0" encoding="UTF-8"?>
<testsuite xmlns:xsi="http://www.w3.org/2001/XMLSchema-instance" xsi:noNamespaceSchemaLocation="https://maven.apache.org/surefire/maven-surefire-plugin/xsd/surefire-test-report.xsd" version="3.0.2" name="TestSuite" time="12.156" tests="72" errors="0" skipped="48" failures="24">
  <properties>
    <property name="java.specification.version" value="21"/>
    <property name="sun.jnu.encoding" value="UTF-8"/>
    <property name="sun.awt.enableExtraMouseButtons" value="true"/>
    <property name="java.class.path" value="/Users/gabrield/eclipse-workspace/NinjaV6/target/test-classes:/Users/gabrield/eclipse-workspace/NinjaV6/target/classes:/Users/gabrield/.m2/repository/org/seleniumhq/selenium/selenium-java/4.31.0/selenium-java-4.31.0.jar:/Users/gabrield/.m2/repository/org/seleniumhq/selenium/selenium-api/4.31.0/selenium-api-4.31.0.jar:/Users/gabrield/.m2/repository/org/jspecify/jspecify/1.0.0/jspecify-1.0.0.jar:/Users/gabrield/.m2/repository/org/seleniumhq/selenium/selenium-chrome-driver/4.31.0/selenium-chrome-driver-4.31.0.jar:/Users/gabrield/.m2/repository/com/google/auto/service/auto-service-annotations/1.1.1/auto-service-annotations-1.1.1.jar:/Users/gabrield/.m2/repository/org/seleniumhq/selenium/selenium-chromium-driver/4.31.0/selenium-chromium-driver-4.31.0.jar:/Users/gabrield/.m2/repository/org/seleniumhq/selenium/selenium-json/4.31.0/selenium-json-4.31.0.jar:/Users/gabrield/.m2/repository/org/seleniumhq/selenium/selenium-manager/4.31.0/selenium-manager-4.31.0.jar:/Users/gabrield/.m2/repository/org/seleniumhq/selenium/selenium-devtools-v133/4.31.0/selenium-devtools-v133-4.31.0.jar:/Users/gabrield/.m2/repository/org/seleniumhq/selenium/selenium-devtools-v134/4.31.0/selenium-devtools-v134-4.31.0.jar:/Users/gabrield/.m2/repository/org/seleniumhq/selenium/selenium-devtools-v135/4.31.0/selenium-devtools-v135-4.31.0.jar:/Users/gabrield/.m2/repository/org/seleniumhq/selenium/selenium-edge-driver/4.31.0/selenium-edge-driver-4.31.0.jar:/Users/gabrield/.m2/repository/org/seleniumhq/selenium/selenium-firefox-driver/4.31.0/selenium-firefox-driver-4.31.0.jar:/Users/gabrield/.m2/repository/org/seleniumhq/selenium/selenium-http/4.31.0/selenium-http-4.31.0.jar:/Users/gabrield/.m2/repository/org/seleniumhq/selenium/selenium-ie-driver/4.31.0/selenium-ie-driver-4.31.0.jar:/Users/gabrield/.m2/repository/org/seleniumhq/selenium/selenium-remote-driver/4.31.0/selenium-remote-driver-4.31.0.jar:/Users/gabrield/.m2/repository/com/google/guava/guava/33.4.6-jre/guava-33.4.6-jre.jar:/Users/gabrield/.m2/repository/com/google/guava/failureaccess/1.0.3/failureaccess-1.0.3.jar:/Users/gabrield/.m2/repository/com/google/guava/listenablefuture/9999.0-empty-to-avoid-conflict-with-guava/listenablefuture-9999.0-empty-to-avoid-conflict-with-guava.jar:/Users/gabrield/.m2/repository/com/google/errorprone/error_prone_annotations/2.36.0/error_prone_annotations-2.36.0.jar:/Users/gabrield/.m2/repository/com/google/j2objc/j2objc-annotations/3.0.0/j2objc-annotations-3.0.0.jar:/Users/gabrield/.m2/repository/io/opentelemetry/opentelemetry-api/1.48.0/opentelemetry-api-1.48.0.jar:/Users/gabrield/.m2/repository/io/opentelemetry/opentelemetry-context/1.48.0/opentelemetry-context-1.48.0.jar:/Users/gabrield/.m2/repository/io/opentelemetry/opentelemetry-exporter-logging/1.48.0/opentelemetry-exporter-logging-1.48.0.jar:/Users/gabrield/.m2/repository/io/opentelemetry/opentelemetry-sdk-common/1.48.0/opentelemetry-sdk-common-1.48.0.jar:/Users/gabrield/.m2/repository/io/opentelemetry/opentelemetry-sdk-extension-autoconfigure-spi/1.48.0/opentelemetry-sdk-extension-autoconfigure-spi-1.48.0.jar:/Users/gabrield/.m2/repository/io/opentelemetry/opentelemetry-sdk-extension-autoconfigure/1.48.0/opentelemetry-sdk-extension-autoconfigure-1.48.0.jar:/Users/gabrield/.m2/repository/io/opentelemetry/opentelemetry-sdk-trace/1.48.0/opentelemetry-sdk-trace-1.48.0.jar:/Users/gabrield/.m2/repository/io/opentelemetry/opentelemetry-sdk/1.48.0/opentelemetry-sdk-1.48.0.jar:/Users/gabrield/.m2/repository/io/opentelemetry/opentelemetry-sdk-metrics/1.48.0/opentelemetry-sdk-metrics-1.48.0.jar:/Users/gabrield/.m2/repository/io/opentelemetry/opentelemetry-sdk-logs/1.48.0/opentelemetry-sdk-logs-1.48.0.jar:/Users/gabrield/.m2/repository/net/bytebuddy/byte-buddy/1.17.5/byte-buddy-1.17.5.jar:/Users/gabrield/.m2/repository/org/seleniumhq/selenium/selenium-os/4.31.0/selenium-os-4.31.0.jar:/Users/gabrield/.m2/repository/org/apache/commons/commons-exec/1.4.0/commons-exec-1.4.0.jar:/Users/gabrield/.m2/repository/org/seleniumhq/selenium/selenium-safari-driver/4.31.0/selenium-safari-driver-4.31.0.jar:/Users/gabrield/.m2/repository/org/seleniumhq/selenium/selenium-support/4.31.0/selenium-support-4.31.0.jar:/Users/gabrield/.m2/repository/org/testng/testng/7.11.0/testng-7.11.0.jar:/Users/gabrield/.m2/repository/org/slf4j/slf4j-api/2.0.16/slf4j-api-2.0.16.jar:/Users/gabrield/.m2/repository/org/jcommander/jcommander/1.83/jcommander-1.83.jar:/Users/gabrield/.m2/repository/org/webjars/jquery/3.7.1/jquery-3.7.1.jar:/Users/gabrield/.m2/repository/com/aventstack/extentreports/5.1.2/extentreports-5.1.2.jar:/Users/gabrield/.m2/repository/io/reactivex/rxjava3/rxjava/3.1.6/rxjava-3.1.6.jar:/Users/gabrield/.m2/repository/org/reactivestreams/reactive-streams/1.0.4/reactive-streams-1.0.4.jar:/Users/gabrield/.m2/repository/org/freemarker/freemarker/2.3.32/freemarker-2.3.32.jar:/Users/gabrield/.m2/repository/org/projectlombok/lombok/1.18.26/lombok-1.18.26.jar:/Users/gabrield/.m2/repository/com/google/code/gson/gson/2.10.1/gson-2.10.1.jar:/Users/gabrield/.m2/repository/org/apache/poi/poi/5.4.1/poi-5.4.1.jar:/Users/gabrield/.m2/repository/commons-codec/commons-codec/1.18.0/commons-codec-1.18.0.jar:/Users/gabrield/.m2/repository/org/apache/commons/commons-collections4/4.4/commons-collections4-4.4.jar:/Users/gabrield/.m2/repository/org/apache/commons/commons-math3/3.6.1/commons-math3-3.6.1.jar:/Users/gabrield/.m2/repository/commons-io/commons-io/2.18.0/commons-io-2.18.0.jar:/Users/gabrield/.m2/repository/com/zaxxer/SparseBitSet/1.3/SparseBitSet-1.3.jar:/Users/gabrield/.m2/repository/org/apache/poi/poi-ooxml/5.4.1/poi-ooxml-5.4.1.jar:/Users/gabrield/.m2/repository/org/apache/poi/poi-ooxml-lite/5.4.1/poi-ooxml-lite-5.4.1.jar:/Users/gabrield/.m2/repository/org/apache/xmlbeans/xmlbeans/5.3.0/xmlbeans-5.3.0.jar:/Users/gabrield/.m2/repository/org/apache/commons/commons-compress/1.27.1/commons-compress-1.27.1.jar:/Users/gabrield/.m2/repository/org/apache/commons/commons-lang3/3.16.0/commons-lang3-3.16.0.jar:/Users/gabrield/.m2/repository/com/github/virtuald/curvesapi/1.08/curvesapi-1.08.jar:/Users/gabrield/.m2/repository/org/apache/commons/commons-email/1.6.0/commons-email-1.6.0.jar:/Users/gabrield/.m2/repository/com/sun/mail/jakarta.mail/1.6.7/jakarta.mail-1.6.7.jar:/Users/gabrield/.m2/repository/com/sun/activation/jakarta.activation/1.2.1/jakarta.activation-1.2.1.jar:/Users/gabrield/.m2/repository/org/apache/logging/log4j/log4j-core/2.24.3/log4j-core-2.24.3.jar:/Users/gabrield/.m2/repository/org/apache/logging/log4j/log4j-api/2.24.3/log4j-api-2.24.3.jar:/Users/gabrield/.m2/repository/org/apache/logging/log4j/log4j-slf4j-impl/2.24.3/log4j-slf4j-impl-2.24.3.jar:"/>
    <property name="java.vm.vendor" value="Eclipse Adoptium"/>
    <property name="sun.arch.data.model" value="64"/>
    <property name="java.vendor.url" value="https://adoptium.net/"/>
    <property name="user.timezone" value="America/New_York"/>
    <property name="os.name" value="Mac OS X"/>
    <property name="java.vm.specification.version" value="21"/>
    <property name="sun.java.launcher" value="SUN_STANDARD"/>
    <property name="user.country" value="US"/>
    <property name="sun.boot.library.path" value="/Users/gabrield/.p2/pool/plugins/org.eclipse.justj.openjdk.hotspot.jre.full.macosx.x86_64_21.0.6.v20250130-0529/jre/lib"/>
    <property name="sun.java.command" value="/Users/gabrield/eclipse-workspace/NinjaV6/target/surefire/surefirebooter-20250520180533406_3.jar /Users/gabrield/eclipse-workspace/NinjaV6/target/surefire 2025-05-20T18-05-32_553-jvmRun1 surefire-20250520180533406_1tmp surefire_0-20250520180533406_2tmp"/>
    <property name="http.nonProxyHosts" value="local|*.local|169.254/16|*.169.254/16"/>
    <property name="jdk.debug" value="release"/>
    <property name="surefire.test.class.path" value="/Users/gabrield/eclipse-workspace/NinjaV6/target/test-classes:/Users/gabrield/eclipse-workspace/NinjaV6/target/classes:/Users/gabrield/.m2/repository/org/seleniumhq/selenium/selenium-java/4.31.0/selenium-java-4.31.0.jar:/Users/gabrield/.m2/repository/org/seleniumhq/selenium/selenium-api/4.31.0/selenium-api-4.31.0.jar:/Users/gabrield/.m2/repository/org/jspecify/jspecify/1.0.0/jspecify-1.0.0.jar:/Users/gabrield/.m2/repository/org/seleniumhq/selenium/selenium-chrome-driver/4.31.0/selenium-chrome-driver-4.31.0.jar:/Users/gabrield/.m2/repository/com/google/auto/service/auto-service-annotations/1.1.1/auto-service-annotations-1.1.1.jar:/Users/gabrield/.m2/repository/org/seleniumhq/selenium/selenium-chromium-driver/4.31.0/selenium-chromium-driver-4.31.0.jar:/Users/gabrield/.m2/repository/org/seleniumhq/selenium/selenium-json/4.31.0/selenium-json-4.31.0.jar:/Users/gabrield/.m2/repository/org/seleniumhq/selenium/selenium-manager/4.31.0/selenium-manager-4.31.0.jar:/Users/gabrield/.m2/repository/org/seleniumhq/selenium/selenium-devtools-v133/4.31.0/selenium-devtools-v133-4.31.0.jar:/Users/gabrield/.m2/repository/org/seleniumhq/selenium/selenium-devtools-v134/4.31.0/selenium-devtools-v134-4.31.0.jar:/Users/gabrield/.m2/repository/org/seleniumhq/selenium/selenium-devtools-v135/4.31.0/selenium-devtools-v135-4.31.0.jar:/Users/gabrield/.m2/repository/org/seleniumhq/selenium/selenium-edge-driver/4.31.0/selenium-edge-driver-4.31.0.jar:/Users/gabrield/.m2/repository/org/seleniumhq/selenium/selenium-firefox-driver/4.31.0/selenium-firefox-driver-4.31.0.jar:/Users/gabrield/.m2/repository/org/seleniumhq/selenium/selenium-http/4.31.0/selenium-http-4.31.0.jar:/Users/gabrield/.m2/repository/org/seleniumhq/selenium/selenium-ie-driver/4.31.0/selenium-ie-driver-4.31.0.jar:/Users/gabrield/.m2/repository/org/seleniumhq/selenium/selenium-remote-driver/4.31.0/selenium-remote-driver-4.31.0.jar:/Users/gabrield/.m2/repository/com/google/guava/guava/33.4.6-jre/guava-33.4.6-jre.jar:/Users/gabrield/.m2/repository/com/google/guava/failureaccess/1.0.3/failureaccess-1.0.3.jar:/Users/gabrield/.m2/repository/com/google/guava/listenablefuture/9999.0-empty-to-avoid-conflict-with-guava/listenablefuture-9999.0-empty-to-avoid-conflict-with-guava.jar:/Users/gabrield/.m2/repository/com/google/errorprone/error_prone_annotations/2.36.0/error_prone_annotations-2.36.0.jar:/Users/gabrield/.m2/repository/com/google/j2objc/j2objc-annotations/3.0.0/j2objc-annotations-3.0.0.jar:/Users/gabrield/.m2/repository/io/opentelemetry/opentelemetry-api/1.48.0/opentelemetry-api-1.48.0.jar:/Users/gabrield/.m2/repository/io/opentelemetry/opentelemetry-context/1.48.0/opentelemetry-context-1.48.0.jar:/Users/gabrield/.m2/repository/io/opentelemetry/opentelemetry-exporter-logging/1.48.0/opentelemetry-exporter-logging-1.48.0.jar:/Users/gabrield/.m2/repository/io/opentelemetry/opentelemetry-sdk-common/1.48.0/opentelemetry-sdk-common-1.48.0.jar:/Users/gabrield/.m2/repository/io/opentelemetry/opentelemetry-sdk-extension-autoconfigure-spi/1.48.0/opentelemetry-sdk-extension-autoconfigure-spi-1.48.0.jar:/Users/gabrield/.m2/repository/io/opentelemetry/opentelemetry-sdk-extension-autoconfigure/1.48.0/opentelemetry-sdk-extension-autoconfigure-1.48.0.jar:/Users/gabrield/.m2/repository/io/opentelemetry/opentelemetry-sdk-trace/1.48.0/opentelemetry-sdk-trace-1.48.0.jar:/Users/gabrield/.m2/repository/io/opentelemetry/opentelemetry-sdk/1.48.0/opentelemetry-sdk-1.48.0.jar:/Users/gabrield/.m2/repository/io/opentelemetry/opentelemetry-sdk-metrics/1.48.0/opentelemetry-sdk-metrics-1.48.0.jar:/Users/gabrield/.m2/repository/io/opentelemetry/opentelemetry-sdk-logs/1.48.0/opentelemetry-sdk-logs-1.48.0.jar:/Users/gabrield/.m2/repository/net/bytebuddy/byte-buddy/1.17.5/byte-buddy-1.17.5.jar:/Users/gabrield/.m2/repository/org/seleniumhq/selenium/selenium-os/4.31.0/selenium-os-4.31.0.jar:/Users/gabrield/.m2/repository/org/apache/commons/commons-exec/1.4.0/commons-exec-1.4.0.jar:/Users/gabrield/.m2/repository/org/seleniumhq/selenium/selenium-safari-driver/4.31.0/selenium-safari-driver-4.31.0.jar:/Users/gabrield/.m2/repository/org/seleniumhq/selenium/selenium-support/4.31.0/selenium-support-4.31.0.jar:/Users/gabrield/.m2/repository/org/testng/testng/7.11.0/testng-7.11.0.jar:/Users/gabrield/.m2/repository/org/slf4j/slf4j-api/2.0.16/slf4j-api-2.0.16.jar:/Users/gabrield/.m2/repository/org/jcommander/jcommander/1.83/jcommander-1.83.jar:/Users/gabrield/.m2/repository/org/webjars/jquery/3.7.1/jquery-3.7.1.jar:/Users/gabrield/.m2/repository/com/aventstack/extentreports/5.1.2/extentreports-5.1.2.jar:/Users/gabrield/.m2/repository/io/reactivex/rxjava3/rxjava/3.1.6/rxjava-3.1.6.jar:/Users/gabrield/.m2/repository/org/reactivestreams/reactive-streams/1.0.4/reactive-streams-1.0.4.jar:/Users/gabrield/.m2/repository/org/freemarker/freemarker/2.3.32/freemarker-2.3.32.jar:/Users/gabrield/.m2/repository/org/projectlombok/lombok/1.18.26/lombok-1.18.26.jar:/Users/gabrield/.m2/repository/com/google/code/gson/gson/2.10.1/gson-2.10.1.jar:/Users/gabrield/.m2/repository/org/apache/poi/poi/5.4.1/poi-5.4.1.jar:/Users/gabrield/.m2/repository/commons-codec/commons-codec/1.18.0/commons-codec-1.18.0.jar:/Users/gabrield/.m2/repository/org/apache/commons/commons-collections4/4.4/commons-collections4-4.4.jar:/Users/gabrield/.m2/repository/org/apache/commons/commons-math3/3.6.1/commons-math3-3.6.1.jar:/Users/gabrield/.m2/repository/commons-io/commons-io/2.18.0/commons-io-2.18.0.jar:/Users/gabrield/.m2/repository/com/zaxxer/SparseBitSet/1.3/SparseBitSet-1.3.jar:/Users/gabrield/.m2/repository/org/apache/poi/poi-ooxml/5.4.1/poi-ooxml-5.4.1.jar:/Users/gabrield/.m2/repository/org/apache/poi/poi-ooxml-lite/5.4.1/poi-ooxml-lite-5.4.1.jar:/Users/gabrield/.m2/repository/org/apache/xmlbeans/xmlbeans/5.3.0/xmlbeans-5.3.0.jar:/Users/gabrield/.m2/repository/org/apache/commons/commons-compress/1.27.1/commons-compress-1.27.1.jar:/Users/gabrield/.m2/repository/org/apache/commons/commons-lang3/3.16.0/commons-lang3-3.16.0.jar:/Users/gabrield/.m2/repository/com/github/virtuald/curvesapi/1.08/curvesapi-1.08.jar:/Users/gabrield/.m2/repository/org/apache/commons/commons-email/1.6.0/commons-email-1.6.0.jar:/Users/gabrield/.m2/repository/com/sun/mail/jakarta.mail/1.6.7/jakarta.mail-1.6.7.jar:/Users/gabrield/.m2/repository/com/sun/activation/jakarta.activation/1.2.1/jakarta.activation-1.2.1.jar:/Users/gabrield/.m2/repository/org/apache/logging/log4j/log4j-core/2.24.3/log4j-core-2.24.3.jar:/Users/gabrield/.m2/repository/org/apache/logging/log4j/log4j-api/2.24.3/log4j-api-2.24.3.jar:/Users/gabrield/.m2/repository/org/apache/logging/log4j/log4j-slf4j-impl/2.24.3/log4j-slf4j-impl-2.24.3.jar:"/>
    <property name="sun.cpu.endian" value="little"/>
    <property name="user.home" value="/Users/gabrield"/>
    <property name="user.language" value="en"/>
    <property name="java.specification.vendor" value="Oracle Corporation"/>
    <property name="java.version.date" value="2025-01-21"/>
    <property name="java.home" value="/Users/gabrield/.p2/pool/plugins/org.eclipse.justj.openjdk.hotspot.jre.full.macosx.x86_64_21.0.6.v20250130-0529/jre"/>
    <property name="file.separator" value="/"/>
    <property name="basedir" value="/Users/gabrield/eclipse-workspace/NinjaV6"/>
    <property name="style.color" value="always"/>
    <property name="java.vm.compressedOopsMode" value="Zero based"/>
    <property name="line.separator" value="&#10;"/>
    <property name="java.vm.specification.vendor" value="Oracle Corporation"/>
    <property name="java.specification.name" value="Java Platform API Specification"/>
    <property name="apple.awt.application.name" value="ForkedBooter"/>
    <property name="surefire.real.class.path" value="/Users/gabrield/eclipse-workspace/NinjaV6/target/surefire/surefirebooter-20250520180533406_3.jar"/>
    <property name="sun.management.compiler" value="HotSpot 64-Bit Tiered Compilers"/>
    <property name="ftp.nonProxyHosts" value="local|*.local|169.254/16|*.169.254/16"/>
    <property name="java.runtime.version" value="21.0.6+7-LTS"/>
    <property name="user.name" value="gabrield"/>
    <property name="stdout.encoding" value="UTF-8"/>
    <property name="path.separator" value=":"/>
    <property name="otel.metrics.exporter" value="none"/>
    <property name="os.version" value="15.0.1"/>
    <property name="java.runtime.name" value="OpenJDK Runtime Environment"/>
    <property name="otel.traces.exporter" value="none"/>
    <property name="file.encoding" value="UTF-8"/>
    <property name="java.vm.name" value="OpenJDK 64-Bit Server VM"/>
    <property name="java.vendor.version" value="Temurin-21.0.6+7"/>
    <property name="localRepository" value="/Users/gabrield/.m2/repository"/>
    <property name="java.vendor.url.bug" value="https://github.com/adoptium/adoptium-support/issues"/>
    <property name="otel.logs.exporter" value="none"/>
    <property name="java.io.tmpdir" value="/var/folders/dl/ll4dynkx4x93hrdj71_0kv3c0000gn/T/"/>
    <property name="java.version" value="21.0.6"/>
    <property name="user.dir" value="/Users/gabrield/eclipse-workspace/NinjaV6"/>
    <property name="os.arch" value="x86_64"/>
    <property name="java.vm.specification.name" value="Java Virtual Machine Specification"/>
    <property name="native.encoding" value="UTF-8"/>
    <property name="java.library.path" value="/Users/gabrield/Library/Java/Extensions:/Library/Java/Extensions:/Network/Library/Java/Extensions:/System/Library/Java/Extensions:/usr/lib/java:."/>
    <property name="java.vm.info" value="mixed mode, sharing"/>
    <property name="stderr.encoding" value="UTF-8"/>
    <property name="java.vendor" value="Eclipse Adoptium"/>
    <property name="java.vm.version" value="21.0.6+7-LTS"/>
    <property name="sun.io.unicode.encoding" value="UnicodeBig"/>
    <property name="socksNonProxyHosts" value="local|*.local|169.254/16|*.169.254/16"/>
    <property name="java.class.version" value="65.0"/>
  </properties>
  <testcase name="testLaunchApplication" classname="testCases.TC01_LaunchApplication" time="0.0">
    <skipped message="Test failed due to unexpected exception"/>
    <system-out><![CDATA[2025-05-20T22:05:36.838662Z main INFO Starting configuration XmlConfiguration[location=/Users/gabrield/eclipse-workspace/NinjaV6/target/test-classes/log4j2.xml, lastModified=2025-05-20T22:04:47.722Z]...
2025-05-20T22:05:36.842144Z main INFO Start watching for changes to /Users/gabrield/eclipse-workspace/NinjaV6/target/test-classes/log4j2.xml every 0 seconds
2025-05-20T22:05:36.842810Z main INFO Configuration XmlConfiguration[location=/Users/gabrield/eclipse-workspace/NinjaV6/target/test-classes/log4j2.xml, lastModified=2025-05-20T22:04:47.722Z] started.
2025-05-20T22:05:36.846111Z main INFO Stopping configuration org.apache.logging.log4j.core.config.DefaultConfiguration@750e2b97...
2025-05-20T22:05:36.846850Z main INFO Configuration org.apache.logging.log4j.core.config.DefaultConfiguration@750e2b97 stopped.
]]></system-out>
    <system-err><![CDATA[SLF4J(W): No SLF4J providers were found.
SLF4J(W): Defaulting to no-operation (NOP) logger implementation
SLF4J(W): See https://www.slf4j.org/codes.html#noProviders for further details.
SLF4J(W): Class path contains SLF4J bindings targeting slf4j-api versions 1.7.x or earlier.
SLF4J(W): Ignoring binding found at [jar:file:/Users/gabrield/.m2/repository/org/apache/logging/log4j/log4j-slf4j-impl/2.24.3/log4j-slf4j-impl-2.24.3.jar!/org/slf4j/impl/StaticLoggerBinder.class]
SLF4J(W): See https://www.slf4j.org/codes.html#ignoredBindings for an explanation.
May 20, 2025 6:05:37 PM org.openqa.selenium.remote.tracing.opentelemetry.OpenTelemetryTracer createTracer
INFO: Using OpenTelemetry for tracing
]]></system-err>
  </testcase>
  <testcase name="testLaunchApplication" classname="testCases.TC01_LaunchApplication" time="0.0">
    <skipped message="Test failed due to unexpected exception"/>
  </testcase>
  <testcase name="testLaunchApplication" classname="testCases.TC01_LaunchApplication" time="0.0">
    <skipped message="Test failed due to unexpected exception"/>
  </testcase>
  <testcase name="testLaunchApplication" classname="testCases.TC01_LaunchApplication" time="0.0">
    <skipped message="Test failed due to unexpected exception"/>
  </testcase>
  <testcase name="testLaunchApplication" classname="testCases.TC01_LaunchApplication" time="0.0">
    <skipped message="Test failed due to unexpected exception"/>
  </testcase>
  <testcase name="testLaunchApplication" classname="testCases.TC01_LaunchApplication" time="0.0">
    <skipped message="Test failed due to unexpected exception"/>
  </testcase>
  <testcase name="testLaunchApplication" classname="testCases.TC01_LaunchApplication" time="0.028">
    <failure message="Test failed due to unexpected exception" type="java.lang.AssertionError"><![CDATA[java.lang.AssertionError: Test failed due to unexpected exception
	at org.testng.Assert.fail(Assert.java:111)
	at testCases.TC01_LaunchApplication.testLaunchApplication(TC01_LaunchApplication.java:35)
	at java.base/jdk.internal.reflect.DirectMethodHandleAccessor.invoke(DirectMethodHandleAccessor.java:103)
	at java.base/java.lang.reflect.Method.invoke(Method.java:580)
	at org.testng.internal.invokers.MethodInvocationHelper.invokeMethod(MethodInvocationHelper.java:141)
	at org.testng.internal.invokers.TestInvoker.invokeMethod(TestInvoker.java:687)
	at org.testng.internal.invokers.TestInvoker.retryFailed(TestInvoker.java:269)
	at org.testng.internal.invokers.MethodRunner.runInSequence(MethodRunner.java:76)
	at org.testng.internal.invokers.TestInvoker$MethodInvocationAgent.invoke(TestInvoker.java:995)
	at org.testng.internal.invokers.TestInvoker.invokeTestMethods(TestInvoker.java:203)
	at org.testng.internal.invokers.TestMethodWorker.invokeTestMethods(TestMethodWorker.java:154)
	at org.testng.internal.invokers.TestMethodWorker.run(TestMethodWorker.java:134)
	at java.base/java.util.ArrayList.forEach(ArrayList.java:1596)
	at org.testng.TestRunner.privateRun(TestRunner.java:741)
	at org.testng.TestRunner.run(TestRunner.java:616)
	at org.testng.SuiteRunner.runTest(SuiteRunner.java:421)
	at org.testng.SuiteRunner$SuiteWorker.run(SuiteRunner.java:463)
	at org.testng.internal.thread.ThreadUtil.lambda$execute$0(ThreadUtil.java:64)
	at java.base/java.util.concurrent.FutureTask.run(FutureTask.java:317)
	at java.base/java.util.concurrent.ThreadPoolExecutor.runWorker(ThreadPoolExecutor.java:1144)
	at java.base/java.util.concurrent.ThreadPoolExecutor$Worker.run(ThreadPoolExecutor.java:642)
	at java.base/java.lang.Thread.run(Thread.java:1583)
]]></failure>
  </testcase>
  <testcase name="testLaunchApplication" classname="testCases.TC01_LaunchApplication" time="0.028">
    <failure message="Test failed due to unexpected exception" type="java.lang.AssertionError"><![CDATA[java.lang.AssertionError: Test failed due to unexpected exception
	at org.testng.Assert.fail(Assert.java:111)
	at testCases.TC01_LaunchApplication.testLaunchApplication(TC01_LaunchApplication.java:35)
	at java.base/jdk.internal.reflect.DirectMethodHandleAccessor.invoke(DirectMethodHandleAccessor.java:103)
	at java.base/java.lang.reflect.Method.invoke(Method.java:580)
	at org.testng.internal.invokers.MethodInvocationHelper.invokeMethod(MethodInvocationHelper.java:141)
	at org.testng.internal.invokers.TestInvoker.invokeMethod(TestInvoker.java:687)
	at org.testng.internal.invokers.TestInvoker.retryFailed(TestInvoker.java:269)
	at org.testng.internal.invokers.MethodRunner.runInSequence(MethodRunner.java:76)
	at org.testng.internal.invokers.TestInvoker$MethodInvocationAgent.invoke(TestInvoker.java:995)
	at org.testng.internal.invokers.TestInvoker.invokeTestMethods(TestInvoker.java:203)
	at org.testng.internal.invokers.TestMethodWorker.invokeTestMethods(TestMethodWorker.java:154)
	at org.testng.internal.invokers.TestMethodWorker.run(TestMethodWorker.java:134)
	at java.base/java.util.ArrayList.forEach(ArrayList.java:1596)
	at org.testng.TestRunner.privateRun(TestRunner.java:741)
	at org.testng.TestRunner.run(TestRunner.java:616)
	at org.testng.SuiteRunner.runTest(SuiteRunner.java:421)
	at org.testng.SuiteRunner$SuiteWorker.run(SuiteRunner.java:463)
	at org.testng.internal.thread.ThreadUtil.lambda$execute$0(ThreadUtil.java:64)
	at java.base/java.util.concurrent.FutureTask.run(FutureTask.java:317)
	at java.base/java.util.concurrent.ThreadPoolExecutor.runWorker(ThreadPoolExecutor.java:1144)
	at java.base/java.util.concurrent.ThreadPoolExecutor$Worker.run(ThreadPoolExecutor.java:642)
	at java.base/java.lang.Thread.run(Thread.java:1583)
]]></failure>
  </testcase>
  <testcase name="testLaunchApplication" classname="testCases.TC01_LaunchApplication" time="0.028">
    <failure message="Test failed due to unexpected exception" type="java.lang.AssertionError"><![CDATA[java.lang.AssertionError: Test failed due to unexpected exception
	at org.testng.Assert.fail(Assert.java:111)
	at testCases.TC01_LaunchApplication.testLaunchApplication(TC01_LaunchApplication.java:35)
	at java.base/jdk.internal.reflect.DirectMethodHandleAccessor.invoke(DirectMethodHandleAccessor.java:103)
	at java.base/java.lang.reflect.Method.invoke(Method.java:580)
	at org.testng.internal.invokers.MethodInvocationHelper.invokeMethod(MethodInvocationHelper.java:141)
	at org.testng.internal.invokers.TestInvoker.invokeMethod(TestInvoker.java:687)
	at org.testng.internal.invokers.TestInvoker.retryFailed(TestInvoker.java:269)
	at org.testng.internal.invokers.MethodRunner.runInSequence(MethodRunner.java:76)
	at org.testng.internal.invokers.TestInvoker$MethodInvocationAgent.invoke(TestInvoker.java:995)
	at org.testng.internal.invokers.TestInvoker.invokeTestMethods(TestInvoker.java:203)
	at org.testng.internal.invokers.TestMethodWorker.invokeTestMethods(TestMethodWorker.java:154)
	at org.testng.internal.invokers.TestMethodWorker.run(TestMethodWorker.java:134)
	at java.base/java.util.ArrayList.forEach(ArrayList.java:1596)
	at org.testng.TestRunner.privateRun(TestRunner.java:741)
	at org.testng.TestRunner.run(TestRunner.java:616)
	at org.testng.SuiteRunner.runTest(SuiteRunner.java:421)
	at org.testng.SuiteRunner$SuiteWorker.run(SuiteRunner.java:463)
	at org.testng.internal.thread.ThreadUtil.lambda$execute$0(ThreadUtil.java:64)
	at java.base/java.util.concurrent.FutureTask.run(FutureTask.java:317)
	at java.base/java.util.concurrent.ThreadPoolExecutor.runWorker(ThreadPoolExecutor.java:1144)
	at java.base/java.util.concurrent.ThreadPoolExecutor$Worker.run(ThreadPoolExecutor.java:642)
	at java.base/java.lang.Thread.run(Thread.java:1583)
]]></failure>
  </testcase>
  <testcase name="testAddToCart" classname="testCases.TC03_AddToCart" time="0.0">
    <skipped message="Test failed due to unexpected exception."/>
  </testcase>
  <testcase name="testAddToCart" classname="testCases.TC03_AddToCart" time="0.0">
    <skipped message="Test failed due to unexpected exception."/>
  </testcase>
  <testcase name="testAddToCart" classname="testCases.TC03_AddToCart" time="0.0">
    <skipped message="Test failed due to unexpected exception."/>
  </testcase>
  <testcase name="testAddToCart" classname="testCases.TC03_AddToCart" time="0.0">
    <skipped message="Test failed due to unexpected exception."/>
  </testcase>
  <testcase name="testAddToCart" classname="testCases.TC03_AddToCart" time="0.0">
    <skipped message="Test failed due to unexpected exception."/>
  </testcase>
  <testcase name="testAddToCart" classname="testCases.TC03_AddToCart" time="0.0">
    <skipped message="Test failed due to unexpected exception."/>
  </testcase>
  <testcase name="testAddToCart" classname="testCases.TC03_AddToCart" time="0.004">
    <failure message="Test failed due to unexpected exception." type="java.lang.AssertionError"><![CDATA[java.lang.AssertionError: Test failed due to unexpected exception.
	at org.testng.Assert.fail(Assert.java:111)
	at testCases.TC03_AddToCart.testAddToCart(TC03_AddToCart.java:55)
	at java.base/jdk.internal.reflect.DirectMethodHandleAccessor.invoke(DirectMethodHandleAccessor.java:103)
	at java.base/java.lang.reflect.Method.invoke(Method.java:580)
	at org.testng.internal.invokers.MethodInvocationHelper.invokeMethod(MethodInvocationHelper.java:141)
	at org.testng.internal.invokers.TestInvoker.invokeMethod(TestInvoker.java:687)
	at org.testng.internal.invokers.TestInvoker.retryFailed(TestInvoker.java:269)
	at org.testng.internal.invokers.MethodRunner.runInSequence(MethodRunner.java:76)
	at org.testng.internal.invokers.TestInvoker$MethodInvocationAgent.invoke(TestInvoker.java:995)
	at org.testng.internal.invokers.TestInvoker.invokeTestMethods(TestInvoker.java:203)
	at org.testng.internal.invokers.TestMethodWorker.invokeTestMethods(TestMethodWorker.java:154)
	at org.testng.internal.invokers.TestMethodWorker.run(TestMethodWorker.java:134)
	at java.base/java.util.ArrayList.forEach(ArrayList.java:1596)
	at org.testng.TestRunner.privateRun(TestRunner.java:741)
	at org.testng.TestRunner.run(TestRunner.java:616)
	at org.testng.SuiteRunner.runTest(SuiteRunner.java:421)
	at org.testng.SuiteRunner$SuiteWorker.run(SuiteRunner.java:463)
	at org.testng.internal.thread.ThreadUtil.lambda$execute$0(ThreadUtil.java:64)
	at java.base/java.util.concurrent.FutureTask.run(FutureTask.java:317)
	at java.base/java.util.concurrent.ThreadPoolExecutor.runWorker(ThreadPoolExecutor.java:1144)
	at java.base/java.util.concurrent.ThreadPoolExecutor$Worker.run(ThreadPoolExecutor.java:642)
	at java.base/java.lang.Thread.run(Thread.java:1583)
]]></failure>
  </testcase>
  <testcase name="testAddToCart" classname="testCases.TC03_AddToCart" time="0.004">
    <failure message="Test failed due to unexpected exception." type="java.lang.AssertionError"><![CDATA[java.lang.AssertionError: Test failed due to unexpected exception.
	at org.testng.Assert.fail(Assert.java:111)
	at testCases.TC03_AddToCart.testAddToCart(TC03_AddToCart.java:55)
	at java.base/jdk.internal.reflect.DirectMethodHandleAccessor.invoke(DirectMethodHandleAccessor.java:103)
	at java.base/java.lang.reflect.Method.invoke(Method.java:580)
	at org.testng.internal.invokers.MethodInvocationHelper.invokeMethod(MethodInvocationHelper.java:141)
	at org.testng.internal.invokers.TestInvoker.invokeMethod(TestInvoker.java:687)
	at org.testng.internal.invokers.TestInvoker.retryFailed(TestInvoker.java:269)
	at org.testng.internal.invokers.MethodRunner.runInSequence(MethodRunner.java:76)
	at org.testng.internal.invokers.TestInvoker$MethodInvocationAgent.invoke(TestInvoker.java:995)
	at org.testng.internal.invokers.TestInvoker.invokeTestMethods(TestInvoker.java:203)
	at org.testng.internal.invokers.TestMethodWorker.invokeTestMethods(TestMethodWorker.java:154)
	at org.testng.internal.invokers.TestMethodWorker.run(TestMethodWorker.java:134)
	at java.base/java.util.ArrayList.forEach(ArrayList.java:1596)
	at org.testng.TestRunner.privateRun(TestRunner.java:741)
	at org.testng.TestRunner.run(TestRunner.java:616)
	at org.testng.SuiteRunner.runTest(SuiteRunner.java:421)
	at org.testng.SuiteRunner$SuiteWorker.run(SuiteRunner.java:463)
	at org.testng.internal.thread.ThreadUtil.lambda$execute$0(ThreadUtil.java:64)
	at java.base/java.util.concurrent.FutureTask.run(FutureTask.java:317)
	at java.base/java.util.concurrent.ThreadPoolExecutor.runWorker(ThreadPoolExecutor.java:1144)
	at java.base/java.util.concurrent.ThreadPoolExecutor$Worker.run(ThreadPoolExecutor.java:642)
	at java.base/java.lang.Thread.run(Thread.java:1583)
]]></failure>
  </testcase>
  <testcase name="testAddToCart" classname="testCases.TC03_AddToCart" time="0.005">
    <failure message="Test failed due to unexpected exception." type="java.lang.AssertionError"><![CDATA[java.lang.AssertionError: Test failed due to unexpected exception.
	at org.testng.Assert.fail(Assert.java:111)
	at testCases.TC03_AddToCart.testAddToCart(TC03_AddToCart.java:55)
	at java.base/jdk.internal.reflect.DirectMethodHandleAccessor.invoke(DirectMethodHandleAccessor.java:103)
	at java.base/java.lang.reflect.Method.invoke(Method.java:580)
	at org.testng.internal.invokers.MethodInvocationHelper.invokeMethod(MethodInvocationHelper.java:141)
	at org.testng.internal.invokers.TestInvoker.invokeMethod(TestInvoker.java:687)
	at org.testng.internal.invokers.TestInvoker.retryFailed(TestInvoker.java:269)
	at org.testng.internal.invokers.MethodRunner.runInSequence(MethodRunner.java:76)
	at org.testng.internal.invokers.TestInvoker$MethodInvocationAgent.invoke(TestInvoker.java:995)
	at org.testng.internal.invokers.TestInvoker.invokeTestMethods(TestInvoker.java:203)
	at org.testng.internal.invokers.TestMethodWorker.invokeTestMethods(TestMethodWorker.java:154)
	at org.testng.internal.invokers.TestMethodWorker.run(TestMethodWorker.java:134)
	at java.base/java.util.ArrayList.forEach(ArrayList.java:1596)
	at org.testng.TestRunner.privateRun(TestRunner.java:741)
	at org.testng.TestRunner.run(TestRunner.java:616)
	at org.testng.SuiteRunner.runTest(SuiteRunner.java:421)
	at org.testng.SuiteRunner$SuiteWorker.run(SuiteRunner.java:463)
	at org.testng.internal.thread.ThreadUtil.lambda$execute$0(ThreadUtil.java:64)
	at java.base/java.util.concurrent.FutureTask.run(FutureTask.java:317)
	at java.base/java.util.concurrent.ThreadPoolExecutor.runWorker(ThreadPoolExecutor.java:1144)
	at java.base/java.util.concurrent.ThreadPoolExecutor$Worker.run(ThreadPoolExecutor.java:642)
	at java.base/java.lang.Thread.run(Thread.java:1583)
]]></failure>
  </testcase>
  <testcase name="testLogin[smitasharma.qa@gmail.com, ss*QA123](1)" classname="testCases.TC02_Login" time="0.0">
    <skipped message="Unexpected exception during login test execution."/>
  </testcase>
  <testcase name="testLogin[smitasharma.qa@gmail.com, ss*QA123](1)" classname="testCases.TC02_Login" time="0.0">
    <skipped message="Unexpected exception during login test execution."/>
  </testcase>
  <testcase name="testLogin[smitasharma.qa@gmail.com, ss*QA123](1)" classname="testCases.TC02_Login" time="0.0">
    <skipped message="Unexpected exception during login test execution."/>
  </testcase>
  <testcase name="testLogin[smitasharma.qa@gmail.com, ss*QA123](2)" classname="testCases.TC02_Login" time="0.0">
    <skipped message="Unexpected exception during login test execution."/>
  </testcase>
  <testcase name="testLogin[smitasharma.qa@gmail.com, ss*QA123](2)" classname="testCases.TC02_Login" time="0.0">
    <skipped message="Unexpected exception during login test execution."/>
  </testcase>
  <testcase name="testLogin[smitasharma.qa@gmail.com, ss*QA123](2)" classname="testCases.TC02_Login" time="0.0">
    <skipped message="Unexpected exception during login test execution."/>
  </testcase>
  <testcase name="testLogin[smitasharma.qa@gmail.com, ss*QA123](3)" classname="testCases.TC02_Login" time="0.01">
    <failure message="Unexpected exception during login test execution." type="java.lang.AssertionError"><![CDATA[java.lang.AssertionError: Unexpected exception during login test execution.
	at org.testng.Assert.fail(Assert.java:111)
	at testCases.TC02_Login.testLogin(TC02_Login.java:69)
	at java.base/jdk.internal.reflect.DirectMethodHandleAccessor.invoke(DirectMethodHandleAccessor.java:103)
	at java.base/java.lang.reflect.Method.invoke(Method.java:580)
	at org.testng.internal.invokers.MethodInvocationHelper.invokeMethod(MethodInvocationHelper.java:141)
	at org.testng.internal.invokers.TestInvoker.invokeMethod(TestInvoker.java:687)
	at org.testng.internal.invokers.TestInvoker.retryFailed(TestInvoker.java:269)
	at org.testng.internal.invokers.MethodRunner.runInSequence(MethodRunner.java:76)
	at org.testng.internal.invokers.TestInvoker$MethodInvocationAgent.invoke(TestInvoker.java:995)
	at org.testng.internal.invokers.TestInvoker.invokeTestMethods(TestInvoker.java:203)
	at org.testng.internal.invokers.TestMethodWorker.invokeTestMethods(TestMethodWorker.java:154)
	at org.testng.internal.invokers.TestMethodWorker.run(TestMethodWorker.java:134)
	at java.base/java.util.ArrayList.forEach(ArrayList.java:1596)
	at org.testng.TestRunner.privateRun(TestRunner.java:741)
	at org.testng.TestRunner.run(TestRunner.java:616)
	at org.testng.SuiteRunner.runTest(SuiteRunner.java:421)
	at org.testng.SuiteRunner$SuiteWorker.run(SuiteRunner.java:463)
	at org.testng.internal.thread.ThreadUtil.lambda$execute$0(ThreadUtil.java:64)
	at java.base/java.util.concurrent.FutureTask.run(FutureTask.java:317)
	at java.base/java.util.concurrent.ThreadPoolExecutor.runWorker(ThreadPoolExecutor.java:1144)
	at java.base/java.util.concurrent.ThreadPoolExecutor$Worker.run(ThreadPoolExecutor.java:642)
	at java.base/java.lang.Thread.run(Thread.java:1583)
]]></failure>
  </testcase>
  <testcase name="testLogin[smitasharma.qa@gmail.com, ss*QA123](3)" classname="testCases.TC02_Login" time="0.011">
    <failure message="Unexpected exception during login test execution." type="java.lang.AssertionError"><![CDATA[java.lang.AssertionError: Unexpected exception during login test execution.
	at org.testng.Assert.fail(Assert.java:111)
	at testCases.TC02_Login.testLogin(TC02_Login.java:69)
	at java.base/jdk.internal.reflect.DirectMethodHandleAccessor.invoke(DirectMethodHandleAccessor.java:103)
	at java.base/java.lang.reflect.Method.invoke(Method.java:580)
	at org.testng.internal.invokers.MethodInvocationHelper.invokeMethod(MethodInvocationHelper.java:141)
	at org.testng.internal.invokers.TestInvoker.invokeMethod(TestInvoker.java:687)
	at org.testng.internal.invokers.TestInvoker.retryFailed(TestInvoker.java:269)
	at org.testng.internal.invokers.MethodRunner.runInSequence(MethodRunner.java:76)
	at org.testng.internal.invokers.TestInvoker$MethodInvocationAgent.invoke(TestInvoker.java:995)
	at org.testng.internal.invokers.TestInvoker.invokeTestMethods(TestInvoker.java:203)
	at org.testng.internal.invokers.TestMethodWorker.invokeTestMethods(TestMethodWorker.java:154)
	at org.testng.internal.invokers.TestMethodWorker.run(TestMethodWorker.java:134)
	at java.base/java.util.ArrayList.forEach(ArrayList.java:1596)
	at org.testng.TestRunner.privateRun(TestRunner.java:741)
	at org.testng.TestRunner.run(TestRunner.java:616)
	at org.testng.SuiteRunner.runTest(SuiteRunner.java:421)
	at org.testng.SuiteRunner$SuiteWorker.run(SuiteRunner.java:463)
	at org.testng.internal.thread.ThreadUtil.lambda$execute$0(ThreadUtil.java:64)
	at java.base/java.util.concurrent.FutureTask.run(FutureTask.java:317)
	at java.base/java.util.concurrent.ThreadPoolExecutor.runWorker(ThreadPoolExecutor.java:1144)
	at java.base/java.util.concurrent.ThreadPoolExecutor$Worker.run(ThreadPoolExecutor.java:642)
	at java.base/java.lang.Thread.run(Thread.java:1583)
]]></failure>
  </testcase>
  <testcase name="testLogin[smitasharma.qa@gmail.com, ss*QA123](3)" classname="testCases.TC02_Login" time="0.011">
    <failure message="Unexpected exception during login test execution." type="java.lang.AssertionError"><![CDATA[java.lang.AssertionError: Unexpected exception during login test execution.
	at org.testng.Assert.fail(Assert.java:111)
	at testCases.TC02_Login.testLogin(TC02_Login.java:69)
	at java.base/jdk.internal.reflect.DirectMethodHandleAccessor.invoke(DirectMethodHandleAccessor.java:103)
	at java.base/java.lang.reflect.Method.invoke(Method.java:580)
	at org.testng.internal.invokers.MethodInvocationHelper.invokeMethod(MethodInvocationHelper.java:141)
	at org.testng.internal.invokers.TestInvoker.invokeMethod(TestInvoker.java:687)
	at org.testng.internal.invokers.TestInvoker.retryFailed(TestInvoker.java:269)
	at org.testng.internal.invokers.MethodRunner.runInSequence(MethodRunner.java:76)
	at org.testng.internal.invokers.TestInvoker$MethodInvocationAgent.invoke(TestInvoker.java:995)
	at org.testng.internal.invokers.TestInvoker.invokeTestMethods(TestInvoker.java:203)
	at org.testng.internal.invokers.TestMethodWorker.invokeTestMethods(TestMethodWorker.java:154)
	at org.testng.internal.invokers.TestMethodWorker.run(TestMethodWorker.java:134)
	at java.base/java.util.ArrayList.forEach(ArrayList.java:1596)
	at org.testng.TestRunner.privateRun(TestRunner.java:741)
	at org.testng.TestRunner.run(TestRunner.java:616)
	at org.testng.SuiteRunner.runTest(SuiteRunner.java:421)
	at org.testng.SuiteRunner$SuiteWorker.run(SuiteRunner.java:463)
	at org.testng.internal.thread.ThreadUtil.lambda$execute$0(ThreadUtil.java:64)
	at java.base/java.util.concurrent.FutureTask.run(FutureTask.java:317)
	at java.base/java.util.concurrent.ThreadPoolExecutor.runWorker(ThreadPoolExecutor.java:1144)
	at java.base/java.util.concurrent.ThreadPoolExecutor$Worker.run(ThreadPoolExecutor.java:642)
	at java.base/java.lang.Thread.run(Thread.java:1583)
]]></failure>
  </testcase>
  <testcase name="testLogin[nona@yahoo.com, QWER!@#$](4)" classname="testCases.TC02_Login" time="0.0">
    <skipped message="Unexpected exception during login test execution."/>
  </testcase>
  <testcase name="testLogin[nona@yahoo.com, QWER!@#$](4)" classname="testCases.TC02_Login" time="0.0">
    <skipped message="Unexpected exception during login test execution."/>
  </testcase>
  <testcase name="testLogin[nona@yahoo.com, QWER!@#$](4)" classname="testCases.TC02_Login" time="0.0">
    <skipped message="Unexpected exception during login test execution."/>
  </testcase>
  <testcase name="testLogin[nona@yahoo.com, QWER!@#$](5)" classname="testCases.TC02_Login" time="0.0">
    <skipped message="Unexpected exception during login test execution."/>
  </testcase>
  <testcase name="testLogin[nona@yahoo.com, QWER!@#$](5)" classname="testCases.TC02_Login" time="0.0">
    <skipped message="Unexpected exception during login test execution."/>
  </testcase>
  <testcase name="testLogin[nona@yahoo.com, QWER!@#$](5)" classname="testCases.TC02_Login" time="0.0">
    <skipped message="Unexpected exception during login test execution."/>
  </testcase>
  <testcase name="testLogin[nona@yahoo.com, QWER!@#$](6)" classname="testCases.TC02_Login" time="0.017">
    <failure message="Unexpected exception during login test execution." type="java.lang.AssertionError"><![CDATA[java.lang.AssertionError: Unexpected exception during login test execution.
	at org.testng.Assert.fail(Assert.java:111)
	at testCases.TC02_Login.testLogin(TC02_Login.java:69)
	at java.base/jdk.internal.reflect.DirectMethodHandleAccessor.invoke(DirectMethodHandleAccessor.java:103)
	at java.base/java.lang.reflect.Method.invoke(Method.java:580)
	at org.testng.internal.invokers.MethodInvocationHelper.invokeMethod(MethodInvocationHelper.java:141)
	at org.testng.internal.invokers.TestInvoker.invokeMethod(TestInvoker.java:687)
	at org.testng.internal.invokers.TestInvoker.retryFailed(TestInvoker.java:269)
	at org.testng.internal.invokers.MethodRunner.runInSequence(MethodRunner.java:76)
	at org.testng.internal.invokers.TestInvoker$MethodInvocationAgent.invoke(TestInvoker.java:995)
	at org.testng.internal.invokers.TestInvoker.invokeTestMethods(TestInvoker.java:203)
	at org.testng.internal.invokers.TestMethodWorker.invokeTestMethods(TestMethodWorker.java:154)
	at org.testng.internal.invokers.TestMethodWorker.run(TestMethodWorker.java:134)
	at java.base/java.util.ArrayList.forEach(ArrayList.java:1596)
	at org.testng.TestRunner.privateRun(TestRunner.java:741)
	at org.testng.TestRunner.run(TestRunner.java:616)
	at org.testng.SuiteRunner.runTest(SuiteRunner.java:421)
	at org.testng.SuiteRunner$SuiteWorker.run(SuiteRunner.java:463)
	at org.testng.internal.thread.ThreadUtil.lambda$execute$0(ThreadUtil.java:64)
	at java.base/java.util.concurrent.FutureTask.run(FutureTask.java:317)
	at java.base/java.util.concurrent.ThreadPoolExecutor.runWorker(ThreadPoolExecutor.java:1144)
	at java.base/java.util.concurrent.ThreadPoolExecutor$Worker.run(ThreadPoolExecutor.java:642)
	at java.base/java.lang.Thread.run(Thread.java:1583)
]]></failure>
  </testcase>
  <testcase name="testLogin[nona@yahoo.com, QWER!@#$](6)" classname="testCases.TC02_Login" time="0.017">
    <failure message="Unexpected exception during login test execution." type="java.lang.AssertionError"><![CDATA[java.lang.AssertionError: Unexpected exception during login test execution.
	at org.testng.Assert.fail(Assert.java:111)
	at testCases.TC02_Login.testLogin(TC02_Login.java:69)
	at java.base/jdk.internal.reflect.DirectMethodHandleAccessor.invoke(DirectMethodHandleAccessor.java:103)
	at java.base/java.lang.reflect.Method.invoke(Method.java:580)
	at org.testng.internal.invokers.MethodInvocationHelper.invokeMethod(MethodInvocationHelper.java:141)
	at org.testng.internal.invokers.TestInvoker.invokeMethod(TestInvoker.java:687)
	at org.testng.internal.invokers.TestInvoker.retryFailed(TestInvoker.java:269)
	at org.testng.internal.invokers.MethodRunner.runInSequence(MethodRunner.java:76)
	at org.testng.internal.invokers.TestInvoker$MethodInvocationAgent.invoke(TestInvoker.java:995)
	at org.testng.internal.invokers.TestInvoker.invokeTestMethods(TestInvoker.java:203)
	at org.testng.internal.invokers.TestMethodWorker.invokeTestMethods(TestMethodWorker.java:154)
	at org.testng.internal.invokers.TestMethodWorker.run(TestMethodWorker.java:134)
	at java.base/java.util.ArrayList.forEach(ArrayList.java:1596)
	at org.testng.TestRunner.privateRun(TestRunner.java:741)
	at org.testng.TestRunner.run(TestRunner.java:616)
	at org.testng.SuiteRunner.runTest(SuiteRunner.java:421)
	at org.testng.SuiteRunner$SuiteWorker.run(SuiteRunner.java:463)
	at org.testng.internal.thread.ThreadUtil.lambda$execute$0(ThreadUtil.java:64)
	at java.base/java.util.concurrent.FutureTask.run(FutureTask.java:317)
	at java.base/java.util.concurrent.ThreadPoolExecutor.runWorker(ThreadPoolExecutor.java:1144)
	at java.base/java.util.concurrent.ThreadPoolExecutor$Worker.run(ThreadPoolExecutor.java:642)
	at java.base/java.lang.Thread.run(Thread.java:1583)
]]></failure>
  </testcase>
  <testcase name="testLogin[nona@yahoo.com, QWER!@#$](6)" classname="testCases.TC02_Login" time="0.017">
    <failure message="Unexpected exception during login test execution." type="java.lang.AssertionError"><![CDATA[java.lang.AssertionError: Unexpected exception during login test execution.
	at org.testng.Assert.fail(Assert.java:111)
	at testCases.TC02_Login.testLogin(TC02_Login.java:69)
	at java.base/jdk.internal.reflect.DirectMethodHandleAccessor.invoke(DirectMethodHandleAccessor.java:103)
	at java.base/java.lang.reflect.Method.invoke(Method.java:580)
	at org.testng.internal.invokers.MethodInvocationHelper.invokeMethod(MethodInvocationHelper.java:141)
	at org.testng.internal.invokers.TestInvoker.invokeMethod(TestInvoker.java:687)
	at org.testng.internal.invokers.TestInvoker.retryFailed(TestInvoker.java:269)
	at org.testng.internal.invokers.MethodRunner.runInSequence(MethodRunner.java:76)
	at org.testng.internal.invokers.TestInvoker$MethodInvocationAgent.invoke(TestInvoker.java:995)
	at org.testng.internal.invokers.TestInvoker.invokeTestMethods(TestInvoker.java:203)
	at org.testng.internal.invokers.TestMethodWorker.invokeTestMethods(TestMethodWorker.java:154)
	at org.testng.internal.invokers.TestMethodWorker.run(TestMethodWorker.java:134)
	at java.base/java.util.ArrayList.forEach(ArrayList.java:1596)
	at org.testng.TestRunner.privateRun(TestRunner.java:741)
	at org.testng.TestRunner.run(TestRunner.java:616)
	at org.testng.SuiteRunner.runTest(SuiteRunner.java:421)
	at org.testng.SuiteRunner$SuiteWorker.run(SuiteRunner.java:463)
	at org.testng.internal.thread.ThreadUtil.lambda$execute$0(ThreadUtil.java:64)
	at java.base/java.util.concurrent.FutureTask.run(FutureTask.java:317)
	at java.base/java.util.concurrent.ThreadPoolExecutor.runWorker(ThreadPoolExecutor.java:1144)
	at java.base/java.util.concurrent.ThreadPoolExecutor$Worker.run(ThreadPoolExecutor.java:642)
	at java.base/java.lang.Thread.run(Thread.java:1583)
]]></failure>
  </testcase>
  <testcase name="testLogin[sid@cloudberry.services, Test123](7)" classname="testCases.TC02_Login" time="0.0">
    <skipped message="Unexpected exception during login test execution."/>
  </testcase>
  <testcase name="testLogin[sid@cloudberry.services, Test123](7)" classname="testCases.TC02_Login" time="0.0">
    <skipped message="Unexpected exception during login test execution."/>
  </testcase>
  <testcase name="testLogin[sid@cloudberry.services, Test123](7)" classname="testCases.TC02_Login" time="0.0">
    <skipped message="Unexpected exception during login test execution."/>
  </testcase>
  <testcase name="testLogin[sid@cloudberry.services, Test123](8)" classname="testCases.TC02_Login" time="0.0">
    <skipped message="Unexpected exception during login test execution."/>
  </testcase>
  <testcase name="testLogin[sid@cloudberry.services, Test123](8)" classname="testCases.TC02_Login" time="0.0">
    <skipped message="Unexpected exception during login test execution."/>
  </testcase>
  <testcase name="testLogin[sid@cloudberry.services, Test123](8)" classname="testCases.TC02_Login" time="0.0">
    <skipped message="Unexpected exception during login test execution."/>
  </testcase>
  <testcase name="testLogin[sid@cloudberry.services, Test123](9)" classname="testCases.TC02_Login" time="0.007">
    <failure message="Unexpected exception during login test execution." type="java.lang.AssertionError"><![CDATA[java.lang.AssertionError: Unexpected exception during login test execution.
	at org.testng.Assert.fail(Assert.java:111)
	at testCases.TC02_Login.testLogin(TC02_Login.java:69)
	at java.base/jdk.internal.reflect.DirectMethodHandleAccessor.invoke(DirectMethodHandleAccessor.java:103)
	at java.base/java.lang.reflect.Method.invoke(Method.java:580)
	at org.testng.internal.invokers.MethodInvocationHelper.invokeMethod(MethodInvocationHelper.java:141)
	at org.testng.internal.invokers.TestInvoker.invokeMethod(TestInvoker.java:687)
	at org.testng.internal.invokers.TestInvoker.retryFailed(TestInvoker.java:269)
	at org.testng.internal.invokers.MethodRunner.runInSequence(MethodRunner.java:76)
	at org.testng.internal.invokers.TestInvoker$MethodInvocationAgent.invoke(TestInvoker.java:995)
	at org.testng.internal.invokers.TestInvoker.invokeTestMethods(TestInvoker.java:203)
	at org.testng.internal.invokers.TestMethodWorker.invokeTestMethods(TestMethodWorker.java:154)
	at org.testng.internal.invokers.TestMethodWorker.run(TestMethodWorker.java:134)
	at java.base/java.util.ArrayList.forEach(ArrayList.java:1596)
	at org.testng.TestRunner.privateRun(TestRunner.java:741)
	at org.testng.TestRunner.run(TestRunner.java:616)
	at org.testng.SuiteRunner.runTest(SuiteRunner.java:421)
	at org.testng.SuiteRunner$SuiteWorker.run(SuiteRunner.java:463)
	at org.testng.internal.thread.ThreadUtil.lambda$execute$0(ThreadUtil.java:64)
	at java.base/java.util.concurrent.FutureTask.run(FutureTask.java:317)
	at java.base/java.util.concurrent.ThreadPoolExecutor.runWorker(ThreadPoolExecutor.java:1144)
	at java.base/java.util.concurrent.ThreadPoolExecutor$Worker.run(ThreadPoolExecutor.java:642)
	at java.base/java.lang.Thread.run(Thread.java:1583)
]]></failure>
  </testcase>
  <testcase name="testLogin[sid@cloudberry.services, Test123](9)" classname="testCases.TC02_Login" time="0.008">
    <failure message="Unexpected exception during login test execution." type="java.lang.AssertionError"><![CDATA[java.lang.AssertionError: Unexpected exception during login test execution.
	at org.testng.Assert.fail(Assert.java:111)
	at testCases.TC02_Login.testLogin(TC02_Login.java:69)
	at java.base/jdk.internal.reflect.DirectMethodHandleAccessor.invoke(DirectMethodHandleAccessor.java:103)
	at java.base/java.lang.reflect.Method.invoke(Method.java:580)
	at org.testng.internal.invokers.MethodInvocationHelper.invokeMethod(MethodInvocationHelper.java:141)
	at org.testng.internal.invokers.TestInvoker.invokeMethod(TestInvoker.java:687)
	at org.testng.internal.invokers.TestInvoker.retryFailed(TestInvoker.java:269)
	at org.testng.internal.invokers.MethodRunner.runInSequence(MethodRunner.java:76)
	at org.testng.internal.invokers.TestInvoker$MethodInvocationAgent.invoke(TestInvoker.java:995)
	at org.testng.internal.invokers.TestInvoker.invokeTestMethods(TestInvoker.java:203)
	at org.testng.internal.invokers.TestMethodWorker.invokeTestMethods(TestMethodWorker.java:154)
	at org.testng.internal.invokers.TestMethodWorker.run(TestMethodWorker.java:134)
	at java.base/java.util.ArrayList.forEach(ArrayList.java:1596)
	at org.testng.TestRunner.privateRun(TestRunner.java:741)
	at org.testng.TestRunner.run(TestRunner.java:616)
	at org.testng.SuiteRunner.runTest(SuiteRunner.java:421)
	at org.testng.SuiteRunner$SuiteWorker.run(SuiteRunner.java:463)
	at org.testng.internal.thread.ThreadUtil.lambda$execute$0(ThreadUtil.java:64)
	at java.base/java.util.concurrent.FutureTask.run(FutureTask.java:317)
	at java.base/java.util.concurrent.ThreadPoolExecutor.runWorker(ThreadPoolExecutor.java:1144)
	at java.base/java.util.concurrent.ThreadPoolExecutor$Worker.run(ThreadPoolExecutor.java:642)
	at java.base/java.lang.Thread.run(Thread.java:1583)
]]></failure>
  </testcase>
  <testcase name="testLogin[sid@cloudberry.services, Test123](9)" classname="testCases.TC02_Login" time="0.009">
    <failure message="Unexpected exception during login test execution." type="java.lang.AssertionError"><![CDATA[java.lang.AssertionError: Unexpected exception during login test execution.
	at org.testng.Assert.fail(Assert.java:111)
	at testCases.TC02_Login.testLogin(TC02_Login.java:69)
	at java.base/jdk.internal.reflect.DirectMethodHandleAccessor.invoke(DirectMethodHandleAccessor.java:103)
	at java.base/java.lang.reflect.Method.invoke(Method.java:580)
	at org.testng.internal.invokers.MethodInvocationHelper.invokeMethod(MethodInvocationHelper.java:141)
	at org.testng.internal.invokers.TestInvoker.invokeMethod(TestInvoker.java:687)
	at org.testng.internal.invokers.TestInvoker.retryFailed(TestInvoker.java:269)
	at org.testng.internal.invokers.MethodRunner.runInSequence(MethodRunner.java:76)
	at org.testng.internal.invokers.TestInvoker$MethodInvocationAgent.invoke(TestInvoker.java:995)
	at org.testng.internal.invokers.TestInvoker.invokeTestMethods(TestInvoker.java:203)
	at org.testng.internal.invokers.TestMethodWorker.invokeTestMethods(TestMethodWorker.java:154)
	at org.testng.internal.invokers.TestMethodWorker.run(TestMethodWorker.java:134)
	at java.base/java.util.ArrayList.forEach(ArrayList.java:1596)
	at org.testng.TestRunner.privateRun(TestRunner.java:741)
	at org.testng.TestRunner.run(TestRunner.java:616)
	at org.testng.SuiteRunner.runTest(SuiteRunner.java:421)
	at org.testng.SuiteRunner$SuiteWorker.run(SuiteRunner.java:463)
	at org.testng.internal.thread.ThreadUtil.lambda$execute$0(ThreadUtil.java:64)
	at java.base/java.util.concurrent.FutureTask.run(FutureTask.java:317)
	at java.base/java.util.concurrent.ThreadPoolExecutor.runWorker(ThreadPoolExecutor.java:1144)
	at java.base/java.util.concurrent.ThreadPoolExecutor$Worker.run(ThreadPoolExecutor.java:642)
	at java.base/java.lang.Thread.run(Thread.java:1583)
]]></failure>
  </testcase>
  <testcase name="testLogin[apushedwoman@gmail.com, password123](10)" classname="testCases.TC02_Login" time="0.0">
    <skipped message="Unexpected exception during login test execution."/>
  </testcase>
  <testcase name="testLogin[apushedwoman@gmail.com, password123](10)" classname="testCases.TC02_Login" time="0.0">
    <skipped message="Unexpected exception during login test execution."/>
  </testcase>
  <testcase name="testLogin[apushedwoman@gmail.com, password123](10)" classname="testCases.TC02_Login" time="0.0">
    <skipped message="Unexpected exception during login test execution."/>
  </testcase>
  <testcase name="testLogin[apushedwoman@gmail.com, password123](11)" classname="testCases.TC02_Login" time="0.0">
    <skipped message="Unexpected exception during login test execution."/>
  </testcase>
  <testcase name="testLogin[apushedwoman@gmail.com, password123](11)" classname="testCases.TC02_Login" time="0.0">
    <skipped message="Unexpected exception during login test execution."/>
  </testcase>
  <testcase name="testLogin[apushedwoman@gmail.com, password123](11)" classname="testCases.TC02_Login" time="0.0">
    <skipped message="Unexpected exception during login test execution."/>
  </testcase>
  <testcase name="testLogin[apushedwoman@gmail.com, password123](12)" classname="testCases.TC02_Login" time="0.025">
    <failure message="Unexpected exception during login test execution." type="java.lang.AssertionError"><![CDATA[java.lang.AssertionError: Unexpected exception during login test execution.
	at org.testng.Assert.fail(Assert.java:111)
	at testCases.TC02_Login.testLogin(TC02_Login.java:69)
	at java.base/jdk.internal.reflect.DirectMethodHandleAccessor.invoke(DirectMethodHandleAccessor.java:103)
	at java.base/java.lang.reflect.Method.invoke(Method.java:580)
	at org.testng.internal.invokers.MethodInvocationHelper.invokeMethod(MethodInvocationHelper.java:141)
	at org.testng.internal.invokers.TestInvoker.invokeMethod(TestInvoker.java:687)
	at org.testng.internal.invokers.TestInvoker.retryFailed(TestInvoker.java:269)
	at org.testng.internal.invokers.MethodRunner.runInSequence(MethodRunner.java:76)
	at org.testng.internal.invokers.TestInvoker$MethodInvocationAgent.invoke(TestInvoker.java:995)
	at org.testng.internal.invokers.TestInvoker.invokeTestMethods(TestInvoker.java:203)
	at org.testng.internal.invokers.TestMethodWorker.invokeTestMethods(TestMethodWorker.java:154)
	at org.testng.internal.invokers.TestMethodWorker.run(TestMethodWorker.java:134)
	at java.base/java.util.ArrayList.forEach(ArrayList.java:1596)
	at org.testng.TestRunner.privateRun(TestRunner.java:741)
	at org.testng.TestRunner.run(TestRunner.java:616)
	at org.testng.SuiteRunner.runTest(SuiteRunner.java:421)
	at org.testng.SuiteRunner$SuiteWorker.run(SuiteRunner.java:463)
	at org.testng.internal.thread.ThreadUtil.lambda$execute$0(ThreadUtil.java:64)
	at java.base/java.util.concurrent.FutureTask.run(FutureTask.java:317)
	at java.base/java.util.concurrent.ThreadPoolExecutor.runWorker(ThreadPoolExecutor.java:1144)
	at java.base/java.util.concurrent.ThreadPoolExecutor$Worker.run(ThreadPoolExecutor.java:642)
	at java.base/java.lang.Thread.run(Thread.java:1583)
]]></failure>
  </testcase>
  <testcase name="testLogin[apushedwoman@gmail.com, password123](12)" classname="testCases.TC02_Login" time="0.025">
    <failure message="Unexpected exception during login test execution." type="java.lang.AssertionError"><![CDATA[java.lang.AssertionError: Unexpected exception during login test execution.
	at org.testng.Assert.fail(Assert.java:111)
	at testCases.TC02_Login.testLogin(TC02_Login.java:69)
	at java.base/jdk.internal.reflect.DirectMethodHandleAccessor.invoke(DirectMethodHandleAccessor.java:103)
	at java.base/java.lang.reflect.Method.invoke(Method.java:580)
	at org.testng.internal.invokers.MethodInvocationHelper.invokeMethod(MethodInvocationHelper.java:141)
	at org.testng.internal.invokers.TestInvoker.invokeMethod(TestInvoker.java:687)
	at org.testng.internal.invokers.TestInvoker.retryFailed(TestInvoker.java:269)
	at org.testng.internal.invokers.MethodRunner.runInSequence(MethodRunner.java:76)
	at org.testng.internal.invokers.TestInvoker$MethodInvocationAgent.invoke(TestInvoker.java:995)
	at org.testng.internal.invokers.TestInvoker.invokeTestMethods(TestInvoker.java:203)
	at org.testng.internal.invokers.TestMethodWorker.invokeTestMethods(TestMethodWorker.java:154)
	at org.testng.internal.invokers.TestMethodWorker.run(TestMethodWorker.java:134)
	at java.base/java.util.ArrayList.forEach(ArrayList.java:1596)
	at org.testng.TestRunner.privateRun(TestRunner.java:741)
	at org.testng.TestRunner.run(TestRunner.java:616)
	at org.testng.SuiteRunner.runTest(SuiteRunner.java:421)
	at org.testng.SuiteRunner$SuiteWorker.run(SuiteRunner.java:463)
	at org.testng.internal.thread.ThreadUtil.lambda$execute$0(ThreadUtil.java:64)
	at java.base/java.util.concurrent.FutureTask.run(FutureTask.java:317)
	at java.base/java.util.concurrent.ThreadPoolExecutor.runWorker(ThreadPoolExecutor.java:1144)
	at java.base/java.util.concurrent.ThreadPoolExecutor$Worker.run(ThreadPoolExecutor.java:642)
	at java.base/java.lang.Thread.run(Thread.java:1583)
]]></failure>
  </testcase>
  <testcase name="testLogin[apushedwoman@gmail.com, password123](12)" classname="testCases.TC02_Login" time="0.003">
    <failure message="Unexpected exception during login test execution." type="java.lang.AssertionError"><![CDATA[java.lang.AssertionError: Unexpected exception during login test execution.
	at org.testng.Assert.fail(Assert.java:111)
	at testCases.TC02_Login.testLogin(TC02_Login.java:69)
	at java.base/jdk.internal.reflect.DirectMethodHandleAccessor.invoke(DirectMethodHandleAccessor.java:103)
	at java.base/java.lang.reflect.Method.invoke(Method.java:580)
	at org.testng.internal.invokers.MethodInvocationHelper.invokeMethod(MethodInvocationHelper.java:141)
	at org.testng.internal.invokers.TestInvoker.invokeMethod(TestInvoker.java:687)
	at org.testng.internal.invokers.TestInvoker.retryFailed(TestInvoker.java:269)
	at org.testng.internal.invokers.MethodRunner.runInSequence(MethodRunner.java:76)
	at org.testng.internal.invokers.TestInvoker$MethodInvocationAgent.invoke(TestInvoker.java:995)
	at org.testng.internal.invokers.TestInvoker.invokeTestMethods(TestInvoker.java:203)
	at org.testng.internal.invokers.TestMethodWorker.invokeTestMethods(TestMethodWorker.java:154)
	at org.testng.internal.invokers.TestMethodWorker.run(TestMethodWorker.java:134)
	at java.base/java.util.ArrayList.forEach(ArrayList.java:1596)
	at org.testng.TestRunner.privateRun(TestRunner.java:741)
	at org.testng.TestRunner.run(TestRunner.java:616)
	at org.testng.SuiteRunner.runTest(SuiteRunner.java:421)
	at org.testng.SuiteRunner$SuiteWorker.run(SuiteRunner.java:463)
	at org.testng.internal.thread.ThreadUtil.lambda$execute$0(ThreadUtil.java:64)
	at java.base/java.util.concurrent.FutureTask.run(FutureTask.java:317)
	at java.base/java.util.concurrent.ThreadPoolExecutor.runWorker(ThreadPoolExecutor.java:1144)
	at java.base/java.util.concurrent.ThreadPoolExecutor$Worker.run(ThreadPoolExecutor.java:642)
	at java.base/java.lang.Thread.run(Thread.java:1583)
]]></failure>
  </testcase>
  <testcase name="testLogin[hichamkhachiai@gmail.com, hicham123](13)" classname="testCases.TC02_Login" time="0.0">
    <skipped message="Unexpected exception during login test execution."/>
  </testcase>
  <testcase name="testLogin[hichamkhachiai@gmail.com, hicham123](13)" classname="testCases.TC02_Login" time="0.0">
    <skipped message="Unexpected exception during login test execution."/>
  </testcase>
  <testcase name="testLogin[hichamkhachiai@gmail.com, hicham123](13)" classname="testCases.TC02_Login" time="0.0">
    <skipped message="Unexpected exception during login test execution."/>
  </testcase>
  <testcase name="testLogin[hichamkhachiai@gmail.com, hicham123](14)" classname="testCases.TC02_Login" time="0.0">
    <skipped message="Unexpected exception during login test execution."/>
  </testcase>
  <testcase name="testLogin[hichamkhachiai@gmail.com, hicham123](14)" classname="testCases.TC02_Login" time="0.0">
    <skipped message="Unexpected exception during login test execution."/>
  </testcase>
  <testcase name="testLogin[hichamkhachiai@gmail.com, hicham123](14)" classname="testCases.TC02_Login" time="0.0">
    <skipped message="Unexpected exception during login test execution."/>
  </testcase>
  <testcase name="testLogin[hichamkhachiai@gmail.com, hicham123](15)" classname="testCases.TC02_Login" time="0.027">
    <failure message="Unexpected exception during login test execution." type="java.lang.AssertionError"><![CDATA[java.lang.AssertionError: Unexpected exception during login test execution.
	at org.testng.Assert.fail(Assert.java:111)
	at testCases.TC02_Login.testLogin(TC02_Login.java:69)
	at java.base/jdk.internal.reflect.DirectMethodHandleAccessor.invoke(DirectMethodHandleAccessor.java:103)
	at java.base/java.lang.reflect.Method.invoke(Method.java:580)
	at org.testng.internal.invokers.MethodInvocationHelper.invokeMethod(MethodInvocationHelper.java:141)
	at org.testng.internal.invokers.TestInvoker.invokeMethod(TestInvoker.java:687)
	at org.testng.internal.invokers.TestInvoker.retryFailed(TestInvoker.java:269)
	at org.testng.internal.invokers.MethodRunner.runInSequence(MethodRunner.java:76)
	at org.testng.internal.invokers.TestInvoker$MethodInvocationAgent.invoke(TestInvoker.java:995)
	at org.testng.internal.invokers.TestInvoker.invokeTestMethods(TestInvoker.java:203)
	at org.testng.internal.invokers.TestMethodWorker.invokeTestMethods(TestMethodWorker.java:154)
	at org.testng.internal.invokers.TestMethodWorker.run(TestMethodWorker.java:134)
	at java.base/java.util.ArrayList.forEach(ArrayList.java:1596)
	at org.testng.TestRunner.privateRun(TestRunner.java:741)
	at org.testng.TestRunner.run(TestRunner.java:616)
	at org.testng.SuiteRunner.runTest(SuiteRunner.java:421)
	at org.testng.SuiteRunner$SuiteWorker.run(SuiteRunner.java:463)
	at org.testng.internal.thread.ThreadUtil.lambda$execute$0(ThreadUtil.java:64)
	at java.base/java.util.concurrent.FutureTask.run(FutureTask.java:317)
	at java.base/java.util.concurrent.ThreadPoolExecutor.runWorker(ThreadPoolExecutor.java:1144)
	at java.base/java.util.concurrent.ThreadPoolExecutor$Worker.run(ThreadPoolExecutor.java:642)
	at java.base/java.lang.Thread.run(Thread.java:1583)
]]></failure>
  </testcase>
  <testcase name="testLogin[hichamkhachiai@gmail.com, hicham123](15)" classname="testCases.TC02_Login" time="0.027">
    <failure message="Unexpected exception during login test execution." type="java.lang.AssertionError"><![CDATA[java.lang.AssertionError: Unexpected exception during login test execution.
	at org.testng.Assert.fail(Assert.java:111)
	at testCases.TC02_Login.testLogin(TC02_Login.java:69)
	at java.base/jdk.internal.reflect.DirectMethodHandleAccessor.invoke(DirectMethodHandleAccessor.java:103)
	at java.base/java.lang.reflect.Method.invoke(Method.java:580)
	at org.testng.internal.invokers.MethodInvocationHelper.invokeMethod(MethodInvocationHelper.java:141)
	at org.testng.internal.invokers.TestInvoker.invokeMethod(TestInvoker.java:687)
	at org.testng.internal.invokers.TestInvoker.retryFailed(TestInvoker.java:269)
	at org.testng.internal.invokers.MethodRunner.runInSequence(MethodRunner.java:76)
	at org.testng.internal.invokers.TestInvoker$MethodInvocationAgent.invoke(TestInvoker.java:995)
	at org.testng.internal.invokers.TestInvoker.invokeTestMethods(TestInvoker.java:203)
	at org.testng.internal.invokers.TestMethodWorker.invokeTestMethods(TestMethodWorker.java:154)
	at org.testng.internal.invokers.TestMethodWorker.run(TestMethodWorker.java:134)
	at java.base/java.util.ArrayList.forEach(ArrayList.java:1596)
	at org.testng.TestRunner.privateRun(TestRunner.java:741)
	at org.testng.TestRunner.run(TestRunner.java:616)
	at org.testng.SuiteRunner.runTest(SuiteRunner.java:421)
	at org.testng.SuiteRunner$SuiteWorker.run(SuiteRunner.java:463)
	at org.testng.internal.thread.ThreadUtil.lambda$execute$0(ThreadUtil.java:64)
	at java.base/java.util.concurrent.FutureTask.run(FutureTask.java:317)
	at java.base/java.util.concurrent.ThreadPoolExecutor.runWorker(ThreadPoolExecutor.java:1144)
	at java.base/java.util.concurrent.ThreadPoolExecutor$Worker.run(ThreadPoolExecutor.java:642)
	at java.base/java.lang.Thread.run(Thread.java:1583)
]]></failure>
  </testcase>
  <testcase name="testLogin[hichamkhachiai@gmail.com, hicham123](15)" classname="testCases.TC02_Login" time="0.027">
    <failure message="Unexpected exception during login test execution." type="java.lang.AssertionError"><![CDATA[java.lang.AssertionError: Unexpected exception during login test execution.
	at org.testng.Assert.fail(Assert.java:111)
	at testCases.TC02_Login.testLogin(TC02_Login.java:69)
	at java.base/jdk.internal.reflect.DirectMethodHandleAccessor.invoke(DirectMethodHandleAccessor.java:103)
	at java.base/java.lang.reflect.Method.invoke(Method.java:580)
	at org.testng.internal.invokers.MethodInvocationHelper.invokeMethod(MethodInvocationHelper.java:141)
	at org.testng.internal.invokers.TestInvoker.invokeMethod(TestInvoker.java:687)
	at org.testng.internal.invokers.TestInvoker.retryFailed(TestInvoker.java:269)
	at org.testng.internal.invokers.MethodRunner.runInSequence(MethodRunner.java:76)
	at org.testng.internal.invokers.TestInvoker$MethodInvocationAgent.invoke(TestInvoker.java:995)
	at org.testng.internal.invokers.TestInvoker.invokeTestMethods(TestInvoker.java:203)
	at org.testng.internal.invokers.TestMethodWorker.invokeTestMethods(TestMethodWorker.java:154)
	at org.testng.internal.invokers.TestMethodWorker.run(TestMethodWorker.java:134)
	at java.base/java.util.ArrayList.forEach(ArrayList.java:1596)
	at org.testng.TestRunner.privateRun(TestRunner.java:741)
	at org.testng.TestRunner.run(TestRunner.java:616)
	at org.testng.SuiteRunner.runTest(SuiteRunner.java:421)
	at org.testng.SuiteRunner$SuiteWorker.run(SuiteRunner.java:463)
	at org.testng.internal.thread.ThreadUtil.lambda$execute$0(ThreadUtil.java:64)
	at java.base/java.util.concurrent.FutureTask.run(FutureTask.java:317)
	at java.base/java.util.concurrent.ThreadPoolExecutor.runWorker(ThreadPoolExecutor.java:1144)
	at java.base/java.util.concurrent.ThreadPoolExecutor$Worker.run(ThreadPoolExecutor.java:642)
	at java.base/java.lang.Thread.run(Thread.java:1583)
]]></failure>
  </testcase>
  <testcase name="testCompletePurchase" classname="testCases.TC04_CompletePurchase" time="0.0">
    <skipped message="Test failed due to unexpected exception."/>
  </testcase>
  <testcase name="testCompletePurchase" classname="testCases.TC04_CompletePurchase" time="0.0">
    <skipped message="Test failed due to unexpected exception."/>
  </testcase>
  <testcase name="testCompletePurchase" classname="testCases.TC04_CompletePurchase" time="0.0">
    <skipped message="Test failed due to unexpected exception."/>
  </testcase>
  <testcase name="testCompletePurchase" classname="testCases.TC04_CompletePurchase" time="0.0">
    <skipped message="Test failed due to unexpected exception."/>
  </testcase>
  <testcase name="testCompletePurchase" classname="testCases.TC04_CompletePurchase" time="0.0">
    <skipped message="Test failed due to unexpected exception."/>
  </testcase>
  <testcase name="testCompletePurchase" classname="testCases.TC04_CompletePurchase" time="0.0">
    <skipped message="Test failed due to unexpected exception."/>
  </testcase>
  <testcase name="testCompletePurchase" classname="testCases.TC04_CompletePurchase" time="0.004">
    <failure message="Test failed due to unexpected exception." type="java.lang.AssertionError"><![CDATA[java.lang.AssertionError: Test failed due to unexpected exception.
	at org.testng.Assert.fail(Assert.java:111)
	at testCases.TC04_CompletePurchase.testCompletePurchase(TC04_CompletePurchase.java:81)
	at java.base/jdk.internal.reflect.DirectMethodHandleAccessor.invoke(DirectMethodHandleAccessor.java:103)
	at java.base/java.lang.reflect.Method.invoke(Method.java:580)
	at org.testng.internal.invokers.MethodInvocationHelper.invokeMethod(MethodInvocationHelper.java:141)
	at org.testng.internal.invokers.TestInvoker.invokeMethod(TestInvoker.java:687)
	at org.testng.internal.invokers.TestInvoker.retryFailed(TestInvoker.java:269)
	at org.testng.internal.invokers.MethodRunner.runInSequence(MethodRunner.java:76)
	at org.testng.internal.invokers.TestInvoker$MethodInvocationAgent.invoke(TestInvoker.java:995)
	at org.testng.internal.invokers.TestInvoker.invokeTestMethods(TestInvoker.java:203)
	at org.testng.internal.invokers.TestMethodWorker.invokeTestMethods(TestMethodWorker.java:154)
	at org.testng.internal.invokers.TestMethodWorker.run(TestMethodWorker.java:134)
	at java.base/java.util.ArrayList.forEach(ArrayList.java:1596)
	at org.testng.TestRunner.privateRun(TestRunner.java:741)
	at org.testng.TestRunner.run(TestRunner.java:616)
	at org.testng.SuiteRunner.runTest(SuiteRunner.java:421)
	at org.testng.SuiteRunner$SuiteWorker.run(SuiteRunner.java:463)
	at org.testng.internal.thread.ThreadUtil.lambda$execute$0(ThreadUtil.java:64)
	at java.base/java.util.concurrent.FutureTask.run(FutureTask.java:317)
	at java.base/java.util.concurrent.ThreadPoolExecutor.runWorker(ThreadPoolExecutor.java:1144)
	at java.base/java.util.concurrent.ThreadPoolExecutor$Worker.run(ThreadPoolExecutor.java:642)
	at java.base/java.lang.Thread.run(Thread.java:1583)
]]></failure>
  </testcase>
  <testcase name="testCompletePurchase" classname="testCases.TC04_CompletePurchase" time="0.004">
    <failure message="Test failed due to unexpected exception." type="java.lang.AssertionError"><![CDATA[java.lang.AssertionError: Test failed due to unexpected exception.
	at org.testng.Assert.fail(Assert.java:111)
	at testCases.TC04_CompletePurchase.testCompletePurchase(TC04_CompletePurchase.java:81)
	at java.base/jdk.internal.reflect.DirectMethodHandleAccessor.invoke(DirectMethodHandleAccessor.java:103)
	at java.base/java.lang.reflect.Method.invoke(Method.java:580)
	at org.testng.internal.invokers.MethodInvocationHelper.invokeMethod(MethodInvocationHelper.java:141)
	at org.testng.internal.invokers.TestInvoker.invokeMethod(TestInvoker.java:687)
	at org.testng.internal.invokers.TestInvoker.retryFailed(TestInvoker.java:269)
	at org.testng.internal.invokers.MethodRunner.runInSequence(MethodRunner.java:76)
	at org.testng.internal.invokers.TestInvoker$MethodInvocationAgent.invoke(TestInvoker.java:995)
	at org.testng.internal.invokers.TestInvoker.invokeTestMethods(TestInvoker.java:203)
	at org.testng.internal.invokers.TestMethodWorker.invokeTestMethods(TestMethodWorker.java:154)
	at org.testng.internal.invokers.TestMethodWorker.run(TestMethodWorker.java:134)
	at java.base/java.util.ArrayList.forEach(ArrayList.java:1596)
	at org.testng.TestRunner.privateRun(TestRunner.java:741)
	at org.testng.TestRunner.run(TestRunner.java:616)
	at org.testng.SuiteRunner.runTest(SuiteRunner.java:421)
	at org.testng.SuiteRunner$SuiteWorker.run(SuiteRunner.java:463)
	at org.testng.internal.thread.ThreadUtil.lambda$execute$0(ThreadUtil.java:64)
	at java.base/java.util.concurrent.FutureTask.run(FutureTask.java:317)
	at java.base/java.util.concurrent.ThreadPoolExecutor.runWorker(ThreadPoolExecutor.java:1144)
	at java.base/java.util.concurrent.ThreadPoolExecutor$Worker.run(ThreadPoolExecutor.java:642)
	at java.base/java.lang.Thread.run(Thread.java:1583)
]]></failure>
  </testcase>
  <testcase name="testCompletePurchase" classname="testCases.TC04_CompletePurchase" time="0.004">
    <failure message="Test failed due to unexpected exception." type="java.lang.AssertionError"><![CDATA[java.lang.AssertionError: Test failed due to unexpected exception.
	at org.testng.Assert.fail(Assert.java:111)
	at testCases.TC04_CompletePurchase.testCompletePurchase(TC04_CompletePurchase.java:81)
	at java.base/jdk.internal.reflect.DirectMethodHandleAccessor.invoke(DirectMethodHandleAccessor.java:103)
	at java.base/java.lang.reflect.Method.invoke(Method.java:580)
	at org.testng.internal.invokers.MethodInvocationHelper.invokeMethod(MethodInvocationHelper.java:141)
	at org.testng.internal.invokers.TestInvoker.invokeMethod(TestInvoker.java:687)
	at org.testng.internal.invokers.TestInvoker.retryFailed(TestInvoker.java:269)
	at org.testng.internal.invokers.MethodRunner.runInSequence(MethodRunner.java:76)
	at org.testng.internal.invokers.TestInvoker$MethodInvocationAgent.invoke(TestInvoker.java:995)
	at org.testng.internal.invokers.TestInvoker.invokeTestMethods(TestInvoker.java:203)
	at org.testng.internal.invokers.TestMethodWorker.invokeTestMethods(TestMethodWorker.java:154)
	at org.testng.internal.invokers.TestMethodWorker.run(TestMethodWorker.java:134)
	at java.base/java.util.ArrayList.forEach(ArrayList.java:1596)
	at org.testng.TestRunner.privateRun(TestRunner.java:741)
	at org.testng.TestRunner.run(TestRunner.java:616)
	at org.testng.SuiteRunner.runTest(SuiteRunner.java:421)
	at org.testng.SuiteRunner$SuiteWorker.run(SuiteRunner.java:463)
	at org.testng.internal.thread.ThreadUtil.lambda$execute$0(ThreadUtil.java:64)
	at java.base/java.util.concurrent.FutureTask.run(FutureTask.java:317)
	at java.base/java.util.concurrent.ThreadPoolExecutor.runWorker(ThreadPoolExecutor.java:1144)
	at java.base/java.util.concurrent.ThreadPoolExecutor$Worker.run(ThreadPoolExecutor.java:642)
	at java.base/java.lang.Thread.run(Thread.java:1583)
]]></failure>
  </testcase>
</testsuite>