<?xml version="1.0" encoding="UTF-8"?>
<testng-results retried="32" ignored="4" total="52" passed="0" failed="16" skipped="0">
  <reporter-output>
  </reporter-output>
  <suite started-at="2025-05-20T18:05:37 EDT" name="Suite" finished-at="2025-05-20T18:05:43 EDT" duration-ms="5999">
    <groups>
      <group name="datadriven">
        <method signature="TC02_Login.testLogin(java.lang.String,java.lang.String)[pri:0, instance:testCases.TC02_Login@1b75c2e3]" name="testLogin" class="testCases.TC02_Login"/>
        <method signature="TC02_Login.testLogin(java.lang.String,java.lang.String)[pri:0, instance:testCases.TC02_Login@78641d23]" name="testLogin" class="testCases.TC02_Login"/>
        <method signature="TC02_Login.testLogin(java.lang.String,java.lang.String)[pri:0, instance:testCases.TC02_Login@6af9fcb2]" name="testLogin" class="testCases.TC02_Login"/>
      </group> <!-- datadriven -->
      <group name="regression">
        <method signature="TC01_LaunchApplication.testLaunchApplication()[pri:0, instance:testCases.TC01_LaunchApplication@46b61c56]" name="testLaunchApplication" class="testCases.TC01_LaunchApplication"/>
        <method signature="TC02_Login.testLogin(java.lang.String,java.lang.String)[pri:0, instance:testCases.TC02_Login@1b75c2e3]" name="testLogin" class="testCases.TC02_Login"/>
        <method signature="TC03_AddToCart.testAddToCart()[pri:0, instance:testCases.TC03_AddToCart@7e5c856f]" name="testAddToCart" class="testCases.TC03_AddToCart"/>
        <method signature="TC04_CompletePurchase.testCompletePurchase()[pri:0, instance:testCases.TC04_CompletePurchase@1984b1f]" name="testCompletePurchase" class="testCases.TC04_CompletePurchase"/>
        <method signature="TC01_LaunchApplication.testLaunchApplication()[pri:0, instance:testCases.TC01_LaunchApplication@67545b57]" name="testLaunchApplication" class="testCases.TC01_LaunchApplication"/>
        <method signature="TC02_Login.testLogin(java.lang.String,java.lang.String)[pri:0, instance:testCases.TC02_Login@78641d23]" name="testLogin" class="testCases.TC02_Login"/>
        <method signature="TC03_AddToCart.testAddToCart()[pri:0, instance:testCases.TC03_AddToCart@6c2c1385]" name="testAddToCart" class="testCases.TC03_AddToCart"/>
        <method signature="TC04_CompletePurchase.testCompletePurchase()[pri:0, instance:testCases.TC04_CompletePurchase@74589991]" name="testCompletePurchase" class="testCases.TC04_CompletePurchase"/>
        <method signature="TC01_LaunchApplication.testLaunchApplication()[pri:0, instance:testCases.TC01_LaunchApplication@4716be8b]" name="testLaunchApplication" class="testCases.TC01_LaunchApplication"/>
        <method signature="TC02_Login.testLogin(java.lang.String,java.lang.String)[pri:0, instance:testCases.TC02_Login@6af9fcb2]" name="testLogin" class="testCases.TC02_Login"/>
        <method signature="TC03_AddToCart.testAddToCart()[pri:0, instance:testCases.TC03_AddToCart@1fc32e4f]" name="testAddToCart" class="testCases.TC03_AddToCart"/>
        <method signature="TC04_CompletePurchase.testCompletePurchase()[pri:0, instance:testCases.TC04_CompletePurchase@6cce16f4]" name="testCompletePurchase" class="testCases.TC04_CompletePurchase"/>
      </group> <!-- regression -->
      <group name="sanity">
        <method signature="TC01_LaunchApplication.testLaunchApplication()[pri:0, instance:testCases.TC01_LaunchApplication@46b61c56]" name="testLaunchApplication" class="testCases.TC01_LaunchApplication"/>
        <method signature="TC02_Login.testLogin(java.lang.String,java.lang.String)[pri:0, instance:testCases.TC02_Login@1b75c2e3]" name="testLogin" class="testCases.TC02_Login"/>
        <method signature="TC03_AddToCart.testAddToCart()[pri:0, instance:testCases.TC03_AddToCart@7e5c856f]" name="testAddToCart" class="testCases.TC03_AddToCart"/>
        <method signature="TC04_CompletePurchase.testCompletePurchase()[pri:0, instance:testCases.TC04_CompletePurchase@1984b1f]" name="testCompletePurchase" class="testCases.TC04_CompletePurchase"/>
        <method signature="TC01_LaunchApplication.testLaunchApplication()[pri:0, instance:testCases.TC01_LaunchApplication@67545b57]" name="testLaunchApplication" class="testCases.TC01_LaunchApplication"/>
        <method signature="TC02_Login.testLogin(java.lang.String,java.lang.String)[pri:0, instance:testCases.TC02_Login@78641d23]" name="testLogin" class="testCases.TC02_Login"/>
        <method signature="TC03_AddToCart.testAddToCart()[pri:0, instance:testCases.TC03_AddToCart@6c2c1385]" name="testAddToCart" class="testCases.TC03_AddToCart"/>
        <method signature="TC04_CompletePurchase.testCompletePurchase()[pri:0, instance:testCases.TC04_CompletePurchase@74589991]" name="testCompletePurchase" class="testCases.TC04_CompletePurchase"/>
        <method signature="TC01_LaunchApplication.testLaunchApplication()[pri:0, instance:testCases.TC01_LaunchApplication@4716be8b]" name="testLaunchApplication" class="testCases.TC01_LaunchApplication"/>
        <method signature="TC02_Login.testLogin(java.lang.String,java.lang.String)[pri:0, instance:testCases.TC02_Login@6af9fcb2]" name="testLogin" class="testCases.TC02_Login"/>
        <method signature="TC03_AddToCart.testAddToCart()[pri:0, instance:testCases.TC03_AddToCart@1fc32e4f]" name="testAddToCart" class="testCases.TC03_AddToCart"/>
        <method signature="TC04_CompletePurchase.testCompletePurchase()[pri:0, instance:testCases.TC04_CompletePurchase@6cce16f4]" name="testCompletePurchase" class="testCases.TC04_CompletePurchase"/>
      </group> <!-- sanity -->
    </groups>
    <test started-at="2025-05-20T18:05:37 EDT" name="chromeTest" finished-at="2025-05-20T18:05:43 EDT" duration-ms="5999">
      <class name="testCases.TC02_Login">
        <test-method is-config="true" signature="openApp(java.lang.String,java.lang.String)[pri:0, instance:testCases.TC02_Login@1b75c2e3]" started-at="2025-05-20T18:05:39 EDT" name="openApp" finished-at="2025-05-20T18:05:39 EDT" duration-ms="40" status="PASS">
          <params>
            <param index="0">
              <value>
                <![CDATA[windows]]>
              </value>
            </param>
            <param index="1">
              <value>
                <![CDATA[chrome]]>
              </value>
            </param>
          </params>
          <reporter-output>
          </reporter-output>
        </test-method> <!-- openApp -->
        <test-method retried="true" signature="testLogin(java.lang.String,java.lang.String)[pri:0, instance:testCases.TC02_Login@1b75c2e3]" started-at="2025-05-20T18:05:42 EDT" name="testLogin" data-provider="LoginData" finished-at="2025-05-20T18:05:42 EDT" duration-ms="35" status="SKIP">
          <params>
            <param index="0">
              <value>
                <![CDATA[smitasharma.qa@gmail.com]]>
              </value>
            </param>
            <param index="1">
              <value>
                <![CDATA[ss*QA123]]>
              </value>
            </param>
          </params>
          <exception class="java.lang.AssertionError">
            <message>
              <![CDATA[Unexpected exception during login test execution.]]>
            </message>
            <full-stacktrace>
              <![CDATA[java.lang.AssertionError: Unexpected exception during login test execution.
at org.testng.Assert.fail(Assert.java:111)
at testCases.TC02_Login.testLogin(TC02_Login.java:69)
at java.base/jdk.internal.reflect.DirectMethodHandleAccessor.invoke(DirectMethodHandleAccessor.java:103)
at java.base/java.lang.reflect.Method.invoke(Method.java:580)
at org.testng.internal.invokers.MethodInvocationHelper.invokeMethod(MethodInvocationHelper.java:141)
at org.testng.internal.invokers.TestInvoker.invokeMethod(TestInvoker.java:687)
at org.testng.internal.invokers.TestInvoker.invokeTestMethod(TestInvoker.java:230)
at org.testng.internal.invokers.MethodRunner.runInSequence(MethodRunner.java:63)
at org.testng.internal.invokers.TestInvoker$MethodInvocationAgent.invoke(TestInvoker.java:995)
at org.testng.internal.invokers.TestInvoker.invokeTestMethods(TestInvoker.java:203)
at org.testng.internal.invokers.TestMethodWorker.invokeTestMethods(TestMethodWorker.java:154)
at org.testng.internal.invokers.TestMethodWorker.run(TestMethodWorker.java:134)
at java.base/java.util.ArrayList.forEach(ArrayList.java:1596)
at org.testng.TestRunner.privateRun(TestRunner.java:741)
at org.testng.TestRunner.run(TestRunner.java:616)
at org.testng.SuiteRunner.runTest(SuiteRunner.java:421)
at org.testng.SuiteRunner$SuiteWorker.run(SuiteRunner.java:463)
at org.testng.internal.thread.ThreadUtil.lambda$execute$0(ThreadUtil.java:64)
at java.base/java.util.concurrent.FutureTask.run(FutureTask.java:317)
at java.base/java.util.concurrent.ThreadPoolExecutor.runWorker(ThreadPoolExecutor.java:1144)
at java.base/java.util.concurrent.ThreadPoolExecutor$Worker.run(ThreadPoolExecutor.java:642)
at java.base/java.lang.Thread.run(Thread.java:1583)
]]>
            </full-stacktrace>
          </exception> <!-- java.lang.AssertionError -->
          <reporter-output>
          </reporter-output>
        </test-method> <!-- testLogin -->
        <test-method retried="true" signature="testLogin(java.lang.String,java.lang.String)[pri:0, instance:testCases.TC02_Login@1b75c2e3]" started-at="2025-05-20T18:05:42 EDT" name="testLogin" data-provider="LoginData" finished-at="2025-05-20T18:05:42 EDT" duration-ms="27" status="SKIP">
          <params>
            <param index="0">
              <value>
                <![CDATA[smitasharma.qa@gmail.com]]>
              </value>
            </param>
            <param index="1">
              <value>
                <![CDATA[ss*QA123]]>
              </value>
            </param>
          </params>
          <exception class="java.lang.AssertionError">
            <message>
              <![CDATA[Unexpected exception during login test execution.]]>
            </message>
            <full-stacktrace>
              <![CDATA[java.lang.AssertionError: Unexpected exception during login test execution.
at org.testng.Assert.fail(Assert.java:111)
at testCases.TC02_Login.testLogin(TC02_Login.java:69)
at java.base/jdk.internal.reflect.DirectMethodHandleAccessor.invoke(DirectMethodHandleAccessor.java:103)
at java.base/java.lang.reflect.Method.invoke(Method.java:580)
at org.testng.internal.invokers.MethodInvocationHelper.invokeMethod(MethodInvocationHelper.java:141)
at org.testng.internal.invokers.TestInvoker.invokeMethod(TestInvoker.java:687)
at org.testng.internal.invokers.TestInvoker.retryFailed(TestInvoker.java:269)
at org.testng.internal.invokers.MethodRunner.runInSequence(MethodRunner.java:76)
at org.testng.internal.invokers.TestInvoker$MethodInvocationAgent.invoke(TestInvoker.java:995)
at org.testng.internal.invokers.TestInvoker.invokeTestMethods(TestInvoker.java:203)
at org.testng.internal.invokers.TestMethodWorker.invokeTestMethods(TestMethodWorker.java:154)
at org.testng.internal.invokers.TestMethodWorker.run(TestMethodWorker.java:134)
at java.base/java.util.ArrayList.forEach(ArrayList.java:1596)
at org.testng.TestRunner.privateRun(TestRunner.java:741)
at org.testng.TestRunner.run(TestRunner.java:616)
at org.testng.SuiteRunner.runTest(SuiteRunner.java:421)
at org.testng.SuiteRunner$SuiteWorker.run(SuiteRunner.java:463)
at org.testng.internal.thread.ThreadUtil.lambda$execute$0(ThreadUtil.java:64)
at java.base/java.util.concurrent.FutureTask.run(FutureTask.java:317)
at java.base/java.util.concurrent.ThreadPoolExecutor.runWorker(ThreadPoolExecutor.java:1144)
at java.base/java.util.concurrent.ThreadPoolExecutor$Worker.run(ThreadPoolExecutor.java:642)
at java.base/java.lang.Thread.run(Thread.java:1583)
]]>
            </full-stacktrace>
          </exception> <!-- java.lang.AssertionError -->
          <reporter-output>
          </reporter-output>
        </test-method> <!-- testLogin -->
        <test-method signature="testLogin(java.lang.String,java.lang.String)[pri:0, instance:testCases.TC02_Login@1b75c2e3]" started-at="2025-05-20T18:05:42 EDT" name="testLogin" data-provider="LoginData" finished-at="2025-05-20T18:05:42 EDT" duration-ms="5" status="FAIL">
          <params>
            <param index="0">
              <value>
                <![CDATA[smitasharma.qa@gmail.com]]>
              </value>
            </param>
            <param index="1">
              <value>
                <![CDATA[ss*QA123]]>
              </value>
            </param>
          </params>
          <exception class="java.lang.AssertionError">
            <message>
              <![CDATA[Unexpected exception during login test execution.]]>
            </message>
            <full-stacktrace>
              <![CDATA[java.lang.AssertionError: Unexpected exception during login test execution.
at org.testng.Assert.fail(Assert.java:111)
at testCases.TC02_Login.testLogin(TC02_Login.java:69)
at java.base/jdk.internal.reflect.DirectMethodHandleAccessor.invoke(DirectMethodHandleAccessor.java:103)
at java.base/java.lang.reflect.Method.invoke(Method.java:580)
at org.testng.internal.invokers.MethodInvocationHelper.invokeMethod(MethodInvocationHelper.java:141)
at org.testng.internal.invokers.TestInvoker.invokeMethod(TestInvoker.java:687)
at org.testng.internal.invokers.TestInvoker.retryFailed(TestInvoker.java:269)
at org.testng.internal.invokers.MethodRunner.runInSequence(MethodRunner.java:76)
at org.testng.internal.invokers.TestInvoker$MethodInvocationAgent.invoke(TestInvoker.java:995)
at org.testng.internal.invokers.TestInvoker.invokeTestMethods(TestInvoker.java:203)
at org.testng.internal.invokers.TestMethodWorker.invokeTestMethods(TestMethodWorker.java:154)
at org.testng.internal.invokers.TestMethodWorker.run(TestMethodWorker.java:134)
at java.base/java.util.ArrayList.forEach(ArrayList.java:1596)
at org.testng.TestRunner.privateRun(TestRunner.java:741)
at org.testng.TestRunner.run(TestRunner.java:616)
at org.testng.SuiteRunner.runTest(SuiteRunner.java:421)
at org.testng.SuiteRunner$SuiteWorker.run(SuiteRunner.java:463)
at org.testng.internal.thread.ThreadUtil.lambda$execute$0(ThreadUtil.java:64)
at java.base/java.util.concurrent.FutureTask.run(FutureTask.java:317)
at java.base/java.util.concurrent.ThreadPoolExecutor.runWorker(ThreadPoolExecutor.java:1144)
at java.base/java.util.concurrent.ThreadPoolExecutor$Worker.run(ThreadPoolExecutor.java:642)
at java.base/java.lang.Thread.run(Thread.java:1583)
]]>
            </full-stacktrace>
          </exception> <!-- java.lang.AssertionError -->
          <reporter-output>
          </reporter-output>
        </test-method> <!-- testLogin -->
        <test-method retried="true" signature="testLogin(java.lang.String,java.lang.String)[pri:0, instance:testCases.TC02_Login@1b75c2e3]" started-at="2025-05-20T18:05:42 EDT" name="testLogin" data-provider="LoginData" finished-at="2025-05-20T18:05:42 EDT" duration-ms="8" status="SKIP">
          <params>
            <param index="0">
              <value>
                <![CDATA[nona@yahoo.com]]>
              </value>
            </param>
            <param index="1">
              <value>
                <![CDATA[QWER!@#$]]>
              </value>
            </param>
          </params>
          <exception class="java.lang.AssertionError">
            <message>
              <![CDATA[Unexpected exception during login test execution.]]>
            </message>
            <full-stacktrace>
              <![CDATA[java.lang.AssertionError: Unexpected exception during login test execution.
at org.testng.Assert.fail(Assert.java:111)
at testCases.TC02_Login.testLogin(TC02_Login.java:69)
at java.base/jdk.internal.reflect.DirectMethodHandleAccessor.invoke(DirectMethodHandleAccessor.java:103)
at java.base/java.lang.reflect.Method.invoke(Method.java:580)
at org.testng.internal.invokers.MethodInvocationHelper.invokeMethod(MethodInvocationHelper.java:141)
at org.testng.internal.invokers.TestInvoker.invokeMethod(TestInvoker.java:687)
at org.testng.internal.invokers.TestInvoker.invokeTestMethod(TestInvoker.java:230)
at org.testng.internal.invokers.MethodRunner.runInSequence(MethodRunner.java:63)
at org.testng.internal.invokers.TestInvoker$MethodInvocationAgent.invoke(TestInvoker.java:995)
at org.testng.internal.invokers.TestInvoker.invokeTestMethods(TestInvoker.java:203)
at org.testng.internal.invokers.TestMethodWorker.invokeTestMethods(TestMethodWorker.java:154)
at org.testng.internal.invokers.TestMethodWorker.run(TestMethodWorker.java:134)
at java.base/java.util.ArrayList.forEach(ArrayList.java:1596)
at org.testng.TestRunner.privateRun(TestRunner.java:741)
at org.testng.TestRunner.run(TestRunner.java:616)
at org.testng.SuiteRunner.runTest(SuiteRunner.java:421)
at org.testng.SuiteRunner$SuiteWorker.run(SuiteRunner.java:463)
at org.testng.internal.thread.ThreadUtil.lambda$execute$0(ThreadUtil.java:64)
at java.base/java.util.concurrent.FutureTask.run(FutureTask.java:317)
at java.base/java.util.concurrent.ThreadPoolExecutor.runWorker(ThreadPoolExecutor.java:1144)
at java.base/java.util.concurrent.ThreadPoolExecutor$Worker.run(ThreadPoolExecutor.java:642)
at java.base/java.lang.Thread.run(Thread.java:1583)
]]>
            </full-stacktrace>
          </exception> <!-- java.lang.AssertionError -->
          <reporter-output>
          </reporter-output>
        </test-method> <!-- testLogin -->
        <test-method retried="true" signature="testLogin(java.lang.String,java.lang.String)[pri:0, instance:testCases.TC02_Login@1b75c2e3]" started-at="2025-05-20T18:05:42 EDT" name="testLogin" data-provider="LoginData" finished-at="2025-05-20T18:05:43 EDT" duration-ms="29" status="SKIP">
          <params>
            <param index="0">
              <value>
                <![CDATA[nona@yahoo.com]]>
              </value>
            </param>
            <param index="1">
              <value>
                <![CDATA[QWER!@#$]]>
              </value>
            </param>
          </params>
          <exception class="java.lang.AssertionError">
            <message>
              <![CDATA[Unexpected exception during login test execution.]]>
            </message>
            <full-stacktrace>
              <![CDATA[java.lang.AssertionError: Unexpected exception during login test execution.
at org.testng.Assert.fail(Assert.java:111)
at testCases.TC02_Login.testLogin(TC02_Login.java:69)
at java.base/jdk.internal.reflect.DirectMethodHandleAccessor.invoke(DirectMethodHandleAccessor.java:103)
at java.base/java.lang.reflect.Method.invoke(Method.java:580)
at org.testng.internal.invokers.MethodInvocationHelper.invokeMethod(MethodInvocationHelper.java:141)
at org.testng.internal.invokers.TestInvoker.invokeMethod(TestInvoker.java:687)
at org.testng.internal.invokers.TestInvoker.retryFailed(TestInvoker.java:269)
at org.testng.internal.invokers.MethodRunner.runInSequence(MethodRunner.java:76)
at org.testng.internal.invokers.TestInvoker$MethodInvocationAgent.invoke(TestInvoker.java:995)
at org.testng.internal.invokers.TestInvoker.invokeTestMethods(TestInvoker.java:203)
at org.testng.internal.invokers.TestMethodWorker.invokeTestMethods(TestMethodWorker.java:154)
at org.testng.internal.invokers.TestMethodWorker.run(TestMethodWorker.java:134)
at java.base/java.util.ArrayList.forEach(ArrayList.java:1596)
at org.testng.TestRunner.privateRun(TestRunner.java:741)
at org.testng.TestRunner.run(TestRunner.java:616)
at org.testng.SuiteRunner.runTest(SuiteRunner.java:421)
at org.testng.SuiteRunner$SuiteWorker.run(SuiteRunner.java:463)
at org.testng.internal.thread.ThreadUtil.lambda$execute$0(ThreadUtil.java:64)
at java.base/java.util.concurrent.FutureTask.run(FutureTask.java:317)
at java.base/java.util.concurrent.ThreadPoolExecutor.runWorker(ThreadPoolExecutor.java:1144)
at java.base/java.util.concurrent.ThreadPoolExecutor$Worker.run(ThreadPoolExecutor.java:642)
at java.base/java.lang.Thread.run(Thread.java:1583)
]]>
            </full-stacktrace>
          </exception> <!-- java.lang.AssertionError -->
          <reporter-output>
          </reporter-output>
        </test-method> <!-- testLogin -->
        <test-method signature="testLogin(java.lang.String,java.lang.String)[pri:0, instance:testCases.TC02_Login@1b75c2e3]" started-at="2025-05-20T18:05:43 EDT" name="testLogin" data-provider="LoginData" finished-at="2025-05-20T18:05:43 EDT" duration-ms="5" status="FAIL">
          <params>
            <param index="0">
              <value>
                <![CDATA[nona@yahoo.com]]>
              </value>
            </param>
            <param index="1">
              <value>
                <![CDATA[QWER!@#$]]>
              </value>
            </param>
          </params>
          <exception class="java.lang.AssertionError">
            <message>
              <![CDATA[Unexpected exception during login test execution.]]>
            </message>
            <full-stacktrace>
              <![CDATA[java.lang.AssertionError: Unexpected exception during login test execution.
at org.testng.Assert.fail(Assert.java:111)
at testCases.TC02_Login.testLogin(TC02_Login.java:69)
at java.base/jdk.internal.reflect.DirectMethodHandleAccessor.invoke(DirectMethodHandleAccessor.java:103)
at java.base/java.lang.reflect.Method.invoke(Method.java:580)
at org.testng.internal.invokers.MethodInvocationHelper.invokeMethod(MethodInvocationHelper.java:141)
at org.testng.internal.invokers.TestInvoker.invokeMethod(TestInvoker.java:687)
at org.testng.internal.invokers.TestInvoker.retryFailed(TestInvoker.java:269)
at org.testng.internal.invokers.MethodRunner.runInSequence(MethodRunner.java:76)
at org.testng.internal.invokers.TestInvoker$MethodInvocationAgent.invoke(TestInvoker.java:995)
at org.testng.internal.invokers.TestInvoker.invokeTestMethods(TestInvoker.java:203)
at org.testng.internal.invokers.TestMethodWorker.invokeTestMethods(TestMethodWorker.java:154)
at org.testng.internal.invokers.TestMethodWorker.run(TestMethodWorker.java:134)
at java.base/java.util.ArrayList.forEach(ArrayList.java:1596)
at org.testng.TestRunner.privateRun(TestRunner.java:741)
at org.testng.TestRunner.run(TestRunner.java:616)
at org.testng.SuiteRunner.runTest(SuiteRunner.java:421)
at org.testng.SuiteRunner$SuiteWorker.run(SuiteRunner.java:463)
at org.testng.internal.thread.ThreadUtil.lambda$execute$0(ThreadUtil.java:64)
at java.base/java.util.concurrent.FutureTask.run(FutureTask.java:317)
at java.base/java.util.concurrent.ThreadPoolExecutor.runWorker(ThreadPoolExecutor.java:1144)
at java.base/java.util.concurrent.ThreadPoolExecutor$Worker.run(ThreadPoolExecutor.java:642)
at java.base/java.lang.Thread.run(Thread.java:1583)
]]>
            </full-stacktrace>
          </exception> <!-- java.lang.AssertionError -->
          <reporter-output>
          </reporter-output>
        </test-method> <!-- testLogin -->
        <test-method retried="true" signature="testLogin(java.lang.String,java.lang.String)[pri:0, instance:testCases.TC02_Login@1b75c2e3]" started-at="2025-05-20T18:05:43 EDT" name="testLogin" data-provider="LoginData" finished-at="2025-05-20T18:05:43 EDT" duration-ms="8" status="SKIP">
          <params>
            <param index="0">
              <value>
                <![CDATA[sid@cloudberry.services]]>
              </value>
            </param>
            <param index="1">
              <value>
                <![CDATA[Test123]]>
              </value>
            </param>
          </params>
          <exception class="java.lang.AssertionError">
            <message>
              <![CDATA[Unexpected exception during login test execution.]]>
            </message>
            <full-stacktrace>
              <![CDATA[java.lang.AssertionError: Unexpected exception during login test execution.
at org.testng.Assert.fail(Assert.java:111)
at testCases.TC02_Login.testLogin(TC02_Login.java:69)
at java.base/jdk.internal.reflect.DirectMethodHandleAccessor.invoke(DirectMethodHandleAccessor.java:103)
at java.base/java.lang.reflect.Method.invoke(Method.java:580)
at org.testng.internal.invokers.MethodInvocationHelper.invokeMethod(MethodInvocationHelper.java:141)
at org.testng.internal.invokers.TestInvoker.invokeMethod(TestInvoker.java:687)
at org.testng.internal.invokers.TestInvoker.invokeTestMethod(TestInvoker.java:230)
at org.testng.internal.invokers.MethodRunner.runInSequence(MethodRunner.java:63)
at org.testng.internal.invokers.TestInvoker$MethodInvocationAgent.invoke(TestInvoker.java:995)
at org.testng.internal.invokers.TestInvoker.invokeTestMethods(TestInvoker.java:203)
at org.testng.internal.invokers.TestMethodWorker.invokeTestMethods(TestMethodWorker.java:154)
at org.testng.internal.invokers.TestMethodWorker.run(TestMethodWorker.java:134)
at java.base/java.util.ArrayList.forEach(ArrayList.java:1596)
at org.testng.TestRunner.privateRun(TestRunner.java:741)
at org.testng.TestRunner.run(TestRunner.java:616)
at org.testng.SuiteRunner.runTest(SuiteRunner.java:421)
at org.testng.SuiteRunner$SuiteWorker.run(SuiteRunner.java:463)
at org.testng.internal.thread.ThreadUtil.lambda$execute$0(ThreadUtil.java:64)
at java.base/java.util.concurrent.FutureTask.run(FutureTask.java:317)
at java.base/java.util.concurrent.ThreadPoolExecutor.runWorker(ThreadPoolExecutor.java:1144)
at java.base/java.util.concurrent.ThreadPoolExecutor$Worker.run(ThreadPoolExecutor.java:642)
at java.base/java.lang.Thread.run(Thread.java:1583)
]]>
            </full-stacktrace>
          </exception> <!-- java.lang.AssertionError -->
          <reporter-output>
          </reporter-output>
        </test-method> <!-- testLogin -->
        <test-method retried="true" signature="testLogin(java.lang.String,java.lang.String)[pri:0, instance:testCases.TC02_Login@1b75c2e3]" started-at="2025-05-20T18:05:43 EDT" name="testLogin" data-provider="LoginData" finished-at="2025-05-20T18:05:43 EDT" duration-ms="6" status="SKIP">
          <params>
            <param index="0">
              <value>
                <![CDATA[sid@cloudberry.services]]>
              </value>
            </param>
            <param index="1">
              <value>
                <![CDATA[Test123]]>
              </value>
            </param>
          </params>
          <exception class="java.lang.AssertionError">
            <message>
              <![CDATA[Unexpected exception during login test execution.]]>
            </message>
            <full-stacktrace>
              <![CDATA[java.lang.AssertionError: Unexpected exception during login test execution.
at org.testng.Assert.fail(Assert.java:111)
at testCases.TC02_Login.testLogin(TC02_Login.java:69)
at java.base/jdk.internal.reflect.DirectMethodHandleAccessor.invoke(DirectMethodHandleAccessor.java:103)
at java.base/java.lang.reflect.Method.invoke(Method.java:580)
at org.testng.internal.invokers.MethodInvocationHelper.invokeMethod(MethodInvocationHelper.java:141)
at org.testng.internal.invokers.TestInvoker.invokeMethod(TestInvoker.java:687)
at org.testng.internal.invokers.TestInvoker.retryFailed(TestInvoker.java:269)
at org.testng.internal.invokers.MethodRunner.runInSequence(MethodRunner.java:76)
at org.testng.internal.invokers.TestInvoker$MethodInvocationAgent.invoke(TestInvoker.java:995)
at org.testng.internal.invokers.TestInvoker.invokeTestMethods(TestInvoker.java:203)
at org.testng.internal.invokers.TestMethodWorker.invokeTestMethods(TestMethodWorker.java:154)
at org.testng.internal.invokers.TestMethodWorker.run(TestMethodWorker.java:134)
at java.base/java.util.ArrayList.forEach(ArrayList.java:1596)
at org.testng.TestRunner.privateRun(TestRunner.java:741)
at org.testng.TestRunner.run(TestRunner.java:616)
at org.testng.SuiteRunner.runTest(SuiteRunner.java:421)
at org.testng.SuiteRunner$SuiteWorker.run(SuiteRunner.java:463)
at org.testng.internal.thread.ThreadUtil.lambda$execute$0(ThreadUtil.java:64)
at java.base/java.util.concurrent.FutureTask.run(FutureTask.java:317)
at java.base/java.util.concurrent.ThreadPoolExecutor.runWorker(ThreadPoolExecutor.java:1144)
at java.base/java.util.concurrent.ThreadPoolExecutor$Worker.run(ThreadPoolExecutor.java:642)
at java.base/java.lang.Thread.run(Thread.java:1583)
]]>
            </full-stacktrace>
          </exception> <!-- java.lang.AssertionError -->
          <reporter-output>
          </reporter-output>
        </test-method> <!-- testLogin -->
        <test-method signature="testLogin(java.lang.String,java.lang.String)[pri:0, instance:testCases.TC02_Login@1b75c2e3]" started-at="2025-05-20T18:05:43 EDT" name="testLogin" data-provider="LoginData" finished-at="2025-05-20T18:05:43 EDT" duration-ms="1" status="FAIL">
          <params>
            <param index="0">
              <value>
                <![CDATA[sid@cloudberry.services]]>
              </value>
            </param>
            <param index="1">
              <value>
                <![CDATA[Test123]]>
              </value>
            </param>
          </params>
          <exception class="java.lang.AssertionError">
            <message>
              <![CDATA[Unexpected exception during login test execution.]]>
            </message>
            <full-stacktrace>
              <![CDATA[java.lang.AssertionError: Unexpected exception during login test execution.
at org.testng.Assert.fail(Assert.java:111)
at testCases.TC02_Login.testLogin(TC02_Login.java:69)
at java.base/jdk.internal.reflect.DirectMethodHandleAccessor.invoke(DirectMethodHandleAccessor.java:103)
at java.base/java.lang.reflect.Method.invoke(Method.java:580)
at org.testng.internal.invokers.MethodInvocationHelper.invokeMethod(MethodInvocationHelper.java:141)
at org.testng.internal.invokers.TestInvoker.invokeMethod(TestInvoker.java:687)
at org.testng.internal.invokers.TestInvoker.retryFailed(TestInvoker.java:269)
at org.testng.internal.invokers.MethodRunner.runInSequence(MethodRunner.java:76)
at org.testng.internal.invokers.TestInvoker$MethodInvocationAgent.invoke(TestInvoker.java:995)
at org.testng.internal.invokers.TestInvoker.invokeTestMethods(TestInvoker.java:203)
at org.testng.internal.invokers.TestMethodWorker.invokeTestMethods(TestMethodWorker.java:154)
at org.testng.internal.invokers.TestMethodWorker.run(TestMethodWorker.java:134)
at java.base/java.util.ArrayList.forEach(ArrayList.java:1596)
at org.testng.TestRunner.privateRun(TestRunner.java:741)
at org.testng.TestRunner.run(TestRunner.java:616)
at org.testng.SuiteRunner.runTest(SuiteRunner.java:421)
at org.testng.SuiteRunner$SuiteWorker.run(SuiteRunner.java:463)
at org.testng.internal.thread.ThreadUtil.lambda$execute$0(ThreadUtil.java:64)
at java.base/java.util.concurrent.FutureTask.run(FutureTask.java:317)
at java.base/java.util.concurrent.ThreadPoolExecutor.runWorker(ThreadPoolExecutor.java:1144)
at java.base/java.util.concurrent.ThreadPoolExecutor$Worker.run(ThreadPoolExecutor.java:642)
at java.base/java.lang.Thread.run(Thread.java:1583)
]]>
            </full-stacktrace>
          </exception> <!-- java.lang.AssertionError -->
          <reporter-output>
          </reporter-output>
        </test-method> <!-- testLogin -->
        <test-method retried="true" signature="testLogin(java.lang.String,java.lang.String)[pri:0, instance:testCases.TC02_Login@1b75c2e3]" started-at="2025-05-20T18:05:43 EDT" name="testLogin" data-provider="LoginData" finished-at="2025-05-20T18:05:43 EDT" duration-ms="1" status="SKIP">
          <params>
            <param index="0">
              <value>
                <![CDATA[apushedwoman@gmail.com]]>
              </value>
            </param>
            <param index="1">
              <value>
                <![CDATA[password123]]>
              </value>
            </param>
          </params>
          <exception class="java.lang.AssertionError">
            <message>
              <![CDATA[Unexpected exception during login test execution.]]>
            </message>
            <full-stacktrace>
              <![CDATA[java.lang.AssertionError: Unexpected exception during login test execution.
at org.testng.Assert.fail(Assert.java:111)
at testCases.TC02_Login.testLogin(TC02_Login.java:69)
at java.base/jdk.internal.reflect.DirectMethodHandleAccessor.invoke(DirectMethodHandleAccessor.java:103)
at java.base/java.lang.reflect.Method.invoke(Method.java:580)
at org.testng.internal.invokers.MethodInvocationHelper.invokeMethod(MethodInvocationHelper.java:141)
at org.testng.internal.invokers.TestInvoker.invokeMethod(TestInvoker.java:687)
at org.testng.internal.invokers.TestInvoker.invokeTestMethod(TestInvoker.java:230)
at org.testng.internal.invokers.MethodRunner.runInSequence(MethodRunner.java:63)
at org.testng.internal.invokers.TestInvoker$MethodInvocationAgent.invoke(TestInvoker.java:995)
at org.testng.internal.invokers.TestInvoker.invokeTestMethods(TestInvoker.java:203)
at org.testng.internal.invokers.TestMethodWorker.invokeTestMethods(TestMethodWorker.java:154)
at org.testng.internal.invokers.TestMethodWorker.run(TestMethodWorker.java:134)
at java.base/java.util.ArrayList.forEach(ArrayList.java:1596)
at org.testng.TestRunner.privateRun(TestRunner.java:741)
at org.testng.TestRunner.run(TestRunner.java:616)
at org.testng.SuiteRunner.runTest(SuiteRunner.java:421)
at org.testng.SuiteRunner$SuiteWorker.run(SuiteRunner.java:463)
at org.testng.internal.thread.ThreadUtil.lambda$execute$0(ThreadUtil.java:64)
at java.base/java.util.concurrent.FutureTask.run(FutureTask.java:317)
at java.base/java.util.concurrent.ThreadPoolExecutor.runWorker(ThreadPoolExecutor.java:1144)
at java.base/java.util.concurrent.ThreadPoolExecutor$Worker.run(ThreadPoolExecutor.java:642)
at java.base/java.lang.Thread.run(Thread.java:1583)
]]>
            </full-stacktrace>
          </exception> <!-- java.lang.AssertionError -->
          <reporter-output>
          </reporter-output>
        </test-method> <!-- testLogin -->
        <test-method retried="true" signature="testLogin(java.lang.String,java.lang.String)[pri:0, instance:testCases.TC02_Login@1b75c2e3]" started-at="2025-05-20T18:05:43 EDT" name="testLogin" data-provider="LoginData" finished-at="2025-05-20T18:05:43 EDT" duration-ms="2" status="SKIP">
          <params>
            <param index="0">
              <value>
                <![CDATA[apushedwoman@gmail.com]]>
              </value>
            </param>
            <param index="1">
              <value>
                <![CDATA[password123]]>
              </value>
            </param>
          </params>
          <exception class="java.lang.AssertionError">
            <message>
              <![CDATA[Unexpected exception during login test execution.]]>
            </message>
            <full-stacktrace>
              <![CDATA[java.lang.AssertionError: Unexpected exception during login test execution.
at org.testng.Assert.fail(Assert.java:111)
at testCases.TC02_Login.testLogin(TC02_Login.java:69)
at java.base/jdk.internal.reflect.DirectMethodHandleAccessor.invoke(DirectMethodHandleAccessor.java:103)
at java.base/java.lang.reflect.Method.invoke(Method.java:580)
at org.testng.internal.invokers.MethodInvocationHelper.invokeMethod(MethodInvocationHelper.java:141)
at org.testng.internal.invokers.TestInvoker.invokeMethod(TestInvoker.java:687)
at org.testng.internal.invokers.TestInvoker.retryFailed(TestInvoker.java:269)
at org.testng.internal.invokers.MethodRunner.runInSequence(MethodRunner.java:76)
at org.testng.internal.invokers.TestInvoker$MethodInvocationAgent.invoke(TestInvoker.java:995)
at org.testng.internal.invokers.TestInvoker.invokeTestMethods(TestInvoker.java:203)
at org.testng.internal.invokers.TestMethodWorker.invokeTestMethods(TestMethodWorker.java:154)
at org.testng.internal.invokers.TestMethodWorker.run(TestMethodWorker.java:134)
at java.base/java.util.ArrayList.forEach(ArrayList.java:1596)
at org.testng.TestRunner.privateRun(TestRunner.java:741)
at org.testng.TestRunner.run(TestRunner.java:616)
at org.testng.SuiteRunner.runTest(SuiteRunner.java:421)
at org.testng.SuiteRunner$SuiteWorker.run(SuiteRunner.java:463)
at org.testng.internal.thread.ThreadUtil.lambda$execute$0(ThreadUtil.java:64)
at java.base/java.util.concurrent.FutureTask.run(FutureTask.java:317)
at java.base/java.util.concurrent.ThreadPoolExecutor.runWorker(ThreadPoolExecutor.java:1144)
at java.base/java.util.concurrent.ThreadPoolExecutor$Worker.run(ThreadPoolExecutor.java:642)
at java.base/java.lang.Thread.run(Thread.java:1583)
]]>
            </full-stacktrace>
          </exception> <!-- java.lang.AssertionError -->
          <reporter-output>
          </reporter-output>
        </test-method> <!-- testLogin -->
        <test-method signature="testLogin(java.lang.String,java.lang.String)[pri:0, instance:testCases.TC02_Login@1b75c2e3]" started-at="2025-05-20T18:05:43 EDT" name="testLogin" data-provider="LoginData" finished-at="2025-05-20T18:05:43 EDT" duration-ms="22" status="FAIL">
          <params>
            <param index="0">
              <value>
                <![CDATA[apushedwoman@gmail.com]]>
              </value>
            </param>
            <param index="1">
              <value>
                <![CDATA[password123]]>
              </value>
            </param>
          </params>
          <exception class="java.lang.AssertionError">
            <message>
              <![CDATA[Unexpected exception during login test execution.]]>
            </message>
            <full-stacktrace>
              <![CDATA[java.lang.AssertionError: Unexpected exception during login test execution.
at org.testng.Assert.fail(Assert.java:111)
at testCases.TC02_Login.testLogin(TC02_Login.java:69)
at java.base/jdk.internal.reflect.DirectMethodHandleAccessor.invoke(DirectMethodHandleAccessor.java:103)
at java.base/java.lang.reflect.Method.invoke(Method.java:580)
at org.testng.internal.invokers.MethodInvocationHelper.invokeMethod(MethodInvocationHelper.java:141)
at org.testng.internal.invokers.TestInvoker.invokeMethod(TestInvoker.java:687)
at org.testng.internal.invokers.TestInvoker.retryFailed(TestInvoker.java:269)
at org.testng.internal.invokers.MethodRunner.runInSequence(MethodRunner.java:76)
at org.testng.internal.invokers.TestInvoker$MethodInvocationAgent.invoke(TestInvoker.java:995)
at org.testng.internal.invokers.TestInvoker.invokeTestMethods(TestInvoker.java:203)
at org.testng.internal.invokers.TestMethodWorker.invokeTestMethods(TestMethodWorker.java:154)
at org.testng.internal.invokers.TestMethodWorker.run(TestMethodWorker.java:134)
at java.base/java.util.ArrayList.forEach(ArrayList.java:1596)
at org.testng.TestRunner.privateRun(TestRunner.java:741)
at org.testng.TestRunner.run(TestRunner.java:616)
at org.testng.SuiteRunner.runTest(SuiteRunner.java:421)
at org.testng.SuiteRunner$SuiteWorker.run(SuiteRunner.java:463)
at org.testng.internal.thread.ThreadUtil.lambda$execute$0(ThreadUtil.java:64)
at java.base/java.util.concurrent.FutureTask.run(FutureTask.java:317)
at java.base/java.util.concurrent.ThreadPoolExecutor.runWorker(ThreadPoolExecutor.java:1144)
at java.base/java.util.concurrent.ThreadPoolExecutor$Worker.run(ThreadPoolExecutor.java:642)
at java.base/java.lang.Thread.run(Thread.java:1583)
]]>
            </full-stacktrace>
          </exception> <!-- java.lang.AssertionError -->
          <reporter-output>
          </reporter-output>
        </test-method> <!-- testLogin -->
        <test-method retried="true" signature="testLogin(java.lang.String,java.lang.String)[pri:0, instance:testCases.TC02_Login@1b75c2e3]" started-at="2025-05-20T18:05:43 EDT" name="testLogin" data-provider="LoginData" finished-at="2025-05-20T18:05:43 EDT" duration-ms="7" status="SKIP">
          <params>
            <param index="0">
              <value>
                <![CDATA[hichamkhachiai@gmail.com]]>
              </value>
            </param>
            <param index="1">
              <value>
                <![CDATA[hicham123]]>
              </value>
            </param>
          </params>
          <exception class="java.lang.AssertionError">
            <message>
              <![CDATA[Unexpected exception during login test execution.]]>
            </message>
            <full-stacktrace>
              <![CDATA[java.lang.AssertionError: Unexpected exception during login test execution.
at org.testng.Assert.fail(Assert.java:111)
at testCases.TC02_Login.testLogin(TC02_Login.java:69)
at java.base/jdk.internal.reflect.DirectMethodHandleAccessor.invoke(DirectMethodHandleAccessor.java:103)
at java.base/java.lang.reflect.Method.invoke(Method.java:580)
at org.testng.internal.invokers.MethodInvocationHelper.invokeMethod(MethodInvocationHelper.java:141)
at org.testng.internal.invokers.TestInvoker.invokeMethod(TestInvoker.java:687)
at org.testng.internal.invokers.TestInvoker.invokeTestMethod(TestInvoker.java:230)
at org.testng.internal.invokers.MethodRunner.runInSequence(MethodRunner.java:63)
at org.testng.internal.invokers.TestInvoker$MethodInvocationAgent.invoke(TestInvoker.java:995)
at org.testng.internal.invokers.TestInvoker.invokeTestMethods(TestInvoker.java:203)
at org.testng.internal.invokers.TestMethodWorker.invokeTestMethods(TestMethodWorker.java:154)
at org.testng.internal.invokers.TestMethodWorker.run(TestMethodWorker.java:134)
at java.base/java.util.ArrayList.forEach(ArrayList.java:1596)
at org.testng.TestRunner.privateRun(TestRunner.java:741)
at org.testng.TestRunner.run(TestRunner.java:616)
at org.testng.SuiteRunner.runTest(SuiteRunner.java:421)
at org.testng.SuiteRunner$SuiteWorker.run(SuiteRunner.java:463)
at org.testng.internal.thread.ThreadUtil.lambda$execute$0(ThreadUtil.java:64)
at java.base/java.util.concurrent.FutureTask.run(FutureTask.java:317)
at java.base/java.util.concurrent.ThreadPoolExecutor.runWorker(ThreadPoolExecutor.java:1144)
at java.base/java.util.concurrent.ThreadPoolExecutor$Worker.run(ThreadPoolExecutor.java:642)
at java.base/java.lang.Thread.run(Thread.java:1583)
]]>
            </full-stacktrace>
          </exception> <!-- java.lang.AssertionError -->
          <reporter-output>
          </reporter-output>
        </test-method> <!-- testLogin -->
        <test-method retried="true" signature="testLogin(java.lang.String,java.lang.String)[pri:0, instance:testCases.TC02_Login@1b75c2e3]" started-at="2025-05-20T18:05:43 EDT" name="testLogin" data-provider="LoginData" finished-at="2025-05-20T18:05:43 EDT" duration-ms="3" status="SKIP">
          <params>
            <param index="0">
              <value>
                <![CDATA[hichamkhachiai@gmail.com]]>
              </value>
            </param>
            <param index="1">
              <value>
                <![CDATA[hicham123]]>
              </value>
            </param>
          </params>
          <exception class="java.lang.AssertionError">
            <message>
              <![CDATA[Unexpected exception during login test execution.]]>
            </message>
            <full-stacktrace>
              <![CDATA[java.lang.AssertionError: Unexpected exception during login test execution.
at org.testng.Assert.fail(Assert.java:111)
at testCases.TC02_Login.testLogin(TC02_Login.java:69)
at java.base/jdk.internal.reflect.DirectMethodHandleAccessor.invoke(DirectMethodHandleAccessor.java:103)
at java.base/java.lang.reflect.Method.invoke(Method.java:580)
at org.testng.internal.invokers.MethodInvocationHelper.invokeMethod(MethodInvocationHelper.java:141)
at org.testng.internal.invokers.TestInvoker.invokeMethod(TestInvoker.java:687)
at org.testng.internal.invokers.TestInvoker.retryFailed(TestInvoker.java:269)
at org.testng.internal.invokers.MethodRunner.runInSequence(MethodRunner.java:76)
at org.testng.internal.invokers.TestInvoker$MethodInvocationAgent.invoke(TestInvoker.java:995)
at org.testng.internal.invokers.TestInvoker.invokeTestMethods(TestInvoker.java:203)
at org.testng.internal.invokers.TestMethodWorker.invokeTestMethods(TestMethodWorker.java:154)
at org.testng.internal.invokers.TestMethodWorker.run(TestMethodWorker.java:134)
at java.base/java.util.ArrayList.forEach(ArrayList.java:1596)
at org.testng.TestRunner.privateRun(TestRunner.java:741)
at org.testng.TestRunner.run(TestRunner.java:616)
at org.testng.SuiteRunner.runTest(SuiteRunner.java:421)
at org.testng.SuiteRunner$SuiteWorker.run(SuiteRunner.java:463)
at org.testng.internal.thread.ThreadUtil.lambda$execute$0(ThreadUtil.java:64)
at java.base/java.util.concurrent.FutureTask.run(FutureTask.java:317)
at java.base/java.util.concurrent.ThreadPoolExecutor.runWorker(ThreadPoolExecutor.java:1144)
at java.base/java.util.concurrent.ThreadPoolExecutor$Worker.run(ThreadPoolExecutor.java:642)
at java.base/java.lang.Thread.run(Thread.java:1583)
]]>
            </full-stacktrace>
          </exception> <!-- java.lang.AssertionError -->
          <reporter-output>
          </reporter-output>
        </test-method> <!-- testLogin -->
        <test-method signature="testLogin(java.lang.String,java.lang.String)[pri:0, instance:testCases.TC02_Login@1b75c2e3]" started-at="2025-05-20T18:05:43 EDT" name="testLogin" data-provider="LoginData" finished-at="2025-05-20T18:05:43 EDT" duration-ms="10" status="FAIL">
          <params>
            <param index="0">
              <value>
                <![CDATA[hichamkhachiai@gmail.com]]>
              </value>
            </param>
            <param index="1">
              <value>
                <![CDATA[hicham123]]>
              </value>
            </param>
          </params>
          <exception class="java.lang.AssertionError">
            <message>
              <![CDATA[Unexpected exception during login test execution.]]>
            </message>
            <full-stacktrace>
              <![CDATA[java.lang.AssertionError: Unexpected exception during login test execution.
at org.testng.Assert.fail(Assert.java:111)
at testCases.TC02_Login.testLogin(TC02_Login.java:69)
at java.base/jdk.internal.reflect.DirectMethodHandleAccessor.invoke(DirectMethodHandleAccessor.java:103)
at java.base/java.lang.reflect.Method.invoke(Method.java:580)
at org.testng.internal.invokers.MethodInvocationHelper.invokeMethod(MethodInvocationHelper.java:141)
at org.testng.internal.invokers.TestInvoker.invokeMethod(TestInvoker.java:687)
at org.testng.internal.invokers.TestInvoker.retryFailed(TestInvoker.java:269)
at org.testng.internal.invokers.MethodRunner.runInSequence(MethodRunner.java:76)
at org.testng.internal.invokers.TestInvoker$MethodInvocationAgent.invoke(TestInvoker.java:995)
at org.testng.internal.invokers.TestInvoker.invokeTestMethods(TestInvoker.java:203)
at org.testng.internal.invokers.TestMethodWorker.invokeTestMethods(TestMethodWorker.java:154)
at org.testng.internal.invokers.TestMethodWorker.run(TestMethodWorker.java:134)
at java.base/java.util.ArrayList.forEach(ArrayList.java:1596)
at org.testng.TestRunner.privateRun(TestRunner.java:741)
at org.testng.TestRunner.run(TestRunner.java:616)
at org.testng.SuiteRunner.runTest(SuiteRunner.java:421)
at org.testng.SuiteRunner$SuiteWorker.run(SuiteRunner.java:463)
at org.testng.internal.thread.ThreadUtil.lambda$execute$0(ThreadUtil.java:64)
at java.base/java.util.concurrent.FutureTask.run(FutureTask.java:317)
at java.base/java.util.concurrent.ThreadPoolExecutor.runWorker(ThreadPoolExecutor.java:1144)
at java.base/java.util.concurrent.ThreadPoolExecutor$Worker.run(ThreadPoolExecutor.java:642)
at java.base/java.lang.Thread.run(Thread.java:1583)
]]>
            </full-stacktrace>
          </exception> <!-- java.lang.AssertionError -->
          <reporter-output>
          </reporter-output>
        </test-method> <!-- testLogin -->
        <test-method is-config="true" signature="closeApp()[pri:0, instance:testCases.TC02_Login@1b75c2e3]" started-at="2025-05-20T18:05:43 EDT" name="closeApp" finished-at="2025-05-20T18:05:43 EDT" duration-ms="5" status="PASS">
          <reporter-output>
          </reporter-output>
        </test-method> <!-- closeApp -->
      </class> <!-- testCases.TC02_Login -->
      <class name="testCases.TC01_LaunchApplication">
        <test-method is-config="true" signature="openApp(java.lang.String,java.lang.String)[pri:0, instance:testCases.TC01_LaunchApplication@46b61c56]" started-at="2025-05-20T18:05:37 EDT" name="openApp" finished-at="2025-05-20T18:05:39 EDT" duration-ms="1704" status="PASS">
          <params>
            <param index="0">
              <value>
                <![CDATA[windows]]>
              </value>
            </param>
            <param index="1">
              <value>
                <![CDATA[chrome]]>
              </value>
            </param>
          </params>
          <reporter-output>
          </reporter-output>
        </test-method> <!-- openApp -->
        <test-method retried="true" signature="testLaunchApplication()[pri:0, instance:testCases.TC01_LaunchApplication@46b61c56]" started-at="2025-05-20T18:05:39 EDT" name="testLaunchApplication" finished-at="2025-05-20T18:05:39 EDT" duration-ms="116" status="SKIP">
          <exception class="java.lang.AssertionError">
            <message>
              <![CDATA[Test failed due to unexpected exception]]>
            </message>
            <full-stacktrace>
              <![CDATA[java.lang.AssertionError: Test failed due to unexpected exception
at org.testng.Assert.fail(Assert.java:111)
at testCases.TC01_LaunchApplication.testLaunchApplication(TC01_LaunchApplication.java:35)
at java.base/jdk.internal.reflect.DirectMethodHandleAccessor.invoke(DirectMethodHandleAccessor.java:103)
at java.base/java.lang.reflect.Method.invoke(Method.java:580)
at org.testng.internal.invokers.MethodInvocationHelper.invokeMethod(MethodInvocationHelper.java:141)
at org.testng.internal.invokers.TestInvoker.invokeMethod(TestInvoker.java:687)
at org.testng.internal.invokers.TestInvoker.invokeTestMethod(TestInvoker.java:230)
at org.testng.internal.invokers.MethodRunner.runInSequence(MethodRunner.java:63)
at org.testng.internal.invokers.TestInvoker$MethodInvocationAgent.invoke(TestInvoker.java:995)
at org.testng.internal.invokers.TestInvoker.invokeTestMethods(TestInvoker.java:203)
at org.testng.internal.invokers.TestMethodWorker.invokeTestMethods(TestMethodWorker.java:154)
at org.testng.internal.invokers.TestMethodWorker.run(TestMethodWorker.java:134)
at java.base/java.util.ArrayList.forEach(ArrayList.java:1596)
at org.testng.TestRunner.privateRun(TestRunner.java:741)
at org.testng.TestRunner.run(TestRunner.java:616)
at org.testng.SuiteRunner.runTest(SuiteRunner.java:421)
at org.testng.SuiteRunner$SuiteWorker.run(SuiteRunner.java:463)
at org.testng.internal.thread.ThreadUtil.lambda$execute$0(ThreadUtil.java:64)
at java.base/java.util.concurrent.FutureTask.run(FutureTask.java:317)
at java.base/java.util.concurrent.ThreadPoolExecutor.runWorker(ThreadPoolExecutor.java:1144)
at java.base/java.util.concurrent.ThreadPoolExecutor$Worker.run(ThreadPoolExecutor.java:642)
at java.base/java.lang.Thread.run(Thread.java:1583)
]]>
            </full-stacktrace>
          </exception> <!-- java.lang.AssertionError -->
          <reporter-output>
          </reporter-output>
        </test-method> <!-- testLaunchApplication -->
        <test-method retried="true" signature="testLaunchApplication()[pri:0, instance:testCases.TC01_LaunchApplication@46b61c56]" started-at="2025-05-20T18:05:39 EDT" name="testLaunchApplication" finished-at="2025-05-20T18:05:39 EDT" duration-ms="11" status="SKIP">
          <exception class="java.lang.AssertionError">
            <message>
              <![CDATA[Test failed due to unexpected exception]]>
            </message>
            <full-stacktrace>
              <![CDATA[java.lang.AssertionError: Test failed due to unexpected exception
at org.testng.Assert.fail(Assert.java:111)
at testCases.TC01_LaunchApplication.testLaunchApplication(TC01_LaunchApplication.java:35)
at java.base/jdk.internal.reflect.DirectMethodHandleAccessor.invoke(DirectMethodHandleAccessor.java:103)
at java.base/java.lang.reflect.Method.invoke(Method.java:580)
at org.testng.internal.invokers.MethodInvocationHelper.invokeMethod(MethodInvocationHelper.java:141)
at org.testng.internal.invokers.TestInvoker.invokeMethod(TestInvoker.java:687)
at org.testng.internal.invokers.TestInvoker.retryFailed(TestInvoker.java:269)
at org.testng.internal.invokers.MethodRunner.runInSequence(MethodRunner.java:76)
at org.testng.internal.invokers.TestInvoker$MethodInvocationAgent.invoke(TestInvoker.java:995)
at org.testng.internal.invokers.TestInvoker.invokeTestMethods(TestInvoker.java:203)
at org.testng.internal.invokers.TestMethodWorker.invokeTestMethods(TestMethodWorker.java:154)
at org.testng.internal.invokers.TestMethodWorker.run(TestMethodWorker.java:134)
at java.base/java.util.ArrayList.forEach(ArrayList.java:1596)
at org.testng.TestRunner.privateRun(TestRunner.java:741)
at org.testng.TestRunner.run(TestRunner.java:616)
at org.testng.SuiteRunner.runTest(SuiteRunner.java:421)
at org.testng.SuiteRunner$SuiteWorker.run(SuiteRunner.java:463)
at org.testng.internal.thread.ThreadUtil.lambda$execute$0(ThreadUtil.java:64)
at java.base/java.util.concurrent.FutureTask.run(FutureTask.java:317)
at java.base/java.util.concurrent.ThreadPoolExecutor.runWorker(ThreadPoolExecutor.java:1144)
at java.base/java.util.concurrent.ThreadPoolExecutor$Worker.run(ThreadPoolExecutor.java:642)
at java.base/java.lang.Thread.run(Thread.java:1583)
]]>
            </full-stacktrace>
          </exception> <!-- java.lang.AssertionError -->
          <reporter-output>
          </reporter-output>
        </test-method> <!-- testLaunchApplication -->
        <test-method signature="testLaunchApplication()[pri:0, instance:testCases.TC01_LaunchApplication@46b61c56]" started-at="2025-05-20T18:05:39 EDT" name="testLaunchApplication" finished-at="2025-05-20T18:05:39 EDT" duration-ms="12" status="FAIL">
          <exception class="java.lang.AssertionError">
            <message>
              <![CDATA[Test failed due to unexpected exception]]>
            </message>
            <full-stacktrace>
              <![CDATA[java.lang.AssertionError: Test failed due to unexpected exception
at org.testng.Assert.fail(Assert.java:111)
at testCases.TC01_LaunchApplication.testLaunchApplication(TC01_LaunchApplication.java:35)
at java.base/jdk.internal.reflect.DirectMethodHandleAccessor.invoke(DirectMethodHandleAccessor.java:103)
at java.base/java.lang.reflect.Method.invoke(Method.java:580)
at org.testng.internal.invokers.MethodInvocationHelper.invokeMethod(MethodInvocationHelper.java:141)
at org.testng.internal.invokers.TestInvoker.invokeMethod(TestInvoker.java:687)
at org.testng.internal.invokers.TestInvoker.retryFailed(TestInvoker.java:269)
at org.testng.internal.invokers.MethodRunner.runInSequence(MethodRunner.java:76)
at org.testng.internal.invokers.TestInvoker$MethodInvocationAgent.invoke(TestInvoker.java:995)
at org.testng.internal.invokers.TestInvoker.invokeTestMethods(TestInvoker.java:203)
at org.testng.internal.invokers.TestMethodWorker.invokeTestMethods(TestMethodWorker.java:154)
at org.testng.internal.invokers.TestMethodWorker.run(TestMethodWorker.java:134)
at java.base/java.util.ArrayList.forEach(ArrayList.java:1596)
at org.testng.TestRunner.privateRun(TestRunner.java:741)
at org.testng.TestRunner.run(TestRunner.java:616)
at org.testng.SuiteRunner.runTest(SuiteRunner.java:421)
at org.testng.SuiteRunner$SuiteWorker.run(SuiteRunner.java:463)
at org.testng.internal.thread.ThreadUtil.lambda$execute$0(ThreadUtil.java:64)
at java.base/java.util.concurrent.FutureTask.run(FutureTask.java:317)
at java.base/java.util.concurrent.ThreadPoolExecutor.runWorker(ThreadPoolExecutor.java:1144)
at java.base/java.util.concurrent.ThreadPoolExecutor$Worker.run(ThreadPoolExecutor.java:642)
at java.base/java.lang.Thread.run(Thread.java:1583)
]]>
            </full-stacktrace>
          </exception> <!-- java.lang.AssertionError -->
          <reporter-output>
          </reporter-output>
        </test-method> <!-- testLaunchApplication -->
        <test-method is-config="true" signature="closeApp()[pri:0, instance:testCases.TC01_LaunchApplication@46b61c56]" started-at="2025-05-20T18:05:39 EDT" name="closeApp" finished-at="2025-05-20T18:05:39 EDT" duration-ms="18" status="PASS">
          <reporter-output>
          </reporter-output>
        </test-method> <!-- closeApp -->
      </class> <!-- testCases.TC01_LaunchApplication -->
      <class name="testCases.TC03_AddToCart">
        <test-method is-config="true" signature="openApp(java.lang.String,java.lang.String)[pri:0, instance:testCases.TC03_AddToCart@7e5c856f]" started-at="2025-05-20T18:05:39 EDT" name="openApp" finished-at="2025-05-20T18:05:39 EDT" duration-ms="116" status="PASS">
          <params>
            <param index="0">
              <value>
                <![CDATA[windows]]>
              </value>
            </param>
            <param index="1">
              <value>
                <![CDATA[chrome]]>
              </value>
            </param>
          </params>
          <reporter-output>
          </reporter-output>
        </test-method> <!-- openApp -->
        <test-method retried="true" signature="testAddToCart()[pri:0, instance:testCases.TC03_AddToCart@7e5c856f]" started-at="2025-05-20T18:05:39 EDT" name="testAddToCart" finished-at="2025-05-20T18:05:39 EDT" duration-ms="22" status="SKIP">
          <exception class="java.lang.AssertionError">
            <message>
              <![CDATA[Test failed due to unexpected exception.]]>
            </message>
            <full-stacktrace>
              <![CDATA[java.lang.AssertionError: Test failed due to unexpected exception.
at org.testng.Assert.fail(Assert.java:111)
at testCases.TC03_AddToCart.testAddToCart(TC03_AddToCart.java:55)
at java.base/jdk.internal.reflect.DirectMethodHandleAccessor.invoke(DirectMethodHandleAccessor.java:103)
at java.base/java.lang.reflect.Method.invoke(Method.java:580)
at org.testng.internal.invokers.MethodInvocationHelper.invokeMethod(MethodInvocationHelper.java:141)
at org.testng.internal.invokers.TestInvoker.invokeMethod(TestInvoker.java:687)
at org.testng.internal.invokers.TestInvoker.invokeTestMethod(TestInvoker.java:230)
at org.testng.internal.invokers.MethodRunner.runInSequence(MethodRunner.java:63)
at org.testng.internal.invokers.TestInvoker$MethodInvocationAgent.invoke(TestInvoker.java:995)
at org.testng.internal.invokers.TestInvoker.invokeTestMethods(TestInvoker.java:203)
at org.testng.internal.invokers.TestMethodWorker.invokeTestMethods(TestMethodWorker.java:154)
at org.testng.internal.invokers.TestMethodWorker.run(TestMethodWorker.java:134)
at java.base/java.util.ArrayList.forEach(ArrayList.java:1596)
at org.testng.TestRunner.privateRun(TestRunner.java:741)
at org.testng.TestRunner.run(TestRunner.java:616)
at org.testng.SuiteRunner.runTest(SuiteRunner.java:421)
at org.testng.SuiteRunner$SuiteWorker.run(SuiteRunner.java:463)
at org.testng.internal.thread.ThreadUtil.lambda$execute$0(ThreadUtil.java:64)
at java.base/java.util.concurrent.FutureTask.run(FutureTask.java:317)
at java.base/java.util.concurrent.ThreadPoolExecutor.runWorker(ThreadPoolExecutor.java:1144)
at java.base/java.util.concurrent.ThreadPoolExecutor$Worker.run(ThreadPoolExecutor.java:642)
at java.base/java.lang.Thread.run(Thread.java:1583)
]]>
            </full-stacktrace>
          </exception> <!-- java.lang.AssertionError -->
          <reporter-output>
          </reporter-output>
        </test-method> <!-- testAddToCart -->
        <test-method retried="true" signature="testAddToCart()[pri:0, instance:testCases.TC03_AddToCart@7e5c856f]" started-at="2025-05-20T18:05:39 EDT" name="testAddToCart" finished-at="2025-05-20T18:05:39 EDT" duration-ms="4" status="SKIP">
          <exception class="java.lang.AssertionError">
            <message>
              <![CDATA[Test failed due to unexpected exception.]]>
            </message>
            <full-stacktrace>
              <![CDATA[java.lang.AssertionError: Test failed due to unexpected exception.
at org.testng.Assert.fail(Assert.java:111)
at testCases.TC03_AddToCart.testAddToCart(TC03_AddToCart.java:55)
at java.base/jdk.internal.reflect.DirectMethodHandleAccessor.invoke(DirectMethodHandleAccessor.java:103)
at java.base/java.lang.reflect.Method.invoke(Method.java:580)
at org.testng.internal.invokers.MethodInvocationHelper.invokeMethod(MethodInvocationHelper.java:141)
at org.testng.internal.invokers.TestInvoker.invokeMethod(TestInvoker.java:687)
at org.testng.internal.invokers.TestInvoker.retryFailed(TestInvoker.java:269)
at org.testng.internal.invokers.MethodRunner.runInSequence(MethodRunner.java:76)
at org.testng.internal.invokers.TestInvoker$MethodInvocationAgent.invoke(TestInvoker.java:995)
at org.testng.internal.invokers.TestInvoker.invokeTestMethods(TestInvoker.java:203)
at org.testng.internal.invokers.TestMethodWorker.invokeTestMethods(TestMethodWorker.java:154)
at org.testng.internal.invokers.TestMethodWorker.run(TestMethodWorker.java:134)
at java.base/java.util.ArrayList.forEach(ArrayList.java:1596)
at org.testng.TestRunner.privateRun(TestRunner.java:741)
at org.testng.TestRunner.run(TestRunner.java:616)
at org.testng.SuiteRunner.runTest(SuiteRunner.java:421)
at org.testng.SuiteRunner$SuiteWorker.run(SuiteRunner.java:463)
at org.testng.internal.thread.ThreadUtil.lambda$execute$0(ThreadUtil.java:64)
at java.base/java.util.concurrent.FutureTask.run(FutureTask.java:317)
at java.base/java.util.concurrent.ThreadPoolExecutor.runWorker(ThreadPoolExecutor.java:1144)
at java.base/java.util.concurrent.ThreadPoolExecutor$Worker.run(ThreadPoolExecutor.java:642)
at java.base/java.lang.Thread.run(Thread.java:1583)
]]>
            </full-stacktrace>
          </exception> <!-- java.lang.AssertionError -->
          <reporter-output>
          </reporter-output>
        </test-method> <!-- testAddToCart -->
        <test-method signature="testAddToCart()[pri:0, instance:testCases.TC03_AddToCart@7e5c856f]" started-at="2025-05-20T18:05:39 EDT" name="testAddToCart" finished-at="2025-05-20T18:05:39 EDT" duration-ms="6" status="FAIL">
          <exception class="java.lang.AssertionError">
            <message>
              <![CDATA[Test failed due to unexpected exception.]]>
            </message>
            <full-stacktrace>
              <![CDATA[java.lang.AssertionError: Test failed due to unexpected exception.
at org.testng.Assert.fail(Assert.java:111)
at testCases.TC03_AddToCart.testAddToCart(TC03_AddToCart.java:55)
at java.base/jdk.internal.reflect.DirectMethodHandleAccessor.invoke(DirectMethodHandleAccessor.java:103)
at java.base/java.lang.reflect.Method.invoke(Method.java:580)
at org.testng.internal.invokers.MethodInvocationHelper.invokeMethod(MethodInvocationHelper.java:141)
at org.testng.internal.invokers.TestInvoker.invokeMethod(TestInvoker.java:687)
at org.testng.internal.invokers.TestInvoker.retryFailed(TestInvoker.java:269)
at org.testng.internal.invokers.MethodRunner.runInSequence(MethodRunner.java:76)
at org.testng.internal.invokers.TestInvoker$MethodInvocationAgent.invoke(TestInvoker.java:995)
at org.testng.internal.invokers.TestInvoker.invokeTestMethods(TestInvoker.java:203)
at org.testng.internal.invokers.TestMethodWorker.invokeTestMethods(TestMethodWorker.java:154)
at org.testng.internal.invokers.TestMethodWorker.run(TestMethodWorker.java:134)
at java.base/java.util.ArrayList.forEach(ArrayList.java:1596)
at org.testng.TestRunner.privateRun(TestRunner.java:741)
at org.testng.TestRunner.run(TestRunner.java:616)
at org.testng.SuiteRunner.runTest(SuiteRunner.java:421)
at org.testng.SuiteRunner$SuiteWorker.run(SuiteRunner.java:463)
at org.testng.internal.thread.ThreadUtil.lambda$execute$0(ThreadUtil.java:64)
at java.base/java.util.concurrent.FutureTask.run(FutureTask.java:317)
at java.base/java.util.concurrent.ThreadPoolExecutor.runWorker(ThreadPoolExecutor.java:1144)
at java.base/java.util.concurrent.ThreadPoolExecutor$Worker.run(ThreadPoolExecutor.java:642)
at java.base/java.lang.Thread.run(Thread.java:1583)
]]>
            </full-stacktrace>
          </exception> <!-- java.lang.AssertionError -->
          <reporter-output>
          </reporter-output>
        </test-method> <!-- testAddToCart -->
        <test-method is-config="true" signature="closeApp()[pri:0, instance:testCases.TC03_AddToCart@7e5c856f]" started-at="2025-05-20T18:05:39 EDT" name="closeApp" finished-at="2025-05-20T18:05:39 EDT" duration-ms="6" status="PASS">
          <reporter-output>
          </reporter-output>
        </test-method> <!-- closeApp -->
      </class> <!-- testCases.TC03_AddToCart -->
      <class name="testCases.TC04_CompletePurchase">
        <test-method is-config="true" signature="openApp(java.lang.String,java.lang.String)[pri:0, instance:testCases.TC04_CompletePurchase@1984b1f]" started-at="2025-05-20T18:05:43 EDT" name="openApp" finished-at="2025-05-20T18:05:43 EDT" duration-ms="83" status="PASS">
          <params>
            <param index="0">
              <value>
                <![CDATA[windows]]>
              </value>
            </param>
            <param index="1">
              <value>
                <![CDATA[chrome]]>
              </value>
            </param>
          </params>
          <reporter-output>
          </reporter-output>
        </test-method> <!-- openApp -->
        <test-method retried="true" signature="testCompletePurchase()[pri:0, instance:testCases.TC04_CompletePurchase@1984b1f]" started-at="2025-05-20T18:05:43 EDT" name="testCompletePurchase" finished-at="2025-05-20T18:05:43 EDT" duration-ms="6" status="SKIP">
          <exception class="java.lang.AssertionError">
            <message>
              <![CDATA[Test failed due to unexpected exception.]]>
            </message>
            <full-stacktrace>
              <![CDATA[java.lang.AssertionError: Test failed due to unexpected exception.
at org.testng.Assert.fail(Assert.java:111)
at testCases.TC04_CompletePurchase.testCompletePurchase(TC04_CompletePurchase.java:81)
at java.base/jdk.internal.reflect.DirectMethodHandleAccessor.invoke(DirectMethodHandleAccessor.java:103)
at java.base/java.lang.reflect.Method.invoke(Method.java:580)
at org.testng.internal.invokers.MethodInvocationHelper.invokeMethod(MethodInvocationHelper.java:141)
at org.testng.internal.invokers.TestInvoker.invokeMethod(TestInvoker.java:687)
at org.testng.internal.invokers.TestInvoker.invokeTestMethod(TestInvoker.java:230)
at org.testng.internal.invokers.MethodRunner.runInSequence(MethodRunner.java:63)
at org.testng.internal.invokers.TestInvoker$MethodInvocationAgent.invoke(TestInvoker.java:995)
at org.testng.internal.invokers.TestInvoker.invokeTestMethods(TestInvoker.java:203)
at org.testng.internal.invokers.TestMethodWorker.invokeTestMethods(TestMethodWorker.java:154)
at org.testng.internal.invokers.TestMethodWorker.run(TestMethodWorker.java:134)
at java.base/java.util.ArrayList.forEach(ArrayList.java:1596)
at org.testng.TestRunner.privateRun(TestRunner.java:741)
at org.testng.TestRunner.run(TestRunner.java:616)
at org.testng.SuiteRunner.runTest(SuiteRunner.java:421)
at org.testng.SuiteRunner$SuiteWorker.run(SuiteRunner.java:463)
at org.testng.internal.thread.ThreadUtil.lambda$execute$0(ThreadUtil.java:64)
at java.base/java.util.concurrent.FutureTask.run(FutureTask.java:317)
at java.base/java.util.concurrent.ThreadPoolExecutor.runWorker(ThreadPoolExecutor.java:1144)
at java.base/java.util.concurrent.ThreadPoolExecutor$Worker.run(ThreadPoolExecutor.java:642)
at java.base/java.lang.Thread.run(Thread.java:1583)
]]>
            </full-stacktrace>
          </exception> <!-- java.lang.AssertionError -->
          <reporter-output>
          </reporter-output>
        </test-method> <!-- testCompletePurchase -->
        <test-method retried="true" signature="testCompletePurchase()[pri:0, instance:testCases.TC04_CompletePurchase@1984b1f]" started-at="2025-05-20T18:05:43 EDT" name="testCompletePurchase" finished-at="2025-05-20T18:05:43 EDT" duration-ms="6" status="SKIP">
          <exception class="java.lang.AssertionError">
            <message>
              <![CDATA[Test failed due to unexpected exception.]]>
            </message>
            <full-stacktrace>
              <![CDATA[java.lang.AssertionError: Test failed due to unexpected exception.
at org.testng.Assert.fail(Assert.java:111)
at testCases.TC04_CompletePurchase.testCompletePurchase(TC04_CompletePurchase.java:81)
at java.base/jdk.internal.reflect.DirectMethodHandleAccessor.invoke(DirectMethodHandleAccessor.java:103)
at java.base/java.lang.reflect.Method.invoke(Method.java:580)
at org.testng.internal.invokers.MethodInvocationHelper.invokeMethod(MethodInvocationHelper.java:141)
at org.testng.internal.invokers.TestInvoker.invokeMethod(TestInvoker.java:687)
at org.testng.internal.invokers.TestInvoker.retryFailed(TestInvoker.java:269)
at org.testng.internal.invokers.MethodRunner.runInSequence(MethodRunner.java:76)
at org.testng.internal.invokers.TestInvoker$MethodInvocationAgent.invoke(TestInvoker.java:995)
at org.testng.internal.invokers.TestInvoker.invokeTestMethods(TestInvoker.java:203)
at org.testng.internal.invokers.TestMethodWorker.invokeTestMethods(TestMethodWorker.java:154)
at org.testng.internal.invokers.TestMethodWorker.run(TestMethodWorker.java:134)
at java.base/java.util.ArrayList.forEach(ArrayList.java:1596)
at org.testng.TestRunner.privateRun(TestRunner.java:741)
at org.testng.TestRunner.run(TestRunner.java:616)
at org.testng.SuiteRunner.runTest(SuiteRunner.java:421)
at org.testng.SuiteRunner$SuiteWorker.run(SuiteRunner.java:463)
at org.testng.internal.thread.ThreadUtil.lambda$execute$0(ThreadUtil.java:64)
at java.base/java.util.concurrent.FutureTask.run(FutureTask.java:317)
at java.base/java.util.concurrent.ThreadPoolExecutor.runWorker(ThreadPoolExecutor.java:1144)
at java.base/java.util.concurrent.ThreadPoolExecutor$Worker.run(ThreadPoolExecutor.java:642)
at java.base/java.lang.Thread.run(Thread.java:1583)
]]>
            </full-stacktrace>
          </exception> <!-- java.lang.AssertionError -->
          <reporter-output>
          </reporter-output>
        </test-method> <!-- testCompletePurchase -->
        <test-method signature="testCompletePurchase()[pri:0, instance:testCases.TC04_CompletePurchase@1984b1f]" started-at="2025-05-20T18:05:43 EDT" name="testCompletePurchase" finished-at="2025-05-20T18:05:43 EDT" duration-ms="2" status="FAIL">
          <exception class="java.lang.AssertionError">
            <message>
              <![CDATA[Test failed due to unexpected exception.]]>
            </message>
            <full-stacktrace>
              <![CDATA[java.lang.AssertionError: Test failed due to unexpected exception.
at org.testng.Assert.fail(Assert.java:111)
at testCases.TC04_CompletePurchase.testCompletePurchase(TC04_CompletePurchase.java:81)
at java.base/jdk.internal.reflect.DirectMethodHandleAccessor.invoke(DirectMethodHandleAccessor.java:103)
at java.base/java.lang.reflect.Method.invoke(Method.java:580)
at org.testng.internal.invokers.MethodInvocationHelper.invokeMethod(MethodInvocationHelper.java:141)
at org.testng.internal.invokers.TestInvoker.invokeMethod(TestInvoker.java:687)
at org.testng.internal.invokers.TestInvoker.retryFailed(TestInvoker.java:269)
at org.testng.internal.invokers.MethodRunner.runInSequence(MethodRunner.java:76)
at org.testng.internal.invokers.TestInvoker$MethodInvocationAgent.invoke(TestInvoker.java:995)
at org.testng.internal.invokers.TestInvoker.invokeTestMethods(TestInvoker.java:203)
at org.testng.internal.invokers.TestMethodWorker.invokeTestMethods(TestMethodWorker.java:154)
at org.testng.internal.invokers.TestMethodWorker.run(TestMethodWorker.java:134)
at java.base/java.util.ArrayList.forEach(ArrayList.java:1596)
at org.testng.TestRunner.privateRun(TestRunner.java:741)
at org.testng.TestRunner.run(TestRunner.java:616)
at org.testng.SuiteRunner.runTest(SuiteRunner.java:421)
at org.testng.SuiteRunner$SuiteWorker.run(SuiteRunner.java:463)
at org.testng.internal.thread.ThreadUtil.lambda$execute$0(ThreadUtil.java:64)
at java.base/java.util.concurrent.FutureTask.run(FutureTask.java:317)
at java.base/java.util.concurrent.ThreadPoolExecutor.runWorker(ThreadPoolExecutor.java:1144)
at java.base/java.util.concurrent.ThreadPoolExecutor$Worker.run(ThreadPoolExecutor.java:642)
at java.base/java.lang.Thread.run(Thread.java:1583)
]]>
            </full-stacktrace>
          </exception> <!-- java.lang.AssertionError -->
          <reporter-output>
          </reporter-output>
        </test-method> <!-- testCompletePurchase -->
        <test-method is-config="true" signature="closeApp()[pri:0, instance:testCases.TC04_CompletePurchase@1984b1f]" started-at="2025-05-20T18:05:43 EDT" name="closeApp" finished-at="2025-05-20T18:05:43 EDT" duration-ms="4" status="PASS">
          <reporter-output>
          </reporter-output>
        </test-method> <!-- closeApp -->
      </class> <!-- testCases.TC04_CompletePurchase -->
    </test> <!-- chromeTest -->
    <test started-at="2025-05-20T18:05:37 EDT" name="edgeTest" finished-at="2025-05-20T18:05:43 EDT" duration-ms="5999">
      <class name="testCases.TC02_Login">
        <test-method is-config="true" signature="openApp(java.lang.String,java.lang.String)[pri:0, instance:testCases.TC02_Login@6af9fcb2]" started-at="2025-05-20T18:05:39 EDT" name="openApp" finished-at="2025-05-20T18:05:39 EDT" duration-ms="40" status="PASS">
          <params>
            <param index="0">
              <value>
                <![CDATA[windows]]>
              </value>
            </param>
            <param index="1">
              <value>
                <![CDATA[edge]]>
              </value>
            </param>
          </params>
          <reporter-output>
          </reporter-output>
        </test-method> <!-- openApp -->
        <test-method retried="true" signature="testLogin(java.lang.String,java.lang.String)[pri:0, instance:testCases.TC02_Login@6af9fcb2]" started-at="2025-05-20T18:05:42 EDT" name="testLogin" data-provider="LoginData" finished-at="2025-05-20T18:05:42 EDT" duration-ms="38" status="SKIP">
          <params>
            <param index="0">
              <value>
                <![CDATA[smitasharma.qa@gmail.com]]>
              </value>
            </param>
            <param index="1">
              <value>
                <![CDATA[ss*QA123]]>
              </value>
            </param>
          </params>
          <exception class="java.lang.AssertionError">
            <message>
              <![CDATA[Unexpected exception during login test execution.]]>
            </message>
            <full-stacktrace>
              <![CDATA[java.lang.AssertionError: Unexpected exception during login test execution.
at org.testng.Assert.fail(Assert.java:111)
at testCases.TC02_Login.testLogin(TC02_Login.java:69)
at java.base/jdk.internal.reflect.DirectMethodHandleAccessor.invoke(DirectMethodHandleAccessor.java:103)
at java.base/java.lang.reflect.Method.invoke(Method.java:580)
at org.testng.internal.invokers.MethodInvocationHelper.invokeMethod(MethodInvocationHelper.java:141)
at org.testng.internal.invokers.TestInvoker.invokeMethod(TestInvoker.java:687)
at org.testng.internal.invokers.TestInvoker.invokeTestMethod(TestInvoker.java:230)
at org.testng.internal.invokers.MethodRunner.runInSequence(MethodRunner.java:63)
at org.testng.internal.invokers.TestInvoker$MethodInvocationAgent.invoke(TestInvoker.java:995)
at org.testng.internal.invokers.TestInvoker.invokeTestMethods(TestInvoker.java:203)
at org.testng.internal.invokers.TestMethodWorker.invokeTestMethods(TestMethodWorker.java:154)
at org.testng.internal.invokers.TestMethodWorker.run(TestMethodWorker.java:134)
at java.base/java.util.ArrayList.forEach(ArrayList.java:1596)
at org.testng.TestRunner.privateRun(TestRunner.java:741)
at org.testng.TestRunner.run(TestRunner.java:616)
at org.testng.SuiteRunner.runTest(SuiteRunner.java:421)
at org.testng.SuiteRunner$SuiteWorker.run(SuiteRunner.java:463)
at org.testng.internal.thread.ThreadUtil.lambda$execute$0(ThreadUtil.java:64)
at java.base/java.util.concurrent.FutureTask.run(FutureTask.java:317)
at java.base/java.util.concurrent.ThreadPoolExecutor.runWorker(ThreadPoolExecutor.java:1144)
at java.base/java.util.concurrent.ThreadPoolExecutor$Worker.run(ThreadPoolExecutor.java:642)
at java.base/java.lang.Thread.run(Thread.java:1583)
]]>
            </full-stacktrace>
          </exception> <!-- java.lang.AssertionError -->
          <reporter-output>
          </reporter-output>
        </test-method> <!-- testLogin -->
        <test-method retried="true" signature="testLogin(java.lang.String,java.lang.String)[pri:0, instance:testCases.TC02_Login@6af9fcb2]" started-at="2025-05-20T18:05:42 EDT" name="testLogin" data-provider="LoginData" finished-at="2025-05-20T18:05:42 EDT" duration-ms="27" status="SKIP">
          <params>
            <param index="0">
              <value>
                <![CDATA[smitasharma.qa@gmail.com]]>
              </value>
            </param>
            <param index="1">
              <value>
                <![CDATA[ss*QA123]]>
              </value>
            </param>
          </params>
          <exception class="java.lang.AssertionError">
            <message>
              <![CDATA[Unexpected exception during login test execution.]]>
            </message>
            <full-stacktrace>
              <![CDATA[java.lang.AssertionError: Unexpected exception during login test execution.
at org.testng.Assert.fail(Assert.java:111)
at testCases.TC02_Login.testLogin(TC02_Login.java:69)
at java.base/jdk.internal.reflect.DirectMethodHandleAccessor.invoke(DirectMethodHandleAccessor.java:103)
at java.base/java.lang.reflect.Method.invoke(Method.java:580)
at org.testng.internal.invokers.MethodInvocationHelper.invokeMethod(MethodInvocationHelper.java:141)
at org.testng.internal.invokers.TestInvoker.invokeMethod(TestInvoker.java:687)
at org.testng.internal.invokers.TestInvoker.retryFailed(TestInvoker.java:269)
at org.testng.internal.invokers.MethodRunner.runInSequence(MethodRunner.java:76)
at org.testng.internal.invokers.TestInvoker$MethodInvocationAgent.invoke(TestInvoker.java:995)
at org.testng.internal.invokers.TestInvoker.invokeTestMethods(TestInvoker.java:203)
at org.testng.internal.invokers.TestMethodWorker.invokeTestMethods(TestMethodWorker.java:154)
at org.testng.internal.invokers.TestMethodWorker.run(TestMethodWorker.java:134)
at java.base/java.util.ArrayList.forEach(ArrayList.java:1596)
at org.testng.TestRunner.privateRun(TestRunner.java:741)
at org.testng.TestRunner.run(TestRunner.java:616)
at org.testng.SuiteRunner.runTest(SuiteRunner.java:421)
at org.testng.SuiteRunner$SuiteWorker.run(SuiteRunner.java:463)
at org.testng.internal.thread.ThreadUtil.lambda$execute$0(ThreadUtil.java:64)
at java.base/java.util.concurrent.FutureTask.run(FutureTask.java:317)
at java.base/java.util.concurrent.ThreadPoolExecutor.runWorker(ThreadPoolExecutor.java:1144)
at java.base/java.util.concurrent.ThreadPoolExecutor$Worker.run(ThreadPoolExecutor.java:642)
at java.base/java.lang.Thread.run(Thread.java:1583)
]]>
            </full-stacktrace>
          </exception> <!-- java.lang.AssertionError -->
          <reporter-output>
          </reporter-output>
        </test-method> <!-- testLogin -->
        <test-method signature="testLogin(java.lang.String,java.lang.String)[pri:0, instance:testCases.TC02_Login@6af9fcb2]" started-at="2025-05-20T18:05:42 EDT" name="testLogin" data-provider="LoginData" finished-at="2025-05-20T18:05:42 EDT" duration-ms="4" status="FAIL">
          <params>
            <param index="0">
              <value>
                <![CDATA[smitasharma.qa@gmail.com]]>
              </value>
            </param>
            <param index="1">
              <value>
                <![CDATA[ss*QA123]]>
              </value>
            </param>
          </params>
          <exception class="java.lang.AssertionError">
            <message>
              <![CDATA[Unexpected exception during login test execution.]]>
            </message>
            <full-stacktrace>
              <![CDATA[java.lang.AssertionError: Unexpected exception during login test execution.
at org.testng.Assert.fail(Assert.java:111)
at testCases.TC02_Login.testLogin(TC02_Login.java:69)
at java.base/jdk.internal.reflect.DirectMethodHandleAccessor.invoke(DirectMethodHandleAccessor.java:103)
at java.base/java.lang.reflect.Method.invoke(Method.java:580)
at org.testng.internal.invokers.MethodInvocationHelper.invokeMethod(MethodInvocationHelper.java:141)
at org.testng.internal.invokers.TestInvoker.invokeMethod(TestInvoker.java:687)
at org.testng.internal.invokers.TestInvoker.retryFailed(TestInvoker.java:269)
at org.testng.internal.invokers.MethodRunner.runInSequence(MethodRunner.java:76)
at org.testng.internal.invokers.TestInvoker$MethodInvocationAgent.invoke(TestInvoker.java:995)
at org.testng.internal.invokers.TestInvoker.invokeTestMethods(TestInvoker.java:203)
at org.testng.internal.invokers.TestMethodWorker.invokeTestMethods(TestMethodWorker.java:154)
at org.testng.internal.invokers.TestMethodWorker.run(TestMethodWorker.java:134)
at java.base/java.util.ArrayList.forEach(ArrayList.java:1596)
at org.testng.TestRunner.privateRun(TestRunner.java:741)
at org.testng.TestRunner.run(TestRunner.java:616)
at org.testng.SuiteRunner.runTest(SuiteRunner.java:421)
at org.testng.SuiteRunner$SuiteWorker.run(SuiteRunner.java:463)
at org.testng.internal.thread.ThreadUtil.lambda$execute$0(ThreadUtil.java:64)
at java.base/java.util.concurrent.FutureTask.run(FutureTask.java:317)
at java.base/java.util.concurrent.ThreadPoolExecutor.runWorker(ThreadPoolExecutor.java:1144)
at java.base/java.util.concurrent.ThreadPoolExecutor$Worker.run(ThreadPoolExecutor.java:642)
at java.base/java.lang.Thread.run(Thread.java:1583)
]]>
            </full-stacktrace>
          </exception> <!-- java.lang.AssertionError -->
          <reporter-output>
          </reporter-output>
        </test-method> <!-- testLogin -->
        <test-method retried="true" signature="testLogin(java.lang.String,java.lang.String)[pri:0, instance:testCases.TC02_Login@6af9fcb2]" started-at="2025-05-20T18:05:42 EDT" name="testLogin" data-provider="LoginData" finished-at="2025-05-20T18:05:42 EDT" duration-ms="8" status="SKIP">
          <params>
            <param index="0">
              <value>
                <![CDATA[nona@yahoo.com]]>
              </value>
            </param>
            <param index="1">
              <value>
                <![CDATA[QWER!@#$]]>
              </value>
            </param>
          </params>
          <exception class="java.lang.AssertionError">
            <message>
              <![CDATA[Unexpected exception during login test execution.]]>
            </message>
            <full-stacktrace>
              <![CDATA[java.lang.AssertionError: Unexpected exception during login test execution.
at org.testng.Assert.fail(Assert.java:111)
at testCases.TC02_Login.testLogin(TC02_Login.java:69)
at java.base/jdk.internal.reflect.DirectMethodHandleAccessor.invoke(DirectMethodHandleAccessor.java:103)
at java.base/java.lang.reflect.Method.invoke(Method.java:580)
at org.testng.internal.invokers.MethodInvocationHelper.invokeMethod(MethodInvocationHelper.java:141)
at org.testng.internal.invokers.TestInvoker.invokeMethod(TestInvoker.java:687)
at org.testng.internal.invokers.TestInvoker.invokeTestMethod(TestInvoker.java:230)
at org.testng.internal.invokers.MethodRunner.runInSequence(MethodRunner.java:63)
at org.testng.internal.invokers.TestInvoker$MethodInvocationAgent.invoke(TestInvoker.java:995)
at org.testng.internal.invokers.TestInvoker.invokeTestMethods(TestInvoker.java:203)
at org.testng.internal.invokers.TestMethodWorker.invokeTestMethods(TestMethodWorker.java:154)
at org.testng.internal.invokers.TestMethodWorker.run(TestMethodWorker.java:134)
at java.base/java.util.ArrayList.forEach(ArrayList.java:1596)
at org.testng.TestRunner.privateRun(TestRunner.java:741)
at org.testng.TestRunner.run(TestRunner.java:616)
at org.testng.SuiteRunner.runTest(SuiteRunner.java:421)
at org.testng.SuiteRunner$SuiteWorker.run(SuiteRunner.java:463)
at org.testng.internal.thread.ThreadUtil.lambda$execute$0(ThreadUtil.java:64)
at java.base/java.util.concurrent.FutureTask.run(FutureTask.java:317)
at java.base/java.util.concurrent.ThreadPoolExecutor.runWorker(ThreadPoolExecutor.java:1144)
at java.base/java.util.concurrent.ThreadPoolExecutor$Worker.run(ThreadPoolExecutor.java:642)
at java.base/java.lang.Thread.run(Thread.java:1583)
]]>
            </full-stacktrace>
          </exception> <!-- java.lang.AssertionError -->
          <reporter-output>
          </reporter-output>
        </test-method> <!-- testLogin -->
        <test-method retried="true" signature="testLogin(java.lang.String,java.lang.String)[pri:0, instance:testCases.TC02_Login@6af9fcb2]" started-at="2025-05-20T18:05:42 EDT" name="testLogin" data-provider="LoginData" finished-at="2025-05-20T18:05:43 EDT" duration-ms="29" status="SKIP">
          <params>
            <param index="0">
              <value>
                <![CDATA[nona@yahoo.com]]>
              </value>
            </param>
            <param index="1">
              <value>
                <![CDATA[QWER!@#$]]>
              </value>
            </param>
          </params>
          <exception class="java.lang.AssertionError">
            <message>
              <![CDATA[Unexpected exception during login test execution.]]>
            </message>
            <full-stacktrace>
              <![CDATA[java.lang.AssertionError: Unexpected exception during login test execution.
at org.testng.Assert.fail(Assert.java:111)
at testCases.TC02_Login.testLogin(TC02_Login.java:69)
at java.base/jdk.internal.reflect.DirectMethodHandleAccessor.invoke(DirectMethodHandleAccessor.java:103)
at java.base/java.lang.reflect.Method.invoke(Method.java:580)
at org.testng.internal.invokers.MethodInvocationHelper.invokeMethod(MethodInvocationHelper.java:141)
at org.testng.internal.invokers.TestInvoker.invokeMethod(TestInvoker.java:687)
at org.testng.internal.invokers.TestInvoker.retryFailed(TestInvoker.java:269)
at org.testng.internal.invokers.MethodRunner.runInSequence(MethodRunner.java:76)
at org.testng.internal.invokers.TestInvoker$MethodInvocationAgent.invoke(TestInvoker.java:995)
at org.testng.internal.invokers.TestInvoker.invokeTestMethods(TestInvoker.java:203)
at org.testng.internal.invokers.TestMethodWorker.invokeTestMethods(TestMethodWorker.java:154)
at org.testng.internal.invokers.TestMethodWorker.run(TestMethodWorker.java:134)
at java.base/java.util.ArrayList.forEach(ArrayList.java:1596)
at org.testng.TestRunner.privateRun(TestRunner.java:741)
at org.testng.TestRunner.run(TestRunner.java:616)
at org.testng.SuiteRunner.runTest(SuiteRunner.java:421)
at org.testng.SuiteRunner$SuiteWorker.run(SuiteRunner.java:463)
at org.testng.internal.thread.ThreadUtil.lambda$execute$0(ThreadUtil.java:64)
at java.base/java.util.concurrent.FutureTask.run(FutureTask.java:317)
at java.base/java.util.concurrent.ThreadPoolExecutor.runWorker(ThreadPoolExecutor.java:1144)
at java.base/java.util.concurrent.ThreadPoolExecutor$Worker.run(ThreadPoolExecutor.java:642)
at java.base/java.lang.Thread.run(Thread.java:1583)
]]>
            </full-stacktrace>
          </exception> <!-- java.lang.AssertionError -->
          <reporter-output>
          </reporter-output>
        </test-method> <!-- testLogin -->
        <test-method signature="testLogin(java.lang.String,java.lang.String)[pri:0, instance:testCases.TC02_Login@6af9fcb2]" started-at="2025-05-20T18:05:43 EDT" name="testLogin" data-provider="LoginData" finished-at="2025-05-20T18:05:43 EDT" duration-ms="7" status="FAIL">
          <params>
            <param index="0">
              <value>
                <![CDATA[nona@yahoo.com]]>
              </value>
            </param>
            <param index="1">
              <value>
                <![CDATA[QWER!@#$]]>
              </value>
            </param>
          </params>
          <exception class="java.lang.AssertionError">
            <message>
              <![CDATA[Unexpected exception during login test execution.]]>
            </message>
            <full-stacktrace>
              <![CDATA[java.lang.AssertionError: Unexpected exception during login test execution.
at org.testng.Assert.fail(Assert.java:111)
at testCases.TC02_Login.testLogin(TC02_Login.java:69)
at java.base/jdk.internal.reflect.DirectMethodHandleAccessor.invoke(DirectMethodHandleAccessor.java:103)
at java.base/java.lang.reflect.Method.invoke(Method.java:580)
at org.testng.internal.invokers.MethodInvocationHelper.invokeMethod(MethodInvocationHelper.java:141)
at org.testng.internal.invokers.TestInvoker.invokeMethod(TestInvoker.java:687)
at org.testng.internal.invokers.TestInvoker.retryFailed(TestInvoker.java:269)
at org.testng.internal.invokers.MethodRunner.runInSequence(MethodRunner.java:76)
at org.testng.internal.invokers.TestInvoker$MethodInvocationAgent.invoke(TestInvoker.java:995)
at org.testng.internal.invokers.TestInvoker.invokeTestMethods(TestInvoker.java:203)
at org.testng.internal.invokers.TestMethodWorker.invokeTestMethods(TestMethodWorker.java:154)
at org.testng.internal.invokers.TestMethodWorker.run(TestMethodWorker.java:134)
at java.base/java.util.ArrayList.forEach(ArrayList.java:1596)
at org.testng.TestRunner.privateRun(TestRunner.java:741)
at org.testng.TestRunner.run(TestRunner.java:616)
at org.testng.SuiteRunner.runTest(SuiteRunner.java:421)
at org.testng.SuiteRunner$SuiteWorker.run(SuiteRunner.java:463)
at org.testng.internal.thread.ThreadUtil.lambda$execute$0(ThreadUtil.java:64)
at java.base/java.util.concurrent.FutureTask.run(FutureTask.java:317)
at java.base/java.util.concurrent.ThreadPoolExecutor.runWorker(ThreadPoolExecutor.java:1144)
at java.base/java.util.concurrent.ThreadPoolExecutor$Worker.run(ThreadPoolExecutor.java:642)
at java.base/java.lang.Thread.run(Thread.java:1583)
]]>
            </full-stacktrace>
          </exception> <!-- java.lang.AssertionError -->
          <reporter-output>
          </reporter-output>
        </test-method> <!-- testLogin -->
        <test-method retried="true" signature="testLogin(java.lang.String,java.lang.String)[pri:0, instance:testCases.TC02_Login@6af9fcb2]" started-at="2025-05-20T18:05:43 EDT" name="testLogin" data-provider="LoginData" finished-at="2025-05-20T18:05:43 EDT" duration-ms="8" status="SKIP">
          <params>
            <param index="0">
              <value>
                <![CDATA[sid@cloudberry.services]]>
              </value>
            </param>
            <param index="1">
              <value>
                <![CDATA[Test123]]>
              </value>
            </param>
          </params>
          <exception class="java.lang.AssertionError">
            <message>
              <![CDATA[Unexpected exception during login test execution.]]>
            </message>
            <full-stacktrace>
              <![CDATA[java.lang.AssertionError: Unexpected exception during login test execution.
at org.testng.Assert.fail(Assert.java:111)
at testCases.TC02_Login.testLogin(TC02_Login.java:69)
at java.base/jdk.internal.reflect.DirectMethodHandleAccessor.invoke(DirectMethodHandleAccessor.java:103)
at java.base/java.lang.reflect.Method.invoke(Method.java:580)
at org.testng.internal.invokers.MethodInvocationHelper.invokeMethod(MethodInvocationHelper.java:141)
at org.testng.internal.invokers.TestInvoker.invokeMethod(TestInvoker.java:687)
at org.testng.internal.invokers.TestInvoker.invokeTestMethod(TestInvoker.java:230)
at org.testng.internal.invokers.MethodRunner.runInSequence(MethodRunner.java:63)
at org.testng.internal.invokers.TestInvoker$MethodInvocationAgent.invoke(TestInvoker.java:995)
at org.testng.internal.invokers.TestInvoker.invokeTestMethods(TestInvoker.java:203)
at org.testng.internal.invokers.TestMethodWorker.invokeTestMethods(TestMethodWorker.java:154)
at org.testng.internal.invokers.TestMethodWorker.run(TestMethodWorker.java:134)
at java.base/java.util.ArrayList.forEach(ArrayList.java:1596)
at org.testng.TestRunner.privateRun(TestRunner.java:741)
at org.testng.TestRunner.run(TestRunner.java:616)
at org.testng.SuiteRunner.runTest(SuiteRunner.java:421)
at org.testng.SuiteRunner$SuiteWorker.run(SuiteRunner.java:463)
at org.testng.internal.thread.ThreadUtil.lambda$execute$0(ThreadUtil.java:64)
at java.base/java.util.concurrent.FutureTask.run(FutureTask.java:317)
at java.base/java.util.concurrent.ThreadPoolExecutor.runWorker(ThreadPoolExecutor.java:1144)
at java.base/java.util.concurrent.ThreadPoolExecutor$Worker.run(ThreadPoolExecutor.java:642)
at java.base/java.lang.Thread.run(Thread.java:1583)
]]>
            </full-stacktrace>
          </exception> <!-- java.lang.AssertionError -->
          <reporter-output>
          </reporter-output>
        </test-method> <!-- testLogin -->
        <test-method retried="true" signature="testLogin(java.lang.String,java.lang.String)[pri:0, instance:testCases.TC02_Login@6af9fcb2]" started-at="2025-05-20T18:05:43 EDT" name="testLogin" data-provider="LoginData" finished-at="2025-05-20T18:05:43 EDT" duration-ms="4" status="SKIP">
          <params>
            <param index="0">
              <value>
                <![CDATA[sid@cloudberry.services]]>
              </value>
            </param>
            <param index="1">
              <value>
                <![CDATA[Test123]]>
              </value>
            </param>
          </params>
          <exception class="java.lang.AssertionError">
            <message>
              <![CDATA[Unexpected exception during login test execution.]]>
            </message>
            <full-stacktrace>
              <![CDATA[java.lang.AssertionError: Unexpected exception during login test execution.
at org.testng.Assert.fail(Assert.java:111)
at testCases.TC02_Login.testLogin(TC02_Login.java:69)
at java.base/jdk.internal.reflect.DirectMethodHandleAccessor.invoke(DirectMethodHandleAccessor.java:103)
at java.base/java.lang.reflect.Method.invoke(Method.java:580)
at org.testng.internal.invokers.MethodInvocationHelper.invokeMethod(MethodInvocationHelper.java:141)
at org.testng.internal.invokers.TestInvoker.invokeMethod(TestInvoker.java:687)
at org.testng.internal.invokers.TestInvoker.retryFailed(TestInvoker.java:269)
at org.testng.internal.invokers.MethodRunner.runInSequence(MethodRunner.java:76)
at org.testng.internal.invokers.TestInvoker$MethodInvocationAgent.invoke(TestInvoker.java:995)
at org.testng.internal.invokers.TestInvoker.invokeTestMethods(TestInvoker.java:203)
at org.testng.internal.invokers.TestMethodWorker.invokeTestMethods(TestMethodWorker.java:154)
at org.testng.internal.invokers.TestMethodWorker.run(TestMethodWorker.java:134)
at java.base/java.util.ArrayList.forEach(ArrayList.java:1596)
at org.testng.TestRunner.privateRun(TestRunner.java:741)
at org.testng.TestRunner.run(TestRunner.java:616)
at org.testng.SuiteRunner.runTest(SuiteRunner.java:421)
at org.testng.SuiteRunner$SuiteWorker.run(SuiteRunner.java:463)
at org.testng.internal.thread.ThreadUtil.lambda$execute$0(ThreadUtil.java:64)
at java.base/java.util.concurrent.FutureTask.run(FutureTask.java:317)
at java.base/java.util.concurrent.ThreadPoolExecutor.runWorker(ThreadPoolExecutor.java:1144)
at java.base/java.util.concurrent.ThreadPoolExecutor$Worker.run(ThreadPoolExecutor.java:642)
at java.base/java.lang.Thread.run(Thread.java:1583)
]]>
            </full-stacktrace>
          </exception> <!-- java.lang.AssertionError -->
          <reporter-output>
          </reporter-output>
        </test-method> <!-- testLogin -->
        <test-method signature="testLogin(java.lang.String,java.lang.String)[pri:0, instance:testCases.TC02_Login@6af9fcb2]" started-at="2025-05-20T18:05:43 EDT" name="testLogin" data-provider="LoginData" finished-at="2025-05-20T18:05:43 EDT" duration-ms="1" status="FAIL">
          <params>
            <param index="0">
              <value>
                <![CDATA[sid@cloudberry.services]]>
              </value>
            </param>
            <param index="1">
              <value>
                <![CDATA[Test123]]>
              </value>
            </param>
          </params>
          <exception class="java.lang.AssertionError">
            <message>
              <![CDATA[Unexpected exception during login test execution.]]>
            </message>
            <full-stacktrace>
              <![CDATA[java.lang.AssertionError: Unexpected exception during login test execution.
at org.testng.Assert.fail(Assert.java:111)
at testCases.TC02_Login.testLogin(TC02_Login.java:69)
at java.base/jdk.internal.reflect.DirectMethodHandleAccessor.invoke(DirectMethodHandleAccessor.java:103)
at java.base/java.lang.reflect.Method.invoke(Method.java:580)
at org.testng.internal.invokers.MethodInvocationHelper.invokeMethod(MethodInvocationHelper.java:141)
at org.testng.internal.invokers.TestInvoker.invokeMethod(TestInvoker.java:687)
at org.testng.internal.invokers.TestInvoker.retryFailed(TestInvoker.java:269)
at org.testng.internal.invokers.MethodRunner.runInSequence(MethodRunner.java:76)
at org.testng.internal.invokers.TestInvoker$MethodInvocationAgent.invoke(TestInvoker.java:995)
at org.testng.internal.invokers.TestInvoker.invokeTestMethods(TestInvoker.java:203)
at org.testng.internal.invokers.TestMethodWorker.invokeTestMethods(TestMethodWorker.java:154)
at org.testng.internal.invokers.TestMethodWorker.run(TestMethodWorker.java:134)
at java.base/java.util.ArrayList.forEach(ArrayList.java:1596)
at org.testng.TestRunner.privateRun(TestRunner.java:741)
at org.testng.TestRunner.run(TestRunner.java:616)
at org.testng.SuiteRunner.runTest(SuiteRunner.java:421)
at org.testng.SuiteRunner$SuiteWorker.run(SuiteRunner.java:463)
at org.testng.internal.thread.ThreadUtil.lambda$execute$0(ThreadUtil.java:64)
at java.base/java.util.concurrent.FutureTask.run(FutureTask.java:317)
at java.base/java.util.concurrent.ThreadPoolExecutor.runWorker(ThreadPoolExecutor.java:1144)
at java.base/java.util.concurrent.ThreadPoolExecutor$Worker.run(ThreadPoolExecutor.java:642)
at java.base/java.lang.Thread.run(Thread.java:1583)
]]>
            </full-stacktrace>
          </exception> <!-- java.lang.AssertionError -->
          <reporter-output>
          </reporter-output>
        </test-method> <!-- testLogin -->
        <test-method retried="true" signature="testLogin(java.lang.String,java.lang.String)[pri:0, instance:testCases.TC02_Login@6af9fcb2]" started-at="2025-05-20T18:05:43 EDT" name="testLogin" data-provider="LoginData" finished-at="2025-05-20T18:05:43 EDT" duration-ms="1" status="SKIP">
          <params>
            <param index="0">
              <value>
                <![CDATA[apushedwoman@gmail.com]]>
              </value>
            </param>
            <param index="1">
              <value>
                <![CDATA[password123]]>
              </value>
            </param>
          </params>
          <exception class="java.lang.AssertionError">
            <message>
              <![CDATA[Unexpected exception during login test execution.]]>
            </message>
            <full-stacktrace>
              <![CDATA[java.lang.AssertionError: Unexpected exception during login test execution.
at org.testng.Assert.fail(Assert.java:111)
at testCases.TC02_Login.testLogin(TC02_Login.java:69)
at java.base/jdk.internal.reflect.DirectMethodHandleAccessor.invoke(DirectMethodHandleAccessor.java:103)
at java.base/java.lang.reflect.Method.invoke(Method.java:580)
at org.testng.internal.invokers.MethodInvocationHelper.invokeMethod(MethodInvocationHelper.java:141)
at org.testng.internal.invokers.TestInvoker.invokeMethod(TestInvoker.java:687)
at org.testng.internal.invokers.TestInvoker.invokeTestMethod(TestInvoker.java:230)
at org.testng.internal.invokers.MethodRunner.runInSequence(MethodRunner.java:63)
at org.testng.internal.invokers.TestInvoker$MethodInvocationAgent.invoke(TestInvoker.java:995)
at org.testng.internal.invokers.TestInvoker.invokeTestMethods(TestInvoker.java:203)
at org.testng.internal.invokers.TestMethodWorker.invokeTestMethods(TestMethodWorker.java:154)
at org.testng.internal.invokers.TestMethodWorker.run(TestMethodWorker.java:134)
at java.base/java.util.ArrayList.forEach(ArrayList.java:1596)
at org.testng.TestRunner.privateRun(TestRunner.java:741)
at org.testng.TestRunner.run(TestRunner.java:616)
at org.testng.SuiteRunner.runTest(SuiteRunner.java:421)
at org.testng.SuiteRunner$SuiteWorker.run(SuiteRunner.java:463)
at org.testng.internal.thread.ThreadUtil.lambda$execute$0(ThreadUtil.java:64)
at java.base/java.util.concurrent.FutureTask.run(FutureTask.java:317)
at java.base/java.util.concurrent.ThreadPoolExecutor.runWorker(ThreadPoolExecutor.java:1144)
at java.base/java.util.concurrent.ThreadPoolExecutor$Worker.run(ThreadPoolExecutor.java:642)
at java.base/java.lang.Thread.run(Thread.java:1583)
]]>
            </full-stacktrace>
          </exception> <!-- java.lang.AssertionError -->
          <reporter-output>
          </reporter-output>
        </test-method> <!-- testLogin -->
        <test-method retried="true" signature="testLogin(java.lang.String,java.lang.String)[pri:0, instance:testCases.TC02_Login@6af9fcb2]" started-at="2025-05-20T18:05:43 EDT" name="testLogin" data-provider="LoginData" finished-at="2025-05-20T18:05:43 EDT" duration-ms="2" status="SKIP">
          <params>
            <param index="0">
              <value>
                <![CDATA[apushedwoman@gmail.com]]>
              </value>
            </param>
            <param index="1">
              <value>
                <![CDATA[password123]]>
              </value>
            </param>
          </params>
          <exception class="java.lang.AssertionError">
            <message>
              <![CDATA[Unexpected exception during login test execution.]]>
            </message>
            <full-stacktrace>
              <![CDATA[java.lang.AssertionError: Unexpected exception during login test execution.
at org.testng.Assert.fail(Assert.java:111)
at testCases.TC02_Login.testLogin(TC02_Login.java:69)
at java.base/jdk.internal.reflect.DirectMethodHandleAccessor.invoke(DirectMethodHandleAccessor.java:103)
at java.base/java.lang.reflect.Method.invoke(Method.java:580)
at org.testng.internal.invokers.MethodInvocationHelper.invokeMethod(MethodInvocationHelper.java:141)
at org.testng.internal.invokers.TestInvoker.invokeMethod(TestInvoker.java:687)
at org.testng.internal.invokers.TestInvoker.retryFailed(TestInvoker.java:269)
at org.testng.internal.invokers.MethodRunner.runInSequence(MethodRunner.java:76)
at org.testng.internal.invokers.TestInvoker$MethodInvocationAgent.invoke(TestInvoker.java:995)
at org.testng.internal.invokers.TestInvoker.invokeTestMethods(TestInvoker.java:203)
at org.testng.internal.invokers.TestMethodWorker.invokeTestMethods(TestMethodWorker.java:154)
at org.testng.internal.invokers.TestMethodWorker.run(TestMethodWorker.java:134)
at java.base/java.util.ArrayList.forEach(ArrayList.java:1596)
at org.testng.TestRunner.privateRun(TestRunner.java:741)
at org.testng.TestRunner.run(TestRunner.java:616)
at org.testng.SuiteRunner.runTest(SuiteRunner.java:421)
at org.testng.SuiteRunner$SuiteWorker.run(SuiteRunner.java:463)
at org.testng.internal.thread.ThreadUtil.lambda$execute$0(ThreadUtil.java:64)
at java.base/java.util.concurrent.FutureTask.run(FutureTask.java:317)
at java.base/java.util.concurrent.ThreadPoolExecutor.runWorker(ThreadPoolExecutor.java:1144)
at java.base/java.util.concurrent.ThreadPoolExecutor$Worker.run(ThreadPoolExecutor.java:642)
at java.base/java.lang.Thread.run(Thread.java:1583)
]]>
            </full-stacktrace>
          </exception> <!-- java.lang.AssertionError -->
          <reporter-output>
          </reporter-output>
        </test-method> <!-- testLogin -->
        <test-method signature="testLogin(java.lang.String,java.lang.String)[pri:0, instance:testCases.TC02_Login@6af9fcb2]" started-at="2025-05-20T18:05:43 EDT" name="testLogin" data-provider="LoginData" finished-at="2025-05-20T18:05:43 EDT" duration-ms="26" status="FAIL">
          <params>
            <param index="0">
              <value>
                <![CDATA[apushedwoman@gmail.com]]>
              </value>
            </param>
            <param index="1">
              <value>
                <![CDATA[password123]]>
              </value>
            </param>
          </params>
          <exception class="java.lang.AssertionError">
            <message>
              <![CDATA[Unexpected exception during login test execution.]]>
            </message>
            <full-stacktrace>
              <![CDATA[java.lang.AssertionError: Unexpected exception during login test execution.
at org.testng.Assert.fail(Assert.java:111)
at testCases.TC02_Login.testLogin(TC02_Login.java:69)
at java.base/jdk.internal.reflect.DirectMethodHandleAccessor.invoke(DirectMethodHandleAccessor.java:103)
at java.base/java.lang.reflect.Method.invoke(Method.java:580)
at org.testng.internal.invokers.MethodInvocationHelper.invokeMethod(MethodInvocationHelper.java:141)
at org.testng.internal.invokers.TestInvoker.invokeMethod(TestInvoker.java:687)
at org.testng.internal.invokers.TestInvoker.retryFailed(TestInvoker.java:269)
at org.testng.internal.invokers.MethodRunner.runInSequence(MethodRunner.java:76)
at org.testng.internal.invokers.TestInvoker$MethodInvocationAgent.invoke(TestInvoker.java:995)
at org.testng.internal.invokers.TestInvoker.invokeTestMethods(TestInvoker.java:203)
at org.testng.internal.invokers.TestMethodWorker.invokeTestMethods(TestMethodWorker.java:154)
at org.testng.internal.invokers.TestMethodWorker.run(TestMethodWorker.java:134)
at java.base/java.util.ArrayList.forEach(ArrayList.java:1596)
at org.testng.TestRunner.privateRun(TestRunner.java:741)
at org.testng.TestRunner.run(TestRunner.java:616)
at org.testng.SuiteRunner.runTest(SuiteRunner.java:421)
at org.testng.SuiteRunner$SuiteWorker.run(SuiteRunner.java:463)
at org.testng.internal.thread.ThreadUtil.lambda$execute$0(ThreadUtil.java:64)
at java.base/java.util.concurrent.FutureTask.run(FutureTask.java:317)
at java.base/java.util.concurrent.ThreadPoolExecutor.runWorker(ThreadPoolExecutor.java:1144)
at java.base/java.util.concurrent.ThreadPoolExecutor$Worker.run(ThreadPoolExecutor.java:642)
at java.base/java.lang.Thread.run(Thread.java:1583)
]]>
            </full-stacktrace>
          </exception> <!-- java.lang.AssertionError -->
          <reporter-output>
          </reporter-output>
        </test-method> <!-- testLogin -->
        <test-method retried="true" signature="testLogin(java.lang.String,java.lang.String)[pri:0, instance:testCases.TC02_Login@6af9fcb2]" started-at="2025-05-20T18:05:43 EDT" name="testLogin" data-provider="LoginData" finished-at="2025-05-20T18:05:43 EDT" duration-ms="8" status="SKIP">
          <params>
            <param index="0">
              <value>
                <![CDATA[hichamkhachiai@gmail.com]]>
              </value>
            </param>
            <param index="1">
              <value>
                <![CDATA[hicham123]]>
              </value>
            </param>
          </params>
          <exception class="java.lang.AssertionError">
            <message>
              <![CDATA[Unexpected exception during login test execution.]]>
            </message>
            <full-stacktrace>
              <![CDATA[java.lang.AssertionError: Unexpected exception during login test execution.
at org.testng.Assert.fail(Assert.java:111)
at testCases.TC02_Login.testLogin(TC02_Login.java:69)
at java.base/jdk.internal.reflect.DirectMethodHandleAccessor.invoke(DirectMethodHandleAccessor.java:103)
at java.base/java.lang.reflect.Method.invoke(Method.java:580)
at org.testng.internal.invokers.MethodInvocationHelper.invokeMethod(MethodInvocationHelper.java:141)
at org.testng.internal.invokers.TestInvoker.invokeMethod(TestInvoker.java:687)
at org.testng.internal.invokers.TestInvoker.invokeTestMethod(TestInvoker.java:230)
at org.testng.internal.invokers.MethodRunner.runInSequence(MethodRunner.java:63)
at org.testng.internal.invokers.TestInvoker$MethodInvocationAgent.invoke(TestInvoker.java:995)
at org.testng.internal.invokers.TestInvoker.invokeTestMethods(TestInvoker.java:203)
at org.testng.internal.invokers.TestMethodWorker.invokeTestMethods(TestMethodWorker.java:154)
at org.testng.internal.invokers.TestMethodWorker.run(TestMethodWorker.java:134)
at java.base/java.util.ArrayList.forEach(ArrayList.java:1596)
at org.testng.TestRunner.privateRun(TestRunner.java:741)
at org.testng.TestRunner.run(TestRunner.java:616)
at org.testng.SuiteRunner.runTest(SuiteRunner.java:421)
at org.testng.SuiteRunner$SuiteWorker.run(SuiteRunner.java:463)
at org.testng.internal.thread.ThreadUtil.lambda$execute$0(ThreadUtil.java:64)
at java.base/java.util.concurrent.FutureTask.run(FutureTask.java:317)
at java.base/java.util.concurrent.ThreadPoolExecutor.runWorker(ThreadPoolExecutor.java:1144)
at java.base/java.util.concurrent.ThreadPoolExecutor$Worker.run(ThreadPoolExecutor.java:642)
at java.base/java.lang.Thread.run(Thread.java:1583)
]]>
            </full-stacktrace>
          </exception> <!-- java.lang.AssertionError -->
          <reporter-output>
          </reporter-output>
        </test-method> <!-- testLogin -->
        <test-method retried="true" signature="testLogin(java.lang.String,java.lang.String)[pri:0, instance:testCases.TC02_Login@6af9fcb2]" started-at="2025-05-20T18:05:43 EDT" name="testLogin" data-provider="LoginData" finished-at="2025-05-20T18:05:43 EDT" duration-ms="4" status="SKIP">
          <params>
            <param index="0">
              <value>
                <![CDATA[hichamkhachiai@gmail.com]]>
              </value>
            </param>
            <param index="1">
              <value>
                <![CDATA[hicham123]]>
              </value>
            </param>
          </params>
          <exception class="java.lang.AssertionError">
            <message>
              <![CDATA[Unexpected exception during login test execution.]]>
            </message>
            <full-stacktrace>
              <![CDATA[java.lang.AssertionError: Unexpected exception during login test execution.
at org.testng.Assert.fail(Assert.java:111)
at testCases.TC02_Login.testLogin(TC02_Login.java:69)
at java.base/jdk.internal.reflect.DirectMethodHandleAccessor.invoke(DirectMethodHandleAccessor.java:103)
at java.base/java.lang.reflect.Method.invoke(Method.java:580)
at org.testng.internal.invokers.MethodInvocationHelper.invokeMethod(MethodInvocationHelper.java:141)
at org.testng.internal.invokers.TestInvoker.invokeMethod(TestInvoker.java:687)
at org.testng.internal.invokers.TestInvoker.retryFailed(TestInvoker.java:269)
at org.testng.internal.invokers.MethodRunner.runInSequence(MethodRunner.java:76)
at org.testng.internal.invokers.TestInvoker$MethodInvocationAgent.invoke(TestInvoker.java:995)
at org.testng.internal.invokers.TestInvoker.invokeTestMethods(TestInvoker.java:203)
at org.testng.internal.invokers.TestMethodWorker.invokeTestMethods(TestMethodWorker.java:154)
at org.testng.internal.invokers.TestMethodWorker.run(TestMethodWorker.java:134)
at java.base/java.util.ArrayList.forEach(ArrayList.java:1596)
at org.testng.TestRunner.privateRun(TestRunner.java:741)
at org.testng.TestRunner.run(TestRunner.java:616)
at org.testng.SuiteRunner.runTest(SuiteRunner.java:421)
at org.testng.SuiteRunner$SuiteWorker.run(SuiteRunner.java:463)
at org.testng.internal.thread.ThreadUtil.lambda$execute$0(ThreadUtil.java:64)
at java.base/java.util.concurrent.FutureTask.run(FutureTask.java:317)
at java.base/java.util.concurrent.ThreadPoolExecutor.runWorker(ThreadPoolExecutor.java:1144)
at java.base/java.util.concurrent.ThreadPoolExecutor$Worker.run(ThreadPoolExecutor.java:642)
at java.base/java.lang.Thread.run(Thread.java:1583)
]]>
            </full-stacktrace>
          </exception> <!-- java.lang.AssertionError -->
          <reporter-output>
          </reporter-output>
        </test-method> <!-- testLogin -->
        <test-method signature="testLogin(java.lang.String,java.lang.String)[pri:0, instance:testCases.TC02_Login@6af9fcb2]" started-at="2025-05-20T18:05:43 EDT" name="testLogin" data-provider="LoginData" finished-at="2025-05-20T18:05:43 EDT" duration-ms="10" status="FAIL">
          <params>
            <param index="0">
              <value>
                <![CDATA[hichamkhachiai@gmail.com]]>
              </value>
            </param>
            <param index="1">
              <value>
                <![CDATA[hicham123]]>
              </value>
            </param>
          </params>
          <exception class="java.lang.AssertionError">
            <message>
              <![CDATA[Unexpected exception during login test execution.]]>
            </message>
            <full-stacktrace>
              <![CDATA[java.lang.AssertionError: Unexpected exception during login test execution.
at org.testng.Assert.fail(Assert.java:111)
at testCases.TC02_Login.testLogin(TC02_Login.java:69)
at java.base/jdk.internal.reflect.DirectMethodHandleAccessor.invoke(DirectMethodHandleAccessor.java:103)
at java.base/java.lang.reflect.Method.invoke(Method.java:580)
at org.testng.internal.invokers.MethodInvocationHelper.invokeMethod(MethodInvocationHelper.java:141)
at org.testng.internal.invokers.TestInvoker.invokeMethod(TestInvoker.java:687)
at org.testng.internal.invokers.TestInvoker.retryFailed(TestInvoker.java:269)
at org.testng.internal.invokers.MethodRunner.runInSequence(MethodRunner.java:76)
at org.testng.internal.invokers.TestInvoker$MethodInvocationAgent.invoke(TestInvoker.java:995)
at org.testng.internal.invokers.TestInvoker.invokeTestMethods(TestInvoker.java:203)
at org.testng.internal.invokers.TestMethodWorker.invokeTestMethods(TestMethodWorker.java:154)
at org.testng.internal.invokers.TestMethodWorker.run(TestMethodWorker.java:134)
at java.base/java.util.ArrayList.forEach(ArrayList.java:1596)
at org.testng.TestRunner.privateRun(TestRunner.java:741)
at org.testng.TestRunner.run(TestRunner.java:616)
at org.testng.SuiteRunner.runTest(SuiteRunner.java:421)
at org.testng.SuiteRunner$SuiteWorker.run(SuiteRunner.java:463)
at org.testng.internal.thread.ThreadUtil.lambda$execute$0(ThreadUtil.java:64)
at java.base/java.util.concurrent.FutureTask.run(FutureTask.java:317)
at java.base/java.util.concurrent.ThreadPoolExecutor.runWorker(ThreadPoolExecutor.java:1144)
at java.base/java.util.concurrent.ThreadPoolExecutor$Worker.run(ThreadPoolExecutor.java:642)
at java.base/java.lang.Thread.run(Thread.java:1583)
]]>
            </full-stacktrace>
          </exception> <!-- java.lang.AssertionError -->
          <reporter-output>
          </reporter-output>
        </test-method> <!-- testLogin -->
        <test-method is-config="true" signature="closeApp()[pri:0, instance:testCases.TC02_Login@6af9fcb2]" started-at="2025-05-20T18:05:43 EDT" name="closeApp" finished-at="2025-05-20T18:05:43 EDT" duration-ms="5" status="PASS">
          <reporter-output>
          </reporter-output>
        </test-method> <!-- closeApp -->
      </class> <!-- testCases.TC02_Login -->
      <class name="testCases.TC01_LaunchApplication">
        <test-method is-config="true" signature="openApp(java.lang.String,java.lang.String)[pri:0, instance:testCases.TC01_LaunchApplication@4716be8b]" started-at="2025-05-20T18:05:37 EDT" name="openApp" finished-at="2025-05-20T18:05:39 EDT" duration-ms="1704" status="PASS">
          <params>
            <param index="0">
              <value>
                <![CDATA[windows]]>
              </value>
            </param>
            <param index="1">
              <value>
                <![CDATA[edge]]>
              </value>
            </param>
          </params>
          <reporter-output>
          </reporter-output>
        </test-method> <!-- openApp -->
        <test-method retried="true" signature="testLaunchApplication()[pri:0, instance:testCases.TC01_LaunchApplication@4716be8b]" started-at="2025-05-20T18:05:39 EDT" name="testLaunchApplication" finished-at="2025-05-20T18:05:39 EDT" duration-ms="116" status="SKIP">
          <exception class="java.lang.AssertionError">
            <message>
              <![CDATA[Test failed due to unexpected exception]]>
            </message>
            <full-stacktrace>
              <![CDATA[java.lang.AssertionError: Test failed due to unexpected exception
at org.testng.Assert.fail(Assert.java:111)
at testCases.TC01_LaunchApplication.testLaunchApplication(TC01_LaunchApplication.java:35)
at java.base/jdk.internal.reflect.DirectMethodHandleAccessor.invoke(DirectMethodHandleAccessor.java:103)
at java.base/java.lang.reflect.Method.invoke(Method.java:580)
at org.testng.internal.invokers.MethodInvocationHelper.invokeMethod(MethodInvocationHelper.java:141)
at org.testng.internal.invokers.TestInvoker.invokeMethod(TestInvoker.java:687)
at org.testng.internal.invokers.TestInvoker.invokeTestMethod(TestInvoker.java:230)
at org.testng.internal.invokers.MethodRunner.runInSequence(MethodRunner.java:63)
at org.testng.internal.invokers.TestInvoker$MethodInvocationAgent.invoke(TestInvoker.java:995)
at org.testng.internal.invokers.TestInvoker.invokeTestMethods(TestInvoker.java:203)
at org.testng.internal.invokers.TestMethodWorker.invokeTestMethods(TestMethodWorker.java:154)
at org.testng.internal.invokers.TestMethodWorker.run(TestMethodWorker.java:134)
at java.base/java.util.ArrayList.forEach(ArrayList.java:1596)
at org.testng.TestRunner.privateRun(TestRunner.java:741)
at org.testng.TestRunner.run(TestRunner.java:616)
at org.testng.SuiteRunner.runTest(SuiteRunner.java:421)
at org.testng.SuiteRunner$SuiteWorker.run(SuiteRunner.java:463)
at org.testng.internal.thread.ThreadUtil.lambda$execute$0(ThreadUtil.java:64)
at java.base/java.util.concurrent.FutureTask.run(FutureTask.java:317)
at java.base/java.util.concurrent.ThreadPoolExecutor.runWorker(ThreadPoolExecutor.java:1144)
at java.base/java.util.concurrent.ThreadPoolExecutor$Worker.run(ThreadPoolExecutor.java:642)
at java.base/java.lang.Thread.run(Thread.java:1583)
]]>
            </full-stacktrace>
          </exception> <!-- java.lang.AssertionError -->
          <reporter-output>
          </reporter-output>
        </test-method> <!-- testLaunchApplication -->
        <test-method retried="true" signature="testLaunchApplication()[pri:0, instance:testCases.TC01_LaunchApplication@4716be8b]" started-at="2025-05-20T18:05:39 EDT" name="testLaunchApplication" finished-at="2025-05-20T18:05:39 EDT" duration-ms="11" status="SKIP">
          <exception class="java.lang.AssertionError">
            <message>
              <![CDATA[Test failed due to unexpected exception]]>
            </message>
            <full-stacktrace>
              <![CDATA[java.lang.AssertionError: Test failed due to unexpected exception
at org.testng.Assert.fail(Assert.java:111)
at testCases.TC01_LaunchApplication.testLaunchApplication(TC01_LaunchApplication.java:35)
at java.base/jdk.internal.reflect.DirectMethodHandleAccessor.invoke(DirectMethodHandleAccessor.java:103)
at java.base/java.lang.reflect.Method.invoke(Method.java:580)
at org.testng.internal.invokers.MethodInvocationHelper.invokeMethod(MethodInvocationHelper.java:141)
at org.testng.internal.invokers.TestInvoker.invokeMethod(TestInvoker.java:687)
at org.testng.internal.invokers.TestInvoker.retryFailed(TestInvoker.java:269)
at org.testng.internal.invokers.MethodRunner.runInSequence(MethodRunner.java:76)
at org.testng.internal.invokers.TestInvoker$MethodInvocationAgent.invoke(TestInvoker.java:995)
at org.testng.internal.invokers.TestInvoker.invokeTestMethods(TestInvoker.java:203)
at org.testng.internal.invokers.TestMethodWorker.invokeTestMethods(TestMethodWorker.java:154)
at org.testng.internal.invokers.TestMethodWorker.run(TestMethodWorker.java:134)
at java.base/java.util.ArrayList.forEach(ArrayList.java:1596)
at org.testng.TestRunner.privateRun(TestRunner.java:741)
at org.testng.TestRunner.run(TestRunner.java:616)
at org.testng.SuiteRunner.runTest(SuiteRunner.java:421)
at org.testng.SuiteRunner$SuiteWorker.run(SuiteRunner.java:463)
at org.testng.internal.thread.ThreadUtil.lambda$execute$0(ThreadUtil.java:64)
at java.base/java.util.concurrent.FutureTask.run(FutureTask.java:317)
at java.base/java.util.concurrent.ThreadPoolExecutor.runWorker(ThreadPoolExecutor.java:1144)
at java.base/java.util.concurrent.ThreadPoolExecutor$Worker.run(ThreadPoolExecutor.java:642)
at java.base/java.lang.Thread.run(Thread.java:1583)
]]>
            </full-stacktrace>
          </exception> <!-- java.lang.AssertionError -->
          <reporter-output>
          </reporter-output>
        </test-method> <!-- testLaunchApplication -->
        <test-method signature="testLaunchApplication()[pri:0, instance:testCases.TC01_LaunchApplication@4716be8b]" started-at="2025-05-20T18:05:39 EDT" name="testLaunchApplication" finished-at="2025-05-20T18:05:39 EDT" duration-ms="12" status="FAIL">
          <exception class="java.lang.AssertionError">
            <message>
              <![CDATA[Test failed due to unexpected exception]]>
            </message>
            <full-stacktrace>
              <![CDATA[java.lang.AssertionError: Test failed due to unexpected exception
at org.testng.Assert.fail(Assert.java:111)
at testCases.TC01_LaunchApplication.testLaunchApplication(TC01_LaunchApplication.java:35)
at java.base/jdk.internal.reflect.DirectMethodHandleAccessor.invoke(DirectMethodHandleAccessor.java:103)
at java.base/java.lang.reflect.Method.invoke(Method.java:580)
at org.testng.internal.invokers.MethodInvocationHelper.invokeMethod(MethodInvocationHelper.java:141)
at org.testng.internal.invokers.TestInvoker.invokeMethod(TestInvoker.java:687)
at org.testng.internal.invokers.TestInvoker.retryFailed(TestInvoker.java:269)
at org.testng.internal.invokers.MethodRunner.runInSequence(MethodRunner.java:76)
at org.testng.internal.invokers.TestInvoker$MethodInvocationAgent.invoke(TestInvoker.java:995)
at org.testng.internal.invokers.TestInvoker.invokeTestMethods(TestInvoker.java:203)
at org.testng.internal.invokers.TestMethodWorker.invokeTestMethods(TestMethodWorker.java:154)
at org.testng.internal.invokers.TestMethodWorker.run(TestMethodWorker.java:134)
at java.base/java.util.ArrayList.forEach(ArrayList.java:1596)
at org.testng.TestRunner.privateRun(TestRunner.java:741)
at org.testng.TestRunner.run(TestRunner.java:616)
at org.testng.SuiteRunner.runTest(SuiteRunner.java:421)
at org.testng.SuiteRunner$SuiteWorker.run(SuiteRunner.java:463)
at org.testng.internal.thread.ThreadUtil.lambda$execute$0(ThreadUtil.java:64)
at java.base/java.util.concurrent.FutureTask.run(FutureTask.java:317)
at java.base/java.util.concurrent.ThreadPoolExecutor.runWorker(ThreadPoolExecutor.java:1144)
at java.base/java.util.concurrent.ThreadPoolExecutor$Worker.run(ThreadPoolExecutor.java:642)
at java.base/java.lang.Thread.run(Thread.java:1583)
]]>
            </full-stacktrace>
          </exception> <!-- java.lang.AssertionError -->
          <reporter-output>
          </reporter-output>
        </test-method> <!-- testLaunchApplication -->
        <test-method is-config="true" signature="closeApp()[pri:0, instance:testCases.TC01_LaunchApplication@4716be8b]" started-at="2025-05-20T18:05:39 EDT" name="closeApp" finished-at="2025-05-20T18:05:39 EDT" duration-ms="18" status="PASS">
          <reporter-output>
          </reporter-output>
        </test-method> <!-- closeApp -->
      </class> <!-- testCases.TC01_LaunchApplication -->
      <class name="testCases.TC03_AddToCart">
        <test-method is-config="true" signature="openApp(java.lang.String,java.lang.String)[pri:0, instance:testCases.TC03_AddToCart@1fc32e4f]" started-at="2025-05-20T18:05:39 EDT" name="openApp" finished-at="2025-05-20T18:05:39 EDT" duration-ms="130" status="PASS">
          <params>
            <param index="0">
              <value>
                <![CDATA[windows]]>
              </value>
            </param>
            <param index="1">
              <value>
                <![CDATA[edge]]>
              </value>
            </param>
          </params>
          <reporter-output>
          </reporter-output>
        </test-method> <!-- openApp -->
        <test-method retried="true" signature="testAddToCart()[pri:0, instance:testCases.TC03_AddToCart@1fc32e4f]" started-at="2025-05-20T18:05:39 EDT" name="testAddToCart" finished-at="2025-05-20T18:05:39 EDT" duration-ms="13" status="SKIP">
          <exception class="java.lang.AssertionError">
            <message>
              <![CDATA[Test failed due to unexpected exception.]]>
            </message>
            <full-stacktrace>
              <![CDATA[java.lang.AssertionError: Test failed due to unexpected exception.
at org.testng.Assert.fail(Assert.java:111)
at testCases.TC03_AddToCart.testAddToCart(TC03_AddToCart.java:55)
at java.base/jdk.internal.reflect.DirectMethodHandleAccessor.invoke(DirectMethodHandleAccessor.java:103)
at java.base/java.lang.reflect.Method.invoke(Method.java:580)
at org.testng.internal.invokers.MethodInvocationHelper.invokeMethod(MethodInvocationHelper.java:141)
at org.testng.internal.invokers.TestInvoker.invokeMethod(TestInvoker.java:687)
at org.testng.internal.invokers.TestInvoker.invokeTestMethod(TestInvoker.java:230)
at org.testng.internal.invokers.MethodRunner.runInSequence(MethodRunner.java:63)
at org.testng.internal.invokers.TestInvoker$MethodInvocationAgent.invoke(TestInvoker.java:995)
at org.testng.internal.invokers.TestInvoker.invokeTestMethods(TestInvoker.java:203)
at org.testng.internal.invokers.TestMethodWorker.invokeTestMethods(TestMethodWorker.java:154)
at org.testng.internal.invokers.TestMethodWorker.run(TestMethodWorker.java:134)
at java.base/java.util.ArrayList.forEach(ArrayList.java:1596)
at org.testng.TestRunner.privateRun(TestRunner.java:741)
at org.testng.TestRunner.run(TestRunner.java:616)
at org.testng.SuiteRunner.runTest(SuiteRunner.java:421)
at org.testng.SuiteRunner$SuiteWorker.run(SuiteRunner.java:463)
at org.testng.internal.thread.ThreadUtil.lambda$execute$0(ThreadUtil.java:64)
at java.base/java.util.concurrent.FutureTask.run(FutureTask.java:317)
at java.base/java.util.concurrent.ThreadPoolExecutor.runWorker(ThreadPoolExecutor.java:1144)
at java.base/java.util.concurrent.ThreadPoolExecutor$Worker.run(ThreadPoolExecutor.java:642)
at java.base/java.lang.Thread.run(Thread.java:1583)
]]>
            </full-stacktrace>
          </exception> <!-- java.lang.AssertionError -->
          <reporter-output>
          </reporter-output>
        </test-method> <!-- testAddToCart -->
        <test-method retried="true" signature="testAddToCart()[pri:0, instance:testCases.TC03_AddToCart@1fc32e4f]" started-at="2025-05-20T18:05:39 EDT" name="testAddToCart" finished-at="2025-05-20T18:05:39 EDT" duration-ms="9" status="SKIP">
          <exception class="java.lang.AssertionError">
            <message>
              <![CDATA[Test failed due to unexpected exception.]]>
            </message>
            <full-stacktrace>
              <![CDATA[java.lang.AssertionError: Test failed due to unexpected exception.
at org.testng.Assert.fail(Assert.java:111)
at testCases.TC03_AddToCart.testAddToCart(TC03_AddToCart.java:55)
at java.base/jdk.internal.reflect.DirectMethodHandleAccessor.invoke(DirectMethodHandleAccessor.java:103)
at java.base/java.lang.reflect.Method.invoke(Method.java:580)
at org.testng.internal.invokers.MethodInvocationHelper.invokeMethod(MethodInvocationHelper.java:141)
at org.testng.internal.invokers.TestInvoker.invokeMethod(TestInvoker.java:687)
at org.testng.internal.invokers.TestInvoker.retryFailed(TestInvoker.java:269)
at org.testng.internal.invokers.MethodRunner.runInSequence(MethodRunner.java:76)
at org.testng.internal.invokers.TestInvoker$MethodInvocationAgent.invoke(TestInvoker.java:995)
at org.testng.internal.invokers.TestInvoker.invokeTestMethods(TestInvoker.java:203)
at org.testng.internal.invokers.TestMethodWorker.invokeTestMethods(TestMethodWorker.java:154)
at org.testng.internal.invokers.TestMethodWorker.run(TestMethodWorker.java:134)
at java.base/java.util.ArrayList.forEach(ArrayList.java:1596)
at org.testng.TestRunner.privateRun(TestRunner.java:741)
at org.testng.TestRunner.run(TestRunner.java:616)
at org.testng.SuiteRunner.runTest(SuiteRunner.java:421)
at org.testng.SuiteRunner$SuiteWorker.run(SuiteRunner.java:463)
at org.testng.internal.thread.ThreadUtil.lambda$execute$0(ThreadUtil.java:64)
at java.base/java.util.concurrent.FutureTask.run(FutureTask.java:317)
at java.base/java.util.concurrent.ThreadPoolExecutor.runWorker(ThreadPoolExecutor.java:1144)
at java.base/java.util.concurrent.ThreadPoolExecutor$Worker.run(ThreadPoolExecutor.java:642)
at java.base/java.lang.Thread.run(Thread.java:1583)
]]>
            </full-stacktrace>
          </exception> <!-- java.lang.AssertionError -->
          <reporter-output>
          </reporter-output>
        </test-method> <!-- testAddToCart -->
        <test-method signature="testAddToCart()[pri:0, instance:testCases.TC03_AddToCart@1fc32e4f]" started-at="2025-05-20T18:05:39 EDT" name="testAddToCart" finished-at="2025-05-20T18:05:39 EDT" duration-ms="6" status="FAIL">
          <exception class="java.lang.AssertionError">
            <message>
              <![CDATA[Test failed due to unexpected exception.]]>
            </message>
            <full-stacktrace>
              <![CDATA[java.lang.AssertionError: Test failed due to unexpected exception.
at org.testng.Assert.fail(Assert.java:111)
at testCases.TC03_AddToCart.testAddToCart(TC03_AddToCart.java:55)
at java.base/jdk.internal.reflect.DirectMethodHandleAccessor.invoke(DirectMethodHandleAccessor.java:103)
at java.base/java.lang.reflect.Method.invoke(Method.java:580)
at org.testng.internal.invokers.MethodInvocationHelper.invokeMethod(MethodInvocationHelper.java:141)
at org.testng.internal.invokers.TestInvoker.invokeMethod(TestInvoker.java:687)
at org.testng.internal.invokers.TestInvoker.retryFailed(TestInvoker.java:269)
at org.testng.internal.invokers.MethodRunner.runInSequence(MethodRunner.java:76)
at org.testng.internal.invokers.TestInvoker$MethodInvocationAgent.invoke(TestInvoker.java:995)
at org.testng.internal.invokers.TestInvoker.invokeTestMethods(TestInvoker.java:203)
at org.testng.internal.invokers.TestMethodWorker.invokeTestMethods(TestMethodWorker.java:154)
at org.testng.internal.invokers.TestMethodWorker.run(TestMethodWorker.java:134)
at java.base/java.util.ArrayList.forEach(ArrayList.java:1596)
at org.testng.TestRunner.privateRun(TestRunner.java:741)
at org.testng.TestRunner.run(TestRunner.java:616)
at org.testng.SuiteRunner.runTest(SuiteRunner.java:421)
at org.testng.SuiteRunner$SuiteWorker.run(SuiteRunner.java:463)
at org.testng.internal.thread.ThreadUtil.lambda$execute$0(ThreadUtil.java:64)
at java.base/java.util.concurrent.FutureTask.run(FutureTask.java:317)
at java.base/java.util.concurrent.ThreadPoolExecutor.runWorker(ThreadPoolExecutor.java:1144)
at java.base/java.util.concurrent.ThreadPoolExecutor$Worker.run(ThreadPoolExecutor.java:642)
at java.base/java.lang.Thread.run(Thread.java:1583)
]]>
            </full-stacktrace>
          </exception> <!-- java.lang.AssertionError -->
          <reporter-output>
          </reporter-output>
        </test-method> <!-- testAddToCart -->
        <test-method is-config="true" signature="closeApp()[pri:0, instance:testCases.TC03_AddToCart@1fc32e4f]" started-at="2025-05-20T18:05:39 EDT" name="closeApp" finished-at="2025-05-20T18:05:39 EDT" duration-ms="6" status="PASS">
          <reporter-output>
          </reporter-output>
        </test-method> <!-- closeApp -->
      </class> <!-- testCases.TC03_AddToCart -->
      <class name="testCases.TC04_CompletePurchase">
        <test-method is-config="true" signature="openApp(java.lang.String,java.lang.String)[pri:0, instance:testCases.TC04_CompletePurchase@6cce16f4]" started-at="2025-05-20T18:05:43 EDT" name="openApp" finished-at="2025-05-20T18:05:43 EDT" duration-ms="83" status="PASS">
          <params>
            <param index="0">
              <value>
                <![CDATA[windows]]>
              </value>
            </param>
            <param index="1">
              <value>
                <![CDATA[edge]]>
              </value>
            </param>
          </params>
          <reporter-output>
          </reporter-output>
        </test-method> <!-- openApp -->
        <test-method retried="true" signature="testCompletePurchase()[pri:0, instance:testCases.TC04_CompletePurchase@6cce16f4]" started-at="2025-05-20T18:05:43 EDT" name="testCompletePurchase" finished-at="2025-05-20T18:05:43 EDT" duration-ms="6" status="SKIP">
          <exception class="java.lang.AssertionError">
            <message>
              <![CDATA[Test failed due to unexpected exception.]]>
            </message>
            <full-stacktrace>
              <![CDATA[java.lang.AssertionError: Test failed due to unexpected exception.
at org.testng.Assert.fail(Assert.java:111)
at testCases.TC04_CompletePurchase.testCompletePurchase(TC04_CompletePurchase.java:81)
at java.base/jdk.internal.reflect.DirectMethodHandleAccessor.invoke(DirectMethodHandleAccessor.java:103)
at java.base/java.lang.reflect.Method.invoke(Method.java:580)
at org.testng.internal.invokers.MethodInvocationHelper.invokeMethod(MethodInvocationHelper.java:141)
at org.testng.internal.invokers.TestInvoker.invokeMethod(TestInvoker.java:687)
at org.testng.internal.invokers.TestInvoker.invokeTestMethod(TestInvoker.java:230)
at org.testng.internal.invokers.MethodRunner.runInSequence(MethodRunner.java:63)
at org.testng.internal.invokers.TestInvoker$MethodInvocationAgent.invoke(TestInvoker.java:995)
at org.testng.internal.invokers.TestInvoker.invokeTestMethods(TestInvoker.java:203)
at org.testng.internal.invokers.TestMethodWorker.invokeTestMethods(TestMethodWorker.java:154)
at org.testng.internal.invokers.TestMethodWorker.run(TestMethodWorker.java:134)
at java.base/java.util.ArrayList.forEach(ArrayList.java:1596)
at org.testng.TestRunner.privateRun(TestRunner.java:741)
at org.testng.TestRunner.run(TestRunner.java:616)
at org.testng.SuiteRunner.runTest(SuiteRunner.java:421)
at org.testng.SuiteRunner$SuiteWorker.run(SuiteRunner.java:463)
at org.testng.internal.thread.ThreadUtil.lambda$execute$0(ThreadUtil.java:64)
at java.base/java.util.concurrent.FutureTask.run(FutureTask.java:317)
at java.base/java.util.concurrent.ThreadPoolExecutor.runWorker(ThreadPoolExecutor.java:1144)
at java.base/java.util.concurrent.ThreadPoolExecutor$Worker.run(ThreadPoolExecutor.java:642)
at java.base/java.lang.Thread.run(Thread.java:1583)
]]>
            </full-stacktrace>
          </exception> <!-- java.lang.AssertionError -->
          <reporter-output>
          </reporter-output>
        </test-method> <!-- testCompletePurchase -->
        <test-method retried="true" signature="testCompletePurchase()[pri:0, instance:testCases.TC04_CompletePurchase@6cce16f4]" started-at="2025-05-20T18:05:43 EDT" name="testCompletePurchase" finished-at="2025-05-20T18:05:43 EDT" duration-ms="6" status="SKIP">
          <exception class="java.lang.AssertionError">
            <message>
              <![CDATA[Test failed due to unexpected exception.]]>
            </message>
            <full-stacktrace>
              <![CDATA[java.lang.AssertionError: Test failed due to unexpected exception.
at org.testng.Assert.fail(Assert.java:111)
at testCases.TC04_CompletePurchase.testCompletePurchase(TC04_CompletePurchase.java:81)
at java.base/jdk.internal.reflect.DirectMethodHandleAccessor.invoke(DirectMethodHandleAccessor.java:103)
at java.base/java.lang.reflect.Method.invoke(Method.java:580)
at org.testng.internal.invokers.MethodInvocationHelper.invokeMethod(MethodInvocationHelper.java:141)
at org.testng.internal.invokers.TestInvoker.invokeMethod(TestInvoker.java:687)
at org.testng.internal.invokers.TestInvoker.retryFailed(TestInvoker.java:269)
at org.testng.internal.invokers.MethodRunner.runInSequence(MethodRunner.java:76)
at org.testng.internal.invokers.TestInvoker$MethodInvocationAgent.invoke(TestInvoker.java:995)
at org.testng.internal.invokers.TestInvoker.invokeTestMethods(TestInvoker.java:203)
at org.testng.internal.invokers.TestMethodWorker.invokeTestMethods(TestMethodWorker.java:154)
at org.testng.internal.invokers.TestMethodWorker.run(TestMethodWorker.java:134)
at java.base/java.util.ArrayList.forEach(ArrayList.java:1596)
at org.testng.TestRunner.privateRun(TestRunner.java:741)
at org.testng.TestRunner.run(TestRunner.java:616)
at org.testng.SuiteRunner.runTest(SuiteRunner.java:421)
at org.testng.SuiteRunner$SuiteWorker.run(SuiteRunner.java:463)
at org.testng.internal.thread.ThreadUtil.lambda$execute$0(ThreadUtil.java:64)
at java.base/java.util.concurrent.FutureTask.run(FutureTask.java:317)
at java.base/java.util.concurrent.ThreadPoolExecutor.runWorker(ThreadPoolExecutor.java:1144)
at java.base/java.util.concurrent.ThreadPoolExecutor$Worker.run(ThreadPoolExecutor.java:642)
at java.base/java.lang.Thread.run(Thread.java:1583)
]]>
            </full-stacktrace>
          </exception> <!-- java.lang.AssertionError -->
          <reporter-output>
          </reporter-output>
        </test-method> <!-- testCompletePurchase -->
        <test-method signature="testCompletePurchase()[pri:0, instance:testCases.TC04_CompletePurchase@6cce16f4]" started-at="2025-05-20T18:05:43 EDT" name="testCompletePurchase" finished-at="2025-05-20T18:05:43 EDT" duration-ms="2" status="FAIL">
          <exception class="java.lang.AssertionError">
            <message>
              <![CDATA[Test failed due to unexpected exception.]]>
            </message>
            <full-stacktrace>
              <![CDATA[java.lang.AssertionError: Test failed due to unexpected exception.
at org.testng.Assert.fail(Assert.java:111)
at testCases.TC04_CompletePurchase.testCompletePurchase(TC04_CompletePurchase.java:81)
at java.base/jdk.internal.reflect.DirectMethodHandleAccessor.invoke(DirectMethodHandleAccessor.java:103)
at java.base/java.lang.reflect.Method.invoke(Method.java:580)
at org.testng.internal.invokers.MethodInvocationHelper.invokeMethod(MethodInvocationHelper.java:141)
at org.testng.internal.invokers.TestInvoker.invokeMethod(TestInvoker.java:687)
at org.testng.internal.invokers.TestInvoker.retryFailed(TestInvoker.java:269)
at org.testng.internal.invokers.MethodRunner.runInSequence(MethodRunner.java:76)
at org.testng.internal.invokers.TestInvoker$MethodInvocationAgent.invoke(TestInvoker.java:995)
at org.testng.internal.invokers.TestInvoker.invokeTestMethods(TestInvoker.java:203)
at org.testng.internal.invokers.TestMethodWorker.invokeTestMethods(TestMethodWorker.java:154)
at org.testng.internal.invokers.TestMethodWorker.run(TestMethodWorker.java:134)
at java.base/java.util.ArrayList.forEach(ArrayList.java:1596)
at org.testng.TestRunner.privateRun(TestRunner.java:741)
at org.testng.TestRunner.run(TestRunner.java:616)
at org.testng.SuiteRunner.runTest(SuiteRunner.java:421)
at org.testng.SuiteRunner$SuiteWorker.run(SuiteRunner.java:463)
at org.testng.internal.thread.ThreadUtil.lambda$execute$0(ThreadUtil.java:64)
at java.base/java.util.concurrent.FutureTask.run(FutureTask.java:317)
at java.base/java.util.concurrent.ThreadPoolExecutor.runWorker(ThreadPoolExecutor.java:1144)
at java.base/java.util.concurrent.ThreadPoolExecutor$Worker.run(ThreadPoolExecutor.java:642)
at java.base/java.lang.Thread.run(Thread.java:1583)
]]>
            </full-stacktrace>
          </exception> <!-- java.lang.AssertionError -->
          <reporter-output>
          </reporter-output>
        </test-method> <!-- testCompletePurchase -->
        <test-method is-config="true" signature="closeApp()[pri:0, instance:testCases.TC04_CompletePurchase@6cce16f4]" started-at="2025-05-20T18:05:43 EDT" name="closeApp" finished-at="2025-05-20T18:05:43 EDT" duration-ms="4" status="PASS">
          <reporter-output>
          </reporter-output>
        </test-method> <!-- closeApp -->
      </class> <!-- testCases.TC04_CompletePurchase -->
    </test> <!-- edgeTest -->
  </suite> <!-- Suite -->
</testng-results>
