-------------------------------------------------------------------------------
Test set: TestSuite
-------------------------------------------------------------------------------
Tests run: 72, Failures: 24, Errors: 0, Skipped: 48, Time elapsed: 12.16 s <<< FAILURE! -- in TestSuite
testCases.TC01_LaunchApplication.testLaunchApplication -- Time elapsed: 0.028 s <<< FAILURE!
java.lang.AssertionError: Test failed due to unexpected exception
	at org.testng.Assert.fail(Assert.java:111)
	at testCases.TC01_LaunchApplication.testLaunchApplication(TC01_LaunchApplication.java:35)
	at java.base/jdk.internal.reflect.DirectMethodHandleAccessor.invoke(DirectMethodHandleAccessor.java:103)
	at java.base/java.lang.reflect.Method.invoke(Method.java:580)
	at org.testng.internal.invokers.MethodInvocationHelper.invokeMethod(MethodInvocationHelper.java:141)
	at org.testng.internal.invokers.TestInvoker.invokeMethod(TestInvoker.java:687)
	at org.testng.internal.invokers.TestInvoker.retryFailed(TestInvoker.java:269)
	at org.testng.internal.invokers.MethodRunner.runInSequence(MethodRunner.java:76)
	at org.testng.internal.invokers.TestInvoker$MethodInvocationAgent.invoke(TestInvoker.java:995)
	at org.testng.internal.invokers.TestInvoker.invokeTestMethods(TestInvoker.java:203)
	at org.testng.internal.invokers.TestMethodWorker.invokeTestMethods(TestMethodWorker.java:154)
	at org.testng.internal.invokers.TestMethodWorker.run(TestMethodWorker.java:134)
	at java.base/java.util.ArrayList.forEach(ArrayList.java:1596)
	at org.testng.TestRunner.privateRun(TestRunner.java:741)
	at org.testng.TestRunner.run(TestRunner.java:616)
	at org.testng.SuiteRunner.runTest(SuiteRunner.java:421)
	at org.testng.SuiteRunner$SuiteWorker.run(SuiteRunner.java:463)
	at org.testng.internal.thread.ThreadUtil.lambda$execute$0(ThreadUtil.java:64)
	at java.base/java.util.concurrent.FutureTask.run(FutureTask.java:317)
	at java.base/java.util.concurrent.ThreadPoolExecutor.runWorker(ThreadPoolExecutor.java:1144)
	at java.base/java.util.concurrent.ThreadPoolExecutor$Worker.run(ThreadPoolExecutor.java:642)
	at java.base/java.lang.Thread.run(Thread.java:1583)

testCases.TC01_LaunchApplication.testLaunchApplication -- Time elapsed: 0.028 s <<< FAILURE!
java.lang.AssertionError: Test failed due to unexpected exception
	at org.testng.Assert.fail(Assert.java:111)
	at testCases.TC01_LaunchApplication.testLaunchApplication(TC01_LaunchApplication.java:35)
	at java.base/jdk.internal.reflect.DirectMethodHandleAccessor.invoke(DirectMethodHandleAccessor.java:103)
	at java.base/java.lang.reflect.Method.invoke(Method.java:580)
	at org.testng.internal.invokers.MethodInvocationHelper.invokeMethod(MethodInvocationHelper.java:141)
	at org.testng.internal.invokers.TestInvoker.invokeMethod(TestInvoker.java:687)
	at org.testng.internal.invokers.TestInvoker.retryFailed(TestInvoker.java:269)
	at org.testng.internal.invokers.MethodRunner.runInSequence(MethodRunner.java:76)
	at org.testng.internal.invokers.TestInvoker$MethodInvocationAgent.invoke(TestInvoker.java:995)
	at org.testng.internal.invokers.TestInvoker.invokeTestMethods(TestInvoker.java:203)
	at org.testng.internal.invokers.TestMethodWorker.invokeTestMethods(TestMethodWorker.java:154)
	at org.testng.internal.invokers.TestMethodWorker.run(TestMethodWorker.java:134)
	at java.base/java.util.ArrayList.forEach(ArrayList.java:1596)
	at org.testng.TestRunner.privateRun(TestRunner.java:741)
	at org.testng.TestRunner.run(TestRunner.java:616)
	at org.testng.SuiteRunner.runTest(SuiteRunner.java:421)
	at org.testng.SuiteRunner$SuiteWorker.run(SuiteRunner.java:463)
	at org.testng.internal.thread.ThreadUtil.lambda$execute$0(ThreadUtil.java:64)
	at java.base/java.util.concurrent.FutureTask.run(FutureTask.java:317)
	at java.base/java.util.concurrent.ThreadPoolExecutor.runWorker(ThreadPoolExecutor.java:1144)
	at java.base/java.util.concurrent.ThreadPoolExecutor$Worker.run(ThreadPoolExecutor.java:642)
	at java.base/java.lang.Thread.run(Thread.java:1583)

testCases.TC01_LaunchApplication.testLaunchApplication -- Time elapsed: 0.028 s <<< FAILURE!
java.lang.AssertionError: Test failed due to unexpected exception
	at org.testng.Assert.fail(Assert.java:111)
	at testCases.TC01_LaunchApplication.testLaunchApplication(TC01_LaunchApplication.java:35)
	at java.base/jdk.internal.reflect.DirectMethodHandleAccessor.invoke(DirectMethodHandleAccessor.java:103)
	at java.base/java.lang.reflect.Method.invoke(Method.java:580)
	at org.testng.internal.invokers.MethodInvocationHelper.invokeMethod(MethodInvocationHelper.java:141)
	at org.testng.internal.invokers.TestInvoker.invokeMethod(TestInvoker.java:687)
	at org.testng.internal.invokers.TestInvoker.retryFailed(TestInvoker.java:269)
	at org.testng.internal.invokers.MethodRunner.runInSequence(MethodRunner.java:76)
	at org.testng.internal.invokers.TestInvoker$MethodInvocationAgent.invoke(TestInvoker.java:995)
	at org.testng.internal.invokers.TestInvoker.invokeTestMethods(TestInvoker.java:203)
	at org.testng.internal.invokers.TestMethodWorker.invokeTestMethods(TestMethodWorker.java:154)
	at org.testng.internal.invokers.TestMethodWorker.run(TestMethodWorker.java:134)
	at java.base/java.util.ArrayList.forEach(ArrayList.java:1596)
	at org.testng.TestRunner.privateRun(TestRunner.java:741)
	at org.testng.TestRunner.run(TestRunner.java:616)
	at org.testng.SuiteRunner.runTest(SuiteRunner.java:421)
	at org.testng.SuiteRunner$SuiteWorker.run(SuiteRunner.java:463)
	at org.testng.internal.thread.ThreadUtil.lambda$execute$0(ThreadUtil.java:64)
	at java.base/java.util.concurrent.FutureTask.run(FutureTask.java:317)
	at java.base/java.util.concurrent.ThreadPoolExecutor.runWorker(ThreadPoolExecutor.java:1144)
	at java.base/java.util.concurrent.ThreadPoolExecutor$Worker.run(ThreadPoolExecutor.java:642)
	at java.base/java.lang.Thread.run(Thread.java:1583)

testCases.TC03_AddToCart.testAddToCart -- Time elapsed: 0.004 s <<< FAILURE!
java.lang.AssertionError: Test failed due to unexpected exception.
	at org.testng.Assert.fail(Assert.java:111)
	at testCases.TC03_AddToCart.testAddToCart(TC03_AddToCart.java:55)
	at java.base/jdk.internal.reflect.DirectMethodHandleAccessor.invoke(DirectMethodHandleAccessor.java:103)
	at java.base/java.lang.reflect.Method.invoke(Method.java:580)
	at org.testng.internal.invokers.MethodInvocationHelper.invokeMethod(MethodInvocationHelper.java:141)
	at org.testng.internal.invokers.TestInvoker.invokeMethod(TestInvoker.java:687)
	at org.testng.internal.invokers.TestInvoker.retryFailed(TestInvoker.java:269)
	at org.testng.internal.invokers.MethodRunner.runInSequence(MethodRunner.java:76)
	at org.testng.internal.invokers.TestInvoker$MethodInvocationAgent.invoke(TestInvoker.java:995)
	at org.testng.internal.invokers.TestInvoker.invokeTestMethods(TestInvoker.java:203)
	at org.testng.internal.invokers.TestMethodWorker.invokeTestMethods(TestMethodWorker.java:154)
	at org.testng.internal.invokers.TestMethodWorker.run(TestMethodWorker.java:134)
	at java.base/java.util.ArrayList.forEach(ArrayList.java:1596)
	at org.testng.TestRunner.privateRun(TestRunner.java:741)
	at org.testng.TestRunner.run(TestRunner.java:616)
	at org.testng.SuiteRunner.runTest(SuiteRunner.java:421)
	at org.testng.SuiteRunner$SuiteWorker.run(SuiteRunner.java:463)
	at org.testng.internal.thread.ThreadUtil.lambda$execute$0(ThreadUtil.java:64)
	at java.base/java.util.concurrent.FutureTask.run(FutureTask.java:317)
	at java.base/java.util.concurrent.ThreadPoolExecutor.runWorker(ThreadPoolExecutor.java:1144)
	at java.base/java.util.concurrent.ThreadPoolExecutor$Worker.run(ThreadPoolExecutor.java:642)
	at java.base/java.lang.Thread.run(Thread.java:1583)

testCases.TC03_AddToCart.testAddToCart -- Time elapsed: 0.004 s <<< FAILURE!
java.lang.AssertionError: Test failed due to unexpected exception.
	at org.testng.Assert.fail(Assert.java:111)
	at testCases.TC03_AddToCart.testAddToCart(TC03_AddToCart.java:55)
	at java.base/jdk.internal.reflect.DirectMethodHandleAccessor.invoke(DirectMethodHandleAccessor.java:103)
	at java.base/java.lang.reflect.Method.invoke(Method.java:580)
	at org.testng.internal.invokers.MethodInvocationHelper.invokeMethod(MethodInvocationHelper.java:141)
	at org.testng.internal.invokers.TestInvoker.invokeMethod(TestInvoker.java:687)
	at org.testng.internal.invokers.TestInvoker.retryFailed(TestInvoker.java:269)
	at org.testng.internal.invokers.MethodRunner.runInSequence(MethodRunner.java:76)
	at org.testng.internal.invokers.TestInvoker$MethodInvocationAgent.invoke(TestInvoker.java:995)
	at org.testng.internal.invokers.TestInvoker.invokeTestMethods(TestInvoker.java:203)
	at org.testng.internal.invokers.TestMethodWorker.invokeTestMethods(TestMethodWorker.java:154)
	at org.testng.internal.invokers.TestMethodWorker.run(TestMethodWorker.java:134)
	at java.base/java.util.ArrayList.forEach(ArrayList.java:1596)
	at org.testng.TestRunner.privateRun(TestRunner.java:741)
	at org.testng.TestRunner.run(TestRunner.java:616)
	at org.testng.SuiteRunner.runTest(SuiteRunner.java:421)
	at org.testng.SuiteRunner$SuiteWorker.run(SuiteRunner.java:463)
	at org.testng.internal.thread.ThreadUtil.lambda$execute$0(ThreadUtil.java:64)
	at java.base/java.util.concurrent.FutureTask.run(FutureTask.java:317)
	at java.base/java.util.concurrent.ThreadPoolExecutor.runWorker(ThreadPoolExecutor.java:1144)
	at java.base/java.util.concurrent.ThreadPoolExecutor$Worker.run(ThreadPoolExecutor.java:642)
	at java.base/java.lang.Thread.run(Thread.java:1583)

testCases.TC03_AddToCart.testAddToCart -- Time elapsed: 0.005 s <<< FAILURE!
java.lang.AssertionError: Test failed due to unexpected exception.
	at org.testng.Assert.fail(Assert.java:111)
	at testCases.TC03_AddToCart.testAddToCart(TC03_AddToCart.java:55)
	at java.base/jdk.internal.reflect.DirectMethodHandleAccessor.invoke(DirectMethodHandleAccessor.java:103)
	at java.base/java.lang.reflect.Method.invoke(Method.java:580)
	at org.testng.internal.invokers.MethodInvocationHelper.invokeMethod(MethodInvocationHelper.java:141)
	at org.testng.internal.invokers.TestInvoker.invokeMethod(TestInvoker.java:687)
	at org.testng.internal.invokers.TestInvoker.retryFailed(TestInvoker.java:269)
	at org.testng.internal.invokers.MethodRunner.runInSequence(MethodRunner.java:76)
	at org.testng.internal.invokers.TestInvoker$MethodInvocationAgent.invoke(TestInvoker.java:995)
	at org.testng.internal.invokers.TestInvoker.invokeTestMethods(TestInvoker.java:203)
	at org.testng.internal.invokers.TestMethodWorker.invokeTestMethods(TestMethodWorker.java:154)
	at org.testng.internal.invokers.TestMethodWorker.run(TestMethodWorker.java:134)
	at java.base/java.util.ArrayList.forEach(ArrayList.java:1596)
	at org.testng.TestRunner.privateRun(TestRunner.java:741)
	at org.testng.TestRunner.run(TestRunner.java:616)
	at org.testng.SuiteRunner.runTest(SuiteRunner.java:421)
	at org.testng.SuiteRunner$SuiteWorker.run(SuiteRunner.java:463)
	at org.testng.internal.thread.ThreadUtil.lambda$execute$0(ThreadUtil.java:64)
	at java.base/java.util.concurrent.FutureTask.run(FutureTask.java:317)
	at java.base/java.util.concurrent.ThreadPoolExecutor.runWorker(ThreadPoolExecutor.java:1144)
	at java.base/java.util.concurrent.ThreadPoolExecutor$Worker.run(ThreadPoolExecutor.java:642)
	at java.base/java.lang.Thread.run(Thread.java:1583)

testCases.TC02_Login.testLogin[smitasharma.qa@gmail.com, ss*QA123](3) -- Time elapsed: 0.010 s <<< FAILURE!
java.lang.AssertionError: Unexpected exception during login test execution.
	at org.testng.Assert.fail(Assert.java:111)
	at testCases.TC02_Login.testLogin(TC02_Login.java:69)
	at java.base/jdk.internal.reflect.DirectMethodHandleAccessor.invoke(DirectMethodHandleAccessor.java:103)
	at java.base/java.lang.reflect.Method.invoke(Method.java:580)
	at org.testng.internal.invokers.MethodInvocationHelper.invokeMethod(MethodInvocationHelper.java:141)
	at org.testng.internal.invokers.TestInvoker.invokeMethod(TestInvoker.java:687)
	at org.testng.internal.invokers.TestInvoker.retryFailed(TestInvoker.java:269)
	at org.testng.internal.invokers.MethodRunner.runInSequence(MethodRunner.java:76)
	at org.testng.internal.invokers.TestInvoker$MethodInvocationAgent.invoke(TestInvoker.java:995)
	at org.testng.internal.invokers.TestInvoker.invokeTestMethods(TestInvoker.java:203)
	at org.testng.internal.invokers.TestMethodWorker.invokeTestMethods(TestMethodWorker.java:154)
	at org.testng.internal.invokers.TestMethodWorker.run(TestMethodWorker.java:134)
	at java.base/java.util.ArrayList.forEach(ArrayList.java:1596)
	at org.testng.TestRunner.privateRun(TestRunner.java:741)
	at org.testng.TestRunner.run(TestRunner.java:616)
	at org.testng.SuiteRunner.runTest(SuiteRunner.java:421)
	at org.testng.SuiteRunner$SuiteWorker.run(SuiteRunner.java:463)
	at org.testng.internal.thread.ThreadUtil.lambda$execute$0(ThreadUtil.java:64)
	at java.base/java.util.concurrent.FutureTask.run(FutureTask.java:317)
	at java.base/java.util.concurrent.ThreadPoolExecutor.runWorker(ThreadPoolExecutor.java:1144)
	at java.base/java.util.concurrent.ThreadPoolExecutor$Worker.run(ThreadPoolExecutor.java:642)
	at java.base/java.lang.Thread.run(Thread.java:1583)

testCases.TC02_Login.testLogin[smitasharma.qa@gmail.com, ss*QA123](3) -- Time elapsed: 0.011 s <<< FAILURE!
java.lang.AssertionError: Unexpected exception during login test execution.
	at org.testng.Assert.fail(Assert.java:111)
	at testCases.TC02_Login.testLogin(TC02_Login.java:69)
	at java.base/jdk.internal.reflect.DirectMethodHandleAccessor.invoke(DirectMethodHandleAccessor.java:103)
	at java.base/java.lang.reflect.Method.invoke(Method.java:580)
	at org.testng.internal.invokers.MethodInvocationHelper.invokeMethod(MethodInvocationHelper.java:141)
	at org.testng.internal.invokers.TestInvoker.invokeMethod(TestInvoker.java:687)
	at org.testng.internal.invokers.TestInvoker.retryFailed(TestInvoker.java:269)
	at org.testng.internal.invokers.MethodRunner.runInSequence(MethodRunner.java:76)
	at org.testng.internal.invokers.TestInvoker$MethodInvocationAgent.invoke(TestInvoker.java:995)
	at org.testng.internal.invokers.TestInvoker.invokeTestMethods(TestInvoker.java:203)
	at org.testng.internal.invokers.TestMethodWorker.invokeTestMethods(TestMethodWorker.java:154)
	at org.testng.internal.invokers.TestMethodWorker.run(TestMethodWorker.java:134)
	at java.base/java.util.ArrayList.forEach(ArrayList.java:1596)
	at org.testng.TestRunner.privateRun(TestRunner.java:741)
	at org.testng.TestRunner.run(TestRunner.java:616)
	at org.testng.SuiteRunner.runTest(SuiteRunner.java:421)
	at org.testng.SuiteRunner$SuiteWorker.run(SuiteRunner.java:463)
	at org.testng.internal.thread.ThreadUtil.lambda$execute$0(ThreadUtil.java:64)
	at java.base/java.util.concurrent.FutureTask.run(FutureTask.java:317)
	at java.base/java.util.concurrent.ThreadPoolExecutor.runWorker(ThreadPoolExecutor.java:1144)
	at java.base/java.util.concurrent.ThreadPoolExecutor$Worker.run(ThreadPoolExecutor.java:642)
	at java.base/java.lang.Thread.run(Thread.java:1583)

testCases.TC02_Login.testLogin[smitasharma.qa@gmail.com, ss*QA123](3) -- Time elapsed: 0.011 s <<< FAILURE!
java.lang.AssertionError: Unexpected exception during login test execution.
	at org.testng.Assert.fail(Assert.java:111)
	at testCases.TC02_Login.testLogin(TC02_Login.java:69)
	at java.base/jdk.internal.reflect.DirectMethodHandleAccessor.invoke(DirectMethodHandleAccessor.java:103)
	at java.base/java.lang.reflect.Method.invoke(Method.java:580)
	at org.testng.internal.invokers.MethodInvocationHelper.invokeMethod(MethodInvocationHelper.java:141)
	at org.testng.internal.invokers.TestInvoker.invokeMethod(TestInvoker.java:687)
	at org.testng.internal.invokers.TestInvoker.retryFailed(TestInvoker.java:269)
	at org.testng.internal.invokers.MethodRunner.runInSequence(MethodRunner.java:76)
	at org.testng.internal.invokers.TestInvoker$MethodInvocationAgent.invoke(TestInvoker.java:995)
	at org.testng.internal.invokers.TestInvoker.invokeTestMethods(TestInvoker.java:203)
	at org.testng.internal.invokers.TestMethodWorker.invokeTestMethods(TestMethodWorker.java:154)
	at org.testng.internal.invokers.TestMethodWorker.run(TestMethodWorker.java:134)
	at java.base/java.util.ArrayList.forEach(ArrayList.java:1596)
	at org.testng.TestRunner.privateRun(TestRunner.java:741)
	at org.testng.TestRunner.run(TestRunner.java:616)
	at org.testng.SuiteRunner.runTest(SuiteRunner.java:421)
	at org.testng.SuiteRunner$SuiteWorker.run(SuiteRunner.java:463)
	at org.testng.internal.thread.ThreadUtil.lambda$execute$0(ThreadUtil.java:64)
	at java.base/java.util.concurrent.FutureTask.run(FutureTask.java:317)
	at java.base/java.util.concurrent.ThreadPoolExecutor.runWorker(ThreadPoolExecutor.java:1144)
	at java.base/java.util.concurrent.ThreadPoolExecutor$Worker.run(ThreadPoolExecutor.java:642)
	at java.base/java.lang.Thread.run(Thread.java:1583)

testCases.TC02_Login.testLogin[nona@yahoo.com, QWER!@#$](6) -- Time elapsed: 0.017 s <<< FAILURE!
java.lang.AssertionError: Unexpected exception during login test execution.
	at org.testng.Assert.fail(Assert.java:111)
	at testCases.TC02_Login.testLogin(TC02_Login.java:69)
	at java.base/jdk.internal.reflect.DirectMethodHandleAccessor.invoke(DirectMethodHandleAccessor.java:103)
	at java.base/java.lang.reflect.Method.invoke(Method.java:580)
	at org.testng.internal.invokers.MethodInvocationHelper.invokeMethod(MethodInvocationHelper.java:141)
	at org.testng.internal.invokers.TestInvoker.invokeMethod(TestInvoker.java:687)
	at org.testng.internal.invokers.TestInvoker.retryFailed(TestInvoker.java:269)
	at org.testng.internal.invokers.MethodRunner.runInSequence(MethodRunner.java:76)
	at org.testng.internal.invokers.TestInvoker$MethodInvocationAgent.invoke(TestInvoker.java:995)
	at org.testng.internal.invokers.TestInvoker.invokeTestMethods(TestInvoker.java:203)
	at org.testng.internal.invokers.TestMethodWorker.invokeTestMethods(TestMethodWorker.java:154)
	at org.testng.internal.invokers.TestMethodWorker.run(TestMethodWorker.java:134)
	at java.base/java.util.ArrayList.forEach(ArrayList.java:1596)
	at org.testng.TestRunner.privateRun(TestRunner.java:741)
	at org.testng.TestRunner.run(TestRunner.java:616)
	at org.testng.SuiteRunner.runTest(SuiteRunner.java:421)
	at org.testng.SuiteRunner$SuiteWorker.run(SuiteRunner.java:463)
	at org.testng.internal.thread.ThreadUtil.lambda$execute$0(ThreadUtil.java:64)
	at java.base/java.util.concurrent.FutureTask.run(FutureTask.java:317)
	at java.base/java.util.concurrent.ThreadPoolExecutor.runWorker(ThreadPoolExecutor.java:1144)
	at java.base/java.util.concurrent.ThreadPoolExecutor$Worker.run(ThreadPoolExecutor.java:642)
	at java.base/java.lang.Thread.run(Thread.java:1583)

testCases.TC02_Login.testLogin[nona@yahoo.com, QWER!@#$](6) -- Time elapsed: 0.017 s <<< FAILURE!
java.lang.AssertionError: Unexpected exception during login test execution.
	at org.testng.Assert.fail(Assert.java:111)
	at testCases.TC02_Login.testLogin(TC02_Login.java:69)
	at java.base/jdk.internal.reflect.DirectMethodHandleAccessor.invoke(DirectMethodHandleAccessor.java:103)
	at java.base/java.lang.reflect.Method.invoke(Method.java:580)
	at org.testng.internal.invokers.MethodInvocationHelper.invokeMethod(MethodInvocationHelper.java:141)
	at org.testng.internal.invokers.TestInvoker.invokeMethod(TestInvoker.java:687)
	at org.testng.internal.invokers.TestInvoker.retryFailed(TestInvoker.java:269)
	at org.testng.internal.invokers.MethodRunner.runInSequence(MethodRunner.java:76)
	at org.testng.internal.invokers.TestInvoker$MethodInvocationAgent.invoke(TestInvoker.java:995)
	at org.testng.internal.invokers.TestInvoker.invokeTestMethods(TestInvoker.java:203)
	at org.testng.internal.invokers.TestMethodWorker.invokeTestMethods(TestMethodWorker.java:154)
	at org.testng.internal.invokers.TestMethodWorker.run(TestMethodWorker.java:134)
	at java.base/java.util.ArrayList.forEach(ArrayList.java:1596)
	at org.testng.TestRunner.privateRun(TestRunner.java:741)
	at org.testng.TestRunner.run(TestRunner.java:616)
	at org.testng.SuiteRunner.runTest(SuiteRunner.java:421)
	at org.testng.SuiteRunner$SuiteWorker.run(SuiteRunner.java:463)
	at org.testng.internal.thread.ThreadUtil.lambda$execute$0(ThreadUtil.java:64)
	at java.base/java.util.concurrent.FutureTask.run(FutureTask.java:317)
	at java.base/java.util.concurrent.ThreadPoolExecutor.runWorker(ThreadPoolExecutor.java:1144)
	at java.base/java.util.concurrent.ThreadPoolExecutor$Worker.run(ThreadPoolExecutor.java:642)
	at java.base/java.lang.Thread.run(Thread.java:1583)

testCases.TC02_Login.testLogin[nona@yahoo.com, QWER!@#$](6) -- Time elapsed: 0.017 s <<< FAILURE!
java.lang.AssertionError: Unexpected exception during login test execution.
	at org.testng.Assert.fail(Assert.java:111)
	at testCases.TC02_Login.testLogin(TC02_Login.java:69)
	at java.base/jdk.internal.reflect.DirectMethodHandleAccessor.invoke(DirectMethodHandleAccessor.java:103)
	at java.base/java.lang.reflect.Method.invoke(Method.java:580)
	at org.testng.internal.invokers.MethodInvocationHelper.invokeMethod(MethodInvocationHelper.java:141)
	at org.testng.internal.invokers.TestInvoker.invokeMethod(TestInvoker.java:687)
	at org.testng.internal.invokers.TestInvoker.retryFailed(TestInvoker.java:269)
	at org.testng.internal.invokers.MethodRunner.runInSequence(MethodRunner.java:76)
	at org.testng.internal.invokers.TestInvoker$MethodInvocationAgent.invoke(TestInvoker.java:995)
	at org.testng.internal.invokers.TestInvoker.invokeTestMethods(TestInvoker.java:203)
	at org.testng.internal.invokers.TestMethodWorker.invokeTestMethods(TestMethodWorker.java:154)
	at org.testng.internal.invokers.TestMethodWorker.run(TestMethodWorker.java:134)
	at java.base/java.util.ArrayList.forEach(ArrayList.java:1596)
	at org.testng.TestRunner.privateRun(TestRunner.java:741)
	at org.testng.TestRunner.run(TestRunner.java:616)
	at org.testng.SuiteRunner.runTest(SuiteRunner.java:421)
	at org.testng.SuiteRunner$SuiteWorker.run(SuiteRunner.java:463)
	at org.testng.internal.thread.ThreadUtil.lambda$execute$0(ThreadUtil.java:64)
	at java.base/java.util.concurrent.FutureTask.run(FutureTask.java:317)
	at java.base/java.util.concurrent.ThreadPoolExecutor.runWorker(ThreadPoolExecutor.java:1144)
	at java.base/java.util.concurrent.ThreadPoolExecutor$Worker.run(ThreadPoolExecutor.java:642)
	at java.base/java.lang.Thread.run(Thread.java:1583)

testCases.TC02_Login.testLogin[sid@cloudberry.services, Test123](9) -- Time elapsed: 0.007 s <<< FAILURE!
java.lang.AssertionError: Unexpected exception during login test execution.
	at org.testng.Assert.fail(Assert.java:111)
	at testCases.TC02_Login.testLogin(TC02_Login.java:69)
	at java.base/jdk.internal.reflect.DirectMethodHandleAccessor.invoke(DirectMethodHandleAccessor.java:103)
	at java.base/java.lang.reflect.Method.invoke(Method.java:580)
	at org.testng.internal.invokers.MethodInvocationHelper.invokeMethod(MethodInvocationHelper.java:141)
	at org.testng.internal.invokers.TestInvoker.invokeMethod(TestInvoker.java:687)
	at org.testng.internal.invokers.TestInvoker.retryFailed(TestInvoker.java:269)
	at org.testng.internal.invokers.MethodRunner.runInSequence(MethodRunner.java:76)
	at org.testng.internal.invokers.TestInvoker$MethodInvocationAgent.invoke(TestInvoker.java:995)
	at org.testng.internal.invokers.TestInvoker.invokeTestMethods(TestInvoker.java:203)
	at org.testng.internal.invokers.TestMethodWorker.invokeTestMethods(TestMethodWorker.java:154)
	at org.testng.internal.invokers.TestMethodWorker.run(TestMethodWorker.java:134)
	at java.base/java.util.ArrayList.forEach(ArrayList.java:1596)
	at org.testng.TestRunner.privateRun(TestRunner.java:741)
	at org.testng.TestRunner.run(TestRunner.java:616)
	at org.testng.SuiteRunner.runTest(SuiteRunner.java:421)
	at org.testng.SuiteRunner$SuiteWorker.run(SuiteRunner.java:463)
	at org.testng.internal.thread.ThreadUtil.lambda$execute$0(ThreadUtil.java:64)
	at java.base/java.util.concurrent.FutureTask.run(FutureTask.java:317)
	at java.base/java.util.concurrent.ThreadPoolExecutor.runWorker(ThreadPoolExecutor.java:1144)
	at java.base/java.util.concurrent.ThreadPoolExecutor$Worker.run(ThreadPoolExecutor.java:642)
	at java.base/java.lang.Thread.run(Thread.java:1583)

testCases.TC02_Login.testLogin[sid@cloudberry.services, Test123](9) -- Time elapsed: 0.008 s <<< FAILURE!
java.lang.AssertionError: Unexpected exception during login test execution.
	at org.testng.Assert.fail(Assert.java:111)
	at testCases.TC02_Login.testLogin(TC02_Login.java:69)
	at java.base/jdk.internal.reflect.DirectMethodHandleAccessor.invoke(DirectMethodHandleAccessor.java:103)
	at java.base/java.lang.reflect.Method.invoke(Method.java:580)
	at org.testng.internal.invokers.MethodInvocationHelper.invokeMethod(MethodInvocationHelper.java:141)
	at org.testng.internal.invokers.TestInvoker.invokeMethod(TestInvoker.java:687)
	at org.testng.internal.invokers.TestInvoker.retryFailed(TestInvoker.java:269)
	at org.testng.internal.invokers.MethodRunner.runInSequence(MethodRunner.java:76)
	at org.testng.internal.invokers.TestInvoker$MethodInvocationAgent.invoke(TestInvoker.java:995)
	at org.testng.internal.invokers.TestInvoker.invokeTestMethods(TestInvoker.java:203)
	at org.testng.internal.invokers.TestMethodWorker.invokeTestMethods(TestMethodWorker.java:154)
	at org.testng.internal.invokers.TestMethodWorker.run(TestMethodWorker.java:134)
	at java.base/java.util.ArrayList.forEach(ArrayList.java:1596)
	at org.testng.TestRunner.privateRun(TestRunner.java:741)
	at org.testng.TestRunner.run(TestRunner.java:616)
	at org.testng.SuiteRunner.runTest(SuiteRunner.java:421)
	at org.testng.SuiteRunner$SuiteWorker.run(SuiteRunner.java:463)
	at org.testng.internal.thread.ThreadUtil.lambda$execute$0(ThreadUtil.java:64)
	at java.base/java.util.concurrent.FutureTask.run(FutureTask.java:317)
	at java.base/java.util.concurrent.ThreadPoolExecutor.runWorker(ThreadPoolExecutor.java:1144)
	at java.base/java.util.concurrent.ThreadPoolExecutor$Worker.run(ThreadPoolExecutor.java:642)
	at java.base/java.lang.Thread.run(Thread.java:1583)

testCases.TC02_Login.testLogin[sid@cloudberry.services, Test123](9) -- Time elapsed: 0.009 s <<< FAILURE!
java.lang.AssertionError: Unexpected exception during login test execution.
	at org.testng.Assert.fail(Assert.java:111)
	at testCases.TC02_Login.testLogin(TC02_Login.java:69)
	at java.base/jdk.internal.reflect.DirectMethodHandleAccessor.invoke(DirectMethodHandleAccessor.java:103)
	at java.base/java.lang.reflect.Method.invoke(Method.java:580)
	at org.testng.internal.invokers.MethodInvocationHelper.invokeMethod(MethodInvocationHelper.java:141)
	at org.testng.internal.invokers.TestInvoker.invokeMethod(TestInvoker.java:687)
	at org.testng.internal.invokers.TestInvoker.retryFailed(TestInvoker.java:269)
	at org.testng.internal.invokers.MethodRunner.runInSequence(MethodRunner.java:76)
	at org.testng.internal.invokers.TestInvoker$MethodInvocationAgent.invoke(TestInvoker.java:995)
	at org.testng.internal.invokers.TestInvoker.invokeTestMethods(TestInvoker.java:203)
	at org.testng.internal.invokers.TestMethodWorker.invokeTestMethods(TestMethodWorker.java:154)
	at org.testng.internal.invokers.TestMethodWorker.run(TestMethodWorker.java:134)
	at java.base/java.util.ArrayList.forEach(ArrayList.java:1596)
	at org.testng.TestRunner.privateRun(TestRunner.java:741)
	at org.testng.TestRunner.run(TestRunner.java:616)
	at org.testng.SuiteRunner.runTest(SuiteRunner.java:421)
	at org.testng.SuiteRunner$SuiteWorker.run(SuiteRunner.java:463)
	at org.testng.internal.thread.ThreadUtil.lambda$execute$0(ThreadUtil.java:64)
	at java.base/java.util.concurrent.FutureTask.run(FutureTask.java:317)
	at java.base/java.util.concurrent.ThreadPoolExecutor.runWorker(ThreadPoolExecutor.java:1144)
	at java.base/java.util.concurrent.ThreadPoolExecutor$Worker.run(ThreadPoolExecutor.java:642)
	at java.base/java.lang.Thread.run(Thread.java:1583)

testCases.TC02_Login.testLogin[apushedwoman@gmail.com, password123](12) -- Time elapsed: 0.025 s <<< FAILURE!
java.lang.AssertionError: Unexpected exception during login test execution.
	at org.testng.Assert.fail(Assert.java:111)
	at testCases.TC02_Login.testLogin(TC02_Login.java:69)
	at java.base/jdk.internal.reflect.DirectMethodHandleAccessor.invoke(DirectMethodHandleAccessor.java:103)
	at java.base/java.lang.reflect.Method.invoke(Method.java:580)
	at org.testng.internal.invokers.MethodInvocationHelper.invokeMethod(MethodInvocationHelper.java:141)
	at org.testng.internal.invokers.TestInvoker.invokeMethod(TestInvoker.java:687)
	at org.testng.internal.invokers.TestInvoker.retryFailed(TestInvoker.java:269)
	at org.testng.internal.invokers.MethodRunner.runInSequence(MethodRunner.java:76)
	at org.testng.internal.invokers.TestInvoker$MethodInvocationAgent.invoke(TestInvoker.java:995)
	at org.testng.internal.invokers.TestInvoker.invokeTestMethods(TestInvoker.java:203)
	at org.testng.internal.invokers.TestMethodWorker.invokeTestMethods(TestMethodWorker.java:154)
	at org.testng.internal.invokers.TestMethodWorker.run(TestMethodWorker.java:134)
	at java.base/java.util.ArrayList.forEach(ArrayList.java:1596)
	at org.testng.TestRunner.privateRun(TestRunner.java:741)
	at org.testng.TestRunner.run(TestRunner.java:616)
	at org.testng.SuiteRunner.runTest(SuiteRunner.java:421)
	at org.testng.SuiteRunner$SuiteWorker.run(SuiteRunner.java:463)
	at org.testng.internal.thread.ThreadUtil.lambda$execute$0(ThreadUtil.java:64)
	at java.base/java.util.concurrent.FutureTask.run(FutureTask.java:317)
	at java.base/java.util.concurrent.ThreadPoolExecutor.runWorker(ThreadPoolExecutor.java:1144)
	at java.base/java.util.concurrent.ThreadPoolExecutor$Worker.run(ThreadPoolExecutor.java:642)
	at java.base/java.lang.Thread.run(Thread.java:1583)

testCases.TC02_Login.testLogin[apushedwoman@gmail.com, password123](12) -- Time elapsed: 0.025 s <<< FAILURE!
java.lang.AssertionError: Unexpected exception during login test execution.
	at org.testng.Assert.fail(Assert.java:111)
	at testCases.TC02_Login.testLogin(TC02_Login.java:69)
	at java.base/jdk.internal.reflect.DirectMethodHandleAccessor.invoke(DirectMethodHandleAccessor.java:103)
	at java.base/java.lang.reflect.Method.invoke(Method.java:580)
	at org.testng.internal.invokers.MethodInvocationHelper.invokeMethod(MethodInvocationHelper.java:141)
	at org.testng.internal.invokers.TestInvoker.invokeMethod(TestInvoker.java:687)
	at org.testng.internal.invokers.TestInvoker.retryFailed(TestInvoker.java:269)
	at org.testng.internal.invokers.MethodRunner.runInSequence(MethodRunner.java:76)
	at org.testng.internal.invokers.TestInvoker$MethodInvocationAgent.invoke(TestInvoker.java:995)
	at org.testng.internal.invokers.TestInvoker.invokeTestMethods(TestInvoker.java:203)
	at org.testng.internal.invokers.TestMethodWorker.invokeTestMethods(TestMethodWorker.java:154)
	at org.testng.internal.invokers.TestMethodWorker.run(TestMethodWorker.java:134)
	at java.base/java.util.ArrayList.forEach(ArrayList.java:1596)
	at org.testng.TestRunner.privateRun(TestRunner.java:741)
	at org.testng.TestRunner.run(TestRunner.java:616)
	at org.testng.SuiteRunner.runTest(SuiteRunner.java:421)
	at org.testng.SuiteRunner$SuiteWorker.run(SuiteRunner.java:463)
	at org.testng.internal.thread.ThreadUtil.lambda$execute$0(ThreadUtil.java:64)
	at java.base/java.util.concurrent.FutureTask.run(FutureTask.java:317)
	at java.base/java.util.concurrent.ThreadPoolExecutor.runWorker(ThreadPoolExecutor.java:1144)
	at java.base/java.util.concurrent.ThreadPoolExecutor$Worker.run(ThreadPoolExecutor.java:642)
	at java.base/java.lang.Thread.run(Thread.java:1583)

testCases.TC02_Login.testLogin[apushedwoman@gmail.com, password123](12) -- Time elapsed: 0.003 s <<< FAILURE!
java.lang.AssertionError: Unexpected exception during login test execution.
	at org.testng.Assert.fail(Assert.java:111)
	at testCases.TC02_Login.testLogin(TC02_Login.java:69)
	at java.base/jdk.internal.reflect.DirectMethodHandleAccessor.invoke(DirectMethodHandleAccessor.java:103)
	at java.base/java.lang.reflect.Method.invoke(Method.java:580)
	at org.testng.internal.invokers.MethodInvocationHelper.invokeMethod(MethodInvocationHelper.java:141)
	at org.testng.internal.invokers.TestInvoker.invokeMethod(TestInvoker.java:687)
	at org.testng.internal.invokers.TestInvoker.retryFailed(TestInvoker.java:269)
	at org.testng.internal.invokers.MethodRunner.runInSequence(MethodRunner.java:76)
	at org.testng.internal.invokers.TestInvoker$MethodInvocationAgent.invoke(TestInvoker.java:995)
	at org.testng.internal.invokers.TestInvoker.invokeTestMethods(TestInvoker.java:203)
	at org.testng.internal.invokers.TestMethodWorker.invokeTestMethods(TestMethodWorker.java:154)
	at org.testng.internal.invokers.TestMethodWorker.run(TestMethodWorker.java:134)
	at java.base/java.util.ArrayList.forEach(ArrayList.java:1596)
	at org.testng.TestRunner.privateRun(TestRunner.java:741)
	at org.testng.TestRunner.run(TestRunner.java:616)
	at org.testng.SuiteRunner.runTest(SuiteRunner.java:421)
	at org.testng.SuiteRunner$SuiteWorker.run(SuiteRunner.java:463)
	at org.testng.internal.thread.ThreadUtil.lambda$execute$0(ThreadUtil.java:64)
	at java.base/java.util.concurrent.FutureTask.run(FutureTask.java:317)
	at java.base/java.util.concurrent.ThreadPoolExecutor.runWorker(ThreadPoolExecutor.java:1144)
	at java.base/java.util.concurrent.ThreadPoolExecutor$Worker.run(ThreadPoolExecutor.java:642)
	at java.base/java.lang.Thread.run(Thread.java:1583)

testCases.TC02_Login.testLogin[hichamkhachiai@gmail.com, hicham123](15) -- Time elapsed: 0.027 s <<< FAILURE!
java.lang.AssertionError: Unexpected exception during login test execution.
	at org.testng.Assert.fail(Assert.java:111)
	at testCases.TC02_Login.testLogin(TC02_Login.java:69)
	at java.base/jdk.internal.reflect.DirectMethodHandleAccessor.invoke(DirectMethodHandleAccessor.java:103)
	at java.base/java.lang.reflect.Method.invoke(Method.java:580)
	at org.testng.internal.invokers.MethodInvocationHelper.invokeMethod(MethodInvocationHelper.java:141)
	at org.testng.internal.invokers.TestInvoker.invokeMethod(TestInvoker.java:687)
	at org.testng.internal.invokers.TestInvoker.retryFailed(TestInvoker.java:269)
	at org.testng.internal.invokers.MethodRunner.runInSequence(MethodRunner.java:76)
	at org.testng.internal.invokers.TestInvoker$MethodInvocationAgent.invoke(TestInvoker.java:995)
	at org.testng.internal.invokers.TestInvoker.invokeTestMethods(TestInvoker.java:203)
	at org.testng.internal.invokers.TestMethodWorker.invokeTestMethods(TestMethodWorker.java:154)
	at org.testng.internal.invokers.TestMethodWorker.run(TestMethodWorker.java:134)
	at java.base/java.util.ArrayList.forEach(ArrayList.java:1596)
	at org.testng.TestRunner.privateRun(TestRunner.java:741)
	at org.testng.TestRunner.run(TestRunner.java:616)
	at org.testng.SuiteRunner.runTest(SuiteRunner.java:421)
	at org.testng.SuiteRunner$SuiteWorker.run(SuiteRunner.java:463)
	at org.testng.internal.thread.ThreadUtil.lambda$execute$0(ThreadUtil.java:64)
	at java.base/java.util.concurrent.FutureTask.run(FutureTask.java:317)
	at java.base/java.util.concurrent.ThreadPoolExecutor.runWorker(ThreadPoolExecutor.java:1144)
	at java.base/java.util.concurrent.ThreadPoolExecutor$Worker.run(ThreadPoolExecutor.java:642)
	at java.base/java.lang.Thread.run(Thread.java:1583)

testCases.TC02_Login.testLogin[hichamkhachiai@gmail.com, hicham123](15) -- Time elapsed: 0.027 s <<< FAILURE!
java.lang.AssertionError: Unexpected exception during login test execution.
	at org.testng.Assert.fail(Assert.java:111)
	at testCases.TC02_Login.testLogin(TC02_Login.java:69)
	at java.base/jdk.internal.reflect.DirectMethodHandleAccessor.invoke(DirectMethodHandleAccessor.java:103)
	at java.base/java.lang.reflect.Method.invoke(Method.java:580)
	at org.testng.internal.invokers.MethodInvocationHelper.invokeMethod(MethodInvocationHelper.java:141)
	at org.testng.internal.invokers.TestInvoker.invokeMethod(TestInvoker.java:687)
	at org.testng.internal.invokers.TestInvoker.retryFailed(TestInvoker.java:269)
	at org.testng.internal.invokers.MethodRunner.runInSequence(MethodRunner.java:76)
	at org.testng.internal.invokers.TestInvoker$MethodInvocationAgent.invoke(TestInvoker.java:995)
	at org.testng.internal.invokers.TestInvoker.invokeTestMethods(TestInvoker.java:203)
	at org.testng.internal.invokers.TestMethodWorker.invokeTestMethods(TestMethodWorker.java:154)
	at org.testng.internal.invokers.TestMethodWorker.run(TestMethodWorker.java:134)
	at java.base/java.util.ArrayList.forEach(ArrayList.java:1596)
	at org.testng.TestRunner.privateRun(TestRunner.java:741)
	at org.testng.TestRunner.run(TestRunner.java:616)
	at org.testng.SuiteRunner.runTest(SuiteRunner.java:421)
	at org.testng.SuiteRunner$SuiteWorker.run(SuiteRunner.java:463)
	at org.testng.internal.thread.ThreadUtil.lambda$execute$0(ThreadUtil.java:64)
	at java.base/java.util.concurrent.FutureTask.run(FutureTask.java:317)
	at java.base/java.util.concurrent.ThreadPoolExecutor.runWorker(ThreadPoolExecutor.java:1144)
	at java.base/java.util.concurrent.ThreadPoolExecutor$Worker.run(ThreadPoolExecutor.java:642)
	at java.base/java.lang.Thread.run(Thread.java:1583)

testCases.TC02_Login.testLogin[hichamkhachiai@gmail.com, hicham123](15) -- Time elapsed: 0.027 s <<< FAILURE!
java.lang.AssertionError: Unexpected exception during login test execution.
	at org.testng.Assert.fail(Assert.java:111)
	at testCases.TC02_Login.testLogin(TC02_Login.java:69)
	at java.base/jdk.internal.reflect.DirectMethodHandleAccessor.invoke(DirectMethodHandleAccessor.java:103)
	at java.base/java.lang.reflect.Method.invoke(Method.java:580)
	at org.testng.internal.invokers.MethodInvocationHelper.invokeMethod(MethodInvocationHelper.java:141)
	at org.testng.internal.invokers.TestInvoker.invokeMethod(TestInvoker.java:687)
	at org.testng.internal.invokers.TestInvoker.retryFailed(TestInvoker.java:269)
	at org.testng.internal.invokers.MethodRunner.runInSequence(MethodRunner.java:76)
	at org.testng.internal.invokers.TestInvoker$MethodInvocationAgent.invoke(TestInvoker.java:995)
	at org.testng.internal.invokers.TestInvoker.invokeTestMethods(TestInvoker.java:203)
	at org.testng.internal.invokers.TestMethodWorker.invokeTestMethods(TestMethodWorker.java:154)
	at org.testng.internal.invokers.TestMethodWorker.run(TestMethodWorker.java:134)
	at java.base/java.util.ArrayList.forEach(ArrayList.java:1596)
	at org.testng.TestRunner.privateRun(TestRunner.java:741)
	at org.testng.TestRunner.run(TestRunner.java:616)
	at org.testng.SuiteRunner.runTest(SuiteRunner.java:421)
	at org.testng.SuiteRunner$SuiteWorker.run(SuiteRunner.java:463)
	at org.testng.internal.thread.ThreadUtil.lambda$execute$0(ThreadUtil.java:64)
	at java.base/java.util.concurrent.FutureTask.run(FutureTask.java:317)
	at java.base/java.util.concurrent.ThreadPoolExecutor.runWorker(ThreadPoolExecutor.java:1144)
	at java.base/java.util.concurrent.ThreadPoolExecutor$Worker.run(ThreadPoolExecutor.java:642)
	at java.base/java.lang.Thread.run(Thread.java:1583)

testCases.TC04_CompletePurchase.testCompletePurchase -- Time elapsed: 0.004 s <<< FAILURE!
java.lang.AssertionError: Test failed due to unexpected exception.
	at org.testng.Assert.fail(Assert.java:111)
	at testCases.TC04_CompletePurchase.testCompletePurchase(TC04_CompletePurchase.java:81)
	at java.base/jdk.internal.reflect.DirectMethodHandleAccessor.invoke(DirectMethodHandleAccessor.java:103)
	at java.base/java.lang.reflect.Method.invoke(Method.java:580)
	at org.testng.internal.invokers.MethodInvocationHelper.invokeMethod(MethodInvocationHelper.java:141)
	at org.testng.internal.invokers.TestInvoker.invokeMethod(TestInvoker.java:687)
	at org.testng.internal.invokers.TestInvoker.retryFailed(TestInvoker.java:269)
	at org.testng.internal.invokers.MethodRunner.runInSequence(MethodRunner.java:76)
	at org.testng.internal.invokers.TestInvoker$MethodInvocationAgent.invoke(TestInvoker.java:995)
	at org.testng.internal.invokers.TestInvoker.invokeTestMethods(TestInvoker.java:203)
	at org.testng.internal.invokers.TestMethodWorker.invokeTestMethods(TestMethodWorker.java:154)
	at org.testng.internal.invokers.TestMethodWorker.run(TestMethodWorker.java:134)
	at java.base/java.util.ArrayList.forEach(ArrayList.java:1596)
	at org.testng.TestRunner.privateRun(TestRunner.java:741)
	at org.testng.TestRunner.run(TestRunner.java:616)
	at org.testng.SuiteRunner.runTest(SuiteRunner.java:421)
	at org.testng.SuiteRunner$SuiteWorker.run(SuiteRunner.java:463)
	at org.testng.internal.thread.ThreadUtil.lambda$execute$0(ThreadUtil.java:64)
	at java.base/java.util.concurrent.FutureTask.run(FutureTask.java:317)
	at java.base/java.util.concurrent.ThreadPoolExecutor.runWorker(ThreadPoolExecutor.java:1144)
	at java.base/java.util.concurrent.ThreadPoolExecutor$Worker.run(ThreadPoolExecutor.java:642)
	at java.base/java.lang.Thread.run(Thread.java:1583)

testCases.TC04_CompletePurchase.testCompletePurchase -- Time elapsed: 0.004 s <<< FAILURE!
java.lang.AssertionError: Test failed due to unexpected exception.
	at org.testng.Assert.fail(Assert.java:111)
	at testCases.TC04_CompletePurchase.testCompletePurchase(TC04_CompletePurchase.java:81)
	at java.base/jdk.internal.reflect.DirectMethodHandleAccessor.invoke(DirectMethodHandleAccessor.java:103)
	at java.base/java.lang.reflect.Method.invoke(Method.java:580)
	at org.testng.internal.invokers.MethodInvocationHelper.invokeMethod(MethodInvocationHelper.java:141)
	at org.testng.internal.invokers.TestInvoker.invokeMethod(TestInvoker.java:687)
	at org.testng.internal.invokers.TestInvoker.retryFailed(TestInvoker.java:269)
	at org.testng.internal.invokers.MethodRunner.runInSequence(MethodRunner.java:76)
	at org.testng.internal.invokers.TestInvoker$MethodInvocationAgent.invoke(TestInvoker.java:995)
	at org.testng.internal.invokers.TestInvoker.invokeTestMethods(TestInvoker.java:203)
	at org.testng.internal.invokers.TestMethodWorker.invokeTestMethods(TestMethodWorker.java:154)
	at org.testng.internal.invokers.TestMethodWorker.run(TestMethodWorker.java:134)
	at java.base/java.util.ArrayList.forEach(ArrayList.java:1596)
	at org.testng.TestRunner.privateRun(TestRunner.java:741)
	at org.testng.TestRunner.run(TestRunner.java:616)
	at org.testng.SuiteRunner.runTest(SuiteRunner.java:421)
	at org.testng.SuiteRunner$SuiteWorker.run(SuiteRunner.java:463)
	at org.testng.internal.thread.ThreadUtil.lambda$execute$0(ThreadUtil.java:64)
	at java.base/java.util.concurrent.FutureTask.run(FutureTask.java:317)
	at java.base/java.util.concurrent.ThreadPoolExecutor.runWorker(ThreadPoolExecutor.java:1144)
	at java.base/java.util.concurrent.ThreadPoolExecutor$Worker.run(ThreadPoolExecutor.java:642)
	at java.base/java.lang.Thread.run(Thread.java:1583)

testCases.TC04_CompletePurchase.testCompletePurchase -- Time elapsed: 0.004 s <<< FAILURE!
java.lang.AssertionError: Test failed due to unexpected exception.
	at org.testng.Assert.fail(Assert.java:111)
	at testCases.TC04_CompletePurchase.testCompletePurchase(TC04_CompletePurchase.java:81)
	at java.base/jdk.internal.reflect.DirectMethodHandleAccessor.invoke(DirectMethodHandleAccessor.java:103)
	at java.base/java.lang.reflect.Method.invoke(Method.java:580)
	at org.testng.internal.invokers.MethodInvocationHelper.invokeMethod(MethodInvocationHelper.java:141)
	at org.testng.internal.invokers.TestInvoker.invokeMethod(TestInvoker.java:687)
	at org.testng.internal.invokers.TestInvoker.retryFailed(TestInvoker.java:269)
	at org.testng.internal.invokers.MethodRunner.runInSequence(MethodRunner.java:76)
	at org.testng.internal.invokers.TestInvoker$MethodInvocationAgent.invoke(TestInvoker.java:995)
	at org.testng.internal.invokers.TestInvoker.invokeTestMethods(TestInvoker.java:203)
	at org.testng.internal.invokers.TestMethodWorker.invokeTestMethods(TestMethodWorker.java:154)
	at org.testng.internal.invokers.TestMethodWorker.run(TestMethodWorker.java:134)
	at java.base/java.util.ArrayList.forEach(ArrayList.java:1596)
	at org.testng.TestRunner.privateRun(TestRunner.java:741)
	at org.testng.TestRunner.run(TestRunner.java:616)
	at org.testng.SuiteRunner.runTest(SuiteRunner.java:421)
	at org.testng.SuiteRunner$SuiteWorker.run(SuiteRunner.java:463)
	at org.testng.internal.thread.ThreadUtil.lambda$execute$0(ThreadUtil.java:64)
	at java.base/java.util.concurrent.FutureTask.run(FutureTask.java:317)
	at java.base/java.util.concurrent.ThreadPoolExecutor.runWorker(ThreadPoolExecutor.java:1144)
	at java.base/java.util.concurrent.ThreadPoolExecutor$Worker.run(ThreadPoolExecutor.java:642)
	at java.base/java.lang.Thread.run(Thread.java:1583)

