<?xml version="1.0" encoding="UTF-8"?>
<!-- Generated by org.testng.reporters.JUnitReportReporter -->
<testsuite hostname="MacBookAir" failures="10" tests="30" name="testCases.TC02_Login" time="0.346" errors="0" timestamp="2025-05-20T18:05:47 EDT" skipped="20">
  <testcase classname="testCases.TC02_Login" name="testLogin" time="0.035">
    <skipped/>
  </testcase> <!-- testLogin -->
  <testcase classname="testCases.TC02_Login" name="testLogin" time="0.005">
    <failure message="Unexpected exception during login test execution." type="java.lang.AssertionError">
      <![CDATA[java.lang.AssertionError: Unexpected exception during login test execution.
at org.testng.Assert.fail(Assert.java:111)
at testCases.TC02_Login.testLogin(TC02_Login.java:69)
at java.base/jdk.internal.reflect.DirectMethodHandleAccessor.invoke(DirectMethodHandleAccessor.java:103)
at java.base/java.lang.reflect.Method.invoke(Method.java:580)
at org.testng.internal.invokers.MethodInvocationHelper.invokeMethod(MethodInvocationHelper.java:141)
at org.testng.internal.invokers.TestInvoker.invokeMethod(TestInvoker.java:687)
at org.testng.internal.invokers.TestInvoker.retryFailed(TestInvoker.java:269)
at org.testng.internal.invokers.MethodRunner.runInSequence(MethodRunner.java:76)
at org.testng.internal.invokers.TestInvoker$MethodInvocationAgent.invoke(TestInvoker.java:995)
at org.testng.internal.invokers.TestInvoker.invokeTestMethods(TestInvoker.java:203)
at org.testng.internal.invokers.TestMethodWorker.invokeTestMethods(TestMethodWorker.java:154)
at org.testng.internal.invokers.TestMethodWorker.run(TestMethodWorker.java:134)
at java.base/java.util.ArrayList.forEach(ArrayList.java:1596)
at org.testng.TestRunner.privateRun(TestRunner.java:741)
at org.testng.TestRunner.run(TestRunner.java:616)
at org.testng.SuiteRunner.runTest(SuiteRunner.java:421)
at org.testng.SuiteRunner$SuiteWorker.run(SuiteRunner.java:463)
at org.testng.internal.thread.ThreadUtil.lambda$execute$0(ThreadUtil.java:64)
at java.base/java.util.concurrent.FutureTask.run(FutureTask.java:317)
at java.base/java.util.concurrent.ThreadPoolExecutor.runWorker(ThreadPoolExecutor.java:1144)
at java.base/java.util.concurrent.ThreadPoolExecutor$Worker.run(ThreadPoolExecutor.java:642)
at java.base/java.lang.Thread.run(Thread.java:1583)
]]>
    </failure>
  </testcase> <!-- testLogin -->
  <testcase classname="testCases.TC02_Login" name="testLogin" time="0.029">
    <skipped/>
  </testcase> <!-- testLogin -->
  <testcase classname="testCases.TC02_Login" name="testLogin" time="0.007">
    <skipped/>
  </testcase> <!-- testLogin -->
  <testcase classname="testCases.TC02_Login" name="testLogin" time="0.002">
    <skipped/>
  </testcase> <!-- testLogin -->
  <testcase classname="testCases.TC02_Login" name="testLogin" time="0.027">
    <skipped/>
  </testcase> <!-- testLogin -->
  <testcase classname="testCases.TC02_Login" name="testLogin" time="0.008">
    <skipped/>
  </testcase> <!-- testLogin -->
  <testcase classname="testCases.TC02_Login" name="testLogin" time="0.006">
    <skipped/>
  </testcase> <!-- testLogin -->
  <testcase classname="testCases.TC02_Login" name="testLogin" time="0.038">
    <skipped/>
  </testcase> <!-- testLogin -->
  <testcase classname="testCases.TC02_Login" name="testLogin" time="0.004">
    <skipped/>
  </testcase> <!-- testLogin -->
  <testcase classname="testCases.TC02_Login" name="testLogin" time="0.007">
    <failure message="Unexpected exception during login test execution." type="java.lang.AssertionError">
      <![CDATA[java.lang.AssertionError: Unexpected exception during login test execution.
at org.testng.Assert.fail(Assert.java:111)
at testCases.TC02_Login.testLogin(TC02_Login.java:69)
at java.base/jdk.internal.reflect.DirectMethodHandleAccessor.invoke(DirectMethodHandleAccessor.java:103)
at java.base/java.lang.reflect.Method.invoke(Method.java:580)
at org.testng.internal.invokers.MethodInvocationHelper.invokeMethod(MethodInvocationHelper.java:141)
at org.testng.internal.invokers.TestInvoker.invokeMethod(TestInvoker.java:687)
at org.testng.internal.invokers.TestInvoker.retryFailed(TestInvoker.java:269)
at org.testng.internal.invokers.MethodRunner.runInSequence(MethodRunner.java:76)
at org.testng.internal.invokers.TestInvoker$MethodInvocationAgent.invoke(TestInvoker.java:995)
at org.testng.internal.invokers.TestInvoker.invokeTestMethods(TestInvoker.java:203)
at org.testng.internal.invokers.TestMethodWorker.invokeTestMethods(TestMethodWorker.java:154)
at org.testng.internal.invokers.TestMethodWorker.run(TestMethodWorker.java:134)
at java.base/java.util.ArrayList.forEach(ArrayList.java:1596)
at org.testng.TestRunner.privateRun(TestRunner.java:741)
at org.testng.TestRunner.run(TestRunner.java:616)
at org.testng.SuiteRunner.runTest(SuiteRunner.java:421)
at org.testng.SuiteRunner$SuiteWorker.run(SuiteRunner.java:463)
at org.testng.internal.thread.ThreadUtil.lambda$execute$0(ThreadUtil.java:64)
at java.base/java.util.concurrent.FutureTask.run(FutureTask.java:317)
at java.base/java.util.concurrent.ThreadPoolExecutor.runWorker(ThreadPoolExecutor.java:1144)
at java.base/java.util.concurrent.ThreadPoolExecutor$Worker.run(ThreadPoolExecutor.java:642)
at java.base/java.lang.Thread.run(Thread.java:1583)
]]>
    </failure>
  </testcase> <!-- testLogin -->
  <testcase classname="testCases.TC02_Login" name="testLogin" time="0.002">
    <skipped/>
  </testcase> <!-- testLogin -->
  <testcase classname="testCases.TC02_Login" name="testLogin" time="0.010">
    <failure message="Unexpected exception during login test execution." type="java.lang.AssertionError">
      <![CDATA[java.lang.AssertionError: Unexpected exception during login test execution.
at org.testng.Assert.fail(Assert.java:111)
at testCases.TC02_Login.testLogin(TC02_Login.java:69)
at java.base/jdk.internal.reflect.DirectMethodHandleAccessor.invoke(DirectMethodHandleAccessor.java:103)
at java.base/java.lang.reflect.Method.invoke(Method.java:580)
at org.testng.internal.invokers.MethodInvocationHelper.invokeMethod(MethodInvocationHelper.java:141)
at org.testng.internal.invokers.TestInvoker.invokeMethod(TestInvoker.java:687)
at org.testng.internal.invokers.TestInvoker.retryFailed(TestInvoker.java:269)
at org.testng.internal.invokers.MethodRunner.runInSequence(MethodRunner.java:76)
at org.testng.internal.invokers.TestInvoker$MethodInvocationAgent.invoke(TestInvoker.java:995)
at org.testng.internal.invokers.TestInvoker.invokeTestMethods(TestInvoker.java:203)
at org.testng.internal.invokers.TestMethodWorker.invokeTestMethods(TestMethodWorker.java:154)
at org.testng.internal.invokers.TestMethodWorker.run(TestMethodWorker.java:134)
at java.base/java.util.ArrayList.forEach(ArrayList.java:1596)
at org.testng.TestRunner.privateRun(TestRunner.java:741)
at org.testng.TestRunner.run(TestRunner.java:616)
at org.testng.SuiteRunner.runTest(SuiteRunner.java:421)
at org.testng.SuiteRunner$SuiteWorker.run(SuiteRunner.java:463)
at org.testng.internal.thread.ThreadUtil.lambda$execute$0(ThreadUtil.java:64)
at java.base/java.util.concurrent.FutureTask.run(FutureTask.java:317)
at java.base/java.util.concurrent.ThreadPoolExecutor.runWorker(ThreadPoolExecutor.java:1144)
at java.base/java.util.concurrent.ThreadPoolExecutor$Worker.run(ThreadPoolExecutor.java:642)
at java.base/java.lang.Thread.run(Thread.java:1583)
]]>
    </failure>
  </testcase> <!-- testLogin -->
  <testcase classname="testCases.TC02_Login" name="testLogin" time="0.010">
    <failure message="Unexpected exception during login test execution." type="java.lang.AssertionError">
      <![CDATA[java.lang.AssertionError: Unexpected exception during login test execution.
at org.testng.Assert.fail(Assert.java:111)
at testCases.TC02_Login.testLogin(TC02_Login.java:69)
at java.base/jdk.internal.reflect.DirectMethodHandleAccessor.invoke(DirectMethodHandleAccessor.java:103)
at java.base/java.lang.reflect.Method.invoke(Method.java:580)
at org.testng.internal.invokers.MethodInvocationHelper.invokeMethod(MethodInvocationHelper.java:141)
at org.testng.internal.invokers.TestInvoker.invokeMethod(TestInvoker.java:687)
at org.testng.internal.invokers.TestInvoker.retryFailed(TestInvoker.java:269)
at org.testng.internal.invokers.MethodRunner.runInSequence(MethodRunner.java:76)
at org.testng.internal.invokers.TestInvoker$MethodInvocationAgent.invoke(TestInvoker.java:995)
at org.testng.internal.invokers.TestInvoker.invokeTestMethods(TestInvoker.java:203)
at org.testng.internal.invokers.TestMethodWorker.invokeTestMethods(TestMethodWorker.java:154)
at org.testng.internal.invokers.TestMethodWorker.run(TestMethodWorker.java:134)
at java.base/java.util.ArrayList.forEach(ArrayList.java:1596)
at org.testng.TestRunner.privateRun(TestRunner.java:741)
at org.testng.TestRunner.run(TestRunner.java:616)
at org.testng.SuiteRunner.runTest(SuiteRunner.java:421)
at org.testng.SuiteRunner$SuiteWorker.run(SuiteRunner.java:463)
at org.testng.internal.thread.ThreadUtil.lambda$execute$0(ThreadUtil.java:64)
at java.base/java.util.concurrent.FutureTask.run(FutureTask.java:317)
at java.base/java.util.concurrent.ThreadPoolExecutor.runWorker(ThreadPoolExecutor.java:1144)
at java.base/java.util.concurrent.ThreadPoolExecutor$Worker.run(ThreadPoolExecutor.java:642)
at java.base/java.lang.Thread.run(Thread.java:1583)
]]>
    </failure>
  </testcase> <!-- testLogin -->
  <testcase classname="testCases.TC02_Login" name="testLogin" time="0.005">
    <failure message="Unexpected exception during login test execution." type="java.lang.AssertionError">
      <![CDATA[java.lang.AssertionError: Unexpected exception during login test execution.
at org.testng.Assert.fail(Assert.java:111)
at testCases.TC02_Login.testLogin(TC02_Login.java:69)
at java.base/jdk.internal.reflect.DirectMethodHandleAccessor.invoke(DirectMethodHandleAccessor.java:103)
at java.base/java.lang.reflect.Method.invoke(Method.java:580)
at org.testng.internal.invokers.MethodInvocationHelper.invokeMethod(MethodInvocationHelper.java:141)
at org.testng.internal.invokers.TestInvoker.invokeMethod(TestInvoker.java:687)
at org.testng.internal.invokers.TestInvoker.retryFailed(TestInvoker.java:269)
at org.testng.internal.invokers.MethodRunner.runInSequence(MethodRunner.java:76)
at org.testng.internal.invokers.TestInvoker$MethodInvocationAgent.invoke(TestInvoker.java:995)
at org.testng.internal.invokers.TestInvoker.invokeTestMethods(TestInvoker.java:203)
at org.testng.internal.invokers.TestMethodWorker.invokeTestMethods(TestMethodWorker.java:154)
at org.testng.internal.invokers.TestMethodWorker.run(TestMethodWorker.java:134)
at java.base/java.util.ArrayList.forEach(ArrayList.java:1596)
at org.testng.TestRunner.privateRun(TestRunner.java:741)
at org.testng.TestRunner.run(TestRunner.java:616)
at org.testng.SuiteRunner.runTest(SuiteRunner.java:421)
at org.testng.SuiteRunner$SuiteWorker.run(SuiteRunner.java:463)
at org.testng.internal.thread.ThreadUtil.lambda$execute$0(ThreadUtil.java:64)
at java.base/java.util.concurrent.FutureTask.run(FutureTask.java:317)
at java.base/java.util.concurrent.ThreadPoolExecutor.runWorker(ThreadPoolExecutor.java:1144)
at java.base/java.util.concurrent.ThreadPoolExecutor$Worker.run(ThreadPoolExecutor.java:642)
at java.base/java.lang.Thread.run(Thread.java:1583)
]]>
    </failure>
  </testcase> <!-- testLogin -->
  <testcase classname="testCases.TC02_Login" name="testLogin" time="0.004">
    <failure message="Unexpected exception during login test execution." type="java.lang.AssertionError">
      <![CDATA[java.lang.AssertionError: Unexpected exception during login test execution.
at org.testng.Assert.fail(Assert.java:111)
at testCases.TC02_Login.testLogin(TC02_Login.java:69)
at java.base/jdk.internal.reflect.DirectMethodHandleAccessor.invoke(DirectMethodHandleAccessor.java:103)
at java.base/java.lang.reflect.Method.invoke(Method.java:580)
at org.testng.internal.invokers.MethodInvocationHelper.invokeMethod(MethodInvocationHelper.java:141)
at org.testng.internal.invokers.TestInvoker.invokeMethod(TestInvoker.java:687)
at org.testng.internal.invokers.TestInvoker.retryFailed(TestInvoker.java:269)
at org.testng.internal.invokers.MethodRunner.runInSequence(MethodRunner.java:76)
at org.testng.internal.invokers.TestInvoker$MethodInvocationAgent.invoke(TestInvoker.java:995)
at org.testng.internal.invokers.TestInvoker.invokeTestMethods(TestInvoker.java:203)
at org.testng.internal.invokers.TestMethodWorker.invokeTestMethods(TestMethodWorker.java:154)
at org.testng.internal.invokers.TestMethodWorker.run(TestMethodWorker.java:134)
at java.base/java.util.ArrayList.forEach(ArrayList.java:1596)
at org.testng.TestRunner.privateRun(TestRunner.java:741)
at org.testng.TestRunner.run(TestRunner.java:616)
at org.testng.SuiteRunner.runTest(SuiteRunner.java:421)
at org.testng.SuiteRunner$SuiteWorker.run(SuiteRunner.java:463)
at org.testng.internal.thread.ThreadUtil.lambda$execute$0(ThreadUtil.java:64)
at java.base/java.util.concurrent.FutureTask.run(FutureTask.java:317)
at java.base/java.util.concurrent.ThreadPoolExecutor.runWorker(ThreadPoolExecutor.java:1144)
at java.base/java.util.concurrent.ThreadPoolExecutor$Worker.run(ThreadPoolExecutor.java:642)
at java.base/java.lang.Thread.run(Thread.java:1583)
]]>
    </failure>
  </testcase> <!-- testLogin -->
  <testcase classname="testCases.TC02_Login" name="testLogin" time="0.029">
    <skipped/>
  </testcase> <!-- testLogin -->
  <testcase classname="testCases.TC02_Login" name="testLogin" time="0.004">
    <skipped/>
  </testcase> <!-- testLogin -->
  <testcase classname="testCases.TC02_Login" name="testLogin" time="0.003">
    <skipped/>
  </testcase> <!-- testLogin -->
  <testcase classname="testCases.TC02_Login" name="testLogin" time="0.027">
    <skipped/>
  </testcase> <!-- testLogin -->
  <testcase classname="testCases.TC02_Login" name="testLogin" time="0.008">
    <skipped/>
  </testcase> <!-- testLogin -->
  <testcase classname="testCases.TC02_Login" name="testLogin" time="0.001">
    <failure message="Unexpected exception during login test execution." type="java.lang.AssertionError">
      <![CDATA[java.lang.AssertionError: Unexpected exception during login test execution.
at org.testng.Assert.fail(Assert.java:111)
at testCases.TC02_Login.testLogin(TC02_Login.java:69)
at java.base/jdk.internal.reflect.DirectMethodHandleAccessor.invoke(DirectMethodHandleAccessor.java:103)
at java.base/java.lang.reflect.Method.invoke(Method.java:580)
at org.testng.internal.invokers.MethodInvocationHelper.invokeMethod(MethodInvocationHelper.java:141)
at org.testng.internal.invokers.TestInvoker.invokeMethod(TestInvoker.java:687)
at org.testng.internal.invokers.TestInvoker.retryFailed(TestInvoker.java:269)
at org.testng.internal.invokers.MethodRunner.runInSequence(MethodRunner.java:76)
at org.testng.internal.invokers.TestInvoker$MethodInvocationAgent.invoke(TestInvoker.java:995)
at org.testng.internal.invokers.TestInvoker.invokeTestMethods(TestInvoker.java:203)
at org.testng.internal.invokers.TestMethodWorker.invokeTestMethods(TestMethodWorker.java:154)
at org.testng.internal.invokers.TestMethodWorker.run(TestMethodWorker.java:134)
at java.base/java.util.ArrayList.forEach(ArrayList.java:1596)
at org.testng.TestRunner.privateRun(TestRunner.java:741)
at org.testng.TestRunner.run(TestRunner.java:616)
at org.testng.SuiteRunner.runTest(SuiteRunner.java:421)
at org.testng.SuiteRunner$SuiteWorker.run(SuiteRunner.java:463)
at org.testng.internal.thread.ThreadUtil.lambda$execute$0(ThreadUtil.java:64)
at java.base/java.util.concurrent.FutureTask.run(FutureTask.java:317)
at java.base/java.util.concurrent.ThreadPoolExecutor.runWorker(ThreadPoolExecutor.java:1144)
at java.base/java.util.concurrent.ThreadPoolExecutor$Worker.run(ThreadPoolExecutor.java:642)
at java.base/java.lang.Thread.run(Thread.java:1583)
]]>
    </failure>
  </testcase> <!-- testLogin -->
  <testcase classname="testCases.TC02_Login" name="testLogin" time="0.008">
    <skipped/>
  </testcase> <!-- testLogin -->
  <testcase classname="testCases.TC02_Login" name="testLogin" time="0.022">
    <failure message="Unexpected exception during login test execution." type="java.lang.AssertionError">
      <![CDATA[java.lang.AssertionError: Unexpected exception during login test execution.
at org.testng.Assert.fail(Assert.java:111)
at testCases.TC02_Login.testLogin(TC02_Login.java:69)
at java.base/jdk.internal.reflect.DirectMethodHandleAccessor.invoke(DirectMethodHandleAccessor.java:103)
at java.base/java.lang.reflect.Method.invoke(Method.java:580)
at org.testng.internal.invokers.MethodInvocationHelper.invokeMethod(MethodInvocationHelper.java:141)
at org.testng.internal.invokers.TestInvoker.invokeMethod(TestInvoker.java:687)
at org.testng.internal.invokers.TestInvoker.retryFailed(TestInvoker.java:269)
at org.testng.internal.invokers.MethodRunner.runInSequence(MethodRunner.java:76)
at org.testng.internal.invokers.TestInvoker$MethodInvocationAgent.invoke(TestInvoker.java:995)
at org.testng.internal.invokers.TestInvoker.invokeTestMethods(TestInvoker.java:203)
at org.testng.internal.invokers.TestMethodWorker.invokeTestMethods(TestMethodWorker.java:154)
at org.testng.internal.invokers.TestMethodWorker.run(TestMethodWorker.java:134)
at java.base/java.util.ArrayList.forEach(ArrayList.java:1596)
at org.testng.TestRunner.privateRun(TestRunner.java:741)
at org.testng.TestRunner.run(TestRunner.java:616)
at org.testng.SuiteRunner.runTest(SuiteRunner.java:421)
at org.testng.SuiteRunner$SuiteWorker.run(SuiteRunner.java:463)
at org.testng.internal.thread.ThreadUtil.lambda$execute$0(ThreadUtil.java:64)
at java.base/java.util.concurrent.FutureTask.run(FutureTask.java:317)
at java.base/java.util.concurrent.ThreadPoolExecutor.runWorker(ThreadPoolExecutor.java:1144)
at java.base/java.util.concurrent.ThreadPoolExecutor$Worker.run(ThreadPoolExecutor.java:642)
at java.base/java.lang.Thread.run(Thread.java:1583)
]]>
    </failure>
  </testcase> <!-- testLogin -->
  <testcase classname="testCases.TC02_Login" name="testLogin" time="0.001">
    <skipped/>
  </testcase> <!-- testLogin -->
  <testcase classname="testCases.TC02_Login" name="testLogin" time="0.001">
    <skipped/>
  </testcase> <!-- testLogin -->
  <testcase classname="testCases.TC02_Login" name="testLogin" time="0.001">
    <failure message="Unexpected exception during login test execution." type="java.lang.AssertionError">
      <![CDATA[java.lang.AssertionError: Unexpected exception during login test execution.
at org.testng.Assert.fail(Assert.java:111)
at testCases.TC02_Login.testLogin(TC02_Login.java:69)
at java.base/jdk.internal.reflect.DirectMethodHandleAccessor.invoke(DirectMethodHandleAccessor.java:103)
at java.base/java.lang.reflect.Method.invoke(Method.java:580)
at org.testng.internal.invokers.MethodInvocationHelper.invokeMethod(MethodInvocationHelper.java:141)
at org.testng.internal.invokers.TestInvoker.invokeMethod(TestInvoker.java:687)
at org.testng.internal.invokers.TestInvoker.retryFailed(TestInvoker.java:269)
at org.testng.internal.invokers.MethodRunner.runInSequence(MethodRunner.java:76)
at org.testng.internal.invokers.TestInvoker$MethodInvocationAgent.invoke(TestInvoker.java:995)
at org.testng.internal.invokers.TestInvoker.invokeTestMethods(TestInvoker.java:203)
at org.testng.internal.invokers.TestMethodWorker.invokeTestMethods(TestMethodWorker.java:154)
at org.testng.internal.invokers.TestMethodWorker.run(TestMethodWorker.java:134)
at java.base/java.util.ArrayList.forEach(ArrayList.java:1596)
at org.testng.TestRunner.privateRun(TestRunner.java:741)
at org.testng.TestRunner.run(TestRunner.java:616)
at org.testng.SuiteRunner.runTest(SuiteRunner.java:421)
at org.testng.SuiteRunner$SuiteWorker.run(SuiteRunner.java:463)
at org.testng.internal.thread.ThreadUtil.lambda$execute$0(ThreadUtil.java:64)
at java.base/java.util.concurrent.FutureTask.run(FutureTask.java:317)
at java.base/java.util.concurrent.ThreadPoolExecutor.runWorker(ThreadPoolExecutor.java:1144)
at java.base/java.util.concurrent.ThreadPoolExecutor$Worker.run(ThreadPoolExecutor.java:642)
at java.base/java.lang.Thread.run(Thread.java:1583)
]]>
    </failure>
  </testcase> <!-- testLogin -->
  <testcase classname="testCases.TC02_Login" name="testLogin" time="0.026">
    <failure message="Unexpected exception during login test execution." type="java.lang.AssertionError">
      <![CDATA[java.lang.AssertionError: Unexpected exception during login test execution.
at org.testng.Assert.fail(Assert.java:111)
at testCases.TC02_Login.testLogin(TC02_Login.java:69)
at java.base/jdk.internal.reflect.DirectMethodHandleAccessor.invoke(DirectMethodHandleAccessor.java:103)
at java.base/java.lang.reflect.Method.invoke(Method.java:580)
at org.testng.internal.invokers.MethodInvocationHelper.invokeMethod(MethodInvocationHelper.java:141)
at org.testng.internal.invokers.TestInvoker.invokeMethod(TestInvoker.java:687)
at org.testng.internal.invokers.TestInvoker.retryFailed(TestInvoker.java:269)
at org.testng.internal.invokers.MethodRunner.runInSequence(MethodRunner.java:76)
at org.testng.internal.invokers.TestInvoker$MethodInvocationAgent.invoke(TestInvoker.java:995)
at org.testng.internal.invokers.TestInvoker.invokeTestMethods(TestInvoker.java:203)
at org.testng.internal.invokers.TestMethodWorker.invokeTestMethods(TestMethodWorker.java:154)
at org.testng.internal.invokers.TestMethodWorker.run(TestMethodWorker.java:134)
at java.base/java.util.ArrayList.forEach(ArrayList.java:1596)
at org.testng.TestRunner.privateRun(TestRunner.java:741)
at org.testng.TestRunner.run(TestRunner.java:616)
at org.testng.SuiteRunner.runTest(SuiteRunner.java:421)
at org.testng.SuiteRunner$SuiteWorker.run(SuiteRunner.java:463)
at org.testng.internal.thread.ThreadUtil.lambda$execute$0(ThreadUtil.java:64)
at java.base/java.util.concurrent.FutureTask.run(FutureTask.java:317)
at java.base/java.util.concurrent.ThreadPoolExecutor.runWorker(ThreadPoolExecutor.java:1144)
at java.base/java.util.concurrent.ThreadPoolExecutor$Worker.run(ThreadPoolExecutor.java:642)
at java.base/java.lang.Thread.run(Thread.java:1583)
]]>
    </failure>
  </testcase> <!-- testLogin -->
  <testcase classname="testCases.TC02_Login" name="testLogin" time="0.008">
    <skipped/>
  </testcase> <!-- testLogin -->
  <testcase classname="testCases.TC02_Login" name="testLogin" time="0.008">
    <skipped/>
  </testcase> <!-- testLogin -->
</testsuite> <!-- testCases.TC02_Login -->
